Workbook

Sheet 2023レビュー
A1: 【R5 さっぽろテレビ塔ビアガーデン振り返り】
A2: ①売上 | I2: 単位：円 | J2: 平均気温 | L2: ①コメント
A3: 月 | B3: 実績 | C3: 予算 | D3: 予算比 | E3: 差異 | F3: 予測 | G3: 予測比 | H3: 差異 | I3: 1日平均売上 | J3: LOW | K3: HIGH | L3: 売上については左記の通り、対予算123.9％にて終了いたしました。コロナ禍前の2019年と比較しても対比125.4％（+22,223千円）の結果となりました。これまで1億円の大台に達したことはなかったということです。その大きな要因としてはスタッフの頑張りはもちろんですが、やはり史上稀に見る猛暑となったことが挙げられます。特に6月と8月は気象庁の観測史上最高値を記録し、7月においても史上2番目の平均気温となりました。ただ、天候要因については影響値として一定の条件下で記録していかなければならないもので、いかにこの天候要因を限定的にできるか？というのが引き続きの課題となります。※各月に天候要因を数値化したものを載せています。次年度へ向け今年度のデータを活かし、テーブル配置・スタッフアサインメント・予約システム再構築・RPA/DX 促進・メニューラインナップの見直し等により、さらにポテンシャルを引き出し売上を積み上げられると認識しています。
A4: 5 | B4: 1795227.3 | C4: 6890000 | D4: =B4/C4 -> 0.26055548 | E4: =B4-C4 -> -5094772.7 | F4: 1963000 | G4: =B4/F4 -> 0.91453249 | H4: =B4-F4 -> -167772.73 | I4: =B4/T4 -> 359045.45 | T4: 5
A5: 6 | B5: 19049727 | C5: 25440000 | D5: =B5/C5 -> 0.74881003 | E5: =B5-C5 -> -6390272.7 | F5: 17338000 | G5: =B5/F5 -> 1.0987269 | H5: =B5-F5 -> 1711727.3 | I5: =B5/T5 -> 634990.91 | J5: 12.7℃ | K5: 20.0℃ | T5: 30
A6: 7 | B6: 44856909 | C6: 25440000 | D6: =B6/C6 -> 1.7632433 | E6: =B6-C6 -> 19416909 | F6: 35016000 | G6: =B6/F6 -> 1.2810404 | H6: =B6-F6 -> 9840909.1 | I6: =B6/T6 -> 1446997.1 | J6: 15.6℃ | K6: 24.1℃ | T6: 31
A7: 8 | B7: 44863045 | C7: 25440000 | D7: =B7/C7 -> 1.7634845 | E7: =B7-C7 -> 19423045 | F7: 39760000 | G7: =B7/F7 -> 1.1283462 | H7: =B7-F7 -> 5103045.5 | I7: =B7/T7 -> 1447195 | J7: 21.0℃ | K7: 27.8℃ | T7: 31
A8: 9 | B8: 4058727.3 | C8: 9275000 | D8: =B8/C8 -> 0.43759863 | E8: =B8-C8 -> -5216272.7 | F8: 4300000 | G8: =B8/F8 -> 0.94389006 | H8: =B8-F8 -> -241272.73 | I8: =B8/T8 -> 1352909.1 | J8: 24.0℃ | K8: 30.9℃ | T8: 3
A9: TOTAL | B9: =SUM(B4:B8) -> 1.1462364e+08 | C9: =SUM(C4:C8) -> 92485000 | D9: =B9/C9 -> 1.2393754 | E9: =B9-C9 -> 22138636 | F9: =SUM(F4:F8) -> 98377000 | G9: =B9/F9 -> 1.1651467 | H9: =B9-F9 -> 16246636 | I9: =B9/T9 -> 1146236.4 | J9: 21.4℃ | K9: 28.6℃ | T9: 100
A11: ②客数 | I11: 単位：名 | L11: ②コメント
A12: 月 | B12: 実績 | C12: 予算 | D12: 予算比 | E12: 差異 | F12: 予測 | G12: 予測比 | H12: 差異 | I12: 1日平均 | L12: 入客実績は左記の通りです。7/21（金）から8/16（土）の間で開催された大通りビアガーデン期間中も1日平均405名の入客となり、客数減少懸念は杞憂となりました。過去開催の数値によると盆明けは下降線を辿るはずでしたが、①にもある通り観測史上最高の平均気温となったことやチケットの駆け込み利用もあり、勢いを保ったまま最終日まで賑わいが続きました。シーズン設定をして6月末までは20:30クローズ、7月1日〜は21:30クローズとしたことは大きな成果に繋がったと考えています。7/22（土）が717名の来場とピーク、また、この週（7月第4週・通期では第9週）が最大の売上・入客となりました。次年度は予約システムをさらに活用し、入客を引き上げたいと考えています。
A13: 5 | B13: 506 | C13: 1300 | D13: =B13/C13 -> 0.38923077 | E13: =B13-C13 -> -794 | F13: 395 | G13: =B13/F13 -> 1.2810127 | H13: =B13-F13 -> 111 | I13: =B13/T13 -> 101.2 | T13: 5
A14: 6 | B14: 5309 | C14: 4800 | D14: =B14/C14 -> 1.1060417 | E14: =B14-C14 -> 509 | F14: 3450 | G14: =B14/F14 -> 1.5388406 | H14: =B14-F14 -> 1859 | I14: =B14/T14 -> 176.96667 | T14: 30
A15: 7 | B15: 11036 | C15: 4800 | D15: =B15/C15 -> 2.2991667 | E15: =B15-C15 -> 6236 | F15: 7050 | G15: =B15/F15 -> 1.5653901 | H15: =B15-F15 -> 3986 | I15: =B15/T15 -> 356 | T15: 31
A16: 8 | B16: 11093 | C16: 4800 | D16: =B16/C16 -> 2.3110417 | E16: =B16-C16 -> 6293 | F16: 8100 | G16: =B16/F16 -> 1.3695062 | H16: =B16-F16 -> 2993 | I16: =B16/T16 -> 357.83871 | T16: 31
A17: 9 | B17: 974 | C17: 1750 | D17: =B17/C17 -> 0.55657143 | E17: =B17-C17 -> -776 | F17: 880 | G17: =B17/F17 -> 1.1068182 | H17: =B17-F17 -> 94 | I17: =B17/T17 -> 324.66667 | T17: 3
A18: TOTAL | B18: =SUM(B13:B17) -> 28918 | C18: =SUM(C13:C17) -> 17450 | D18: =B18/C18 -> 1.657192 | E18: =B18-C18 -> 11468 | F18: =SUM(F13:F17) -> 19875 | G18: =B18/F18 -> 1.4549937 | H18: =B18-F18 -> 9043 | I18: =B18/T18 -> 289.18 | T18: 100
A20: ③-1 客単価 | I20: 単位：円 | L20: ③コメント
A21: 月 | B21: 実績 | C21: 予算 | D21: 予算比 | E21: 差異 | F21: 予測 | G21: 予測比 | H21: 差異 | L21: 通期での客単価は3,964円にて着地いたしました。予算設定時点では80%がプラン利用を想定しての数値でしたので、予算値からはマイナスとなっています。最終的にプラン利用率は53.6%となり、アラカルト（単品）利用率を上回りました。左記データから読み取れるのは、とてもシンプルですが、パッサージュ（フリー入客）利用率が高いと客単価が下がるという事実と、予約数を高めることにより客単価が伸びるという事実です。このことから、次年度は今回25％程であった予約利用率を35％程度まで引き上げることで、いわゆる「値上げ」の必要がなく、客単価と入客の天秤関係を限定的にしながら、【入客を高めつつ客単価も引き上げることができる】という伸び代を確認することができました。また今回はテーブルチェックを導入し、専用LPと紐付けして予約受注を行ったことにより、約83%の方がWebから予約をしてくださいました。これまでの開催は全て電話予約で対応し紙台帳管理をしていたという課題を、予約システム導入によって解決できた大きな成果と認められます。現地オペレーションとの連携を高めていけば、まだまだこうしたシステムを活かすことができます。今年度実績を基にし、人員発注と人員配置、予約システムの強みをさらに引き出しての予約受注強化（相性が良いと見られるLINE/L-STEPの活用など）や、天候要件の影響値を最小化（※悪天候時でも当日キャンセルは2割に満たない）していくことで、次年度は客席拡大、スタッフ増員に強気で臨むことができます。設備を含めて改善しつつ、さらに客単価を10％程度引き上げることで、売上も今年度の1日平均114万円から130万円（合計1億3,000万円）までは伸ばすことができると確信しています。
A22: 5 | B22: =B4/B13 -> 3547.88 | C22: 5300 | D22: =B22/C22 -> 0.66941132 | E22: =B22-C22 -> -1752.12 | F22: 4970 | G22: =B22/F22 -> 0.71385915 | H22: =B22-F22 -> -1422.12
A23: 6 | B23: =B5/B14 -> 3588.195 | C23: 5300 | D23: =B23/C23 -> 0.67701793 | E23: =B23-C23 -> -1711.805 | F23: 5026 | G23: =B23/F23 -> 0.71392658 | H23: =B23-F23 -> -1437.805
A24: 7 | B24: =B6/B15 -> 4064.5985 | C24: 5300 | D24: =B24/C24 -> 0.76690538 | E24: =B24-C24 -> -1235.4015 | F24: 4967 | G24: =B24/F24 -> 0.81832062 | H24: =B24-F24 -> -902.4015
A25: 8 | B25: =B7/B16 -> 4044.2662 | C25: 5300 | D25: =B25/C25 -> 0.7630691 | E25: =B25-C25 -> -1255.7338 | F25: 4909 | G25: =B25/F25 -> 0.82384727 | H25: =B25-F25 -> -864.73376
A26: 9 | B26: =B8/B17 -> 4167.0711 | C26: 5300 | D26: =B26/C26 -> 0.78623983 | E26: =B26-C26 -> -1132.9289 | F26: 4886 | G26: =B26/F26 -> 0.85285942 | H26: =B26-F26 -> -718.92888
A27: TOTAL | B27: =B9/B18 -> 3963.747 | C27: =C9/C18 -> 5300 | D27: =B27/C27 -> 0.7478768 | E27: =B27-C27 -> -1336.253 | F27: =F9/F18 -> 4949.7862 | G27: =B27/F27 -> 0.80079157 | H27: =B27-F27 -> -986.03914
A29: ③-2 プラン出卓数と月別プラン利用率
A30: 月 | B30: 客数 | C30: 5,500プラン | D30: 利用率 | E30: 6,600プラン | F30: 利用率 | G30: 8,800プラン | H30: 利用率 | I30: 小計
A31: 5 | B31: 506 | C31: 205 | D31: =C31/B31 -> 0.40513834 | E31: 7 | F31: =E31/B31 -> 0.013833992 | G31: 2 | H31: =G31/B31 -> 0.0039525692 | I31: =C31+E31+G31 -> 214
A32: 6 | B32: 5309 | C32: 2074 | D32: =C32/B32 -> 0.39065737 | E32: 80 | F32: =E32/B32 -> 0.015068751 | G32: 9 | H32: =G32/B32 -> 0.0016952345 | I32: =C32+E32+G32 -> 2163
A33: 7 | B33: 11036 | C33: 5792 | D33: =C33/B33 -> 0.52482784 | E33: 190 | F33: =E33/B33 -> 0.017216383 | G33: 161 | H33: =G33/B33 -> 0.014588619 | I33: =C33+E33+G33 -> 6143
A34: 8 | B34: 11093 | C34: 5149 | D34: =C34/B34 -> 0.46416659 | E34: 271 | F34: =E34/B34 -> 0.024429821 | G34: 77 | H34: =G34/B34 -> 0.0069413143 | I34: =C34+E34+G34 -> 5497
A35: 9 | B35: 974 | C35: 314 | D35: =C35/B35 -> 0.32238193 | E35: 34 | F35: =E35/B35 -> 0.034907598 | G35: 9 | H35: =G35/B35 -> 0.0092402464 | I35: =C35+E35+G35 -> 357
A36: TOTAL | B36: =SUM(B31:B35) -> 28918 | C36: =SUM(C31:C35) -> 13534 | D36: =C36/B36 -> 0.468013 | E36: =SUM(E31:E35) -> 582 | F36: =E36/B36 -> 0.020125873 | G36: =SUM(G31:G35) -> 258 | H36: =G36/B36 -> 0.0089217788 | I36: =C36+E36+G36 -> 14374
A37: 月 | B37: 客数 | C37: チケットプラン | D37: 利用率 | E37: プラン合計 | F37: 利用率 | G37: アラカルト利用 | H37: 利用率
A38: 5 | B38: 506 | C38: 0 | D38: =C38/B38 -> 0 | E38: =C38+I31 -> 214 | F38: =E38/B38 -> 0.4229249 | G38: =B38-E38 -> 292 | H38: =G38/B38 -> 0.5770751 | L38: ④memo
A39: 6 | B39: 5309 | C39: 0 | D39: =C39/B39 -> 0 | E39: =C39+I32 -> 2163 | F39: =E39/B39 -> 0.40742136 | G39: =B39-E39 -> 3146 | H39: =G39/B39 -> 0.59257864 | L39: 設備・備品課題※情報共有前 ◆英字メニュー ◆テーブル番号札（視認性・会計） ◆会計カード（プラスチック札）の作成 ◆会計の仕方がわからない ◆キャッシュレス決済が行えることの告知 ◆エクスキューズ（場内案内・トイレ・会計方法など） ◆飲み放題と単品オーダーの判別がつきづらい ◆床清掃の定期スケジュールと不定期実施のオペレーション ◆ワインの利用方法と場所 ◆ワインコーナーにローズマリーのプランター設置 ◆イベント開催 ◆キャッシャー増設検討 ◆ジョッキのサイズ ◆グラス洗浄マシンとの相性 ◆鍋洗い機（高圧洗浄機）の複数洗浄機導入 ◆Wi-Fi環境 ◆問い合わせ専用電話の設置
A40: 7 | B40: 11036 | C40: 107 | D40: =C40/B40 -> 0.0096955419 | E40: =C40+I33 -> 6250 | F40: =E40/B40 -> 0.56632838 | G40: =B40-E40 -> 4786 | H40: =G40/B40 -> 0.43367162
A41: 8 | B41: 11093 | C41: 765 | D41: =C41/B41 -> 0.068962409 | E41: =C41+I34 -> 6262 | F41: =E41/B41 -> 0.56450014 | G41: =B41-E41 -> 4831 | H41: =G41/B41 -> 0.43549986
A42: 9 | B42: 974 | C42: 240 | D42: =C42/B42 -> 0.24640657 | E42: =C42+I35 -> 597 | F42: =E42/B42 -> 0.61293634 | G42: =B42-E42 -> 377 | H42: =G42/B42 -> 0.38706366
A43: TOTAL | B43: =SUM(B38:B42) -> 28918 | C43: =SUM(C38:C42) -> 1112 | D43: =C43/B43 -> 0.038453558 | E43: =SUM(E38:E42) -> 15486 | F43: =E43/B43 -> 0.53551421 | G43: =SUM(G38:G42) -> 13432 | H43: =G43/B43 -> 0.46448579
...

Sheet 2024レビュー
A1: 【R6 さっぽろテレビ塔ビアガーデン（ピコレワインガーデン）振り返り】
A2: ①売上 | I2: 単位：円 | J2: 平均気温 | L2: ①コメント
A3: 月 | B3: 実績 | C3: 予算 | D3: 予算比 | E3: 差異 | F3: 予測 | G3: 予測比 | H3: 差異 | I3: 1日平均売上 | J3: LOW | K3: HIGH | V3: BG営業天候指数 | Y3: 2024 | Z3: 平均気温 | AB3: 2023 | AC3: 平均気温 | AE3: 差異 | AF3: 平均気温
A4: 4 | B4: 499227 | C4: 260000 | D4: =B4/C4 -> 1.9201038 | E4: =B4-C4 -> 239227 | F4: 260000 | G4: =B4/F4 -> 1.9201038 | H4: =B4-F4 -> 239227 | I4: =B4/T4 -> 124806.75 | T4: 4 | U4: 月 | V4: 2024 | W4: 2023 | Y4: 月 | Z4: LOW | AA4: HIGH | AB4: 月 | AC4: LOW | AD4: HIGH | AE4: 月 | AF4: LOW | AG4: HIGH | AJ4: 2024 | AK4: 期 間 | AL4: 日 数 | AM4: 売 上 | AN4: 客 数 | AO4: 客単価 | AP4: 2023 | AQ4: 期 間 | AR4: 日 数 | AS4: 売 上 | AT4: 客 数 | AU4: 客単価 | AV4: 売 上 前 年 比 | AX4: 客 数 前 年 比 | AZ4: 客 単 価 前 年 比
A5: 5 | B5: 2919145 | C5: 1851200 | D5: =B5/C5 -> 1.5768934 | E5: =B5-C5 -> 1067945 | F5: 1851200 | G5: =B5/F5 -> 1.5768934 | H5: =B5-F5 -> 1067945 | I5: =B5/T5 -> 121631.04 | J5: 11.6℃ | K5: 17.0℃ | T5: 24 | U5: 4 | V5: 1.33 | W5: 2.1 | X5: =V5/W5 -> 0.63333333 | Y5: 4 | AB5: 4 | AE5: 4 | AF5: =Z5-AC5 -> 0 | AG5: =AA5-AD5 -> 0 | AJ5: 4~5 | AK5: PC 4/27-5/19 | AL5: 23 | AM5: 2939522 | AN5: 2348 | AO5: =AM5/AN5 -> 1251.9259 | AP5: 4~5 | AQ5: PC営業なし | AR5: 0 | AS5: 0 | AT5: 0 | AU5: =AS5/AT5 -> #DIV/0! | AV5: =AM5-AS5 -> 2939522 | AW5: =AM5/AS5 -> #DIV/0! | AX5: =AN5-AT5 -> 2348 | AY5: =AN5/AT5 -> #DIV/0! | AZ5: =AO5-AU5 -> #DIV/0! | BA5: =AO5/AU5 -> #DIV/0!
A6: 6 | B6: 19194436 | C6: 25690000 | D6: =B6/C6 -> 0.74715594 | E6: =B6-C6 -> -6495564 | F6: 22000000 | G6: =B6/F6 -> 0.87247436 | H6: =B6-F6 -> -2805564 | I6: =B6/T6 -> 639814.53 | J6: 15.6℃ | K6: 23.9℃ | T6: 30 | U6: 5 | V6: 2.78 | W6: 3.37 | X6: =V6/W6 -> 0.82492582 | Y6: 5 | Z6: 11.6 | AA6: 17 | AB6: 5 | AC6: 12.7 | AD6: 20 | AE6: 5 | AF6: =Z6-AC6 -> -1.1 | AG6: =AA6-AD6 -> -3 | AJ6: 5 | AK6: BG 5/27-5/31 | AL6: 5 | AM6: 477807 | AN6: 133 | AO6: =AM6/AN6 -> 3592.5338 | AP6: 5 | AQ6: BG 5/27-5/31 | AR6: 5 | AS6: 1795227.3 | AT6: 506 | AU6: =AS6/AT6 -> 3547.88 | AV6: =AM6-AS6 -> -1317420.3 | AW6: =AM6/AS6 -> 0.26615404 | AX6: =AN6-AT6 -> -373 | AY6: =AN6/AT6 -> 0.26284585 | AZ6: =AO6-AU6 -> 44.653849 | BA6: =AO6/AU6 -> 1.0125861
A7: 7 | B7: 47613345 | C7: 51610000 | D7: =B7/C7 -> 0.92256045 | E7: =B7-C7 -> -3996655 | F7: 50000000 | G7: =B7/F7 -> 0.9522669 | H7: =B7-F7 -> -2386655 | I7: =B7/T7 -> 1535914.4 | J7: 20.5℃ | K7: 28.0℃ | T7: 31 | U7: 6 | V7: 3.19 | W7: 3.49 | X7: =V7/W7 -> 0.91404011 | Y7: 6 | Z7: 15.6 | AA7: 23.9 | AB7: 6 | AC7: 15.6 | AD7: 24.1 | AE7: 6 | AF7: =Z7-AC7 -> 0 | AG7: =AA7-AD7 -> -0.2 | AJ7: 6 | AK7: BG フル営業 | AL7: 30 | AM7: 19170665 | AN7: 5174 | AO7: =AM7/AN7 -> 3705.1923 | AP7: 6 | AQ7: BG フル営業 | AR7: 30 | AS7: 19049727 | AT7: 5309 | AU7: =AS7/AT7 -> 3588.195 | AV7: =AM7-AS7 -> 120937.73 | AW7: =AM7/AS7 -> 1.0063485 | AX7: =AN7-AT7 -> -135 | AY7: =AN7/AT7 -> 0.97457148 | AZ7: =AO7-AU7 -> 116.9973 | BA7: =AO7/AU7 -> 1.0326062
A8: 8 | B8: 55874978 | C8: 49500000 | D8: =B8/C8 -> 1.1287874 | E8: =B8-C8 -> 6374978 | F8: 50000000 | G8: =B8/F8 -> 1.1174996 | H8: =B8-F8 -> 5874978 | I8: =B8/T8 -> 1802418.6 | J8: 22.0℃ | K8: 28.4℃ | T8: 31 | U8: 7 | V8: 3.04 | W8: 3.39 | X8: =V8/W8 -> 0.89675516 | Y8: 7 | Z8: 20.5 | AA8: 28 | AB8: 7 | AC8: 21 | AD8: 27.8 | AE8: 7 | AF8: =Z8-AC8 -> -0.5 | AG8: =AA8-AD8 -> 0.2 | AJ8: 7 | AK8: BG フル営業 | AL8: 31 | AM8: 47598067 | AN8: 11438 | AO8: =AM8/AN8 -> 4161.3977 | AP8: 7 | AQ8: BG フル営業 | AR8: 31 | AS8: 44856909 | AT8: 11036 | AU8: =AS8/AT8 -> 4064.5985 | AV8: =AM8-AS8 -> 2741157.9 | AW8: =AM8/AS8 -> 1.0611089 | AX8: =AN8-AT8 -> 402 | AY8: =AN8/AT8 -> 1.0364262 | AZ8: =AO8-AU8 -> 96.799205 | BA8: =AO8/AU8 -> 1.0238152
A9: 9 | B9: 12350827 | C9: 7000000 | D9: =B9/C9 -> 1.7644039 | E9: =B9-C9 -> 5350827 | F9: 8000000 | G9: =B9/F9 -> 1.5438534 | H9: =B9-F9 -> 4350827 | I9: =B9/T9 -> 494033.08 | J9: 15.6℃ | K9: 24.0℃ | T9: 25 | U9: 8 | V9: 3.55 | W9: 3.44 | X9: =V9/W9 -> 1.0319767 | Y9: 8 | Z9: 22 | AA9: 28.4 | AB9: 8 | AC9: 24 | AD9: 30.9 | AE9: 8 | AF9: =Z9-AC9 -> -2 | AG9: =AA9-AD9 -> -2.5 | AJ9: 8 | AK9: BG フル営業 | AL9: 31 | AM9: 55870570 | AN9: 13891 | AO9: =AM9/AN9 -> 4022.0697 | AP9: 8 | AQ9: BG フル営業 | AR9: 31 | AS9: 44860591 | AT9: 11093 | AU9: =AS9/AT9 -> 4044.045 | AV9: =AM9-AS9 -> 11009979 | AW9: =AM9/AS9 -> 1.2454265 | AX9: =AN9-AT9 -> 2798 | AY9: =AN9/AT9 -> 1.2522311 | AZ9: =AO9-AU9 -> -21.97529 | BA9: =AO9/AU9 -> 0.99456601
A10: 10 | B10: 1454318 | C10: 455000 | D10: =B10/C10 -> 3.1963033 | E10: =B10-C10 -> 999318 | F10: 692727 | G10: =B10/F10 -> 2.09941 | H10: =B10-F10 -> 761591 | I10: =B10/T10 -> 242386.33 | J10: 13.7℃ | K10: 20.7℃ | T10: 6 | U10: 9 | V10: 2.72 | W10: - | X10: =V10/W10 -> #VALUE! | Y10: 9 | Z10: 15.6 | AA10: 24 | AB10: 9 | AC10: 21.4 | AD10: 28.6 | AE10: 9 | AF10: =Z10-AC10 -> -5.8 | AG10: =AA10-AD10 -> -4.6 | AJ10: 9 | AK10: BG 9/1-9/8 | AL10: 8 | AM10: 8816632 | AN10: 2410 | AO10: =AM10/AN10 -> 3658.3535 | AP10: 9 | AQ10: BG 9/1-9/3 | AR10: 8 | AS10: 4058727.3 | AT10: =263+385+76 -> 724 | AU10: =AS10/AT10 -> 5605.9769 | AV10: =AM10-AS10 -> 4757904.7 | AW10: =AM10/AS10 -> 2.1722652 | AX10: =AN10-AT10 -> 1686 | AY10: =AN10/AT10 -> 3.3287293 | AZ10: =AO10-AU10 -> -1947.6234 | BA10: =AO10/AU10 -> 0.65258091
A11: TOTAL | B11: =SUM(B4:B10) -> 139906276 | C11: =SUM(C4:C10) -> 136366200 | D11: =B11/C11 -> 1.0259601 | E11: =B11-C11 -> 3540076 | F11: =SUM(F4:F10) -> 132803927 | G11: =B11/F11 -> 1.05348 | H11: =B11-F11 -> 7102349 | I11: =B11/T11 -> 926531.63 | T11: =SUM(T4:T10) -> 151 | U11: 10 | V11: =SUM(V5:V10)/6 -> 2.7683333 | W11: =SUM(W5:W10)/5 -> 3.158 | X11: =V11/W11 -> 0.87660967 | Y11: 10 | Z11: 13.7 | AA11: 20.7 | AB11: 10 | AE11: 10 | AF11: =Z11-AC11 -> 13.7 | AG11: =AA11-AD11 -> 20.7 | AJ11: 9~10 | AK11: PC-BG 秋営業 9/14-10/6 | AL11: 23 | AM11: 4982837 | AN11: 1704 | AO11: =AM11/AN11 -> 2924.2001 | AP11: 9~10 | AQ11: PC 9/9-10/1 | AR11: 23 | AS11: 1489815.5 | AT11: 1365 | AU11: =AS11/AT11 -> 1091.4399 | AV11: =AM11-AS11 -> 3493021.5 | AW11: =AM11/AS11 -> 3.3446002 | AX11: =AN11-AT11 -> 339 | AY11: =AN11/AT11 -> 1.2483516 | AZ11: =AO11-AU11 -> 1832.7602 | BA11: =AO11/AU11 -> 2.6792132
AJ12: ビアガのみ105日 | AL12: =AL7+AL6+AL8+AL9+AL10 -> 105 | AM12: =AM7+AM6+AM8+AM9+AM10 -> 131933741 | AN12: =AN7+AN6+AN8+AN9+AN10 -> 33046 | AO12: =AM12/AN12 -> 3992.427 | AP12: ビアガのみ105日 | AR12: =AR7+AR6+AR8+AR9+AR10 -> 105 | AS12: =AS7+AS6+AS8+AS9+AS10 -> 1.1462118e+08 | AT12: =AT7+AT6+AT8+AT9+AT10 -> 28668 | AU12: =AS12/AT12 -> 3998.2274 | AV12: =AM12-AS12 -> 17312559 | AW12: =AM12/AS12 -> 1.1510415 | AX12: =AN12-AT12 -> 4378 | AY12: =AN12/AT12 -> 1.1527138 | AZ12: =AO12-AU12 -> -5.8004049 | BA12: =AO12/AU12 -> 0.99854926
A13: ②客数 | I13: 単位：名 | L13: ②コメント | V13: =V11-W11 -> -0.38966667 | AJ13: ピコレ&ピコレ共催 | AL13: =AL5+AL11 -> 46 | AM13: =AM5+AM11 -> 7922359 | AN13: =AN5+AN11 -> 4052 | AO13: =AM13/AN13 -> 1955.1725 | AP13: ピコレ&ピコレ共催 | AR13: =AR5+AR11 -> 23 | AS13: =AS5+AS11 -> 1489815.5 | AT13: =AT5+AT11 -> 1365 | AU13: =AS13/AT13 -> 1091.4399 | AV13: =AM13-AS13 -> 6432543.5 | AW13: =AM13/AS13 -> 5.3176781 | AX13: =AN13-AT13 -> 2687 | AY13: =AN13/AT13 -> 2.9684982 | AZ13: =AO13-AU13 -> 863.73261 | BA13: =AO13/AU13 -> 1.7913698
A14: 月 | B14: 実績 | C14: 予算 | D14: 予算比 | E14: 差異 | F14: 予測 | G14: 予測比 | H14: 差異 | I14: 1日平均 | V14: 2369 | AJ14: 総合計 | AL14: =SUM(AL5:AL11) -> 151 | AM14: =SUM(AM5:AM11) -> 139856100 | AN14: =SUM(AN5:AN11) -> 37098 | AO14: =AM14/AN14 -> 3769.9094 | AP14: 総合計 | AR14: =SUM(AR5:AR11) -> 128 | AS14: =SUM(AS5:AS11) -> 1.16111e+08 | AT14: =SUM(AT5:AT11) -> 30033 | AU14: =AS14/AT14 -> 3866.1139 | AV14: =AM14-AS14 -> 23745103 | AW14: =AM14/AS14 -> 1.2045035 | AX14: =AN14-AT14 -> 7065 | AY14: =AN14/AT14 -> 1.2352412 | AZ14: =AO14-AU14 -> -96.204421 | BA14: =AO14/AU14 -> 0.97511599
A15: 4 | B15: 379 | C15: 200 | D15: =B15/C15 -> 1.895 | E15: =B15-C15 -> 179 | F15: 395 | G15: =B15/F15 -> 0.95949367 | H15: =B15-F15 -> -16 | I15: =B15/T15 -> 75.8 | T15: 5
A16: 5 | B16: =133+1236+223+278+120 -> 1990 | C16: 520 | D16: =B16/C16 -> 3.8269231 | E16: =B16-C16 -> 1470 | F16: 372 | G16: =B16/F16 -> 5.3494624 | H16: =B16-F16 -> 1618 | I16: =B16/T16 -> #DIV/0! | V16: 133
A17: 6 | B17: 5174 | C17: 7000 | D17: =B17/C17 -> 0.73914286 | E17: =B17-C17 -> -1826 | F17: 5558 | G17: =B17/F17 -> 0.9309104 | H17: =B17-F17 -> -384 | I17: =B17/T17 -> 172.46667 | T17: 30 | V17: =V14-V16 -> 2236
A18: 7 | B18: 11438 | C18: 13000 | D18: =B18/C18 -> 0.87984615 | E18: =B18-C18 -> -1562 | F18: 12016 | G18: =B18/F18 -> 0.95189747 | H18: =B18-F18 -> -578 | I18: =B18/T18 -> 368.96774 | T18: 31
A19: 8 | B19: 13891 | C19: 12500 | D19: =B19/C19 -> 1.11128 | E19: =B19-C19 -> 1391 | F19: 12386 | G19: =B19/F19 -> 1.1215082 | H19: =B19-F19 -> 1505 | I19: =B19/T19 -> 448.09677 | T19: 31
A20: 9 | B20: 3458 | C20: 2000 | D20: =B20/C20 -> 1.729 | E20: =B20-C20 -> 1458 | F20: 1976 | G20: =B20/F20 -> 1.75 | H20: =B20-F20 -> 1482 | I20: =B20/T20 -> #DIV/0!
A21: 10 | B21: 538 | C21: 350 | D21: =B21/C21 -> 1.5371429 | E21: =B21-C21 -> 188 | F21: 194 | G21: =B21/F21 -> 2.7731959 | H21: =B21-F21 -> 344 | I21: =B21/T21 -> 179.33333 | T21: 3
A22: TOTAL | B22: =SUM(B15:B21) -> 36868 | C22: =SUM(C15:C21) -> 35570 | D22: =B22/C22 -> 1.0364914 | E22: =B22-C22 -> 1298 | F22: =SUM(F15:F21) -> 32897 | G22: =B22/F22 -> 1.1207101 | H22: =B22-F22 -> 3971 | I22: =B22/T22 -> 368.68 | T22: 100
A24: ③-1 客単価 | I24: 単位：円 | L24: ③コメント
A25: 月 | B25: 実績 | C25: 予算 | D25: 予算比 | E25: 差異 | F25: 予測 | G25: 予測比 | H25: 差異
A26: 4 | B26: =B4/B15 -> 1317.2216 | C26: 1300 | D26: =B26/C26 -> 1.0132474 | E26: =B26-C26 -> 17.221636 | F26: =F4/F15 -> 658.22785 | G26: =B26/F26 -> 2.0011636 | H26: =B26-F26 -> 658.99379
A27: 5 | B27: =B5/B16 -> 1466.907 | C27: 3500 | D27: =B27/C27 -> 0.4191163 | E27: =B27-C27 -> -2033.093 | F27: =F5/F16 -> 4976.3441 | G27: =B27/F27 -> 0.29477605 | H27: =B27-F27 -> -3509.4371
A28: 6 | B28: =B6/B17 -> 3709.7866 | C28: 3600 | D28: =B28/C28 -> 1.0304963 | E28: =B28-C28 -> 109.78663 | F28: =F6/F17 -> 3958.2584 | G28: =B28/F28 -> 0.937227 | H28: =B28-F28 -> -248.47174
A29: 7 | B29: =B7/B18 -> 4162.7334 | C29: 3900 | D29: =B29/C29 -> 1.0673675 | E29: =B29-C29 -> 262.73343 | F29: =F7/F18 -> 4161.1185 | G29: =B29/F29 -> 1.0003881 | H29: =B29-F29 -> 1.6149238
A30: 8 | B30: =B8/B19 -> 4022.387 | C30: 3900 | D30: =B30/C30 -> 1.0313813 | E30: =B30-C30 -> 122.38701 | F30: =F8/F19 -> 4036.8158 | G30: =B30/F30 -> 0.99642571 | H30: =B30-F30 -> -14.428747
A31: 9 | B31: =B9/B20 -> 3571.6677 | C31: 3500 | D31: =B31/C31 -> 1.0204765 | E31: =B31-C31 -> 71.667727 | F31: =F9/F20 -> 4048.583 | G31: =B31/F31 -> 0.88220193 | H31: =B31-F31 -> -476.91527
A32: 10 | B32: =B10/B21 -> 2703.1933 | C32: 1300 | D32: =B32/C32 -> 2.0793795 | E32: =B32-C32 -> 1403.1933 | F32: =F10/F21 -> 3570.7577 | G32: =B32/F32 -> 0.75703632 | H32: =B32-F32 -> -867.56442
A33: TOTAL | B33: =B11/B22 -> 3794.7889 | C33: =C11/C22 -> 3833.7419 | D33: =B33/C33 -> 0.98983942 | E33: =B33-C33 -> -38.953049 | F33: =F11/F22 -> 4036.9616 | G33: =B33/F33 -> 0.94001113 | H33: =B33-F33 -> -242.17277
A35: ③-2 プラン出卓数と月別プラン利用率
A36: 月 | B36: 客数 | C36: 5,500プラン | D36: 利用率 | E36: 6,600プラン | F36: 利用率 | G36: 8,800プラン | H36: 利用率 | I36: 小計
A37: 4 | B37: 379 | C37: 0 | D37: =C37/B37 -> 0 | E37: 0 | F37: =E37/B37 -> 0 | G37: 0 | H37: =G37/B37 -> 0 | I37: =C37+E37+G37 -> 0
A38: 5 | B38: =133+1236+223+278+120 -> 1990 | C38: 59 | D38: =C38/B38 -> 0.029648241 | E38: 0 | F38: =E38/B38 -> 0 | G38: 4 | H38: =G38/B38 -> 0.0020100503 | I38: =C38+E38+G38 -> 63
A39: 6 | B39: 5174 | C39: 2281 | D39: =C39/B39 -> 0.44085814 | E39: 58 | F39: =E39/B39 -> 0.011209896 | G39: 17 | H39: =G39/B39 -> 0.0032856591 | I39: =C39+E39+G39 -> 2356
A40: 7 | B40: 11438 | C40: 5791 | D40: =C40/B40 -> 0.50629481 | E40: 226 | F40: =E40/B40 -> 0.019758699 | G40: 167 | H40: =G40/B40 -> 0.014600455 | I40: =C40+E40+G40 -> 6184
A41: 8 | B41: 13891 | C41: 6305 | D41: =C41/B41 -> 0.45389101 | E41: 397 | F41: =E41/B41 -> 0.028579656 | G41: 140 | H41: =G41/B41 -> 0.010078468 | I41: =C41+E41+G41 -> 6842
A42: 9 | B42: 3458 | C42: 863 | D42: =C42/B42 -> 0.24956622 | E42: 37 | F42: =E42/B42 -> 0.010699826 | G42: 2 | H42: =G42/B42 -> 0.000578369 | I42: =C42+E42+G42 -> 902
...

Sheet 2023通期実績
A1: ■R5年さっぽろテレビ塔ビアガーデン売上計画（予算）・売上予測・実績進捗確認表
B2: 計画値 | E2: 予測値 | K2: 実績進捗（派遣分のみ） | R2: ノヴェロさん請求内容 | Y2: 家賃 | AA2: 概算（仮置き）
A3: 月 | B3: 売上予算 | C3: 客数 | D3: 客単価 | E3: 労働時間（予測値） | F3: 人時生産性 | G3: 想定人件費 | H3: 人件費率 | I3: 売上予測 | J3: 対予算 | K3: 売上実績 | L3: 対予測 | M3: 対予算 | N3: 実労働時間 | O3: 人時生産性 | P3: 概算人件費率 | Q3: 派遣人件費（リザルト） | R3: 人件費 | S3: 営業日数 | T3: 拘束時間 | U3: 残業時間 | V3: 人件費合計 | W3: 交通費合計 | X3: 合計 | Y3: 家賃 | Z3: 1日 | AA3: =K9 -> 1.1462364e+08
A4: 5 | B4: 6890000 | C4: 1300 | D4: =B4/C4 -> 5300 | E4: 310 | F4: =I4/E4 -> 6332.2581 | G4: =E4*R4 -> 526437.81 | H4: =G4/B4 -> 0.076406068 | I4: 1963000 | J4: =I4/B4 -> 0.28490566 | K4: 1795227.3 | L4: =K4/I4 -> 0.91453249 | M4: =K4/B4 -> 0.26055548 | N4: =T4+U4 -> 488 | O4: =K4/N4 -> 3678.7444 | P4: =Q4/K4 -> 0.46162122 | Q4: =X4 -> 828715 | R4: =Q4/N4 -> 1698.1865 | S4: 5 | T4: 479.5 | U4: 8.5 | V4: 759715 | W4: 69000 | X4: =V4+W4 -> 828715 | Y4: 150000 | Z4: 30000 | AA4: =AA3*23.8% -> 27280425 | AB4: 人件費
A5: 6 | B5: 25440000 | C5: 4800 | D5: =B5/C5 -> 5300 | E5: 3555 | F5: =I5/E5 -> 4877.0745 | G5: =E5*R5 -> 6025477.3 | H5: =G5/B5 -> 0.23685052 | I5: 17338000 | J5: =I5/B5 -> 0.68152516 | K5: 19049727 | L5: =K5/I5 -> 1.0987269 | M5: =K5/B5 -> 0.74881003 | N5: =2946+32.5 -> 2978.5 | O5: =K5/N5 -> 6395.7453 | P5: =Q5/K5 -> 0.26500904 | Q5: =X5 -> 5048350 | R5: =Q5/N5 -> 1694.9303 | S5: 30 | T5: 2946 | U5: 32.5 | V5: 4629350 | W5: 419000 | X5: =V5+W5 -> 5048350 | Y5: 2250000 | Z5: 75000 | AA5: =AA3*31.5% -> 36106445 | AB5: 材料費
A6: 7 | B6: 25440000 | C6: 4800 | D6: =B6/C6 -> 5300 | E6: 4940 | F6: =I6/E6 -> 7088.2591 | G6: =E6*R6 -> 8385722.9 | H6: =G6/B6 -> 0.32962747 | I6: 35016000 | J6: =I6/B6 -> 1.3764151 | K6: 44856909 | L6: =K6/I6 -> 1.2810404 | M6: =K6/B6 -> 1.7632433 | N6: =4281.75+241.75 -> 4523.5 | O6: =K6/N6 -> 9916.4163 | P6: =Q6/K6 -> 0.17118228 | Q6: =X6 -> 7678708 | R6: =Q6/N6 -> 1697.5148 | S6: 31 | T6: 4281.75 | U6: 241.75 | V6: 7105708 | W6: 573000 | X6: =V6+W6 -> 7678708 | Y6: 3100000 | Z6: 100000 | AA6: =AA3*7% -> 8023654.5 | AB6: 消耗品費
A7: 8 | B7: 25440000 | C7: 4800 | D7: =B7/C7 -> 5300 | E7: 5080 | F7: =I7/E7 -> 7826.7717 | G7: =E7*R7 -> 9144000 | H7: =G7/B7 -> 0.35943396 | I7: 39760000 | J7: =I7/B7 -> 1.5628931 | K7: 44863045 | L7: =K7/I7 -> 1.1283462 | M7: =K7/B7 -> 1.7634845 | N7: =T7+U7 -> 4935.5 | O7: =K7/N7 -> 9089.8684 | P7: =Q7/K7 -> 0.20105169 | Q7: =X7 -> 9019791 | R7: 1800 | S7: 31 | T7: 4717.25 | U7: 218.25 | V7: 8392791 | W7: 627000 | X7: =V7+W7 -> 9019791 | Y7: 3100000 | Z7: 100000 | AA7: =AA3*15% -> 17193545 | AB7: イニシャル
A8: 9 | B8: 9275000 | C8: 1750 | D8: =B8/C8 -> 5300 | E8: 510 | F8: =I8/E8 -> 8431.3725 | G8: =E8*R8 -> 950482.65 | H8: =G8/B8 -> 0.10247791 | I8: 4300000 | J8: =I8/B8 -> 0.46361186 | K8: 4058727.3 | L8: =K8/I8 -> 0.94389006 | M8: =K8/B8 -> 0.43759863 | N8: =T8+U8 -> 551 | O8: =K8/N8 -> 7366.1112 | P8: =Q8/K8 -> 0.25300887 | Q8: =X8 -> 1026894 | R8: =Q8/N8 -> 1863.6915 | S8: 3 | T8: 506 | U8: 45 | V8: 958894 | W8: 68000 | X8: =V8+W8 -> 1026894 | Y8: 90000 | Z8: 30000 | AA8: =Y9 -> 8690000 | AB8: 家賃
A9: TOTAL | B9: =SUM(B4:B8) -> 92485000 | C9: =SUM(C4:C8) -> 17450 | D9: =B9/C9 -> 5300 | E9: =SUM(E4:E8) -> 14395 | F9: =I9/E9 -> 6834.1091 | G9: =E9*R9 -> 25211100 | H9: =G9/B9 -> 0.27259663 | I9: =SUM(I4:I8) -> 98377000 | J9: =I9/B9 -> 1.0637076 | K9: =SUM(K4:K8) -> 1.1462364e+08 | L9: =K9/I9 -> 1.1651467 | M9: =K9/B9 -> 1.2393754 | N9: =SUM(N4:N8) -> 13476.5 | O9: =K9/N9 -> 8505.4455 | P9: =Q9/K9 -> 0.20591266 | Q9: =SUM(Q4:Q8) -> 23602458 | R9: =Q9/N9 -> 1751.3789 | S9: =SUM(S4:S8) -> 100 | T9: =SUM(T4:T8) -> 12930.5 | U9: =SUM(U4:U8) -> 546 | V9: =SUM(V4:V8) -> 21846458 | W9: =SUM(W4:W8) -> 1756000 | X9: =SUM(X4:X8) -> 23602458 | Y9: =SUM(Y4:Y8) -> 8690000 | Z9: =SUM(Z4:Z8) -> 335000 | AA9: =AA3*5% -> 5731181.8 | AB9: 流動固定費
B10: 92485000 | C10: 提出予算 | G10: ※ノヴェロ派遣分のみ算出 | I10: ※天気要因見込まず算出 | K10: 43710 | L10: 終了時点の進捗状況 | N10: =K9/S10 -> 1146236.4 | O10: =K9-B10 -> 22138636 | P10: =K9/B10 -> 1.2393754 | S10: 100 | X10: =X9/K9 -> 0.20591266 | AA10: =AA3-AA4-AA5-AA6-AA7-AA8-AA9 -> 11598384 | AB10: 利益
B11: =B9-B10 -> 0 | C11: 差異 | D11: ※予算値は115日計算でP/D（1日平均）804千円にて積み上げ。予測は100日営業、各施策と季節波動を効かせて算出。
I14: 100000000 | J14: 予算まで | K14: =B9-K9 -> -22138636 | L14: 12 | M14: =K14/L14 -> -1844886.4 | N14: 2019 | O14: 58190982 | P14: =K9/O14 -> 1.9697835
I15: 111111111 | J15: 予測まで | K15: =I9-K9 -> -16246636 | L15: 12 | M15: =K15/L15 -> -1353886.4 | N15: 2018 | O15: 44179221 | P15: =K9/O15 -> 2.5945147
J16: 一億円まで | K16: =I14-K9 -> -14623636 | L16: 12 | M16: =K16/L16 -> -1218636.4 | N16: 平均 | O16: =(O14+O15)/2 -> 51185102 | P16: =K9/O16 -> 2.2393945
G17: 2019年度 | J17: 一億一千万まで | K17: =I15-K9 -> -3512525.4 | L17: 12 | M17: =K17/L17 -> -292710.45
G18: 91399704 | H18: =K6-K7 -> -6136.3636 | I18: 945247 | J18: =I18-H18 -> 951383.36 | K18: =K9 -> 1.1462364e+08 | L18: =K18/G18 -> 1.254092 | M18: =K18-G18 -> 23223932
F19: 0.13 | G19: =G18*0.13 -> 11881962
L25: 5187 | M25: 6717 | N25: =M25-L25 -> 1530 | O25: =M25/L25 -> 1.2949682
L26: 992 | M26: 1941 | N26: =M26-L26 -> 949 | O26: =M26/L26 -> 1.9566532
L27: 318 | M27: 2503 | N27: =M27-L27 -> 2185 | O27: =M27/L27 -> 7.8710692
L28: =SUM(L25:L27) -> 6497 | M28: =SUM(M25:M27) -> 11161 | N28: =SUM(N25:N27) -> 4664 | O28: =M28/L28 -> 1.7178698

Sheet 24-23天候指数対比
B1: ◆2024-2023 天候指数対比
B2: 4月 天候指数対比 <気象庁資料マクロクリマ> | F2: 平均気温 最高 15.7℃ （13.5℃）最低 6.5℃（5.5℃） カッコ内は前年値 <M-4th> | P2: 8月 天候指数対比 <現地ミクロクリマ> | T2: 平均気温 最高 28.4℃ （30.9℃）最低 22.0℃（24.0℃） カッコ内は前年値 <M-1st>
B3: 天候状況 | E3: ポイント | F3: 2024日数＊3 | G3: 2024合計 | H3: 比率 | I3: 2023日数＊3 | J3: 2023合計 | K3: 比率 | L3: 前年差異 | P3: 天候状況 | S3: ポイント | T3: 2024日数＊3 | U3: 2024合計 | V3: 比率 | W3: 2023日数＊3 | X3: 2023合計 | Y3: 比率 | Z3: 前年差異
B4: ポジティブ | C4: 晴れ（33度まで） | E4: 5 | F4: 0 | G4: =E4*F4 -> 0 | H4: =(F4+F5+F6)/F10 -> #DIV/0! | I4: 0 | J4: =E4*I4 -> 0 | K4: =(I4+I5+I6)/I10 -> #DIV/0! | L4: =F4-I4 -> 0 | M4: =G4-J4 -> 0 | N4: =H4-K4 -> #DIV/0! | P4: ポジティブ | Q4: 晴れ（33度まで） | S4: 5 | T4: 27 | U4: =S4*T4 -> 135 | V4: =(T4+T5+T6)/T10 -> 0.69892473 | W4: 31 | X4: =S4*W4 -> 155 | Y4: =(W4+W5+W6)/W10 -> 0.82795699 | Z4: =T4-W4 -> -4 | AA4: =U4-X4 -> -20 | AB4: =V4-Y4 -> -0.12903226
C5: 晴れ（25度以下） | E5: 4 | F5: 0 | G5: =E5*F5 -> 0 | I5: 0 | J5: =E5*I5 -> 0 | L5: =F5-I5 -> 0 | M5: =G5-J5 -> 0 | Q5: 晴れ（25度以下） | S5: 4 | T5: 0 | U5: =S5*T5 -> 0 | W5: 6 | X5: =S5*W5 -> 24 | Z5: =T5-W5 -> -6 | AA5: =U5-X5 -> -24
C6: 晴れ（33度以上15以下） 曇25度以上 | E6: 3 | F6: 0 | G6: =E6*F6 -> 0 | I6: 0 | J6: =E6*I6 -> 0 | L6: =F6-I6 -> 0 | M6: =G6-J6 -> 0 | Q6: 晴れ（33度以上15以下） 曇25度以上 | S6: 3 | T6: 38 | U6: =S6*T6 -> 114 | W6: 40 | X6: =S6*W6 -> 120 | Z6: =T6-W6 -> -2 | AA6: =U6-X6 -> -6
B7: ネガティブ | C7: 曇 | E7: 2 | F7: 0 | G7: =E7*F7 -> 0 | H7: =(F7+F8+F9)/F10 -> #DIV/0! | I7: 0 | J7: =E7*I7 -> 0 | K7: =(I7+I8+I9)/I10 -> #DIV/0! | L7: =F7-I7 -> 0 | M7: =G7-J7 -> 0 | N7: =H7-K7 -> #DIV/0! | P7: ネガティブ | Q7: 曇 | S7: 2 | T7: 6 | U7: =S7*T7 -> 12 | V7: =(T7+T8+T9)/T10 -> 0.30107527 | W7: 0 | X7: =S7*W7 -> 0 | Y7: =(W7+W8+W9)/W10 -> 0.17204301 | Z7: =T7-W7 -> 6 | AA7: =U7-X7 -> 12 | AB7: =V7-Y7 -> 0.12903226
C8: 雨 | E8: 1 | F8: 0 | G8: =E8*F8 -> 0 | I8: 0 | J8: =E8*I8 -> 0 | L8: =F8-I8 -> 0 | M8: =G8-J8 -> 0 | Q8: 雨 | S8: 1 | T8: 22 | U8: =S8*T8 -> 22 | W8: 16 | X8: =S8*W8 -> 16 | Z8: =T8-W8 -> 6 | AA8: =U8-X8 -> 6
C9: 豪雨・雷雨 | E9: 0 | F9: 0 | G9: =E9*F9 -> 0 | J9: =E9*I9 -> 0 | L9: =F9-I9 -> 0 | M9: =G9-J9 -> 0 | Q9: 豪雨・雷雨 | S9: 0 | T9: 0 | U9: =S9*T9 -> 0 | W9: 0 | X9: =S9*W9 -> 0 | Z9: =T9-W9 -> 0 | AA9: =U9-X9 -> 0
B10: TOTAL | F10: =SUM(F4:F9) -> 0 | G10: =SUM(G4:G9) -> 0 | H10: =H4+H7 -> #DIV/0! | I10: =SUM(I4:I9) -> 0 | J10: =SUM(J4:J9) -> 0 | K10: =K4+K7 -> #DIV/0! | L10: =SUM(L4:L9) -> 0 | M10: =SUM(M4:M9) -> 0 | N10: =G10/J10 -> #DIV/0! | P10: TOTAL | T10: =SUM(T4:T9) -> 93 | U10: =SUM(U4:U9) -> 283 | V10: =V4+V7 -> 1 | W10: =SUM(W4:W9) -> 93 | X10: =SUM(X4:X9) -> 315 | Y10: =Y4+Y7 -> 1 | Z10: =SUM(Z4:Z9) -> 0 | AA10: =SUM(AA4:AA9) -> -32 | AB10: =U10/X10 -> 0.8984127
F11: =G10/F10 -> #DIV/0! | I11: =J10/I10 -> #DIV/0! | L11: =F11-I11 -> #DIV/0! | N11: =F11/I11 -> #DIV/0! | T11: =U10/T10 -> 3.0430108 | W11: =X10/W10 -> 3.3870968 | Z11: =T11-W11 -> -0.34408602 | AB11: =T11/W11 -> 0.8984127
B13: 5月 天候指数対比 <現地ミクロクリマ> | F13: 平均気温 最高 17.0℃ （20.0℃）最低 11.6℃（12.7℃） カッコ内は前年値 <M-4th> | P13: 9月 天候指数対比 <現地ミクロクリマ> | T13: 平均気温 最高 24.0℃ （28.6℃）最低 15.6℃（21.4℃） カッコ内は前年値 <M- 2nd>
B14: 天候状況 | E14: ポイント | F14: 2024日数＊3 | G14: 2024合計 | H14: 比率 | I14: 2023日数＊3 | J14: 2023合計 | K14: 比率 | L14: 前年差異 | P14: 天候状況 | S14: ポイント | T14: 2024日数＊3 | U14: 2024合計 | V14: 比率 | W14: 2023日数＊3 | X14: 2023合計 | Y14: 比率 | Z14: 前年差異
B15: ポジティブ | C15: 晴れ（33度まで） | E15: 5 | F15: 0 | G15: =E15*F15 -> 0 | H15: =(F15+F16+F17)/F21 -> 0.066666667 | I15: 2 | J15: =E15*I15 -> 10 | K15: =(I15+I16+I17)/I21 -> 0.4 | L15: =F15-I15 -> -2 | M15: =G15-J15 -> -10 | N15: =H15-K15 -> -0.33333333 | P15: ポジティブ | Q15: 晴れ（33度まで） | S15: 5 | T15: 16 | U15: =S15*T15 -> 80 | V15: =(T15+T16+T17)/T21 -> 0.74666667 | W15: 5 | X15: =S15*W15 -> 25 | Y15: =(W15+W16+W17)/W21 -> 0.66666667 | Z15: =T15-W15 -> 11 | AA15: =U15-X15 -> 55 | AB15: =V15-Y15 -> 0.08
C16: 晴れ（25度以下） | E16: 4 | F16: 0 | G16: =E16*F16 -> 0 | I16: 4 | J16: =E16*I16 -> 16 | L16: =F16-I16 -> -4 | M16: =G16-J16 -> -16 | Q16: 晴れ（25度以下） | S16: 4 | T16: 32 | U16: =S16*T16 -> 128 | W16: 0 | X16: =S16*W16 -> 0 | Z16: =T16-W16 -> 32 | AA16: =U16-X16 -> 128
C17: 晴れ（33度以上15以下） 曇25度以上 | E17: 3 | F17: 1 | G17: =E17*F17 -> 3 | I17: 0 | J17: =E17*I17 -> 0 | L17: =F17-I17 -> 1 | M17: =G17-J17 -> 3 | Q17: 晴れ（33度以上15以下） 曇25度以上 | S17: 3 | T17: 8 | U17: =S17*T17 -> 24 | W17: 1 | X17: =S17*W17 -> 3 | Z17: =T17-W17 -> 7 | AA17: =U17-X17 -> 21
B18: ネガティブ | C18: 曇 | E18: 2 | F18: 5 | G18: =E18*F18 -> 10 | H18: =(F18+F19+F20)/F21 -> 0.93333333 | I18: 4 | J18: =E18*I18 -> 8 | K18: =(I18+I19+I20)/I21 -> 0.6 | L18: =F18-I18 -> 1 | M18: =G18-J18 -> 2 | N18: =H18-K18 -> 0.33333333 | P18: ネガティブ | Q18: 曇 | S18: 2 | T18: 15 | U18: =S18*T18 -> 30 | V18: =(T18+T19+T20)/T21 -> 0.25333333 | W18: 0 | X18: =S18*W18 -> 0 | Y18: =(W18+W19+W20)/W21 -> 0.33333333 | Z18: =T18-W18 -> 15 | AA18: =U18-X18 -> 30 | AB18: =V18-Y18 -> -0.08
C19: 雨 | E19: 1 | F19: 7 | G19: =E19*F19 -> 7 | I19: 5 | J19: =E19*I19 -> 5 | L19: =F19-I19 -> 2 | M19: =G19-J19 -> 2 | Q19: 雨 | S19: 1 | T19: 4 | U19: =S19*T19 -> 4 | W19: 3 | X19: =S19*W19 -> 3 | Z19: =T19-W19 -> 1 | AA19: =U19-X19 -> 1
C20: 豪雨・雷雨 | E20: 0 | F20: 2 | G20: =E20*F20 -> 0 | J20: =E20*I20 -> 0 | L20: =F20-I20 -> 2 | M20: =G20-J20 -> 0 | Q20: 豪雨・雷雨 | S20: 0 | T20: 0 | U20: =S20*T20 -> 0 | X20: =S20*W20 -> 0 | Z20: =T20-W20 -> 0 | AA20: =U20-X20 -> 0
B21: TOTAL | F21: =SUM(F15:F20) -> 15 | G21: =SUM(G15:G20) -> 20 | H21: =H15+H18 -> 1 | I21: =SUM(I15:I20) -> 15 | J21: =SUM(J15:J20) -> 39 | K21: =K15+K18 -> 1 | L21: =SUM(L15:L20) -> 0 | M21: =SUM(M15:M20) -> -19 | N21: =G21/J21 -> 0.51282051 | P21: TOTAL | T21: =SUM(T15:T20) -> 75 | U21: =SUM(U15:U20) -> 266 | V21: =V15+V18 -> 1 | W21: =SUM(W15:W20) -> 9 | X21: =SUM(X15:X20) -> 31 | Y21: =Y15+Y18 -> 1 | Z21: =SUM(Z15:Z20) -> 66 | AA21: =SUM(AA15:AA20) -> 235 | AB21: =U21/X21 -> 8.5806452
F22: =G21/F21 -> 1.3333333 | I22: =J21/I21 -> 2.6 | L22: =F22-I22 -> -1.2666667 | N22: =F22/I22 -> 0.51282051 | T22: =U21/T21 -> 3.5466667 | W22: =X21/W21 -> 3.4444444 | Z22: =T22-W22 -> 0.10222222 | AB22: =T22/W22 -> 1.0296774
B24: 6月 天候指数対比 <現地ミクロクリマ> | F24: 平均気温 最高 23.9℃ （24.1℃）最低 15.6℃（15.6℃） カッコ内は前年値 <M-3rd> | P24: 10月 天候指数対比 <気象庁資料マクロクリマ> | T24: 平均気温 最高 18.3℃ （17.9℃）最低 9.0℃（9.3℃） カッコ内は前年値 <M-5th>
B25: 天候状況 | E25: ポイント | F25: 2024日数＊3 | G25: 2024合計 | H25: 比率 | I25: 2023日数＊3 | J25: 2023合計 | K25: 比率 | L25: 前年差異 | P25: 天候状況 | S25: ポイント | T25: 2024日数＊3 | U25: 2024合計 | V25: 比率 | W25: 2023日数＊3 | X25: 2023合計 | Y25: 比率 | Z25: 前年差異
B26: ポジティブ | C26: 晴れ（33度まで） | E26: 5 | F26: 13 | G26: =E26*F26 -> 65 | H26: =(F26+F27+F28)/F32 -> 0.48888889 | I26: 20 | J26: =E26*I26 -> 100 | K26: =(I26+I27+I28)/I32 -> 0.71111111 | L26: =F26-I26 -> -7 | M26: =G26-J26 -> -35 | N26: =H26-K26 -> -0.22222222 | P26: ポジティブ | Q26: 晴れ（33度まで） | S26: 5 | T26: 2 | U26: =S26*T26 -> 10 | V26: =(T26+T27+T28)/T32 -> 0.38888889 | W26: 0 | X26: =S26*W26 -> 0 | Y26: =(W26+W27+W28)/W32 -> #DIV/0! | Z26: =T26-W26 -> 2 | AA26: =U26-X26 -> 10 | AB26: =V26-Y26 -> #DIV/0!
C27: 晴れ（25度以下） | E27: 4 | F27: 16 | G27: =E27*F27 -> 64 | I27: 38 | J27: =E27*I27 -> 152 | L27: =F27-I27 -> -22 | M27: =G27-J27 -> -88 | Q27: 晴れ（25度以下） | S27: 4 | T27: 5 | U27: =S27*T27 -> 20 | W27: 0 | X27: =S27*W27 -> 0 | Z27: =T27-W27 -> 5 | AA27: =U27-X27 -> 20
C28: 晴れ（33度以上15以下） 曇25度以上 | E28: 3 | F28: 15 | G28: =E28*F28 -> 45 | I28: 6 | J28: =E28*I28 -> 18 | L28: =F28-I28 -> 9 | M28: =G28-J28 -> 27 | Q28: 晴れ（33度以上15以下） 曇25度以上 | S28: 3 | T28: 0 | U28: =S28*T28 -> 0 | W28: 0 | X28: =S28*W28 -> 0 | Z28: =T28-W28 -> 0 | AA28: =U28-X28 -> 0
B29: ネガティブ | C29: 曇 | E29: 2 | F29: 30 | G29: =E29*F29 -> 60 | H29: =(F29+F30+F31)/F32 -> 0.51111111 | I29: 7 | J29: =E29*I29 -> 14 | K29: =(I29+I30+I31)/I32 -> 0.28888889 | L29: =F29-I29 -> 23 | M29: =G29-J29 -> 46 | N29: =H29-K29 -> 0.22222222 | P29: ネガティブ | Q29: 曇 | S29: 2 | T29: 8 | U29: =S29*T29 -> 16 | V29: =(T29+T30+T31)/T32 -> 0.61111111 | W29: 0 | X29: =S29*W29 -> 0 | Y29: =(W29+W30+W31)/W32 -> #DIV/0! | Z29: =T29-W29 -> 8 | AA29: =U29-X29 -> 16 | AB29: =V29-Y29 -> #DIV/0!
C30: 雨 | E30: 1 | F30: 15 | G30: =E30*F30 -> 15 | I30: 19 | J30: =E30*I30 -> 19 | L30: =F30-I30 -> -4 | M30: =G30-J30 -> -4 | Q30: 雨 | S30: 1 | T30: 3 | U30: =S30*T30 -> 3 | W30: 0 | X30: =S30*W30 -> 0 | Z30: =T30-W30 -> 3 | AA30: =U30-X30 -> 3
C31: 豪雨・雷雨 | E31: 0 | F31: 1 | G31: =E31*F31 -> 0 | I31: 0 | J31: =E31*I31 -> 0 | L31: =F31-I31 -> 1 | M31: =G31-J31 -> 0 | Q31: 豪雨・雷雨 | S31: 0 | T31: 0 | U31: =S31*T31 -> 0 | W31: 0 | X31: =S31*W31 -> 0 | Z31: =T31-W31 -> 0 | AA31: =U31-X31 -> 0
B32: TOTAL | F32: =SUM(F26:F31) -> 90 | G32: =SUM(G26:G31) -> 249 | H32: =H26+H29 -> 1 | I32: =SUM(I26:I31) -> 90 | J32: =SUM(J26:J31) -> 303 | K32: =K26+K29 -> 1 | L32: =SUM(L26:L31) -> 0 | M32: =SUM(M26:M31) -> -54 | N32: =G32/J32 -> 0.82178218 | P32: TOTAL | T32: =SUM(T26:T31) -> 18 | U32: =SUM(U26:U31) -> 49 | V32: =V26+V29 -> 1 | W32: =SUM(W26:W31) -> 0 | X32: =SUM(X26:X31) -> 0 | Y32: =Y26+Y29 -> #DIV/0! | Z32: =SUM(Z26:Z31) -> 18 | AA32: =SUM(AA26:AA31) -> 49 | AB32: =U32/X32 -> #DIV/0!
F33: =G32/F32 -> 2.7666667 | I33: =J32/I32 -> 3.3666667 | L33: =F33-I33 -> -0.6 | N33: =F33/I33 -> 0.82178218 | T33: =U32/T32 -> 2.7222222 | W33: =X32/W32 -> #DIV/0! | Z33: =T33-W33 -> #DIV/0! | AB33: =T33/W33 -> #DIV/0!
B35: 7月 天候指数対比 <現地ミクロクリマ> | F35: 平均気温 最高 28.0℃ （27.8℃）最低 20.5℃（21.0℃） カッコ内は前年値 <M-1st> | P35: TOTAL 天候指数 対比
B36: 天候状況 | E36: ポイント | F36: 2024日数＊3 | G36: 2024合計 | H36: 比率 | I36: 2023日数＊3 | J36: 2023合計 | K36: 比率 | L36: 前年差異 | P36: 天候状況 | S36: ポイント | T36: 2024日数＊3 | U36: 2024合計 | V36: 比率 | W36: 2023日数＊3 | X36: 2023合計 | Y36: 比率 | Z36: 前年差異
B37: ポジティブ | C37: 晴れ（33度まで） | E37: 5 | F37: 26 | G37: =E37*F37 -> 130 | H37: =(F37+F38+F39)/F43 -> 0.74193548 | I37: 35 | J37: =E37*I37 -> 175 | K37: =(I37+I38+I39)/I43 -> 0.79569892 | L37: =F37-I37 -> -9 | M37: =G37-J37 -> -45 | N37: =H37-K37 -> -0.053763441 | P37: ポジティブ | Q37: 晴れ（33度まで） | S37: 5 | T37: =F4+F15+F26+F37+T4+T15+T26 -> 84 | U37: =S37*T37 -> 420 | V37: =(T37+T38+T39)/T43 -> 0.63020833 | W37: =I4+I15+I26+I37+W4+W15+W26 -> 93 | X37: =S37*W37 -> 465 | Y37: =(W37+W38+W39)/W43 -> 0.75666667 | Z37: =T37-W37 -> -9 | AA37: =U37-X37 -> -45 | AB37: =V37-Y37 -> -0.12645833
C38: 晴れ（25度以下） | E38: 4 | F38: 5 | G38: =E38*F38 -> 20 | I38: 10 | J38: =E38*I38 -> 40 | L38: =F38-I38 -> -5 | M38: =G38-J38 -> -20 | Q38: 晴れ（25度以下） | S38: 4 | T38: =F5+F16+F27+F38+T5+T16+T27 -> 58 | U38: =S38*T38 -> 232 | W38: =I5+I16+I27+I38+W5+W16+W27 -> 58 | X38: =S38*W38 -> 232 | Z38: =T38-W38 -> 0 | AA38: =U38-X38 -> 0
C39: 晴れ（33度以上15以下） 曇25度以上 | E39: 3 | F39: 38 | G39: =E39*F39 -> 114 | I39: 29 | J39: =E39*I39 -> 87 | L39: =F39-I39 -> 9 | M39: =G39-J39 -> 27 | Q39: 晴れ（33度以上15以下） 曇25度以上 | S39: 3 | T39: =F6+F17+F28+F39+T6+T17+T28 -> 100 | U39: =S39*T39 -> 300 | W39: =I6+I17+I28+I39+W6+W17+W28 -> 76 | X39: =S39*W39 -> 228 | Z39: =T39-W39 -> 24 | AA39: =U39-X39 -> 72
B40: ネガティブ | C40: 曇 | E40: 2 | F40: 9 | G40: =E40*F40 -> 18 | H40: =(F40+F41+F42)/F43 -> 0.25806452 | I40: 4 | J40: =E40*I40 -> 8 | K40: =(I40+I41+I42)/I43 -> 0.20430108 | L40: =F40-I40 -> 5 | M40: =G40-J40 -> 10 | N40: =H40-K40 -> 0.053763441 | P40: ネガティブ | Q40: 曇 | S40: 2 | T40: =F7+F18+F29+F40+T7+T18+T29 -> 73 | U40: =S40*T40 -> 146 | V40: =(T40+T41+T42)/T43 -> 0.36979167 | W40: =I7+I18+I29+I40+W7+W18+W29 -> 15 | X40: =S40*W40 -> 30 | Y40: =(W40+W41+W42)/W43 -> 0.24333333 | Z40: =T40-W40 -> 58 | AA40: =U40-X40 -> 116 | AB40: =V40-Y40 -> 0.12645833
C41: 雨 | E41: 1 | F41: 15 | G41: =E41*F41 -> 15 | I41: 15 | J41: =E41*I41 -> 15 | L41: =F41-I41 -> 0 | M41: =G41-J41 -> 0 | Q41: 雨 | S41: 1 | T41: =F8+F19+F30+F41+T8+T19+T30 -> 66 | U41: =S41*T41 -> 66 | W41: =I8+I19+I30+I41+W8+W19+W30 -> 58 | X41: =S41*W41 -> 58 | Z41: =T41-W41 -> 8 | AA41: =U41-X41 -> 8
C42: 豪雨・雷雨 | E42: 0 | F42: 0 | G42: =E42*F42 -> 0 | J42: =E42*I42 -> 0 | L42: =F42-I42 -> 0 | M42: =G42-J42 -> 0 | Q42: 豪雨・雷雨 | S42: 0 | T42: =F9+F20+F31+F42+T9+T20+T31 -> 3 | U42: =S42*T42 -> 0 | W42: =I9+I20+I31+I42+W9+W20+W31 -> 0 | X42: =S42*W42 -> 0 | Z42: =T42-W42 -> 3 | AA42: =U42-X42 -> 0
B43: TOTAL | F43: =SUM(F37:F42) -> 93 | G43: =SUM(G37:G42) -> 297 | H43: =H37+H40 -> 1 | I43: =SUM(I37:I42) -> 93 | J43: =SUM(J37:J42) -> 325 | K43: =K37+K40 -> 1 | L43: =SUM(L37:L42) -> 0 | M43: =SUM(M37:M42) -> -28 | N43: =G43/J43 -> 0.91384615 | P43: TOTAL | T43: =SUM(T37:T42) -> 384 | U43: =SUM(U37:U42) -> 1164 | V43: =V37+V40 -> 1 | W43: =SUM(W37:W42) -> 300 | X43: =SUM(X37:X42) -> 1013 | Y43: =Y37+Y40 -> 1 | Z43: =SUM(Z37:Z42) -> 84 | AA43: =SUM(AA37:AA42) -> 151 | AB43: =U43/X43 -> 1.1490622
...

Sheet 24-23期間別KPI対比
B1: 【KPI対比（予算比・前年比）】
B2: 実績 | C2: 営 業 形 態 | D2: 日 数 | E2: 売 上 | F2: 客 数 | G2: 客単価 | H2: 予算 | I2: 予 定 | J2: 日 数 | K2: 売 上 | L2: 客 数 | M2: 客単価 | N2: 売 上 予 算 比 | P2: 客 数 予 算 比 | R2: 客 単 価 予 算 比
B3: 4 | C3: PC | D3: 5 | E3: 499227 | F3: 400 | G3: =E3/F3 -> 1248.0675 | H3: 4 | I3: PC | J3: 5 | K3: 260000 | L3: 200 | M3: =K3/L3 -> 1300 | N3: =E3-K3 -> 239227 | O3: =E3/K3 -> 1.9201038 | P3: =F3-L3 -> 200 | Q3: =F3/L3 -> 2 | R3: =G3-M3 -> -51.9325 | S3: =G3/M3 -> 0.96005192
B4: 5 | C4: PC & BG | D4: 23 | E4: 2919145 | F4: 2102 | G4: =E4/F4 -> 1388.7464 | H4: 5 | I4: PC & BG | J4: 23 | K4: 1853120 | L4: 520 | M4: =K4/L4 -> 3563.6923 | N4: =E4-K4 -> 1066025 | O4: =E4/K4 -> 1.5752596 | P4: =F4-L4 -> 1582 | Q4: =F4/L4 -> 4.0423077 | R4: =G4-M4 -> -2174.9459 | S4: =G4/M4 -> 0.38969314
B5: 6 | C5: BG フル営業 | D5: 30 | E5: 19170665 | F5: 5174 | G5: =E5/F5 -> 3705.1923 | H5: 6 | I5: BG フル営業 | J5: 30 | K5: 25690000 | L5: 7000 | M5: =K5/L5 -> 3670 | N5: =E5-K5 -> -6519335 | O5: =E5/K5 -> 0.74623063 | P5: =F5-L5 -> -1826 | Q5: =F5/L5 -> 0.73914286 | R5: =G5-M5 -> 35.192308 | S5: =G5/M5 -> 1.0095892
B6: 7 | C6: BG フル営業 | D6: 31 | E6: 47598067 | F6: 11438 | G6: =E6/F6 -> 4161.3977 | H6: 7 | I6: BG フル営業 | J6: 31 | K6: 51610000 | L6: 13000 | M6: =K6/L6 -> 3970 | N6: =E6-K6 -> -4011933 | O6: =E6/K6 -> 0.92226443 | P6: =F6-L6 -> -1562 | Q6: =F6/L6 -> 0.87984615 | R6: =G6-M6 -> 191.39771 | S6: =G6/M6 -> 1.048211
B7: 8 | C7: BG フル営業 | D7: 31 | E7: 55870570 | F7: 13891 | G7: =E7/F7 -> 4022.0697 | H7: 8 | I7: BG フル営業 | J7: 31 | K7: 49500000 | L7: 12500 | M7: =K7/L7 -> 3960 | N7: =E7-K7 -> 6370570 | O7: =E7/K7 -> 1.1286984 | P7: =F7-L7 -> 1391 | Q7: =F7/L7 -> 1.11128 | R7: =G7-M7 -> 62.069685 | S7: =G7/M7 -> 1.0156742
B8: 9 | C8: BG & PC | D8: 25 | E8: =12344645-537 -> 12344108 | F8: 3585 | G8: =E8/F8 -> 3443.2658 | H8: 9 | I8: BG & PC | J8: 25 | K8: 7000000 | L8: 2000 | M8: =K8/L8 -> 3500 | N8: =E8-K8 -> 5344108 | O8: =E8/K8 -> 1.763444 | P8: =F8-L8 -> 1585 | Q8: =F8/L8 -> 1.7925 | R8: =G8-M8 -> -56.73417 | S8: =G8/M8 -> 0.98379024
B9: 10 | C9: BG & PC | D9: 6 | E9: 1454318 | F9: 508 | G9: =E9/F9 -> 2862.8307 | H9: 10 | I9: PC | J9: 6 | K9: 455000 | L9: 350 | M9: =K9/L9 -> 1300 | N9: =E9-K9 -> 999318 | O9: =E9/K9 -> 3.1963033 | P9: =F9-L9 -> 158 | Q9: =F9/L9 -> 1.4514286 | R9: =G9-M9 -> 1562.8307 | S9: =G9/M9 -> 2.2021775
B10: 総合計 | D10: =SUM(D3:D9) -> 151 | E10: =SUM(E3:E9) -> 139856100 | F10: =SUM(F3:F9) -> 37098 | G10: =E10/F10 -> 3769.9094 | H10: 総合計 | J10: =SUM(J3:J9) -> 151 | K10: =SUM(K3:K9) -> 136368120 | L10: =SUM(L3:L9) -> 35570 | M10: =K10/L10 -> 3833.7959 | N10: =E10-K10 -> 3487980 | O10: =E10/K10 -> 1.0255777 | P10: =F10-L10 -> 1528 | Q10: =F10/L10 -> 1.0429575 | R10: =G10-M10 -> -63.886466 | S10: =G10/M10 -> 0.98333598
B12: 2024 | C12: 営 業 形 態 | D12: 日 数 | E12: 売 上 | F12: 客 数 | G12: 客単価 | H12: 2023 | I12: 営 業 形 態 | J12: 日 数 | K12: 売 上 | L12: 客 数 | M12: 客単価 | N12: 売 上 前 年 比 | P12: 客 数 前 年 比 | R12: 客 単 価 前 年 比
B13: 4~5 | C13: PC 4/27-5/19 | D13: 23 | E13: 2939522 | F13: 2348 | G13: =E13/F13 -> 1251.9259 | H13: 4~5 | I13: PC営業なし | J13: 0 | K13: 0 | L13: 0 | M13: =K13/L13 -> #DIV/0! | N13: =E13-K13 -> 2939522 | O13: =E13/K13 -> #DIV/0! | P13: =F13-L13 -> 2348 | Q13: =F13/L13 -> #DIV/0! | R13: =G13-M13 -> #DIV/0! | S13: =G13/M13 -> #DIV/0!
B14: 5 | C14: BG 5/27-5/31 | D14: 5 | E14: 477807 | F14: 133 | G14: =E14/F14 -> 3592.5338 | H14: 5 | I14: BG 5/27-5/31 | J14: 5 | K14: 1795227.3 | L14: 506 | M14: =K14/L14 -> 3547.88 | N14: =E14-K14 -> -1317420.3 | O14: =E14/K14 -> 0.26615404 | P14: =F14-L14 -> -373 | Q14: =F14/L14 -> 0.26284585 | R14: =G14-M14 -> 44.653849 | S14: =G14/M14 -> 1.0125861
B15: 6 | C15: BG フル営業 | D15: 30 | E15: 19170665 | F15: 5174 | G15: =E15/F15 -> 3705.1923 | H15: 6 | I15: BG フル営業 | J15: 30 | K15: 19049727 | L15: 5309 | M15: =K15/L15 -> 3588.195 | N15: =E15-K15 -> 120937.73 | O15: =E15/K15 -> 1.0063485 | P15: =F15-L15 -> -135 | Q15: =F15/L15 -> 0.97457148 | R15: =G15-M15 -> 116.9973 | S15: =G15/M15 -> 1.0326062
B16: 7 | C16: BG フル営業 | D16: 31 | E16: 47598067 | F16: 11438 | G16: =E16/F16 -> 4161.3977 | H16: 7 | I16: BG フル営業 | J16: 31 | K16: 44856909 | L16: 11036 | M16: =K16/L16 -> 4064.5985 | N16: =E16-K16 -> 2741157.9 | O16: =E16/K16 -> 1.0611089 | P16: =F16-L16 -> 402 | Q16: =F16/L16 -> 1.0364262 | R16: =G16-M16 -> 96.799205 | S16: =G16/M16 -> 1.0238152
B17: 8 | C17: BG フル営業 | D17: 31 | E17: 55870570 | F17: 13891 | G17: =E17/F17 -> 4022.0697 | H17: 8 | I17: BG フル営業 | J17: 31 | K17: 44860591 | L17: 11093 | M17: =K17/L17 -> 4044.045 | N17: =E17-K17 -> 11009979 | O17: =E17/K17 -> 1.2454265 | P17: =F17-L17 -> 2798 | Q17: =F17/L17 -> 1.2522311 | R17: =G17-M17 -> -21.97529 | S17: =G17/M17 -> 0.99456601
B18: 9 | C18: BG 9/1-9/8 | D18: 8 | E18: 8816632 | F18: 2410 | G18: =E18/F18 -> 3658.3535 | H18: 9 | I18: BG 9/1-9/3 | J18: 3 | K18: 4058727.3 | L18: =263+385+76 -> 724 | M18: =K18/L18 -> 5605.9769 | N18: =E18-K18 -> 4757904.7 | O18: =E18/K18 -> 2.1722652 | P18: =F18-L18 -> 1686 | Q18: =F18/L18 -> 3.3287293 | R18: =G18-M18 -> -1947.6234 | S18: =G18/M18 -> 0.65258091
B19: 9~10 | C19: PC-BG 秋営業 9/14-10/6 | D19: 23 | E19: 4982837 | F19: 1704 | G19: =E19/F19 -> 2924.2001 | H19: 9~10 | I19: PC 9/9-10/1 | J19: 23 | K19: 1489815.5 | L19: 1365 | M19: =K19/L19 -> 1091.4399 | N19: =E19-K19 -> 3493021.5 | O19: =E19/K19 -> 3.3446002 | P19: =F19-L19 -> 339 | Q19: =F19/L19 -> 1.2483516 | R19: =G19-M19 -> 1832.7602 | S19: =G19/M19 -> 2.6792132
B20: ビアガのみ105日 | D20: =D15+D14+D16+D17+D18 -> 105 | E20: =E15+E14+E16+E17+E18 -> 131933741 | F20: =F15+F14+F16+F17+F18 -> 33046 | G20: =E20/F20 -> 3992.427 | H20: ビアガのみ100日 | J20: =J15+J14+J16+J17+J18 -> 100 | K20: =K15+K14+K16+K17+K18 -> 1.1462118e+08 | L20: =L15+L14+L16+L17+L18 -> 28668 | M20: =K20/L20 -> 3998.2274 | N20: =E20-K20 -> 17312559 | O20: =E20/K20 -> 1.1510415 | P20: =F20-L20 -> 4378 | Q20: =F20/L20 -> 1.1527138 | R20: =G20-M20 -> -5.8004049 | S20: =G20/M20 -> 0.99854926
B21: ピコレ&ピコレ共催 | D21: =D13+D19 -> 46 | E21: =E13+E19 -> 7922359 | F21: =F13+F19 -> 4052 | G21: =E21/F21 -> 1955.1725 | H21: ピコレ&ピコレ共催 | J21: =J13+J19 -> 23 | K21: =K13+K19 -> 1489815.5 | L21: =L13+L19 -> 1365 | M21: =K21/L21 -> 1091.4399 | N21: =E21-K21 -> 6432543.5 | O21: =E21/K21 -> 5.3176781 | P21: =F21-L21 -> 2687 | Q21: =F21/L21 -> 2.9684982 | R21: =G21-M21 -> 863.73261 | S21: =G21/M21 -> 1.7913698
B22: 総合計 | D22: =SUM(D13:D19) -> 151 | E22: =SUM(E13:E19) -> 139856100 | F22: =SUM(F13:F19) -> 37098 | G22: =E22/F22 -> 3769.9094 | H22: 総合計 | J22: =SUM(J13:J19) -> 123 | K22: =SUM(K13:K19) -> 1.16111e+08 | L22: =SUM(L13:L19) -> 30033 | M22: =K22/L22 -> 3866.1139 | N22: =E22-K22 -> 23745103 | O22: =E22/K22 -> 1.2045035 | P22: =F22-L22 -> 7065 | Q22: =F22/L22 -> 1.2352412 | R22: =G22-M22 -> -96.204421 | S22: =G22/M22 -> 0.97511599

Sheet 2024計画値・予測・実績進捗
A1: ■R6年 ポップアップ ヒツジニワイン / さっぽろテレビ塔ビアガーデン売上計画（予算）・売上予測（9/8まで）・実績進捗確認表
B2: 計画値 | E2: 予測値（目標値） | K2: 実績進捗（派遣分のみ） | R2: ノヴェロさん請求内容 | Z2: 家賃 | AB2: 概算（仮置き）
A3: 月 | B3: 売上予算 | C3: 客数 | D3: 客単価 | E3: 労働時間（予測値） | F3: 人時生産性 | G3: 想定人件費 | H3: 人件費率 | I3: 売上予測 | J3: 対予算 | K3: 売上実績 | L3: 対予測 | M3: 対予算 | N3: 実労働時間 | O3: 人時生産性 | P3: 概算人件費率 | Q3: 派遣人件費（リザルト） | R3: 人件費 | S3: 営業日数 | T3: 拘束時間 | U3: 残業時間 | V3: 人件費合計 | W3: 交通費合計 | X3: 手当 | Y3: 合計 | Z3: 家賃 | AA3: 1日 | AB3: =K11 -> 1.4045928e+08 | AQ3: =AQ4/AQ5 -> 1.1585148
A4: 4 | B4: 260000 | C4: 200 | D4: =B4/C4 -> 1300 | E4: 200 | F4: =I4/E4 -> 1300 | G4: =E4*R4 -> #DIV/0! | H4: =G4/B4 -> #DIV/0! | I4: 260000 | J4: =I4/B4 -> 1 | K4: 499227 | L4: =K4/I4 -> 1.9201038 | M4: =K4/B4 -> 1.9201038 | N4: =T4+U4 -> 0 | O4: =K4/N4 -> #DIV/0! | P4: =Q4/K4 -> 0 | Q4: =Y4 -> 0 | R4: =Q4/N4 -> #DIV/0! | Y4: =V4+W4 -> 0 | AA4: 30000 | AB4: =AB3*23.8% -> 33429308 | AC4: 人件費 | AD4: 時給＋交通費 | AH4: 499227 | AO4: =AO8*AO6 -> 6865350 | AP4: =AP8*AP6 -> 3664000 | AQ4: =AO4+AP4 -> 10529350
A5: 5 | B5: 1851200 | C5: 520 | D5: =B5/C5 -> 3560 | E5: 550 | F5: =I5/E5 -> 3365.8182 | G5: =E5*R5 -> 991969.37 | H5: =G5/B5 -> 0.53585208 | I5: 1851200 | J5: =I5/B5 -> 1 | K5: 2919145 | L5: =K5/I5 -> 1.5768934 | M5: =K5/B5 -> 1.5768934 | N5: =T5+U5 -> 579.5 | O5: =K5/N5 -> 5037.3512 | P5: =Q5/K5 -> 0.35804148 | Q5: =Y5 -> 1045175 | R5: =Q5/N5 -> 1803.5807 | S5: 5 | T5: 579.5 | U5: 0 | V5: 956175 | W5: 89000 | Y5: =V5+W5+X5 -> 1045175 | AA5: 30000 | AD5: Timee | AF5: Forking | AH5: 2919145 | AO5: =AO7*AO6 -> 7555862.5 | AP5: =AP7*AP6 -> 1532800 | AQ5: =AO5+AP5 -> 9088662.5
A6: 6 | B6: 25690000 | C6: 7000 | D6: =B6/C6 -> 3670 | E6: 4500 | F6: =I6/E6 -> 4888.8889 | G6: =E6*R6 -> 8136786.5 | H6: =G6/B6 -> 0.31672972 | I6: 22000000 | J6: =I6/B6 -> 0.85636434 | K6: ='2024.6月 '!CE93 -> 19747436 | L6: =K6/I6 -> 0.89761074 | M6: =K6/B6 -> 0.76868184 | N6: =T6+U6 -> 3587.5 | O6: =K6/N6 -> 5504.5119 | P6: =Q6/K6 -> 0.32848958 | Q6: =Y6 -> 6486827 | R6: =Q6/N6 -> 1808.1748 | S6: 30 | T6: 3580.5 | U6: 7 | V6: 5939877 | W6: 545000 | X6: 1950 | Y6: =V6+W6+X6 -> 6486827 | AA6: 75000 | AD6: 0 | AE6: 0 | AF6: 250 | AG6: 370861 | AM6: 157 | AO6: 1850 | AP6: 1600
A7: 7 | B7: 51610000 | C7: 13000 | D7: =B7/C7 -> 3970 | E7: 5600 | F7: =I7/E7 -> 8928.5714 | G7: =E7*R7 -> 8405473.9 | H7: =G7/B7 -> 0.16286522 | I7: 50000000 | J7: =I7/B7 -> 0.9688045 | K7: ='2024.7月'!CE93 -> 47613345 | L7: =K7/I7 -> 0.95226691 | M7: =K7/B7 -> 0.92256046 | N7: =T7+AD7+AF7+U7 -> 5074.25 | O7: =K7/N7 -> 9383.3267 | P7: =Q7/K7 -> 0.15996219 | Q7: =Y7 -> 7616335 | R7: =Q7/N7 -> 1500.9775 | S7: 31 | T7: 4084.25 | U7: 32 | V7: 7019597 | W7: 583000 | X7: 13738 | Y7: =V7+W7+X7 -> 7616335 | AA7: 100000 | AB7: =AB3*31.5% -> 44244672 | AC7: 材料費 | AD7: 303 | AE7: 391038 | AF7: 655 | AG7: 976046 | AH7: =AE7+AG7 -> 1367084 | AN7: =AF7+AD7+T7 -> 5042.25 | AO7: =AN7-AP7 -> 4084.25 | AP7: =AD7+AF7 -> 958
A8: 8 | B8: 49500000 | C8: 12500 | D8: =B8/C8 -> 3960 | E8: 5600 | F8: =I8/E8 -> 8928.5714 | G8: =E8*R8 -> 8711664.7 | H8: =G8/B8 -> 0.17599323 | I8: 50000000 | J8: =I8/B8 -> 1.010101 | K8: ='2024.8月'!CE93 -> 55874978 | L8: =K8/I8 -> 1.1174996 | M8: =K8/B8 -> 1.1287874 | N8: =T8+U8+AD8+AF8 -> 5382 | O8: =K8/N8 -> 10381.824 | P8: =Q8/K8 -> 0.14984403 | Q8: =Y8 -> 8372532 | R8: =Q8/N8 -> 1555.6544 | S8: 31 | T8: 4444 | U8: 39 | V8: 7728270 | W8: 633000 | X8: 11262 | Y8: =V8+W8+X8 -> 8372532 | AA8: 100000 | AB8: =AB3*7% -> 9832149.4 | AC8: 消耗品費 | AD8: 23 | AE8: 52747 | AF8: 876 | AG8: 1316824 | AH8: =AE8+AG8 -> 1369571 | AN8: 6001 | AO8: =AN8-AP8 -> 3711 | AP8: 2290
A9: 9 | B9: 7000000 | C9: 2000 | D9: =B9/C9 -> 3500 | E9: 1400 | F9: =I9/E9 -> 5714.2857 | G9: =E9*R9 -> 2660000 | H9: =G9/B9 -> 0.38 | I9: 8000000 | J9: =I9/B9 -> 1.1428571 | K9: ='2024.9月'!CE93 -> 12350827 | L9: =K9/I9 -> 1.5438534 | M9: =K9/B9 -> 1.7644039 | N9: =T9+U9 -> 1065 | O9: =K9/N9 -> 11597.021 | P9: =Q9/K9 -> 0.16334582 | Q9: =Y9 -> 2017456 | R9: 1900 | S9: 8 | T9: 1063 | U9: 2 | V9: 1866106 | W9: 150000 | X9: 1350 | Y9: =V9+W9+X9 -> 2017456 | AA9: 30000 | AB9: 25266300 | AC9: イニシャル | AD9: 23 | AE9: =51100+5700 -> 56800 | AF9: 912 | AG9: 1468290 | AH9: =AE9+AG9 -> 1525090 | AJ9: 17040 | AN9: =AN8/AN7 -> 1.1901433 | AO9: =AO8/AO7 -> 0.90861235 | AP9: =AP8/AP7 -> 2.3903967
A10: 10 | B10: 455000 | C10: 350 | D10: =B10/C10 -> 1300 | E10: 100 | F10: =I10/E10 -> 6927.2727 | G10: =E10*R10 -> 190000 | H10: =G10/B10 -> 0.41758242 | I10: ='2024.10'!BL93 -> 692727.27 | J10: =I10/B10 -> 1.5224775 | K10: ='2024.10'!CD93 -> 1454318.2 | L10: =K10/I10 -> 2.0994094 | M10: =K10/B10 -> 3.1963037 | N10: =T10+U10 -> 0 | O10: =K10/N10 -> #DIV/0! | P10: =Q10/K10 -> 0 | R10: 1900 | Y10: =V10+W10 -> 0 | AA10: 30000 | AB10: 14000000 | AC10: 家賃 | AF10: 278 | AG10: 462089 | AH10: =AE10+AG10 -> 462089 | AJ10: 業務委託＆スキマ人件費費用圧縮対策<25年度想定>
A11: TOTAL | B11: =SUM(B4:B10) -> 136366200 | C11: =SUM(C4:C10) -> 35570 | D11: =B11/C11 -> 3833.7419 | E11: =SUM(E4:E10) -> 17950 | F11: =I11/E11 -> 7398.5475 | G11: =E11*R11 -> 29220145 | H11: =G11/B11 -> 0.21427703 | I11: =SUM(I4:I10) -> 1.3280393e+08 | J11: =I11/B11 -> 0.97387716 | K11: =SUM(K4:K10) -> 1.4045928e+08 | L11: =K11/I11 -> 1.057644 | M11: =K11/B11 -> 1.0300153 | N11: =SUM(N4:N10) -> 15688.25 | O11: =K11/N11 -> 8953.1514 | P11: =Q11/K11 -> 0.18182014 | Q11: =SUM(Q4:Q10) -> 25538325 | R11: =Q11/N11 -> 1627.8632 | S11: =SUM(S4:S10) -> 105 | T11: =SUM(T4:T10) -> 13751.25 | U11: =SUM(U4:U10) -> 80 | V11: =SUM(V4:V10) -> 23510025 | W11: =SUM(W4:W10) -> 2000000 | Y11: =SUM(Y4:Y10) -> 25538325 | Z11: =SUM(Z4:Z10) -> 0 | AA11: =SUM(AA4:AA10) -> 395000 | AB11: =AB3*5% -> 7022963.9 | AC11: 流動固定費 | AD11: =SUM(AD7:AD10) -> 349 | AE11: =SUM(AE7:AE10) -> 500585 | AF11: =SUM(AF6:AF10) -> 2971 | AG11: =SUM(AG6:AG10) -> 4594110 | AH11: スキマ | AI11: =AE11+AG11 -> 5094695 | AJ11: =AI11/AI13 -> 0.16631383 | AK11: =AF11+AD11 -> 3320 | AL11: =AI11/AK11 -> 1534.5467 | AM11: =AK11/AK13 -> 0.19357472 | AN11: 6000 | AO11: 1560 | AP11: =AN11*AO11 -> 9360000 | AQ11: =AN11/AN13 -> 0.34983383 | AR11: =AP11/AP13 -> 0.30641407 | AS11: =AO11*AK11 -> 5179200
B12: 136366200 | C12: 提出予算 | I12: ※天気要因見込まず算出 | K12: 44109 | L12: 終了時点の進捗状況 | N12: =K11/S12 -> 1404592.8 | O12: =K11-B12 -> 4093077.5 | P12: =K11/B12 -> 1.0300153 | Q12: =Q11/K11 -> 0.18182014 | S12: 100 | Y12: =Y11/K11 -> 0.18182014 | AB12: =AB3-AB4-AB7-AB8-AB9-AB10-AB11 -> 6663883.7 | AC12: 利益 | AE12: =AE11/AD11 -> 1434.341 | AG12: =AG11/AF11 -> 1546.3177 | AH12: 派遣 | AI12: =Q11 -> 25538325 | AJ12: =AI12/AI13 -> 0.83368617 | AK12: 13831 | AL12: =AI12/AK12 -> 1846.4554 | AM12: =AK12/AK13 -> 0.80642528 | AN12: =AK13-AN11 -> 11151 | AO12: 1900 | AP12: =AN12*AO12 -> 21186900 | AQ12: =AN12/AN13 -> 0.65016617 | AR12: =AP12/AP13 -> 0.69358593 | AS12: =AO12*AK12 -> 26278900
B13: =B11-B12 -> 0 | C13: 差異 | AG13: 139916000 | AH13: 合計 | AI13: =SUM(AI11:AI12) -> 30633020 | AJ13: =AI13/AG13 -> 0.21893865 | AK13: =SUM(AK11:AK12) -> 17151 | AL13: =(AL11+AL12)/2 -> 1690.5011 | AN13: =SUM(AN11:AN12) -> 17151 | AO13: =(AO11+AO12)/2 -> 1730 | AP13: =SUM(AP11:AP12) -> 30546900 | AS13: =SUM(AS11:AS12) -> 31458100
AJ14: 人件費率 | AK14: 労働時間 | AL14: 単価 | AM14: 比率 | AN14: 労働時間 | AO14: 単価 | AP14: 人件費 | AQ14: 労働時間比率 | AR14: 人件費比率 | AS14: =AS13/AG13 -> 0.22483562
AP15: =AS13-AP13 -> 911200 | AS15: =AS13-AI13 -> 825080
I16: 100000000 | J16: 予算まで | K16: =B11-K11 -> -4093077.5 | L16: 12 | M16: =K16/L16 -> -341089.79 | N16: 2019 | O16: 58190982 | P16: =K11/O16 -> 2.4137637 | V16: 税込 | AP16: =AS15-AP15 -> -86120
B17: =B7+B8 -> 101110000 | C17: =K7+K8 -> 1.0348832e+08 | D17: =C17-B17 -> 2378323.6 | I17: 111111111 | J17: 予測まで | K17: =I11-K11 -> -7655350.2 | L17: 12 | M17: =K17/L17 -> -637945.85 | N17: 2018 | O17: 44179221 | P17: =K11/O17 -> 3.1793063 | U17: 5 | V17: 1149692
J18: 一億円まで | K18: =I16-K11 -> -40459277 | L18: 12 | M18: =K18/L18 -> -3371606.5 | N18: 平均 | O18: =(O16+O17)/2 -> 51185102 | P18: =K11/O18 -> 2.7441438 | U18: 6 | V18: 7135509
G19: 2019年度 | J19: 一億一千万まで | K19: =I17-K11 -> -29348166 | L19: 12 | M19: =K19/L19 -> -2445680.5 | U19: 7 | V19: 8381268 | Z19: 4085 | AB19: =K7 -> 47613345
G20: 91399704 | H20: =K8-K9 -> 43524151 | I20: 945247 | J20: =I20-H20 -> -42578904 | K20: =K11 -> 1.4045928e+08 | L20: =K20/G20 -> 1.5367586 | M20: =K20-G20 -> 49059573 | U20: 8 | V20: 9209785 | Y20: 3700 | Z20: 3700 | AB20: 63000000
U21: 9 | V21: 2219201 | Z21: =Z20/Z19 -> 0.90575275 | AB21: =AB20/AB19 -> 1.3231584
V22: =SUM(V17:V21) -> 28095455
I23: 115000000 | K23: =K11 -> 1.4045928e+08 | L23: =K23/I23 -> 1.221385 | N23: =K23*1.1 -> 1.5450521e+08
M24: 150000000 | N24: =M24*10/110 -> 13636364 | O24: =M24-N24 -> 1.3636364e+08 | P24: =K11-O24 -> 4095641.1
A25: ■大通りビアガーデン2024 実績
A26: 推計 | B26: 2019 | C26: ー | D26: 2023 | E26: 2024 | F26: 2006 | H26: 2019 | I26: =G20 -> 91399704 | J26: =K11/I26 -> 1.5367586 | K26: =K11-I26 -> 49059573
A27: 来場者数 | B27: 1170000 | D27: 886000 | E27: 902000 | F27: 1523000 | H27: 2023 | I27: 114623699 | J27: =K11/I27 -> 1.2253947 | K27: =K11-I27 -> 25835578 | L27: 5187 | M27: 6717 | N27: =M27-L27 -> 1530 | O27: =M27/L27 -> 1.2949682
A28: 前年比 | B28: - | D28: 75.8 | E28: 101.8 | F28: =F27/E27 -> 1.6884701 | L28: 992 | M28: 1941 | N28: =M28-L28 -> 949 | O28: =M28/L28 -> 1.9566532
A29: ビール消費量（L） | B29: 441456 | D29: 334182 | E29: 340050 | F29: 574842 | L29: 318 | M29: 2503 | N29: =M29-L29 -> 2185 | O29: =M29/L29 -> 7.8710692
A30: 前年比 | B30: - | D30: 75.7 | E30: =E29/D29 -> 1.0175593 | F30: =F29/E29 -> 1.6904632 | L30: =SUM(L27:L29) -> 6497 | M30: =SUM(M27:M29) -> 11161 | N30: =SUM(N27:N29) -> 4664 | O30: =M30/L30 -> 1.7178698
A31: 20L樽本数 | B31: =B29/20 -> 22072.8 | D31: =D29/20 -> 16709.1 | E31: =E29/20 -> 17002.5 | F31: =F29/20 -> 28742.1 | J31: 2024 | K31: 期間 | L31: 売上 | M31: 値引き | N31: 税抜売上 | O31: 税込売上 | P31: 値引き | Q31: 税込売上合計
A32: 前年比 | D32: =D31/B31 -> 0.75699957 | E32: =E31/D31 -> 1.0175593 | F32: =F31/E31 -> 1.6904632 | J32: 4~5 | K32: ピコレ4/27-5/19 | L32: 2939522 | M32: 4040 | N32: =L32-M32 -> 2935482 | O32: 3232260 | P32: 4040 | Q32: =O32-P32 -> 3228220 | R32: 23
A33: ビール原価金額 | B33: =B31*9000 -> 198655200 | C33: 原価率想定 | D33: =D31*9000 -> 150381900 | E33: =E31*9700 -> 164924250 | F33: =F31*9000 -> 258678900 | J33: 5 | K33: ビアガ5/27-5/31 | L33: 477807 | M33: 3480 | N33: =L33-M33 -> 474327 | O33: 525570 | P33: 3480 | Q33: =O33-P33 -> 522090 | R33: 5
A34: ビール売上推定金額 | B34: =B33*3.5 -> 695293200 | C34: =B33/B34 -> 0.28571429 | D34: =D33*3.5 -> 526336650 | E34: =E33*3.5 -> 577234875 | F34: =F33*3.5 -> 905376150 | J34: 6 | K34: ビアガフル | L34: 19170665 | M34: 26790 | N34: =L34-M34 -> 19143875 | O34: 21087090 | P34: 26790 | Q34: =O34-P34 -> 21060300 | R34: 30
A35: ひとり当たりのビール購入額 | B35: =B34/B27 -> 594.26769 | C35: =C34/C27 -> #DIV/0! | D35: =D34/D27 -> 594.05942 | E35: =E34/E27 -> 639.94997 | F35: =F34/F27 -> 594.46891 | J35: 7 | K35: ビアガフル | L35: 47598067 | M35: 17800 | N35: =L35-M35 -> 47580267 | O35: 52356880 | P35: 17800 | Q35: =O35-P35 -> 52339080 | R35: 31
A36: 客単価想定 | B36: 1300 | D36: 1300 | E36: 1300 | F36: 1300 | J36: 8 | K36: ビアガフル | L36: 55870570 | M36: 5980 | N36: =L36-M36 -> 55864590 | O36: 61456496 | P36: 5980 | Q36: =O36-P36 -> 61450516 | R36: 31
A37: 推定売上額 | B37: =B27*B36 -> 1521000000 | D37: =D27*D36 -> 1151800000 | E37: =E27*E36 -> 1172600000 | F37: =F27*F36 -> 1979900000 | J37: 9 | K37: ビアガ9/1-9/8 | L37: 8816632 | M37: 5700 | N37: =L37-M37 -> 8810932 | O37: 9698100 | P37: 5700 | Q37: =O37-P37 -> 9692400 | R37: 8
J38: 9~10 | K38: ピコレ共催アキノジン | L38: 4982837 | M38: 1100 | N38: =L38-M38 -> 4981737 | O38: 5480760 | P38: 1100 | Q38: =O38-P38 -> 5479660 | R38: 23
K39: ビアガのみ105日 | L39: =L34+L33+L35+L36+L37 -> 131933741 | M39: =M34+M33+M35+M36+M37 -> 59750 | N39: =N34+N33+N35+N36+N37 -> 131873991 | O39: =O34+O33+O35+O36+O37 -> 145124136 | P39: =P34+P33+P35+P36+P37 -> 59750 | Q39: =Q34+Q33+Q35+Q36+Q37 -> 145064386 | R39: =R34+R33+R35+R36+R37 -> 105
K40: ピコレ&ピコレ共催 | L40: =L32+L38 -> 7922359 | M40: =M32+M38 -> 5140 | N40: =N32+N38 -> 7917219 | O40: =O32+O38 -> 8713020 | P40: =P32+P38 -> 5140 | Q40: =Q32+Q38 -> 8707880 | R40: =R32+R38 -> 46
...

Sheet 25-24天候指数対比
B1: ◆2025-2024 天候指数対比
B2: 4月 天候指数対比 <気象庁資料マクロクリマ> | F2: 平均気温 最高 13.0℃ （13.5℃）最低 5.2℃（5.5℃） カッコ内は前年値 <M-4th> | P2: 8月 天候指数対比 <現地ミクロクリマ> | T2: 平均気温 最高 28.8℃ （28.4℃）最低 21.6℃（22.0℃） カッコ内は前年値 <M-1st>
B3: 天候状況 | E3: ポイント | F3: 2025日数＊3 | G3: 2025合計 | H3: 比率 | I3: 2024日数＊3 | J3: 2024合計 | K3: 比率 | L3: 前年差異 | P3: 天候状況 | S3: ポイント | T3: 2025日数＊3 | U3: 2025合計 | V3: 比率 | W3: 2024日数＊3 | X3: 2024合計 | Y3: 比率 | Z3: 前年差異
B4: ポジティブ | C4: 晴れ（33度まで） | E4: 5 | F4: 0 | G4: =E4*F4 -> 0 | H4: =(F4+F5+F6)/F10 -> #DIV/0! | I4: 0 | J4: =E4*I4 -> 0 | K4: =(I4+I5+I6)/I10 -> #DIV/0! | L4: =F4-I4 -> 0 | M4: =G4-J4 -> 0 | N4: =H4-K4 -> #DIV/0! | P4: ポジティブ | Q4: 晴れ（33度まで） | S4: 5 | T4: 37 | U4: =S4*T4 -> 185 | V4: =(T4+T5+T6)/T10 -> 0.80645161 | W4: 27 | X4: =S4*W4 -> 135 | Y4: =(W4+W5+W6)/W10 -> 0.69892473 | Z4: =T4-W4 -> 10 | AA4: =U4-X4 -> 50 | AB4: =V4-Y4 -> 0.10752688
C5: 晴れ（25度以下） | E5: 4 | F5: 0 | G5: =E5*F5 -> 0 | I5: 0 | J5: =E5*I5 -> 0 | L5: =F5-I5 -> 0 | M5: =G5-J5 -> 0 | Q5: 晴れ（25度以下） | S5: 4 | T5: 0 | U5: =S5*T5 -> 0 | W5: 0 | X5: =S5*W5 -> 0 | Z5: =T5-W5 -> 0 | AA5: =U5-X5 -> 0
C6: 晴れ（33度以上15以下） 曇25度以上 | E6: 3 | F6: 0 | G6: =E6*F6 -> 0 | I6: 0 | J6: =E6*I6 -> 0 | L6: =F6-I6 -> 0 | M6: =G6-J6 -> 0 | Q6: 晴れ（33度以上15以下） 曇25度以上 | S6: 3 | T6: 38 | U6: =S6*T6 -> 114 | W6: 38 | X6: =S6*W6 -> 114 | Z6: =T6-W6 -> 0 | AA6: =U6-X6 -> 0
B7: ネガティブ | C7: 曇 | E7: 2 | F7: 0 | G7: =E7*F7 -> 0 | H7: =(F7+F8+F9)/F10 -> #DIV/0! | I7: 0 | J7: =E7*I7 -> 0 | K7: =(I7+I8+I9)/I10 -> #DIV/0! | L7: =F7-I7 -> 0 | M7: =G7-J7 -> 0 | N7: =H7-K7 -> #DIV/0! | P7: ネガティブ | Q7: 曇 | S7: 2 | T7: 0 | U7: =S7*T7 -> 0 | V7: =(T7+T8+T9)/T10 -> 0.19354839 | W7: 6 | X7: =S7*W7 -> 12 | Y7: =(W7+W8+W9)/W10 -> 0.30107527 | Z7: =T7-W7 -> -6 | AA7: =U7-X7 -> -12 | AB7: =V7-Y7 -> -0.10752688
C8: 雨 | E8: 1 | F8: 0 | G8: =E8*F8 -> 0 | I8: 0 | J8: =E8*I8 -> 0 | L8: =F8-I8 -> 0 | M8: =G8-J8 -> 0 | Q8: 雨 | S8: 1 | T8: 18 | U8: =S8*T8 -> 18 | W8: 22 | X8: =S8*W8 -> 22 | Z8: =T8-W8 -> -4 | AA8: =U8-X8 -> -4
C9: 豪雨・雷雨 | E9: 0 | F9: 0 | G9: =E9*F9 -> 0 | J9: =E9*I9 -> 0 | L9: =F9-I9 -> 0 | M9: =G9-J9 -> 0 | Q9: 豪雨・雷雨 | S9: 0 | T9: 0 | U9: =S9*T9 -> 0 | W9: 0 | X9: =S9*W9 -> 0 | Z9: =T9-W9 -> 0 | AA9: =U9-X9 -> 0
B10: TOTAL | F10: =SUM(F4:F9) -> 0 | G10: =SUM(G4:G9) -> 0 | H10: =H4+H7 -> #DIV/0! | I10: =SUM(I4:I9) -> 0 | J10: =SUM(J4:J9) -> 0 | K10: =K4+K7 -> #DIV/0! | L10: =SUM(L4:L9) -> 0 | M10: =SUM(M4:M9) -> 0 | N10: =G10/J10 -> #DIV/0! | P10: TOTAL | T10: =SUM(T4:T9) -> 93 | U10: =SUM(U4:U9) -> 317 | V10: =V4+V7 -> 1 | W10: =SUM(W4:W9) -> 93 | X10: =SUM(X4:X9) -> 283 | Y10: =Y4+Y7 -> 1 | Z10: =SUM(Z4:Z9) -> 0 | AA10: =SUM(AA4:AA9) -> 34 | AB10: =U10/X10 -> 1.1201413
F11: =G10/F10 -> #DIV/0! | I11: =J10/I10 -> #DIV/0! | L11: =F11-I11 -> #DIV/0! | N11: =F11/I11 -> #DIV/0! | T11: =U10/T10 -> 3.4086022 | W11: =X10/W10 -> 3.0430108 | Z11: =T11-W11 -> 0.3655914 | AB11: =T11/W11 -> 1.1201413
B13: 5月 天候指数対比 <現地ミクロクリマ> | F13: 平均気温 最高 25.9℃ （17.0℃）最低 14.8℃（11.6℃） カッコ内は前年値 <M-2nd> | P13: 9月 天候指数対比 <現地ミクロクリマ> | T13: 平均気温 最高 27.0℃ （24.0℃）最低 19.0℃（15.6℃） カッコ内は前年値 <M- 2nd>
