Workbook

Sheet 料飲
A1: 令和７年度（第69期）事業予算 損益計算書 | AN1: 令和７年度（第69期）事業予算 損益計算書
AK2: [単位：千円(税抜)] | BM2: [単位：千円(税抜)] | BP2: [単位：千円(税抜)]
A3: 名称
T4: 大倉山 | AI4: 藻岩山 | AX4: テレビ塔 | BE4: 赤れんが テラス
E5: ﾇｰﾍﾞﾙﾌﾟｰｽ | J5: 大倉山ｶﾌｪ | O5: 大倉山ﾗｳﾝｼﾞ | Y5: ｽｷｰﾛｯｼﾞ食堂 | AD5: 藻岩山レストラン | AN5: ｶﾞｰﾃﾞﾝ | AS5: ﾋﾞｱｶﾞｰﾃﾞﾝ | BC5: ブリック | BD5: ルスツ羊蹄豚 | BF5: 料飲共通 | BK5: 料飲部合計 | BP5: 料飲部合計
E6: ①R7予算 | F6: ②R6決見 | G6: ①－② | H6: ③R6予算 | I6: ①－③ | J6: ①R7予算 | K6: ②R6決見 | L6: ①－② | M6: ③R6予算 | N6: ①－③ | O6: ①R7予算 | P6: ②R6決見 | Q6: ①－② | R6: ③R6予算 | S6: ①－③ | T6: ①R7予算 | U6: ②R6決見 | V6: ①－② | W6: ③R6予算 | X6: ①－③ | Y6: ①R7予算 | Z6: ②R6決見 | AA6: ①－② | AB6: ③R6予算 | AC6: ①－③ | AD6: ①R7予算 | AE6: ②R6決見 | AF6: ①－② | AG6: ③R6予算 | AH6: ①－③ | AI6: ①R7予算 | AJ6: ②R6決見 | AK6: ①－② | AL6: ③R6予算 | AM6: ①－③ | AN6: ①R7予算 | AO6: ①R6決見 | AP6: ①－② | AQ6: ③R6予算 | AR6: ①－③ | AS6: ①R7予算 | AT6: ①R6決見 | AU6: ①－② | AV6: ③R6予算 | AW6: ①－③ | AX6: ①R7予算 | AY6: ②R6決見 | AZ6: ①－② | BA6: ③R6予算 | BB6: ①－③ | BC6: ①R7予算 | BD6: ①R7予算 | BE6: ①R7予算 | BF6: ①R7予算 | BG6: ②R6決見 | BH6: ①－② | BI6: ③R6予算 | BJ6: ①－③ | BK6: ①R7予算 | BL6: ②R6決見 | BM6: ①－② | BN6: ③R6予算 | BO6: ①－③ | BP6: ①R7予算 | BQ6: ②R6決見 | BR6: ①－② | BS6: ③R6予算 | BT6: ①－③
A7: 総売上高 | E7: =+ﾇｰﾍﾞﾙﾌﾟｰｽ!W6/1000 -> 98216.5 | F7: 97828.758 | G7: =+E7-F7 -> 387.742 | H7: 89665 | I7: =+E7-H7 -> 8551.5 | J7: =+ｶﾌｪﾙﾎﾟ!W6/1000 -> 9212.097 | K7: 8192.423 | L7: =+J7-K7 -> 1019.674 | M7: 10007 | N7: =+J7-M7 -> -794.903 | O7: =+ｶﾌｪｾﾚｽﾃ!W6/1000 -> 19649 | P7: 18903.479 | Q7: =+O7-P7 -> 745.521 | R7: 15319 | S7: =+O7-R7 -> 4330 | T7: =+E7+J7+O7 -> 127077.6 | U7: =+F7+K7+P7 -> 124924.66 | V7: =+T7-U7 -> 2152.937 | W7: =+H7+M7+R7 -> 114991 | X7: =+T7-W7 -> 12086.597 | Y7: 0 | Z7: 23648.19 | AA7: =+Y7-Z7 -> -23648.19 | AB7: 20772 | AC7: =+Y7-AB7 -> -20772 | AD7: =+ｼﾞｭｴﾙｽﾞ!W6/1000 -> 164317.97 | AE7: 157913.61 | AF7: =+AD7-AE7 -> 6404.36 | AG7: 141204 | AH7: =+AD7-AG7 -> 23113.966 | AI7: =+Y7+AD7 -> 164317.97 | AJ7: =+Z7+AE7 -> 181561.8 | AK7: =+AI7-AJ7 -> -17243.83 | AL7: =+AB7+AG7 -> 161976 | AM7: =+AI7-AL7 -> 2341.966 | AN7: =+ｶﾞｰﾃﾞﾝ!W6/1000 -> 136763.17 | AO7: 132999.91 | AP7: =+AN7-AO7 -> 3763.265 | AQ7: 132211 | AR7: =+AN7-AQ7 -> 4552.172 | AS7: =+ﾋﾞｱｶﾞｰﾃﾞﾝ!W6/1000 -> 154408.3 | AT7: 140806.36 | AU7: =+AS7-AT7 -> 13601.935 | AV7: 136366 | AW7: =+AS7-AV7 -> 18042.295 | AX7: =+AN7+AS7 -> 291171.47 | AY7: =+AO7+AT7 -> 273806.27 | AZ7: =+AX7-AY7 -> 17365.2 | BA7: =+AQ7+AV7 -> 268577 | BB7: =+AX7-BA7 -> 22594.467 | BC7: =SUM(BC8:BC17) -> 75365.66 | BD7: =SUM(BD8:BD17) -> 50302.4 | BE7: =+BC7+BD7 -> 125668.06 | BF7: =+料飲共通!W6/1000 -> 0 | BG7: 0 | BH7: =+BF7-BG7 -> 0 | BI7: 0 | BJ7: =+BF7-BI7 -> 0 | BK7: =+T7+AI7+AX7+BE7+BF7 -> 708235.09 | BL7: =+U7+AJ7+AY7+BG7 -> 580292.72 | BM7: =+BK7-BL7 -> 127942.37 | BN7: =+W7+AL7+BA7+BI7 -> 545544 | BO7: =+BK7-BN7 -> 162691.09 | BP7: =+BK7-BE7 -> 582567.03 | BQ7: =+BL7-Z7 -> 556644.53 | BR7: =+BP7-BQ7 -> 25922.497 | BS7: =+BN7-AB7 -> 524772 | BT7: =+BP7-BS7 -> 57795.03
B8: 売上 | E8: =+ﾇｰﾍﾞﾙﾌﾟｰｽ!W7/1000 -> 98216.5 | F8: 97828.758 | G8: =+E8-F8 -> 387.742 | H8: 89665 | I8: =+E8-H8 -> 8551.5 | J8: =+ｶﾌｪﾙﾎﾟ!W7/1000 -> 9212.097 | K8: 8192.423 | L8: =+J8-K8 -> 1019.674 | M8: 10007 | N8: =+J8-M8 -> -794.903 | O8: =+ｶﾌｪｾﾚｽﾃ!W7/1000 -> 19649 | P8: 18903.479 | Q8: =+O8-P8 -> 745.521 | R8: 15319 | S8: =+O8-R8 -> 4330 | T8: =+E8+J8+O8 -> 127077.6 | U8: =+F8+K8+P8 -> 124924.66 | V8: =+T8-U8 -> 2152.937 | W8: =+H8+M8+R8 -> 114991 | X8: =+T8-W8 -> 12086.597 | Y8: 0 | Z8: 23648.19 | AA8: =+Y8-Z8 -> -23648.19 | AB8: 20772 | AC8: =+Y8-AB8 -> -20772 | AD8: =+ｼﾞｭｴﾙｽﾞ!W7/1000 -> 164317.97 | AE8: 157913.61 | AF8: =+AD8-AE8 -> 6404.36 | AG8: 141204 | AH8: =+AD8-AG8 -> 23113.966 | AI8: =+Y8+AD8 -> 164317.97 | AJ8: =+Z8+AE8 -> 181561.8 | AK8: =+AI8-AJ8 -> -17243.83 | AL8: =+AB8+AG8 -> 161976 | AM8: =+AI8-AL8 -> 2341.966 | AN8: =+ｶﾞｰﾃﾞﾝ!W7/1000 -> 136763.17 | AO8: 132999.91 | AP8: =+AN8-AO8 -> 3763.265 | AQ8: 132211 | AR8: =+AN8-AQ8 -> 4552.172 | AS8: =+ﾋﾞｱｶﾞｰﾃﾞﾝ!W7/1000 -> 154408.3 | AT8: 140806.36 | AU8: =+AS8-AT8 -> 13601.935 | AV8: 136366 | AW8: =+AS8-AV8 -> 18042.295 | AX8: =+AN8+AS8 -> 291171.47 | AY8: =+AO8+AT8 -> 273806.27 | AZ8: =+AX8-AY8 -> 17365.2 | BA8: =+AQ8+AV8 -> 268577 | BB8: =+AX8-BA8 -> 22594.467 | BC8: =+赤れんが!X8/1000 -> 75365.66 | BD8: =+赤れんが!Z8/1000 -> 50302.4 | BE8: =+BC8+BD8 -> 125668.06 | BF8: =+料飲共通!W7/1000 -> 0 | BG8: 0 | BH8: =+BF8-BG8 -> 0 | BI8: 0 | BJ8: =+BF8-BI8 -> 0 | BK8: =+T8+AI8+AX8+BE8+BF8 -> 708235.09 | BL8: =+U8+AJ8+AY8+BG8 -> 580292.72 | BM8: =+BK8-BL8 -> 127942.37 | BN8: =+W8+AL8+BA8+BI8 -> 545544 | BO8: =+BK8-BN8 -> 162691.09 | BP8: =+BK8-BE8 -> 582567.03 | BQ8: =+BL8-Z8 -> 556644.53 | BR8: =+BP8-BQ8 -> 25922.497 | BS8: =+BN8-AB8 -> 524772 | BT8: =+BP8-BS8 -> 57795.03
B9: 損保代理店収入 | E9: =+ﾇｰﾍﾞﾙﾌﾟｰｽ!W8/1000 -> 0 | F9: 0 | G9: =+E9-F9 -> 0 | H9: 0 | I9: =+E9-H9 -> 0 | J9: =+ｶﾌｪﾙﾎﾟ!W8/1000 -> 0 | K9: 0 | L9: =+J9-K9 -> 0 | M9: 0 | N9: =+J9-M9 -> 0 | O9: =+ｶﾌｪｾﾚｽﾃ!W8/1000 -> 0 | P9: 0 | Q9: =+O9-P9 -> 0 | R9: 0 | S9: =+O9-R9 -> 0 | T9: =+E9+J9+O9 -> 0 | U9: =+F9+K9+P9 -> 0 | V9: =+T9-U9 -> 0 | W9: =+H9+M9+R9 -> 0 | X9: =+T9-W9 -> 0 | Y9: 0 | Z9: 0 | AA9: =+Y9-Z9 -> 0 | AB9: 0 | AC9: =+Y9-AB9 -> 0 | AD9: =+ｼﾞｭｴﾙｽﾞ!W8/1000 -> 0 | AE9: 0 | AF9: =+AD9-AE9 -> 0 | AG9: 0 | AH9: =+AD9-AG9 -> 0 | AI9: =+Y9+AD9 -> 0 | AJ9: =+Z9+AE9 -> 0 | AK9: =+AI9-AJ9 -> 0 | AL9: =+AB9+AG9 -> 0 | AM9: =+AI9-AL9 -> 0 | AN9: =+ｶﾞｰﾃﾞﾝ!W8/1000 -> 0 | AO9: 0 | AP9: =+AN9-AO9 -> 0 | AQ9: 0 | AR9: =+AN9-AQ9 -> 0 | AS9: =+ﾋﾞｱｶﾞｰﾃﾞﾝ!W8/1000 -> 0 | AT9: 0 | AU9: =+AS9-AT9 -> 0 | AV9: 0 | AW9: =+AS9-AV9 -> 0 | AX9: =+AN9+AS9 -> 0 | AY9: =+AO9+AT9 -> 0 | AZ9: =+AX9-AY9 -> 0 | BA9: =+AQ9+AV9 -> 0 | BB9: =+AX9-BA9 -> 0 | BC9: 0 | BD9: 0 | BE9: =+BC9+BD9 -> 0 | BF9: =+料飲共通!W8/1000 -> 0 | BG9: 0 | BH9: =+BF9-BG9 -> 0 | BI9: 0 | BJ9: =+BF9-BI9 -> 0 | BK9: =+T9+AI9+AX9+BE9+BF9 -> 0 | BL9: =+U9+AJ9+AY9+BG9 -> 0 | BM9: =+BK9-BL9 -> 0 | BN9: =+W9+AL9+BA9+BI9 -> 0 | BO9: =+BK9-BN9 -> 0 | BP9: =+BK9-BE9 -> 0 | BQ9: =+BL9-Z9 -> 0 | BR9: =+BP9-BQ9 -> 0 | BS9: =+BN9-AB9 -> 0 | BT9: =+BP9-BS9 -> 0
B10: 販売手数料収入 | E10: =+ﾇｰﾍﾞﾙﾌﾟｰｽ!W9/1000 -> 0 | F10: 0 | G10: =+E10-F10 -> 0 | H10: 0 | I10: =+E10-H10 -> 0 | J10: =+ｶﾌｪﾙﾎﾟ!W9/1000 -> 0 | K10: 0 | L10: =+J10-K10 -> 0 | M10: 0 | N10: =+J10-M10 -> 0 | O10: =+ｶﾌｪｾﾚｽﾃ!W9/1000 -> 0 | P10: 0 | Q10: =+O10-P10 -> 0 | R10: 0 | S10: =+O10-R10 -> 0 | T10: =+E10+J10+O10 -> 0 | U10: =+F10+K10+P10 -> 0 | V10: =+T10-U10 -> 0 | W10: =+H10+M10+R10 -> 0 | X10: =+T10-W10 -> 0 | Y10: 0 | Z10: 0 | AA10: =+Y10-Z10 -> 0 | AB10: 0 | AC10: =+Y10-AB10 -> 0 | AD10: =+ｼﾞｭｴﾙｽﾞ!W9/1000 -> 0 | AE10: 0 | AF10: =+AD10-AE10 -> 0 | AG10: 0 | AH10: =+AD10-AG10 -> 0 | AI10: =+Y10+AD10 -> 0 | AJ10: =+Z10+AE10 -> 0 | AK10: =+AI10-AJ10 -> 0 | AL10: =+AB10+AG10 -> 0 | AM10: =+AI10-AL10 -> 0 | AN10: =+ｶﾞｰﾃﾞﾝ!W9/1000 -> 0 | AO10: 0 | AP10: =+AN10-AO10 -> 0 | AQ10: 0 | AR10: =+AN10-AQ10 -> 0 | AS10: =+ﾋﾞｱｶﾞｰﾃﾞﾝ!W9/1000 -> 0 | AT10: 0 | AU10: =+AS10-AT10 -> 0 | AV10: 0 | AW10: =+AS10-AV10 -> 0 | AX10: =+AN10+AS10 -> 0 | AY10: =+AO10+AT10 -> 0 | AZ10: =+AX10-AY10 -> 0 | BA10: =+AQ10+AV10 -> 0 | BB10: =+AX10-BA10 -> 0 | BC10: 0 | BD10: 0 | BE10: =+BC10+BD10 -> 0 | BF10: =+料飲共通!W9/1000 -> 0 | BG10: 0 | BH10: =+BF10-BG10 -> 0 | BI10: 0 | BJ10: =+BF10-BI10 -> 0 | BK10: =+T10+AI10+AX10+BE10+BF10 -> 0 | BL10: =+U10+AJ10+AY10+BG10 -> 0 | BM10: =+BK10-BL10 -> 0 | BN10: =+W10+AL10+BA10+BI10 -> 0 | BO10: =+BK10-BN10 -> 0 | BP10: =+BK10-BE10 -> 0 | BQ10: =+BL10-Z10 -> 0 | BR10: =+BP10-BQ10 -> 0 | BS10: =+BN10-AB10 -> 0 | BT10: =+BP10-BS10 -> 0
B11: 索道収入 | E11: =+ﾇｰﾍﾞﾙﾌﾟｰｽ!W10/1000 -> 0 | F11: 0 | G11: =+E11-F11 -> 0 | H11: 0 | I11: =+E11-H11 -> 0 | J11: =+ｶﾌｪﾙﾎﾟ!W10/1000 -> 0 | K11: 0 | L11: =+J11-K11 -> 0 | M11: 0 | N11: =+J11-M11 -> 0 | O11: =+ｶﾌｪｾﾚｽﾃ!W10/1000 -> 0 | P11: 0 | Q11: =+O11-P11 -> 0 | R11: 0 | S11: =+O11-R11 -> 0 | T11: =+E11+J11+O11 -> 0 | U11: =+F11+K11+P11 -> 0 | V11: =+T11-U11 -> 0 | W11: =+H11+M11+R11 -> 0 | X11: =+T11-W11 -> 0 | Y11: 0 | Z11: 0 | AA11: =+Y11-Z11 -> 0 | AB11: 0 | AC11: =+Y11-AB11 -> 0 | AD11: =+ｼﾞｭｴﾙｽﾞ!W10/1000 -> 0 | AE11: 0 | AF11: =+AD11-AE11 -> 0 | AG11: 0 | AH11: =+AD11-AG11 -> 0 | AI11: =+Y11+AD11 -> 0 | AJ11: =+Z11+AE11 -> 0 | AK11: =+AI11-AJ11 -> 0 | AL11: =+AB11+AG11 -> 0 | AM11: =+AI11-AL11 -> 0 | AN11: =+ｶﾞｰﾃﾞﾝ!W10/1000 -> 0 | AO11: 0 | AP11: =+AN11-AO11 -> 0 | AQ11: 0 | AR11: =+AN11-AQ11 -> 0 | AS11: =+ﾋﾞｱｶﾞｰﾃﾞﾝ!W10/1000 -> 0 | AT11: 0 | AU11: =+AS11-AT11 -> 0 | AV11: 0 | AW11: =+AS11-AV11 -> 0 | AX11: =+AN11+AS11 -> 0 | AY11: =+AO11+AT11 -> 0 | AZ11: =+AX11-AY11 -> 0 | BA11: =+AQ11+AV11 -> 0 | BB11: =+AX11-BA11 -> 0 | BC11: 0 | BD11: 0 | BE11: =+BC11+BD11 -> 0 | BF11: =+料飲共通!W10/1000 -> 0 | BG11: 0 | BH11: =+BF11-BG11 -> 0 | BI11: 0 | BJ11: =+BF11-BI11 -> 0 | BK11: =+T11+AI11+AX11+BE11+BF11 -> 0 | BL11: =+U11+AJ11+AY11+BG11 -> 0 | BM11: =+BK11-BL11 -> 0 | BN11: =+W11+AL11+BA11+BI11 -> 0 | BO11: =+BK11-BN11 -> 0 | BP11: =+BK11-BE11 -> 0 | BQ11: =+BL11-Z11 -> 0 | BR11: =+BP11-BQ11 -> 0 | BS11: =+BN11-AB11 -> 0 | BT11: =+BP11-BS11 -> 0
B12: 地代収入 | E12: =+ﾇｰﾍﾞﾙﾌﾟｰｽ!W11/1000 -> 0 | F12: 0 | G12: =+E12-F12 -> 0 | H12: 0 | I12: =+E12-H12 -> 0 | J12: =+ｶﾌｪﾙﾎﾟ!W11/1000 -> 0 | K12: 0 | L12: =+J12-K12 -> 0 | M12: 0 | N12: =+J12-M12 -> 0 | O12: =+ｶﾌｪｾﾚｽﾃ!W11/1000 -> 0 | P12: 0 | Q12: =+O12-P12 -> 0 | R12: 0 | S12: =+O12-R12 -> 0 | T12: =+E12+J12+O12 -> 0 | U12: =+F12+K12+P12 -> 0 | V12: =+T12-U12 -> 0 | W12: =+H12+M12+R12 -> 0 | X12: =+T12-W12 -> 0 | Y12: 0 | Z12: 0 | AA12: =+Y12-Z12 -> 0 | AB12: 0 | AC12: =+Y12-AB12 -> 0 | AD12: =+ｼﾞｭｴﾙｽﾞ!W11/1000 -> 0 | AE12: 0 | AF12: =+AD12-AE12 -> 0 | AG12: 0 | AH12: =+AD12-AG12 -> 0 | AI12: =+Y12+AD12 -> 0 | AJ12: =+Z12+AE12 -> 0 | AK12: =+AI12-AJ12 -> 0 | AL12: =+AB12+AG12 -> 0 | AM12: =+AI12-AL12 -> 0 | AN12: =+ｶﾞｰﾃﾞﾝ!W11/1000 -> 0 | AO12: 0 | AP12: =+AN12-AO12 -> 0 | AQ12: 0 | AR12: =+AN12-AQ12 -> 0 | AS12: =+ﾋﾞｱｶﾞｰﾃﾞﾝ!W11/1000 -> 0 | AT12: 0 | AU12: =+AS12-AT12 -> 0 | AV12: 0 | AW12: =+AS12-AV12 -> 0 | AX12: =+AN12+AS12 -> 0 | AY12: =+AO12+AT12 -> 0 | AZ12: =+AX12-AY12 -> 0 | BA12: =+AQ12+AV12 -> 0 | BB12: =+AX12-BA12 -> 0 | BC12: 0 | BD12: 0 | BE12: =+BC12+BD12 -> 0 | BF12: =+料飲共通!W11/1000 -> 0 | BG12: 0 | BH12: =+BF12-BG12 -> 0 | BI12: 0 | BJ12: =+BF12-BI12 -> 0 | BK12: =+T12+AI12+AX12+BE12+BF12 -> 0 | BL12: =+U12+AJ12+AY12+BG12 -> 0 | BM12: =+BK12-BL12 -> 0 | BN12: =+W12+AL12+BA12+BI12 -> 0 | BO12: =+BK12-BN12 -> 0 | BP12: =+BK12-BE12 -> 0 | BQ12: =+BL12-Z12 -> 0 | BR12: =+BP12-BQ12 -> 0 | BS12: =+BN12-AB12 -> 0 | BT12: =+BP12-BS12 -> 0
B13: 家賃収入 | E13: =+ﾇｰﾍﾞﾙﾌﾟｰｽ!W12/1000 -> 0 | F13: 0 | G13: =+E13-F13 -> 0 | H13: 0 | I13: =+E13-H13 -> 0 | J13: =+ｶﾌｪﾙﾎﾟ!W12/1000 -> 0 | K13: 0 | L13: =+J13-K13 -> 0 | M13: 0 | N13: =+J13-M13 -> 0 | O13: =+ｶﾌｪｾﾚｽﾃ!W12/1000 -> 0 | P13: 0 | Q13: =+O13-P13 -> 0 | R13: 0 | S13: =+O13-R13 -> 0 | T13: =+E13+J13+O13 -> 0 | U13: =+F13+K13+P13 -> 0 | V13: =+T13-U13 -> 0 | W13: =+H13+M13+R13 -> 0 | X13: =+T13-W13 -> 0 | Y13: 0 | Z13: 0 | AA13: =+Y13-Z13 -> 0 | AB13: 0 | AC13: =+Y13-AB13 -> 0 | AD13: =+ｼﾞｭｴﾙｽﾞ!W12/1000 -> 0 | AE13: 0 | AF13: =+AD13-AE13 -> 0 | AG13: 0 | AH13: =+AD13-AG13 -> 0 | AI13: =+Y13+AD13 -> 0 | AJ13: =+Z13+AE13 -> 0 | AK13: =+AI13-AJ13 -> 0 | AL13: =+AB13+AG13 -> 0 | AM13: =+AI13-AL13 -> 0 | AN13: =+ｶﾞｰﾃﾞﾝ!W12/1000 -> 0 | AO13: 0 | AP13: =+AN13-AO13 -> 0 | AQ13: 0 | AR13: =+AN13-AQ13 -> 0 | AS13: =+ﾋﾞｱｶﾞｰﾃﾞﾝ!W12/1000 -> 0 | AT13: 0 | AU13: =+AS13-AT13 -> 0 | AV13: 0 | AW13: =+AS13-AV13 -> 0 | AX13: =+AN13+AS13 -> 0 | AY13: =+AO13+AT13 -> 0 | AZ13: =+AX13-AY13 -> 0 | BA13: =+AQ13+AV13 -> 0 | BB13: =+AX13-BA13 -> 0 | BC13: 0 | BD13: 0 | BE13: =+BC13+BD13 -> 0 | BF13: =+料飲共通!W12/1000 -> 0 | BG13: 0 | BH13: =+BF13-BG13 -> 0 | BI13: 0 | BJ13: =+BF13-BI13 -> 0 | BK13: =+T13+AI13+AX13+BE13+BF13 -> 0 | BL13: =+U13+AJ13+AY13+BG13 -> 0 | BM13: =+BK13-BL13 -> 0 | BN13: =+W13+AL13+BA13+BI13 -> 0 | BO13: =+BK13-BN13 -> 0 | BP13: =+BK13-BE13 -> 0 | BQ13: =+BL13-Z13 -> 0 | BR13: =+BP13-BQ13 -> 0 | BS13: =+BN13-AB13 -> 0 | BT13: =+BP13-BS13 -> 0
B14: 駐車場収入 | E14: =+ﾇｰﾍﾞﾙﾌﾟｰｽ!W13/1000 -> 0 | F14: 0 | G14: =+E14-F14 -> 0 | H14: 0 | I14: =+E14-H14 -> 0 | J14: =+ｶﾌｪﾙﾎﾟ!W13/1000 -> 0 | K14: 0 | L14: =+J14-K14 -> 0 | M14: 0 | N14: =+J14-M14 -> 0 | O14: =+ｶﾌｪｾﾚｽﾃ!W13/1000 -> 0 | P14: 0 | Q14: =+O14-P14 -> 0 | R14: 0 | S14: =+O14-R14 -> 0 | T14: =+E14+J14+O14 -> 0 | U14: =+F14+K14+P14 -> 0 | V14: =+T14-U14 -> 0 | W14: =+H14+M14+R14 -> 0 | X14: =+T14-W14 -> 0 | Y14: 0 | Z14: 0 | AA14: =+Y14-Z14 -> 0 | AB14: 0 | AC14: =+Y14-AB14 -> 0 | AD14: =+ｼﾞｭｴﾙｽﾞ!W13/1000 -> 0 | AE14: 0 | AF14: =+AD14-AE14 -> 0 | AG14: 0 | AH14: =+AD14-AG14 -> 0 | AI14: =+Y14+AD14 -> 0 | AJ14: =+Z14+AE14 -> 0 | AK14: =+AI14-AJ14 -> 0 | AL14: =+AB14+AG14 -> 0 | AM14: =+AI14-AL14 -> 0 | AN14: =+ｶﾞｰﾃﾞﾝ!W13/1000 -> 0 | AO14: 0 | AP14: =+AN14-AO14 -> 0 | AQ14: 0 | AR14: =+AN14-AQ14 -> 0 | AS14: =+ﾋﾞｱｶﾞｰﾃﾞﾝ!W13/1000 -> 0 | AT14: 0 | AU14: =+AS14-AT14 -> 0 | AV14: 0 | AW14: =+AS14-AV14 -> 0 | AX14: =+AN14+AS14 -> 0 | AY14: =+AO14+AT14 -> 0 | AZ14: =+AX14-AY14 -> 0 | BA14: =+AQ14+AV14 -> 0 | BB14: =+AX14-BA14 -> 0 | BC14: 0 | BD14: 0 | BE14: =+BC14+BD14 -> 0 | BF14: =+料飲共通!W13/1000 -> 0 | BG14: 0 | BH14: =+BF14-BG14 -> 0 | BI14: 0 | BJ14: =+BF14-BI14 -> 0 | BK14: =+T14+AI14+AX14+BE14+BF14 -> 0 | BL14: =+U14+AJ14+AY14+BG14 -> 0 | BM14: =+BK14-BL14 -> 0 | BN14: =+W14+AL14+BA14+BI14 -> 0 | BO14: =+BK14-BN14 -> 0 | BP14: =+BK14-BE14 -> 0 | BQ14: =+BL14-Z14 -> 0 | BR14: =+BP14-BQ14 -> 0 | BS14: =+BN14-AB14 -> 0 | BT14: =+BP14-BS14 -> 0
B15: 受託料 | E15: =+ﾇｰﾍﾞﾙﾌﾟｰｽ!W14/1000 -> 0 | F15: 0 | G15: =+E15-F15 -> 0 | H15: 0 | I15: =+E15-H15 -> 0 | J15: =+ｶﾌｪﾙﾎﾟ!W14/1000 -> 0 | K15: 0 | L15: =+J15-K15 -> 0 | M15: 0 | N15: =+J15-M15 -> 0 | O15: =+ｶﾌｪｾﾚｽﾃ!W14/1000 -> 0 | P15: 0 | Q15: =+O15-P15 -> 0 | R15: 0 | S15: =+O15-R15 -> 0 | T15: =+E15+J15+O15 -> 0 | U15: =+F15+K15+P15 -> 0 | V15: =+T15-U15 -> 0 | W15: =+H15+M15+R15 -> 0 | X15: =+T15-W15 -> 0 | Y15: 0 | Z15: 0 | AA15: =+Y15-Z15 -> 0 | AB15: 0 | AC15: =+Y15-AB15 -> 0 | AD15: =+ｼﾞｭｴﾙｽﾞ!W14/1000 -> 0 | AE15: 0 | AF15: =+AD15-AE15 -> 0 | AG15: 0 | AH15: =+AD15-AG15 -> 0 | AI15: =+Y15+AD15 -> 0 | AJ15: =+Z15+AE15 -> 0 | AK15: =+AI15-AJ15 -> 0 | AL15: =+AB15+AG15 -> 0 | AM15: =+AI15-AL15 -> 0 | AN15: =+ｶﾞｰﾃﾞﾝ!W14/1000 -> 0 | AO15: 0 | AP15: =+AN15-AO15 -> 0 | AQ15: 0 | AR15: =+AN15-AQ15 -> 0 | AS15: =+ﾋﾞｱｶﾞｰﾃﾞﾝ!W14/1000 -> 0 | AT15: 0 | AU15: =+AS15-AT15 -> 0 | AV15: 0 | AW15: =+AS15-AV15 -> 0 | AX15: =+AN15+AS15 -> 0 | AY15: =+AO15+AT15 -> 0 | AZ15: =+AX15-AY15 -> 0 | BA15: =+AQ15+AV15 -> 0 | BB15: =+AX15-BA15 -> 0 | BC15: 0 | BD15: 0 | BE15: =+BC15+BD15 -> 0 | BF15: =+料飲共通!W14/1000 -> 0 | BG15: 0 | BH15: =+BF15-BG15 -> 0 | BI15: 0 | BJ15: =+BF15-BI15 -> 0 | BK15: =+T15+AI15+AX15+BE15+BF15 -> 0 | BL15: =+U15+AJ15+AY15+BG15 -> 0 | BM15: =+BK15-BL15 -> 0 | BN15: =+W15+AL15+BA15+BI15 -> 0 | BO15: =+BK15-BN15 -> 0 | BP15: =+BK15-BE15 -> 0 | BQ15: =+BL15-Z15 -> 0 | BR15: =+BP15-BQ15 -> 0 | BS15: =+BN15-AB15 -> 0 | BT15: =+BP15-BS15 -> 0
B16: 利用料金収入 | E16: =+ﾇｰﾍﾞﾙﾌﾟｰｽ!W15/1000 -> 0 | F16: 0 | G16: =+E16-F16 -> 0 | H16: 0 | I16: =+E16-H16 -> 0 | J16: =+ｶﾌｪﾙﾎﾟ!W15/1000 -> 0 | K16: 0 | L16: =+J16-K16 -> 0 | M16: 0 | N16: =+J16-M16 -> 0 | O16: =+ｶﾌｪｾﾚｽﾃ!W15/1000 -> 0 | P16: 0 | Q16: =+O16-P16 -> 0 | R16: 0 | S16: =+O16-R16 -> 0 | T16: =+E16+J16+O16 -> 0 | U16: =+F16+K16+P16 -> 0 | V16: =+T16-U16 -> 0 | W16: =+H16+M16+R16 -> 0 | X16: =+T16-W16 -> 0 | Y16: 0 | Z16: 0 | AA16: =+Y16-Z16 -> 0 | AB16: 0 | AC16: =+Y16-AB16 -> 0 | AD16: =+ｼﾞｭｴﾙｽﾞ!W15/1000 -> 0 | AE16: 0 | AF16: =+AD16-AE16 -> 0 | AG16: 0 | AH16: =+AD16-AG16 -> 0 | AI16: =+Y16+AD16 -> 0 | AJ16: =+Z16+AE16 -> 0 | AK16: =+AI16-AJ16 -> 0 | AL16: =+AB16+AG16 -> 0 | AM16: =+AI16-AL16 -> 0 | AN16: =+ｶﾞｰﾃﾞﾝ!W15/1000 -> 0 | AO16: 0 | AP16: =+AN16-AO16 -> 0 | AQ16: 0 | AR16: =+AN16-AQ16 -> 0 | AS16: =+ﾋﾞｱｶﾞｰﾃﾞﾝ!W15/1000 -> 0 | AT16: 0 | AU16: =+AS16-AT16 -> 0 | AV16: 0 | AW16: =+AS16-AV16 -> 0 | AX16: =+AN16+AS16 -> 0 | AY16: =+AO16+AT16 -> 0 | AZ16: =+AX16-AY16 -> 0 | BA16: =+AQ16+AV16 -> 0 | BB16: =+AX16-BA16 -> 0 | BC16: 0 | BD16: 0 | BE16: =+BC16+BD16 -> 0 | BF16: =+料飲共通!W15/1000 -> 0 | BG16: 0 | BH16: =+BF16-BG16 -> 0 | BI16: 0 | BJ16: =+BF16-BI16 -> 0 | BK16: =+T16+AI16+AX16+BE16+BF16 -> 0 | BL16: =+U16+AJ16+AY16+BG16 -> 0 | BM16: =+BK16-BL16 -> 0 | BN16: =+W16+AL16+BA16+BI16 -> 0 | BO16: =+BK16-BN16 -> 0 | BP16: =+BK16-BE16 -> 0 | BQ16: =+BL16-Z16 -> 0 | BR16: =+BP16-BQ16 -> 0 | BS16: =+BN16-AB16 -> 0 | BT16: =+BP16-BS16 -> 0
B17: 管理手数料収入 | E17: =+ﾇｰﾍﾞﾙﾌﾟｰｽ!W16/1000 -> 0 | F17: 0 | G17: =+E17-F17 -> 0 | H17: 0 | I17: =+E17-H17 -> 0 | J17: =+ｶﾌｪﾙﾎﾟ!W16/1000 -> 0 | K17: 0 | L17: =+J17-K17 -> 0 | M17: 0 | N17: =+J17-M17 -> 0 | O17: =+ｶﾌｪｾﾚｽﾃ!W16/1000 -> 0 | P17: 0 | Q17: =+O17-P17 -> 0 | R17: 0 | S17: =+O17-R17 -> 0 | T17: =+E17+J17+O17 -> 0 | U17: =+F17+K17+P17 -> 0 | V17: =+T17-U17 -> 0 | W17: =+H17+M17+R17 -> 0 | X17: =+T17-W17 -> 0 | Y17: 0 | Z17: 0 | AA17: =+Y17-Z17 -> 0 | AB17: 0 | AC17: =+Y17-AB17 -> 0 | AD17: =+ｼﾞｭｴﾙｽﾞ!W16/1000 -> 0 | AE17: 0 | AF17: =+AD17-AE17 -> 0 | AG17: 0 | AH17: =+AD17-AG17 -> 0 | AI17: =+Y17+AD17 -> 0 | AJ17: =+Z17+AE17 -> 0 | AK17: =+AI17-AJ17 -> 0 | AL17: =+AB17+AG17 -> 0 | AM17: =+AI17-AL17 -> 0 | AN17: =+ｶﾞｰﾃﾞﾝ!W16/1000 -> 0 | AO17: 0 | AP17: =+AN17-AO17 -> 0 | AQ17: 0 | AR17: =+AN17-AQ17 -> 0 | AS17: =+ﾋﾞｱｶﾞｰﾃﾞﾝ!W16/1000 -> 0 | AT17: 0 | AU17: =+AS17-AT17 -> 0 | AV17: 0 | AW17: =+AS17-AV17 -> 0 | AX17: =+AN17+AS17 -> 0 | AY17: =+AO17+AT17 -> 0 | AZ17: =+AX17-AY17 -> 0 | BA17: =+AQ17+AV17 -> 0 | BB17: =+AX17-BA17 -> 0 | BC17: 0 | BD17: 0 | BE17: =+BC17+BD17 -> 0 | BF17: =+料飲共通!W16/1000 -> 0 | BG17: 0 | BH17: =+BF17-BG17 -> 0 | BI17: 0 | BJ17: =+BF17-BI17 -> 0 | BK17: =+T17+AI17+AX17+BE17+BF17 -> 0 | BL17: =+U17+AJ17+AY17+BG17 -> 0 | BM17: =+BK17-BL17 -> 0 | BN17: =+W17+AL17+BA17+BI17 -> 0 | BO17: =+BK17-BN17 -> 0 | BP17: =+BK17-BE17 -> 0 | BQ17: =+BL17-Z17 -> 0 | BR17: =+BP17-BQ17 -> 0 | BS17: =+BN17-AB17 -> 0 | BT17: =+BP17-BS17 -> 0
A18: 売上原価 | E18: =+ﾇｰﾍﾞﾙﾌﾟｰｽ!W17/1000 -> 28482.785 | F18: 28320.083 | G18: =+E18-F18 -> 162.70169 | H18: 26899 | I18: =+E18-H18 -> 1583.785 | J18: =+ｶﾌｪﾙﾎﾟ!W17/1000 -> 2947.871 | K18: 2580.2876 | L18: =+J18-K18 -> 367.58342 | M18: 3102 | N18: =+J18-M18 -> -154.12896 | O18: =+ｶﾌｪｾﾚｽﾃ!W17/1000 -> 5992.945 | P18: 5770.5787 | Q18: =+O18-P18 -> 222.36626 | R18: 4519 | S18: =+O18-R18 -> 1473.945 | T18: =+E18+J18+O18 -> 37423.601 | U18: =+F18+K18+P18 -> 36670.95 | V18: =+T18-U18 -> 752.65136 | W18: =+H18+M18+R18 -> 34520 | X18: =+T18-W18 -> 2903.601 | Y18: 0 | Z18: 7881.9417 | AA18: =+Y18-Z18 -> -7881.9417 | AB18: 6854 | AC18: =+Y18-AB18 -> -6854 | AD18: =+ｼﾞｭｴﾙｽﾞ!W17/1000 -> 47241.415 | AE18: 44933.767 | AF18: =+AD18-AE18 -> 2307.6487 | AG18: 42361 | AH18: =+AD18-AG18 -> 4880.4152 | AI18: =+Y18+AD18 -> 47241.415 | AJ18: =+Z18+AE18 -> 52815.708 | AK18: =+AI18-AJ18 -> -5574.2931 | AL18: =+AB18+AG18 -> 49215 | AM18: =+AI18-AL18 -> -1973.5848 | AN18: =+ｶﾞｰﾃﾞﾝ!W17/1000 -> 42396.583 | AO18: 42039.85 | AP18: =+AN18-AO18 -> 356.7331 | AQ18: 39663 | AR18: =+AN18-AQ18 -> 2733.5833 | AS18: =+ﾋﾞｱｶﾞｰﾃﾞﾝ!W17/1000 -> 49044.367 | AT18: 43689.866 | AU18: =+AS18-AT18 -> 5354.5007 | AV18: 40909 | AW18: =+AS18-AV18 -> 8135.3667 | AX18: =+AN18+AS18 -> 91440.95 | AY18: =+AO18+AT18 -> 85729.716 | AZ18: =+AX18-AY18 -> 5711.2338 | BA18: =+AQ18+AV18 -> 80572 | BB18: =+AX18-BA18 -> 10868.95 | BC18: =+赤れんが!X18/1000 -> 21479 | BD18: =+赤れんが!Z18/1000 -> 17605.84 | BE18: =+BC18+BD18 -> 39084.84 | BF18: =+料飲共通!W17/1000 -> 0 | BG18: 0 | BH18: =+BF18-BG18 -> 0 | BI18: 0 | BJ18: =+BF18-BI18 -> 0 | BK18: =+T18+AI18+AX18+BE18+BF18 -> 215190.81 | BL18: =+U18+AJ18+AY18+BG18 -> 175216.37 | BM18: =+BK18-BL18 -> 39974.432 | BN18: =+W18+AL18+BA18+BI18 -> 164307 | BO18: =+BK18-BN18 -> 50883.806 | BP18: =+BK18-BE18 -> 176105.97 | BQ18: =+BL18-Z18 -> 167334.43 | BR18: =+BP18-BQ18 -> 8771.5338 | BS18: =+BN18-AB18 -> 157453 | BT18: =+BP18-BS18 -> 18652.966
A19: 売上総利益 | E19: =+ﾇｰﾍﾞﾙﾌﾟｰｽ!W18/1000 -> 69733.715 | F19: 69508.675 | G19: =+E19-F19 -> 225.04031 | H19: 62765 | I19: =+E19-H19 -> 6968.715 | J19: =+ｶﾌｪﾙﾎﾟ!W18/1000 -> 6264.226 | K19: 5612.1354 | L19: =+J19-K19 -> 652.09058 | M19: 6905 | N19: =+J19-M19 -> -640.77404 | O19: =+ｶﾌｪｾﾚｽﾃ!W18/1000 -> 13656.055 | P19: 13132.9 | Q19: =+O19-P19 -> 523.15474 | R19: 10800 | S19: =+O19-R19 -> 2856.055 | T19: =+E19+J19+O19 -> 89653.996 | U19: =+F19+K19+P19 -> 88253.71 | V19: =+T19-U19 -> 1400.2856 | W19: =+H19+M19+R19 -> 80470 | X19: =+T19-W19 -> 9183.996 | Y19: 0 | Z19: 15766.248 | AA19: =+Y19-Z19 -> -15766.248 | AB19: 13917 | AC19: =+Y19-AB19 -> -13917 | AD19: =+ｼﾞｭｴﾙｽﾞ!W18/1000 -> 117076.55 | AE19: 112979.84 | AF19: =+AD19-AE19 -> 4096.7113 | AG19: 98842 | AH19: =+AD19-AG19 -> 18234.551 | AI19: =+Y19+AD19 -> 117076.55 | AJ19: =+Z19+AE19 -> 128746.09 | AK19: =+AI19-AJ19 -> -11669.537 | AL19: =+AB19+AG19 -> 112759 | AM19: =+AI19-AL19 -> 4317.5508 | AN19: =+ｶﾞｰﾃﾞﾝ!W18/1000 -> 94366.589 | AO19: 90960.057 | AP19: =+AN19-AO19 -> 3406.5319 | AQ19: 92548 | AR19: =+AN19-AQ19 -> 1818.5887 | AS19: =+ﾋﾞｱｶﾞｰﾃﾞﾝ!W18/1000 -> 105363.93 | AT19: 97116.494 | AU19: =+AS19-AT19 -> 8247.4343 | AV19: 95456 | AW19: =+AS19-AV19 -> 9907.9283 | AX19: =+AN19+AS19 -> 199730.52 | AY19: =+AO19+AT19 -> 188076.55 | AZ19: =+AX19-AY19 -> 11653.966 | BA19: =+AQ19+AV19 -> 188004 | BB19: =+AX19-BA19 -> 11726.517 | BC19: =+BC7-BC18 -> 53886.66 | BD19: =+BD7-BD18 -> 32696.56 | BE19: =+BC19+BD19 -> 86583.22 | BF19: =+料飲共通!W18/1000 -> 0 | BG19: 0 | BH19: =+BF19-BG19 -> 0 | BI19: 0 | BJ19: =+BF19-BI19 -> 0 | BK19: =+T19+AI19+AX19+BE19+BF19 -> 493044.28 | BL19: =+U19+AJ19+AY19+BG19 -> 405076.35 | BM19: =+BK19-BL19 -> 87967.935 | BN19: =+W19+AL19+BA19+BI19 -> 381233 | BO19: =+BK19-BN19 -> 111811.28 | BP19: =+BK19-BE19 -> 406461.06 | BQ19: =+BL19-Z19 -> 389310.1 | BR19: =+BP19-BQ19 -> 17150.963 | BS19: =+BN19-AB19 -> 367316 | BT19: =+BP19-BS19 -> 39145.064
A20: 人件費 | E20: =+ﾇｰﾍﾞﾙﾌﾟｰｽ!W19/1000 -> 53667.197 | F20: 50619.247 | G20: =+E20-F20 -> 3047.95 | H20: 50248 | I20: =+E20-H20 -> 3419.197 | J20: =+ｶﾌｪﾙﾎﾟ!W19/1000 -> 2876.874 | K20: 3274.776 | L20: =+J20-K20 -> -397.902 | M20: 2838 | N20: =+J20-M20 -> 38.874 | O20: =+ｶﾌｪｾﾚｽﾃ!W19/1000 -> 2876.875 | P20: 3257.375 | Q20: =+O20-P20 -> -380.5 | R20: 2838 | S20: =+O20-R20 -> 38.875 | T20: =+E20+J20+O20 -> 59420.946 | U20: =+F20+K20+P20 -> 57151.398 | V20: =+T20-U20 -> 2269.548 | W20: =+H20+M20+R20 -> 55924 | X20: =+T20-W20 -> 3496.946 | Y20: 0 | Z20: 6101.9184 | AA20: =+Y20-Z20 -> -6101.9184 | AB20: 9311 | AC20: =+Y20-AB20 -> -9311 | AD20: =+ｼﾞｭｴﾙｽﾞ!W19/1000 -> 66777.382 | AE20: 64470.377 | AF20: =+AD20-AE20 -> 2307.0054 | AG20: 63978 | AH20: =+AD20-AG20 -> 2799.3824 | AI20: =+Y20+AD20 -> 66777.382 | AJ20: =+Z20+AE20 -> 70572.295 | AK20: =+AI20-AJ20 -> -3794.913 | AL20: =+AB20+AG20 -> 73289 | AM20: =+AI20-AL20 -> -6511.6176 | AN20: =+ｶﾞｰﾃﾞﾝ!Y19/1000 -> 58176.028 | AO20: 56094.852 | AP20: =+AN20-AO20 -> 2081.176 | AQ20: 61992 | AR20: =+AN20-AQ20 -> -3815.972 | AS20: =+ﾋﾞｱｶﾞｰﾃﾞﾝ!X19/1000 -> 24932.582 | AT20: 24040.651 | AU20: =+AS20-AT20 -> 891.93137 | AV20: 7352 | AW20: =+AS20-AV20 -> 17580.582 | AX20: =+AN20+AS20 -> 83108.61 | AY20: =+AO20+AT20 -> 80135.503 | AZ20: =+AX20-AY20 -> 2973.1074 | BA20: =+AQ20+AV20 -> 69344 | BB20: =+AX20-BA20 -> 13764.61 | BC20: =+BC21+BC22+BC23+BC27+BC30+BC31+BC32+BC36+BC37 -> 30146 | BD20: =+BD21+BD22+BD23+BD27+BD30+BD31+BD32+BD36+BD37 -> 16230 | BE20: =+BC20+BD20 -> 46376 | BF20: =+料飲共通!W19/1000 -> 25580.282 | BG20: 25495.928 | BH20: =+BF20-BG20 -> 84.354448 | BI20: 28147 | BJ20: =+BF20-BI20 -> -2566.7176 | BK20: =+T20+AI20+AX20+BE20+BF20 -> 281263.22 | BL20: =+U20+AJ20+AY20+BG20 -> 233355.12 | BM20: =+BK20-BL20 -> 47908.097 | BN20: =+W20+AL20+BA20+BI20 -> 226704 | BO20: =+BK20-BN20 -> 54559.221 | BP20: =+BK20-BE20 -> 234887.22 | BQ20: =+BL20-Z20 -> 227253.21 | BR20: =+BP20-BQ20 -> 7634.0152 | BS20: =+BN20-AB20 -> 217393 | BT20: =+BP20-BS20 -> 17494.221
B21: 役員報酬 | E21: =+ﾇｰﾍﾞﾙﾌﾟｰｽ!W20/1000 -> 0 | F21: 0 | G21: =+E21-F21 -> 0 | H21: 0 | I21: =+E21-H21 -> 0 | J21: =+ｶﾌｪﾙﾎﾟ!W20/1000 -> 0 | K21: 0 | L21: =+J21-K21 -> 0 | M21: 0 | N21: =+J21-M21 -> 0 | O21: =+ｶﾌｪｾﾚｽﾃ!W20/1000 -> 0 | P21: 0 | Q21: =+O21-P21 -> 0 | R21: 0 | S21: =+O21-R21 -> 0 | T21: =+E21+J21+O21 -> 0 | U21: =+F21+K21+P21 -> 0 | V21: =+T21-U21 -> 0 | W21: =+H21+M21+R21 -> 0 | X21: =+T21-W21 -> 0 | Y21: 0 | Z21: 0 | AA21: =+Y21-Z21 -> 0 | AB21: 0 | AC21: =+Y21-AB21 -> 0 | AD21: =+ｼﾞｭｴﾙｽﾞ!W20/1000 -> 0 | AE21: 0 | AF21: =+AD21-AE21 -> 0 | AG21: 0 | AH21: =+AD21-AG21 -> 0 | AI21: =+Y21+AD21 -> 0 | AJ21: =+Z21+AE21 -> 0 | AK21: =+AI21-AJ21 -> 0 | AL21: =+AB21+AG21 -> 0 | AM21: =+AI21-AL21 -> 0 | AN21: =+ｶﾞｰﾃﾞﾝ!Y20/1000 -> 0 | AO21: 0 | AP21: =+AN21-AO21 -> 0 | AQ21: 0 | AR21: =+AN21-AQ21 -> 0 | AS21: =+ﾋﾞｱｶﾞｰﾃﾞﾝ!X20/1000 -> 0 | AT21: 0 | AU21: =+AS21-AT21 -> 0 | AV21: 0 | AW21: =+AS21-AV21 -> 0 | AX21: =+AN21+AS21 -> 0 | AY21: =+AO21+AT21 -> 0 | AZ21: =+AX21-AY21 -> 0 | BA21: =+AQ21+AV21 -> 0 | BB21: =+AX21-BA21 -> 0 | BD21: 0 | BE21: =+BC21+BD21 -> 0 | BF21: =+料飲共通!W20/1000 -> 0 | BG21: 0 | BH21: =+BF21-BG21 -> 0 | BI21: 0 | BJ21: =+BF21-BI21 -> 0 | BK21: =+T21+AI21+AX21+BE21+BF21 -> 0 | BL21: =+U21+AJ21+AY21+BG21 -> 0 | BM21: =+BK21-BL21 -> 0 | BN21: =+W21+AL21+BA21+BI21 -> 0 | BO21: =+BK21-BN21 -> 0 | BP21: =+BK21-BE21 -> 0 | BQ21: =+BL21-Z21 -> 0 | BR21: =+BP21-BQ21 -> 0 | BS21: =+BN21-AB21 -> 0 | BT21: =+BP21-BS21 -> 0
B22: 社員給与費 | E22: =+ﾇｰﾍﾞﾙﾌﾟｰｽ!W21/1000 -> 0 | F22: 0 | G22: =+E22-F22 -> 0 | H22: 0 | I22: =+E22-H22 -> 0 | J22: =+ｶﾌｪﾙﾎﾟ!W21/1000 -> 0 | K22: 0 | L22: =+J22-K22 -> 0 | M22: 0 | N22: =+J22-M22 -> 0 | O22: =+ｶﾌｪｾﾚｽﾃ!W21/1000 -> 0 | P22: 0 | Q22: =+O22-P22 -> 0 | R22: 0 | S22: =+O22-R22 -> 0 | T22: =+E22+J22+O22 -> 0 | U22: =+F22+K22+P22 -> 0 | V22: =+T22-U22 -> 0 | W22: =+H22+M22+R22 -> 0 | X22: =+T22-W22 -> 0 | Y22: 0 | Z22: 0 | AA22: =+Y22-Z22 -> 0 | AB22: 0 | AC22: =+Y22-AB22 -> 0 | AD22: =+ｼﾞｭｴﾙｽﾞ!W21/1000 -> 0 | AE22: 13.1 | AF22: =+AD22-AE22 -> -13.1 | AG22: 0 | AH22: =+AD22-AG22 -> 0 | AI22: =+Y22+AD22 -> 0 | AJ22: =+Z22+AE22 -> 13.1 | AK22: =+AI22-AJ22 -> -13.1 | AL22: =+AB22+AG22 -> 0 | AM22: =+AI22-AL22 -> 0 | AN22: =+ｶﾞｰﾃﾞﾝ!Y21/1000 -> 0 | AO22: 0 | AP22: =+AN22-AO22 -> 0 | AQ22: 0 | AR22: =+AN22-AQ22 -> 0 | AS22: =+ﾋﾞｱｶﾞｰﾃﾞﾝ!X21/1000 -> 0 | AT22: 0 | AU22: =+AS22-AT22 -> 0 | AV22: 0 | AW22: =+AS22-AV22 -> 0 | AX22: =+AN22+AS22 -> 0 | AY22: =+AO22+AT22 -> 0 | AZ22: =+AX22-AY22 -> 0 | BA22: =+AQ22+AV22 -> 0 | BB22: =+AX22-BA22 -> 0 | BC22: 0 | BD22: 0 | BE22: =+BC22+BD22 -> 0 | BF22: =+料飲共通!W21/1000 -> 21846.07 | BG22: 21621.517 | BH22: =+BF22-BG22 -> 224.553 | BI22: 20811 | BJ22: =+BF22-BI22 -> 1035.07 | BK22: =+T22+AI22+AX22+BE22+BF22 -> 21846.07 | BL22: =+U22+AJ22+AY22+BG22 -> 21634.617 | BM22: =+BK22-BL22 -> 211.453 | BN22: =+W22+AL22+BA22+BI22 -> 20811 | BO22: =+BK22-BN22 -> 1035.07 | BP22: =+BK22-BE22 -> 21846.07 | BQ22: =+BL22-Z22 -> 21634.617 | BR22: =+BP22-BQ22 -> 211.453 | BS22: =+BN22-AB22 -> 20811 | BT22: =+BP22-BS22 -> 1035.07
B23: 専門等給与費 | E23: =+ﾇｰﾍﾞﾙﾌﾟｰｽ!W22/1000 -> 44651.64 | F23: 43294.594 | G23: =+E23-F23 -> 1357.046 | H23: 41992 | I23: =+E23-H23 -> 2659.64 | J23: =+ｶﾌｪﾙﾎﾟ!W22/1000 -> 2524.2 | K23: 2933.994 | L23: =+J23-K23 -> -409.794 | M23: 2532 | N23: =+J23-M23 -> -7.8 | O23: =+ｶﾌｪｾﾚｽﾃ!W22/1000 -> 2524.2 | P23: 2933.994 | Q23: =+O23-P23 -> -409.794 | R23: 2532 | S23: =+O23-R23 -> -7.8 | T23: =+E23+J23+O23 -> 49700.04 | U23: =+F23+K23+P23 -> 49162.582 | V23: =+T23-U23 -> 537.458 | W23: =+H23+M23+R23 -> 47056 | X23: =+T23-W23 -> 2644.04 | Y23: 0 | Z23: 5497.3054 | AA23: =+Y23-Z23 -> -5497.3054 | AB23: 8241 | AC23: =+Y23-AB23 -> -8241 | AD23: =+ｼﾞｭｴﾙｽﾞ!W22/1000 -> 55698.34 | AE23: 55178.98 | AF23: =+AD23-AE23 -> 519.36 | AG23: 54040 | AH23: =+AD23-AG23 -> 1658.34 | AI23: =+Y23+AD23 -> 55698.34 | AJ23: =+Z23+AE23 -> 60676.285 | AK23: =+AI23-AJ23 -> -4977.9454 | AL23: =+AB23+AG23 -> 62281 | AM23: =+AI23-AL23 -> -6582.66 | AN23: =+ｶﾞｰﾃﾞﾝ!Y22/1000 -> 49303.667 | AO23: 48006.785 | AP23: =+AN23-AO23 -> 1296.882 | AQ23: 53804 | AR23: =+AN23-AQ23 -> -4500.333 | AS23: =+ﾋﾞｱｶﾞｰﾃﾞﾝ!X22/1000 -> 21130.143 | AT23: 20574.337 | AU23: =+AS23-AT23 -> 555.806 | AV23: 6340 | AW23: =+AS23-AV23 -> 14790.143 | AX23: =+AN23+AS23 -> 70433.81 | AY23: =+AO23+AT23 -> 68581.122 | AZ23: =+AX23-AY23 -> 1852.688 | BA23: =+AQ23+AV23 -> 60144 | BB23: =+AX23-BA23 -> 10289.81 | BC23: =+赤れんが!X20/1000 -> 30146 | BD23: =+赤れんが!Z20/1000 -> 16230 | BE23: =+BC23+BD23 -> 46376 | BF23: =+料飲共通!W22/1000 -> 0 | BG23: 0 | BH23: =+BF23-BG23 -> 0 | BI23: 3150 | BJ23: =+BF23-BI23 -> -3150 | BK23: =+T23+AI23+AX23+BE23+BF23 -> 222208.19 | BL23: =+U23+AJ23+AY23+BG23 -> 178419.99 | BM23: =+BK23-BL23 -> 43788.201 | BN23: =+W23+AL23+BA23+BI23 -> 172631 | BO23: =+BK23-BN23 -> 49577.19 | BP23: =+BK23-BE23 -> 175832.19 | BQ23: =+BL23-Z23 -> 172922.68 | BR23: =+BP23-BQ23 -> 2909.506 | BS23: =+BN23-AB23 -> 164390 | BT23: =+BP23-BS23 -> 11442.19
C24: 専門 | E24: =+ﾇｰﾍﾞﾙﾌﾟｰｽ!W23/1000 -> 44462.64 | F24: 41495.924 | G24: =+E24-F24 -> 2966.716 | H24: 41110 | I24: =+E24-H24 -> 3352.64 | J24: =+ｶﾌｪﾙﾎﾟ!W23/1000 -> 0 | K24: 0 | L24: =+J24-K24 -> 0 | M24: 0 | N24: =+J24-M24 -> 0 | O24: =+ｶﾌｪｾﾚｽﾃ!W23/1000 -> 0 | P24: 0 | Q24: =+O24-P24 -> 0 | R24: 0 | S24: =+O24-R24 -> 0 | T24: =+E24+J24+O24 -> 44462.64 | U24: =+F24+K24+P24 -> 41495.924 | V24: =+T24-U24 -> 2966.716 | W24: =+H24+M24+R24 -> 41110 | X24: =+T24-W24 -> 3352.64 | Y24: 0 | Z24: 2105.471 | AA24: =+Y24-Z24 -> -2105.471 | AB24: 3747 | AC24: =+Y24-AB24 -> -3747 | AD24: =+ｼﾞｭｴﾙｽﾞ!W23/1000 -> 50391.64 | AE24: 49336.023 | AF24: =+AD24-AE24 -> 1055.617 | AG24: 46648 | AH24: =+AD24-AG24 -> 3743.64 | AI24: =+Y24+AD24 -> 50391.64 | AJ24: =+Z24+AE24 -> 51441.494 | AK24: =+AI24-AJ24 -> -1049.854 | AL24: =+AB24+AG24 -> 50395 | AM24: =+AI24-AL24 -> -3.36 | AN24: =+ｶﾞｰﾃﾞﾝ!W23/1000 -> 63275.81 | AO24: 40063.794 | AP24: =+AN24-AO24 -> 23212.016 | AQ24: 43908 | AR24: =+AN24-AQ24 -> 19367.81 | AS24: =+ﾋﾞｱｶﾞｰﾃﾞﾝ!W23/1000 -> 0 | AT24: 17170.198 | AU24: =+AS24-AT24 -> -17170.198 | AV24: 6340 | AW24: =+AS24-AV24 -> -6340 | AX24: =+AN24+AS24 -> 63275.81 | AY24: =+AO24+AT24 -> 57233.992 | AZ24: =+AX24-AY24 -> 6041.818 | BA24: =+AQ24+AV24 -> 50248 | BB24: =+AX24-BA24 -> 13027.81 | BC24: 0 | BD24: 0 | BE24: =+BC24+BD24 -> 0 | BF24: =+料飲共通!W23/1000 -> 0 | BG24: 0 | BH24: =+BF24-BG24 -> 0 | BI24: 0 | BJ24: =+BF24-BI24 -> 0 | BK24: =+T24+AI24+AX24+BE24+BF24 -> 158130.09 | BL24: =+U24+AJ24+AY24+BG24 -> 150171.41 | BM24: =+BK24-BL24 -> 7958.68 | BN24: =+W24+AL24+BA24+BI24 -> 141753 | BO24: =+BK24-BN24 -> 16377.09 | BP24: =+BK24-BE24 -> 158130.09 | BQ24: =+BL24-Z24 -> 148065.94 | BR24: =+BP24-BQ24 -> 10064.151 | BS24: =+BN24-AB24 -> 138006 | BT24: =+BP24-BS24 -> 20124.09
C25: 臨時 | E25: =+ﾇｰﾍﾞﾙﾌﾟｰｽ!W24/1000 -> 0 | F25: 0 | G25: =+E25-F25 -> 0 | H25: 0 | I25: =+E25-H25 -> 0 | J25: =+ｶﾌｪﾙﾎﾟ!W24/1000 -> 0 | K25: 0 | L25: =+J25-K25 -> 0 | M25: 0 | N25: =+J25-M25 -> 0 | O25: =+ｶﾌｪｾﾚｽﾃ!W24/1000 -> 0 | P25: 0 | Q25: =+O25-P25 -> 0 | R25: 0 | S25: =+O25-R25 -> 0 | T25: =+E25+J25+O25 -> 0 | U25: =+F25+K25+P25 -> 0 | V25: =+T25-U25 -> 0 | W25: =+H25+M25+R25 -> 0 | X25: =+T25-W25 -> 0 | Y25: 0 | Z25: 0 | AA25: =+Y25-Z25 -> 0 | AB25: 0 | AC25: =+Y25-AB25 -> 0 | AD25: =+ｼﾞｭｴﾙｽﾞ!W24/1000 -> 0 | AE25: 0 | AF25: =+AD25-AE25 -> 0 | AG25: 0 | AH25: =+AD25-AG25 -> 0 | AI25: =+Y25+AD25 -> 0 | AJ25: =+Z25+AE25 -> 0 | AK25: =+AI25-AJ25 -> 0 | AL25: =+AB25+AG25 -> 0 | AM25: =+AI25-AL25 -> 0 | AN25: =+ｶﾞｰﾃﾞﾝ!W24/1000 -> 0 | AO25: 0 | AP25: =+AN25-AO25 -> 0 | AQ25: 0 | AR25: =+AN25-AQ25 -> 0 | AS25: =+ﾋﾞｱｶﾞｰﾃﾞﾝ!W24/1000 -> 0 | AT25: 0 | AU25: =+AS25-AT25 -> 0 | AV25: 0 | AW25: =+AS25-AV25 -> 0 | AX25: =+AN25+AS25 -> 0 | AY25: =+AO25+AT25 -> 0 | AZ25: =+AX25-AY25 -> 0 | BA25: =+AQ25+AV25 -> 0 | BB25: =+AX25-BA25 -> 0 | BC25: 0 | BD25: 0 | BE25: =+BC25+BD25 -> 0 | BF25: =+料飲共通!W24/1000 -> 0 | BG25: 0 | BH25: =+BF25-BG25 -> 0 | BI25: 0 | BJ25: =+BF25-BI25 -> 0 | BK25: =+T25+AI25+AX25+BE25+BF25 -> 0 | BL25: =+U25+AJ25+AY25+BG25 -> 0 | BM25: =+BK25-BL25 -> 0 | BN25: =+W25+AL25+BA25+BI25 -> 0 | BO25: =+BK25-BN25 -> 0 | BP25: =+BK25-BE25 -> 0 | BQ25: =+BL25-Z25 -> 0 | BR25: =+BP25-BQ25 -> 0 | BS25: =+BN25-AB25 -> 0 | BT25: =+BP25-BS25 -> 0
C26: パート | E26: =+ﾇｰﾍﾞﾙﾌﾟｰｽ!W25/1000 -> 189 | F26: 1798.67 | G26: =+E26-F26 -> -1609.67 | H26: 882 | I26: =+E26-H26 -> -693 | J26: =+ｶﾌｪﾙﾎﾟ!W25/1000 -> 2524.2 | K26: 2933.994 | L26: =+J26-K26 -> -409.794 | M26: 2532 | N26: =+J26-M26 -> -7.8 | O26: =+ｶﾌｪｾﾚｽﾃ!W25/1000 -> 2524.2 | P26: 2933.994 | Q26: =+O26-P26 -> -409.794 | R26: 2532 | S26: =+O26-R26 -> -7.8 | T26: =+E26+J26+O26 -> 5237.4 | U26: =+F26+K26+P26 -> 7666.658 | V26: =+T26-U26 -> -2429.258 | W26: =+H26+M26+R26 -> 5946 | X26: =+T26-W26 -> -708.6 | Y26: 0 | Z26: 3391.8344 | AA26: =+Y26-Z26 -> -3391.8344 | AB26: 4494 | AC26: =+Y26-AB26 -> -4494 | AD26: =+ｼﾞｭｴﾙｽﾞ!W25/1000 -> 5306.7 | AE26: 5842.957 | AF26: =+AD26-AE26 -> -536.257 | AG26: 7392 | AH26: =+AD26-AG26 -> -2085.3 | AI26: =+Y26+AD26 -> 5306.7 | AJ26: =+Z26+AE26 -> 9234.7914 | AK26: =+AI26-AJ26 -> -3928.0914 | AL26: =+AB26+AG26 -> 11886 | AM26: =+AI26-AL26 -> -6579.3 | AN26: =+ｶﾞｰﾃﾞﾝ!W25/1000 -> 3528 | AO26: 7942.991 | AP26: =+AN26-AO26 -> -4414.991 | AQ26: 9896 | AR26: =+AN26-AQ26 -> -6368 | AS26: =+ﾋﾞｱｶﾞｰﾃﾞﾝ!W25/1000 -> 3630 | AT26: 3404.139 | AU26: =+AS26-AT26 -> 225.861 | AV26: 0 | AW26: =+AS26-AV26 -> 3630 | AX26: =+AN26+AS26 -> 7158 | AY26: =+AO26+AT26 -> 11347.13 | AZ26: =+AX26-AY26 -> -4189.13 | BA26: =+AQ26+AV26 -> 9896 | BB26: =+AX26-BA26 -> -2738 | BC26: 0 | BD26: 0 | BE26: =+BC26+BD26 -> 0 | BF26: =+料飲共通!W25/1000 -> 0 | BG26: 0 | BH26: =+BF26-BG26 -> 0 | BI26: 3150 | BJ26: =+BF26-BI26 -> -3150 | BK26: =+T26+AI26+AX26+BE26+BF26 -> 17702.1 | BL26: =+U26+AJ26+AY26+BG26 -> 28248.579 | BM26: =+BK26-BL26 -> -10546.479 | BN26: =+W26+AL26+BA26+BI26 -> 30878 | BO26: =+BK26-BN26 -> -13175.9 | BP26: =+BK26-BE26 -> 17702.1 | BQ26: =+BL26-Z26 -> 24856.745 | BR26: =+BP26-BQ26 -> -7154.645 | BS26: =+BN26-AB26 -> 26384 | BT26: =+BP26-BS26 -> -8681.9
B27: 退職金 | E27: =+ﾇｰﾍﾞﾙﾌﾟｰｽ!W26/1000 -> 0 | F27: 0 | G27: =+E27-F27 -> 0 | H27: 0 | I27: =+E27-H27 -> 0 | J27: =+ｶﾌｪﾙﾎﾟ!W26/1000 -> 0 | K27: 0 | L27: =+J27-K27 -> 0 | M27: 0 | N27: =+J27-M27 -> 0 | O27: =+ｶﾌｪｾﾚｽﾃ!W26/1000 -> 0 | P27: 0 | Q27: =+O27-P27 -> 0 | R27: 0 | S27: =+O27-R27 -> 0 | T27: =+E27+J27+O27 -> 0 | U27: =+F27+K27+P27 -> 0 | V27: =+T27-U27 -> 0 | W27: =+H27+M27+R27 -> 0 | X27: =+T27-W27 -> 0 | Y27: 0 | Z27: 0 | AA27: =+Y27-Z27 -> 0 | AB27: 0 | AC27: =+Y27-AB27 -> 0 | AD27: =+ｼﾞｭｴﾙｽﾞ!W26/1000 -> 0 | AE27: 0 | AF27: =+AD27-AE27 -> 0 | AG27: 0 | AH27: =+AD27-AG27 -> 0 | AI27: =+Y27+AD27 -> 0 | AJ27: =+Z27+AE27 -> 0 | AK27: =+AI27-AJ27 -> 0 | AL27: =+AB27+AG27 -> 0 | AM27: =+AI27-AL27 -> 0 | AN27: =+ｶﾞｰﾃﾞﾝ!Y26/1000 -> 0 | AO27: 0 | AP27: =+AN27-AO27 -> 0 | AQ27: 0 | AR27: =+AN27-AQ27 -> 0 | AS27: =+ﾋﾞｱｶﾞｰﾃﾞﾝ!X26/1000 -> 0 | AT27: 0 | AU27: =+AS27-AT27 -> 0 | AV27: 0 | AW27: =+AS27-AV27 -> 0 | AX27: =+AN27+AS27 -> 0 | AY27: =+AO27+AT27 -> 0 | AZ27: =+AX27-AY27 -> 0 | BA27: =+AQ27+AV27 -> 0 | BB27: =+AX27-BA27 -> 0 | BC27: 0 | BD27: 0 | BE27: =+BC27+BD27 -> 0 | BF27: =+料飲共通!W26/1000 -> 0 | BG27: 0 | BH27: =+BF27-BG27 -> 0 | BI27: 0 | BJ27: =+BF27-BI27 -> 0 | BK27: =+T27+AI27+AX27+BE27+BF27 -> 0 | BL27: =+U27+AJ27+AY27+BG27 -> 0 | BM27: =+BK27-BL27 -> 0 | BN27: =+W27+AL27+BA27+BI27 -> 0 | BO27: =+BK27-BN27 -> 0 | BP27: =+BK27-BE27 -> 0 | BQ27: =+BL27-Z27 -> 0 | BR27: =+BP27-BQ27 -> 0 | BS27: =+BN27-AB27 -> 0 | BT27: =+BP27-BS27 -> 0
C28: 役員 | E28: =+ﾇｰﾍﾞﾙﾌﾟｰｽ!W27/1000 -> 0 | F28: 0 | G28: =+E28-F28 -> 0 | H28: 0 | I28: =+E28-H28 -> 0 | J28: =+ｶﾌｪﾙﾎﾟ!W27/1000 -> 0 | K28: 0 | L28: =+J28-K28 -> 0 | M28: 0 | N28: =+J28-M28 -> 0 | O28: =+ｶﾌｪｾﾚｽﾃ!W27/1000 -> 0 | P28: 0 | Q28: =+O28-P28 -> 0 | R28: 0 | S28: =+O28-R28 -> 0 | T28: =+E28+J28+O28 -> 0 | U28: =+F28+K28+P28 -> 0 | V28: =+T28-U28 -> 0 | W28: =+H28+M28+R28 -> 0 | X28: =+T28-W28 -> 0 | Y28: 0 | Z28: 0 | AA28: =+Y28-Z28 -> 0 | AB28: 0 | AC28: =+Y28-AB28 -> 0 | AD28: =+ｼﾞｭｴﾙｽﾞ!W27/1000 -> 0 | AE28: 0 | AF28: =+AD28-AE28 -> 0 | AG28: 0 | AH28: =+AD28-AG28 -> 0 | AI28: =+Y28+AD28 -> 0 | AJ28: =+Z28+AE28 -> 0 | AK28: =+AI28-AJ28 -> 0 | AL28: =+AB28+AG28 -> 0 | AM28: =+AI28-AL28 -> 0 | AN28: =+ｶﾞｰﾃﾞﾝ!W27/1000 -> 0 | AO28: 0 | AP28: =+AN28-AO28 -> 0 | AQ28: 0 | AR28: =+AN28-AQ28 -> 0 | AS28: =+ﾋﾞｱｶﾞｰﾃﾞﾝ!W27/1000 -> 0 | AT28: 0 | AU28: =+AS28-AT28 -> 0 | AV28: 0 | AW28: =+AS28-AV28 -> 0 | AX28: =+AN28+AS28 -> 0 | AY28: =+AO28+AT28 -> 0 | AZ28: =+AX28-AY28 -> 0 | BA28: =+AQ28+AV28 -> 0 | BB28: =+AX28-BA28 -> 0 | BC28: 0 | BD28: 0 | BE28: =+BC28+BD28 -> 0 | BF28: =+料飲共通!W27/1000 -> 0 | BG28: 0 | BH28: =+BF28-BG28 -> 0 | BI28: 0 | BJ28: =+BF28-BI28 -> 0 | BK28: =+T28+AI28+AX28+BE28+BF28 -> 0 | BL28: =+U28+AJ28+AY28+BG28 -> 0 | BM28: =+BK28-BL28 -> 0 | BN28: =+W28+AL28+BA28+BI28 -> 0 | BO28: =+BK28-BN28 -> 0 | BP28: =+BK28-BE28 -> 0 | BQ28: =+BL28-Z28 -> 0 | BR28: =+BP28-BQ28 -> 0 | BS28: =+BN28-AB28 -> 0 | BT28: =+BP28-BS28 -> 0
C29: 社員 | E29: =+ﾇｰﾍﾞﾙﾌﾟｰｽ!W28/1000 -> 0 | F29: 0 | G29: =+E29-F29 -> 0 | H29: 0 | I29: =+E29-H29 -> 0 | J29: =+ｶﾌｪﾙﾎﾟ!W28/1000 -> 0 | K29: 0 | L29: =+J29-K29 -> 0 | M29: 0 | N29: =+J29-M29 -> 0 | O29: =+ｶﾌｪｾﾚｽﾃ!W28/1000 -> 0 | P29: 0 | Q29: =+O29-P29 -> 0 | R29: 0 | S29: =+O29-R29 -> 0 | T29: =+E29+J29+O29 -> 0 | U29: =+F29+K29+P29 -> 0 | V29: =+T29-U29 -> 0 | W29: =+H29+M29+R29 -> 0 | X29: =+T29-W29 -> 0 | Y29: 0 | Z29: 0 | AA29: =+Y29-Z29 -> 0 | AB29: 0 | AC29: =+Y29-AB29 -> 0 | AD29: =+ｼﾞｭｴﾙｽﾞ!W28/1000 -> 0 | AE29: 0 | AF29: =+AD29-AE29 -> 0 | AG29: 0 | AH29: =+AD29-AG29 -> 0 | AI29: =+Y29+AD29 -> 0 | AJ29: =+Z29+AE29 -> 0 | AK29: =+AI29-AJ29 -> 0 | AL29: =+AB29+AG29 -> 0 | AM29: =+AI29-AL29 -> 0 | AN29: =+ｶﾞｰﾃﾞﾝ!W28/1000 -> 0 | AO29: 0 | AP29: =+AN29-AO29 -> 0 | AQ29: 0 | AR29: =+AN29-AQ29 -> 0 | AS29: =+ﾋﾞｱｶﾞｰﾃﾞﾝ!W28/1000 -> 0 | AT29: 0 | AU29: =+AS29-AT29 -> 0 | AV29: 0 | AW29: =+AS29-AV29 -> 0 | AX29: =+AN29+AS29 -> 0 | AY29: =+AO29+AT29 -> 0 | AZ29: =+AX29-AY29 -> 0 | BA29: =+AQ29+AV29 -> 0 | BB29: =+AX29-BA29 -> 0 | BC29: 0 | BD29: 0 | BE29: =+BC29+BD29 -> 0 | BF29: =+料飲共通!W28/1000 -> 0 | BG29: 0 | BH29: =+BF29-BG29 -> 0 | BI29: 0 | BJ29: =+BF29-BI29 -> 0 | BK29: =+T29+AI29+AX29+BE29+BF29 -> 0 | BL29: =+U29+AJ29+AY29+BG29 -> 0 | BM29: =+BK29-BL29 -> 0 | BN29: =+W29+AL29+BA29+BI29 -> 0 | BO29: =+BK29-BN29 -> 0 | BP29: =+BK29-BE29 -> 0 | BQ29: =+BL29-Z29 -> 0 | BR29: =+BP29-BQ29 -> 0 | BS29: =+BN29-AB29 -> 0 | BT29: =+BP29-BS29 -> 0
B30: 法定福利費 | E30: =+ﾇｰﾍﾞﾙﾌﾟｰｽ!W29/1000 -> 7178.685 | F30: 5733.793 | G30: =+E30-F30 -> 1444.892 | H30: 6921 | I30: =+E30-H30 -> 257.68498 | J30: =+ｶﾌｪﾙﾎﾟ!W29/1000 -> 241.664 | K30: 245.156 | L30: =+J30-K30 -> -3.492 | M30: 240 | N30: =+J30-M30 -> 1.664 | O30: =+ｶﾌｪｾﾚｽﾃ!W29/1000 -> 241.665 | P30: 245.156 | Q30: =+O30-P30 -> -3.491 | R30: 240 | S30: =+O30-R30 -> 1.665 | T30: =+E30+J30+O30 -> 7662.014 | U30: =+F30+K30+P30 -> 6224.105 | V30: =+T30-U30 -> 1437.909 | W30: =+H30+M30+R30 -> 7401 | X30: =+T30-W30 -> 261.01398 | Y30: 0 | Z30: 361.254 | AA30: =+Y30-Z30 -> -361.254 | AB30: 689 | AC30: =+Y30-AB30 -> -689 | AD30: =+ｼﾞｭｴﾙｽﾞ!W29/1000 -> 8543.7104 | AE30: 7112.791 | AF30: =+AD30-AE30 -> 1430.9194 | AG30: 7741 | AH30: =+AD30-AG30 -> 802.71042 | AI30: =+Y30+AD30 -> 8543.7104 | AJ30: =+Z30+AE30 -> 7474.045 | AK30: =+AI30-AJ30 -> 1069.6654 | AL30: =+AB30+AG30 -> 8430 | AM30: =+AI30-AL30 -> 113.71042 | AN30: =+ｶﾞｰﾃﾞﾝ!Y29/1000 -> 6767.259 | AO30: 5805.373 | AP30: =+AN30-AO30 -> 961.886 | AQ30: 7759 | AR30: =+AN30-AQ30 -> -991.741 | AS30: =+ﾋﾞｱｶﾞｰﾃﾞﾝ!X29/1000 -> 2900.2534 | AT30: 2488.017 | AU30: =+AS30-AT30 -> 412.23637 | AV30: 880 | AW30: =+AS30-AV30 -> 2020.2534 | AX30: =+AN30+AS30 -> 9667.5124 | AY30: =+AO30+AT30 -> 8293.39 | AZ30: =+AX30-AY30 -> 1374.1224 | BA30: =+AQ30+AV30 -> 8639 | BB30: =+AX30-BA30 -> 1028.5124 | BC30: 0 | BD30: 0 | BE30: =+BC30+BD30 -> 0 | BF30: =+料飲共通!W29/1000 -> 3421.3564 | BG30: 3202.207 | BH30: =+BF30-BG30 -> 219.14945 | BI30: 3849 | BJ30: =+BF30-BI30 -> -427.64355 | BK30: =+T30+AI30+AX30+BE30+BF30 -> 29294.593 | BL30: =+U30+AJ30+AY30+BG30 -> 25193.747 | BM30: =+BK30-BL30 -> 4100.8462 | BN30: =+W30+AL30+BA30+BI30 -> 28319 | BO30: =+BK30-BN30 -> 975.59322 | BP30: =+BK30-BE30 -> 29294.593 | BQ30: =+BL30-Z30 -> 24832.493 | BR30: =+BP30-BQ30 -> 4462.1002 | BS30: =+BN30-AB30 -> 27630 | BT30: =+BP30-BS30 -> 1664.5932
B31: 退職年金掛金 | E31: =+ﾇｰﾍﾞﾙﾌﾟｰｽ!W30/1000 -> 52.8 | F31: 43.6 | G31: =+E31-F31 -> 9.2 | H31: 48 | I31: =+E31-H31 -> 4.8 | J31: =+ｶﾌｪﾙﾎﾟ!W30/1000 -> 0 | K31: 0 | L31: =+J31-K31 -> 0 | M31: 0 | N31: =+J31-M31 -> 0 | O31: =+ｶﾌｪｾﾚｽﾃ!W30/1000 -> 0 | P31: 0 | Q31: =+O31-P31 -> 0 | R31: 0 | S31: =+O31-R31 -> 0 | T31: =+E31+J31+O31 -> 52.8 | U31: =+F31+K31+P31 -> 43.6 | V31: =+T31-U31 -> 9.2 | W31: =+H31+M31+R31 -> 48 | X31: =+T31-W31 -> 4.8 | Y31: 0 | Z31: 2.4 | AA31: =+Y31-Z31 -> -2.4 | AB31: 3 | AC31: =+Y31-AB31 -> -3 | AD31: =+ｼﾞｭｴﾙｽﾞ!W30/1000 -> 62.4 | AE31: 51.2 | AF31: =+AD31-AE31 -> 11.2 | AG31: 57 | AH31: =+AD31-AG31 -> 5.4 | AI31: =+Y31+AD31 -> 62.4 | AJ31: =+Z31+AE31 -> 53.6 | AK31: =+AI31-AJ31 -> 8.8 | AL31: =+AB31+AG31 -> 60 | AM31: =+AI31-AL31 -> 2.4 | AN31: =+ｶﾞｰﾃﾞﾝ!Y30/1000 -> 50.4 | AO31: 50.12 | AP31: =+AN31-AO31 -> 0.28 | AQ31: 52 | AR31: =+AN31-AQ31 -> -1.6 | AS31: =+ﾋﾞｱｶﾞｰﾃﾞﾝ!X30/1000 -> 21.6 | AT31: 21.48 | AU31: =+AS31-AT31 -> 0.12 | AV31: 6 | AW31: =+AS31-AV31 -> 15.6 | AX31: =+AN31+AS31 -> 72 | AY31: =+AO31+AT31 -> 71.6 | AZ31: =+AX31-AY31 -> 0.4 | BA31: =+AQ31+AV31 -> 58 | BB31: =+AX31-BA31 -> 14 | BC31: 0 | BD31: 0 | BE31: =+BC31+BD31 -> 0 | BF31: =+料飲共通!W30/1000 -> 14.4 | BG31: 14.4 | BH31: =+BF31-BG31 -> 0 | BI31: 14 | BJ31: =+BF31-BI31 -> 0.4 | BK31: =+T31+AI31+AX31+BE31+BF31 -> 201.6 | BL31: =+U31+AJ31+AY31+BG31 -> 183.2 | BM31: =+BK31-BL31 -> 18.4 | BN31: =+W31+AL31+BA31+BI31 -> 180 | BO31: =+BK31-BN31 -> 21.6 | BP31: =+BK31-BE31 -> 201.6 | BQ31: =+BL31-Z31 -> 180.8 | BR31: =+BP31-BQ31 -> 20.8 | BS31: =+BN31-AB31 -> 177 | BT31: =+BP31-BS31 -> 24.6
B32: 福利厚生費 | E32: =+ﾇｰﾍﾞﾙﾌﾟｰｽ!W31/1000 -> 609.2 | F32: 489.014 | G32: =+E32-F32 -> 120.186 | H32: 322 | I32: =+E32-H32 -> 287.2 | J32: =+ｶﾌｪﾙﾎﾟ!W31/1000 -> 0 | K32: 17.4 | L32: =+J32-K32 -> -17.4 | M32: 0 | N32: =+J32-M32 -> 0 | O32: =+ｶﾌｪｾﾚｽﾃ!W31/1000 -> 0 | P32: 0 | Q32: =+O32-P32 -> 0 | R32: 0 | S32: =+O32-R32 -> 0 | T32: =+E32+J32+O32 -> 609.2 | U32: =+F32+K32+P32 -> 506.414 | V32: =+T32-U32 -> 102.786 | W32: =+H32+M32+R32 -> 322 | X32: =+T32-W32 -> 287.2 | Y32: 0 | Z32: 3.6 | AA32: =+Y32-Z32 -> -3.6 | AB32: 104 | AC32: =+Y32-AB32 -> -104 | AD32: =+ｼﾞｭｴﾙｽﾞ!W31/1000 -> 623.6 | AE32: 514.454 | AF32: =+AD32-AE32 -> 109.146 | AG32: 389 | AH32: =+AD32-AG32 -> 234.6 | AI32: =+Y32+AD32 -> 623.6 | AJ32: =+Z32+AE32 -> 518.054 | AK32: =+AI32-AJ32 -> 105.546 | AL32: =+AB32+AG32 -> 493 | AM32: =+AI32-AL32 -> 130.6 | AN32: =+ｶﾞｰﾃﾞﾝ!Y31/1000 -> 446.6 | AO32: 419.848 | AP32: =+AN32-AO32 -> 26.752 | AQ32: 329 | AR32: =+AN32-AQ32 -> 117.6 | AS32: =+ﾋﾞｱｶﾞｰﾃﾞﾝ!X31/1000 -> 191.4 | AT32: 179.935 | AU32: =+AS32-AT32 -> 11.465 | AV32: 9 | AW32: =+AS32-AV32 -> 182.4 | AX32: =+AN32+AS32 -> 638 | AY32: =+AO32+AT32 -> 599.783 | AZ32: =+AX32-AY32 -> 38.217 | BA32: =+AQ32+AV32 -> 338 | BB32: =+AX32-BA32 -> 300 | BC32: 0 | BD32: 0 | BE32: =+BC32+BD32 -> 0 | BF32: =+料飲共通!W31/1000 -> 61.6 | BG32: 424.6 | BH32: =+BF32-BG32 -> -363 | BI32: 21 | BJ32: =+BF32-BI32 -> 40.6 | BK32: =+T32+AI32+AX32+BE32+BF32 -> 1932.4 | BL32: =+U32+AJ32+AY32+BG32 -> 2048.851 | BM32: =+BK32-BL32 -> -116.451 | BN32: =+W32+AL32+BA32+BI32 -> 1174 | BO32: =+BK32-BN32 -> 758.4 | BP32: =+BK32-BE32 -> 1932.4 | BQ32: =+BL32-Z32 -> 2045.251 | BR32: =+BP32-BQ32 -> -112.851 | BS32: =+BN32-AB32 -> 1070 | BT32: =+BP32-BS32 -> 862.4
C33: 福利厚生費 | E33: =+ﾇｰﾍﾞﾙﾌﾟｰｽ!W32/1000 -> 79.2 | F33: 53.4 | G33: =+E33-F33 -> 25.8 | H33: 72 | I33: =+E33-H33 -> 7.2 | J33: =+ｶﾌｪﾙﾎﾟ!W32/1000 -> 0 | K33: 0 | L33: =+J33-K33 -> 0 | M33: 0 | N33: =+J33-M33 -> 0 | O33: =+ｶﾌｪｾﾚｽﾃ!W32/1000 -> 0 | P33: 0 | Q33: =+O33-P33 -> 0 | R33: 0 | S33: =+O33-R33 -> 0 | T33: =+E33+J33+O33 -> 79.2 | U33: =+F33+K33+P33 -> 53.4 | V33: =+T33-U33 -> 25.8 | W33: =+H33+M33+R33 -> 72 | X33: =+T33-W33 -> 7.2 | Y33: 0 | Z33: 3.6 | AA33: =+Y33-Z33 -> -3.6 | AB33: 4 | AC33: =+Y33-AB33 -> -4 | AD33: =+ｼﾞｭｴﾙｽﾞ!W32/1000 -> 93.6 | AE33: 65.4 | AF33: =+AD33-AE33 -> 28.2 | AG33: 86 | AH33: =+AD33-AG33 -> 7.6 | AI33: =+Y33+AD33 -> 93.6 | AJ33: =+Z33+AE33 -> 69 | AK33: =+AI33-AJ33 -> 24.6 | AL33: =+AB33+AG33 -> 90 | AM33: =+AI33-AL33 -> 3.6 | AN33: =+ｶﾞｰﾃﾞﾝ!W32/1000 -> 108 | AO33: 54.18 | AP33: =+AN33-AO33 -> 53.82 | AQ33: 79 | AR33: =+AN33-AQ33 -> 29 | AS33: =+ﾋﾞｱｶﾞｰﾃﾞﾝ!W32/1000 -> 0 | AT33: 23.22 | AU33: =+AS33-AT33 -> -23.22 | AV33: 9 | AW33: =+AS33-AV33 -> -9 | AX33: =+AN33+AS33 -> 108 | AY33: =+AO33+AT33 -> 77.4 | AZ33: =+AX33-AY33 -> 30.6 | BA33: =+AQ33+AV33 -> 88 | BB33: =+AX33-BA33 -> 20 | BC33: 0 | BD33: 0 | BE33: =+BC33+BD33 -> 0 | BF33: =+料飲共通!W32/1000 -> 21.6 | BG33: 31.6 | BH33: =+BF33-BG33 -> -10 | BI33: 21 | BJ33: =+BF33-BI33 -> 0.6 | BK33: =+T33+AI33+AX33+BE33+BF33 -> 302.4 | BL33: =+U33+AJ33+AY33+BG33 -> 231.4 | BM33: =+BK33-BL33 -> 71 | BN33: =+W33+AL33+BA33+BI33 -> 271 | BO33: =+BK33-BN33 -> 31.4 | BP33: =+BK33-BE33 -> 302.4 | BQ33: =+BL33-Z33 -> 227.8 | BR33: =+BP33-BQ33 -> 74.6 | BS33: =+BN33-AB33 -> 267 | BT33: =+BP33-BS33 -> 35.4
C34: 被服費 | E34: =+ﾇｰﾍﾞﾙﾌﾟｰｽ!W33/1000 -> 330 | F34: 228.34 | G34: =+E34-F34 -> 101.66 | H34: 250 | I34: =+E34-H34 -> 80 | J34: =+ｶﾌｪﾙﾎﾟ!W33/1000 -> 0 | K34: 17.4 | L34: =+J34-K34 -> -17.4 | M34: 0 | N34: =+J34-M34 -> 0 | O34: =+ｶﾌｪｾﾚｽﾃ!W33/1000 -> 0 | P34: 0 | Q34: =+O34-P34 -> 0 | R34: 0 | S34: =+O34-R34 -> 0 | T34: =+E34+J34+O34 -> 330 | U34: =+F34+K34+P34 -> 245.74 | V34: =+T34-U34 -> 84.26 | W34: =+H34+M34+R34 -> 250 | X34: =+T34-W34 -> 80 | Y34: 0 | Z34: 0 | AA34: =+Y34-Z34 -> 0 | AB34: 100 | AC34: =+Y34-AB34 -> -100 | AD34: =+ｼﾞｭｴﾙｽﾞ!W33/1000 -> 330 | AE34: 241.78 | AF34: =+AD34-AE34 -> 88.22 | AG34: 250 | AH34: =+AD34-AG34 -> 80 | AI34: =+Y34+AD34 -> 330 | AJ34: =+Z34+AE34 -> 241.78 | AK34: =+AI34-AJ34 -> 88.22 | AL34: =+AB34+AG34 -> 350 | AM34: =+AI34-AL34 -> -20 | AN34: =+ｶﾞｰﾃﾞﾝ!W33/1000 -> 330 | AO34: 221.85 | AP34: =+AN34-AO34 -> 108.15 | AQ34: 250 | AR34: =+AN34-AQ34 -> 80 | AS34: =+ﾋﾞｱｶﾞｰﾃﾞﾝ!W33/1000 -> 0 | AT34: 95.078 | AU34: =+AS34-AT34 -> -95.078 | AV34: 0 | AW34: =+AS34-AV34 -> 0 | AX34: =+AN34+AS34 -> 330 | AY34: =+AO34+AT34 -> 316.928 | AZ34: =+AX34-AY34 -> 13.072 | BA34: =+AQ34+AV34 -> 250 | BB34: =+AX34-BA34 -> 80 | BC34: 0 | BD34: 0 | BE34: =+BC34+BD34 -> 0 | BF34: =+料飲共通!W33/1000 -> 40 | BG34: 393 | BH34: =+BF34-BG34 -> -353 | BI34: 0 | BJ34: =+BF34-BI34 -> 40 | BK34: =+T34+AI34+AX34+BE34+BF34 -> 1030 | BL34: =+U34+AJ34+AY34+BG34 -> 1197.448 | BM34: =+BK34-BL34 -> -167.448 | BN34: =+W34+AL34+BA34+BI34 -> 850 | BO34: =+BK34-BN34 -> 180 | BP34: =+BK34-BE34 -> 1030 | BQ34: =+BL34-Z34 -> 1197.448 | BR34: =+BP34-BQ34 -> -167.448 | BS34: =+BN34-AB34 -> 750 | BT34: =+BP34-BS34 -> 280
C35: 研修費 | E35: =+ﾇｰﾍﾞﾙﾌﾟｰｽ!W34/1000 -> 200 | F35: 207.274 | G35: =+E35-F35 -> -7.274 | H35: 0 | I35: =+E35-H35 -> 200 | J35: =+ｶﾌｪﾙﾎﾟ!W34/1000 -> 0 | K35: 0 | L35: =+J35-K35 -> 0 | M35: 0 | N35: =+J35-M35 -> 0 | O35: =+ｶﾌｪｾﾚｽﾃ!W34/1000 -> 0 | P35: 0 | Q35: =+O35-P35 -> 0 | R35: 0 | S35: =+O35-R35 -> 0 | T35: =+E35+J35+O35 -> 200 | U35: =+F35+K35+P35 -> 207.274 | V35: =+T35-U35 -> -7.274 | W35: =+H35+M35+R35 -> 0 | X35: =+T35-W35 -> 200 | Y35: 0 | Z35: 0 | AA35: =+Y35-Z35 -> 0 | AB35: 0 | AC35: =+Y35-AB35 -> 0 | AD35: =+ｼﾞｭｴﾙｽﾞ!W34/1000 -> 200 | AE35: 207.274 | AF35: =+AD35-AE35 -> -7.274 | AG35: 53 | AH35: =+AD35-AG35 -> 147 | AI35: =+Y35+AD35 -> 200 | AJ35: =+Z35+AE35 -> 207.274 | AK35: =+AI35-AJ35 -> -7.274 | AL35: =+AB35+AG35 -> 53 | AM35: =+AI35-AL35 -> 147 | AN35: =+ｶﾞｰﾃﾞﾝ!W34/1000 -> 200 | AO35: 143.819 | AP35: =+AN35-AO35 -> 56.181 | AQ35: 0 | AR35: =+AN35-AQ35 -> 200 | AS35: =+ﾋﾞｱｶﾞｰﾃﾞﾝ!W34/1000 -> 0 | AT35: 61.636 | AU35: =+AS35-AT35 -> -61.636 | AV35: 0 | AW35: =+AS35-AV35 -> 0 | AX35: =+AN35+AS35 -> 200 | AY35: =+AO35+AT35 -> 205.455 | AZ35: =+AX35-AY35 -> -5.455 | BA35: =+AQ35+AV35 -> 0 | BB35: =+AX35-BA35 -> 200 | BC35: 0 | BD35: 0 | BE35: =+BC35+BD35 -> 0 | BF35: =+料飲共通!W34/1000 -> 0 | BG35: 0 | BH35: =+BF35-BG35 -> 0 | BI35: 0 | BJ35: =+BF35-BI35 -> 0 | BK35: =+T35+AI35+AX35+BE35+BF35 -> 600 | BL35: =+U35+AJ35+AY35+BG35 -> 620.003 | BM35: =+BK35-BL35 -> -20.003 | BN35: =+W35+AL35+BA35+BI35 -> 53 | BO35: =+BK35-BN35 -> 547 | BP35: =+BK35-BE35 -> 600 | BQ35: =+BL35-Z35 -> 620.003 | BR35: =+BP35-BQ35 -> -20.003 | BS35: =+BN35-AB35 -> 53 | BT35: =+BP35-BS35 -> 547
B36: 通勤費 | E36: =+ﾇｰﾍﾞﾙﾌﾟｰｽ!W35/1000 -> 1174.872 | F36: 1058.246 | G36: =+E36-F36 -> 116.626 | H36: 964 | I36: =+E36-H36 -> 210.872 | J36: =+ｶﾌｪﾙﾎﾟ!W35/1000 -> 111.01 | K36: 78.226 | L36: =+J36-K36 -> 32.784 | M36: 66 | N36: =+J36-M36 -> 45.01 | O36: =+ｶﾌｪｾﾚｽﾃ!W35/1000 -> 111.01 | P36: 78.225 | Q36: =+O36-P36 -> 32.785 | R36: 66 | S36: =+O36-R36 -> 45.01 | T36: =+E36+J36+O36 -> 1396.892 | U36: =+F36+K36+P36 -> 1214.697 | V36: =+T36-U36 -> 182.195 | W36: =+H36+M36+R36 -> 1096 | X36: =+T36-W36 -> 300.892 | Y36: 0 | Z36: 237.359 | AA36: =+Y36-Z36 -> -237.359 | AB36: 272 | AC36: =+Y36-AB36 -> -272 | AD36: =+ｼﾞｭｴﾙｽﾞ!W35/1000 -> 1849.332 | AE36: 1599.852 | AF36: =+AD36-AE36 -> 249.48 | AG36: 1748 | AH36: =+AD36-AG36 -> 101.332 | AI36: =+Y36+AD36 -> 1849.332 | AJ36: =+Z36+AE36 -> 1837.211 | AK36: =+AI36-AJ36 -> 12.121 | AL36: =+AB36+AG36 -> 2020 | AM36: =+AI36-AL36 -> -170.668 | AN36: =+ｶﾞｰﾃﾞﾝ!Y35/1000 -> 1608.102 | AO36: 1812.726 | AP36: =+AN36-AO36 -> -204.624 | AQ36: 45 | AR36: =+AN36-AQ36 -> 1563.102 | AS36: =+ﾋﾞｱｶﾞｰﾃﾞﾝ!X35/1000 -> 689.186 | AT36: 776.882 | AU36: =+AS36-AT36 -> -87.696 | AV36: 115 | AW36: =+AS36-AV36 -> 574.186 | AX36: =+AN36+AS36 -> 2297.288 | AY36: =+AO36+AT36 -> 2589.608 | AZ36: =+AX36-AY36 -> -292.32 | BA36: =+AQ36+AV36 -> 160 | BB36: =+AX36-BA36 -> 2137.288 | BC36: 0 | BD36: 0 | BE36: =+BC36+BD36 -> 0 | BF36: =+料飲共通!W35/1000 -> 236.856 | BG36: 233.204 | BH36: =+BF36-BG36 -> 3.652 | BI36: 300 | BJ36: =+BF36-BI36 -> -63.144 | BK36: =+T36+AI36+AX36+BE36+BF36 -> 5780.368 | BL36: =+U36+AJ36+AY36+BG36 -> 5874.72 | BM36: =+BK36-BL36 -> -94.352 | BN36: =+W36+AL36+BA36+BI36 -> 3576 | BO36: =+BK36-BN36 -> 2204.368 | BP36: =+BK36-BE36 -> 5780.368 | BQ36: =+BL36-Z36 -> 5637.361 | BR36: =+BP36-BQ36 -> 143.007 | BS36: =+BN36-AB36 -> 3304 | BT36: =+BP36-BS36 -> 2476.368
B37: 引当金繰入額 | E37: =+ﾇｰﾍﾞﾙﾌﾟｰｽ!W36/1000 -> 0 | F37: 0 | G37: =+E37-F37 -> 0 | H37: 0 | I37: =+E37-H37 -> 0 | J37: =+ｶﾌｪﾙﾎﾟ!W36/1000 -> 0 | K37: 0 | L37: =+J37-K37 -> 0 | M37: 0 | N37: =+J37-M37 -> 0 | O37: =+ｶﾌｪｾﾚｽﾃ!W36/1000 -> 0 | P37: 0 | Q37: =+O37-P37 -> 0 | R37: 0 | S37: =+O37-R37 -> 0 | T37: =+E37+J37+O37 -> 0 | U37: =+F37+K37+P37 -> 0 | V37: =+T37-U37 -> 0 | W37: =+H37+M37+R37 -> 0 | X37: =+T37-W37 -> 0 | Y37: 0 | Z37: 0 | AA37: =+Y37-Z37 -> 0 | AB37: 0 | AC37: =+Y37-AB37 -> 0 | AD37: =+ｼﾞｭｴﾙｽﾞ!W36/1000 -> 0 | AE37: 0 | AF37: =+AD37-AE37 -> 0 | AG37: 0 | AH37: =+AD37-AG37 -> 0 | AI37: =+Y37+AD37 -> 0 | AJ37: =+Z37+AE37 -> 0 | AK37: =+AI37-AJ37 -> 0 | AL37: =+AB37+AG37 -> 0 | AM37: =+AI37-AL37 -> 0 | AN37: =+ｶﾞｰﾃﾞﾝ!Y36/1000 -> 0 | AO37: 0 | AP37: =+AN37-AO37 -> 0 | AQ37: 0 | AR37: =+AN37-AQ37 -> 0 | AS37: =+ﾋﾞｱｶﾞｰﾃﾞﾝ!X36/1000 -> 0 | AT37: 0 | AU37: =+AS37-AT37 -> 0 | AV37: 0 | AW37: =+AS37-AV37 -> 0 | AX37: =+AN37+AS37 -> 0 | AY37: =+AO37+AT37 -> 0 | AZ37: =+AX37-AY37 -> 0 | BA37: =+AQ37+AV37 -> 0 | BB37: =+AX37-BA37 -> 0 | BC37: 0 | BD37: 0 | BE37: =+BC37+BD37 -> 0 | BF37: =+料飲共通!W36/1000 -> 0 | BG37: 0 | BH37: =+BF37-BG37 -> 0 | BI37: 0 | BJ37: =+BF37-BI37 -> 0 | BK37: =+T37+AI37+AX37+BE37+BF37 -> 0 | BL37: =+U37+AJ37+AY37+BG37 -> 0 | BM37: =+BK37-BL37 -> 0 | BN37: =+W37+AL37+BA37+BI37 -> 0 | BO37: =+BK37-BN37 -> 0 | BP37: =+BK37-BE37 -> 0 | BQ37: =+BL37-Z37 -> 0 | BR37: =+BP37-BQ37 -> 0 | BS37: =+BN37-AB37 -> 0 | BT37: =+BP37-BS37 -> 0
A38: 物件費 | E38: =+ﾇｰﾍﾞﾙﾌﾟｰｽ!W37/1000 -> 24819.605 | F38: 25544.036 | G38: =+E38-F38 -> -724.431 | H38: 25494 | I38: =+E38-H38 -> -674.395 | J38: =+ｶﾌｪﾙﾎﾟ!W37/1000 -> 2843.405 | K38: 2894.314 | L38: =+J38-K38 -> -50.909 | M38: 2427 | N38: =+J38-M38 -> 416.405 | O38: =+ｶﾌｪｾﾚｽﾃ!W37/1000 -> 1603.983 | P38: 1689.214 | Q38: =+O38-P38 -> -85.231 | R38: 1603 | S38: =+O38-R38 -> 0.983 | T38: =+E38+J38+O38 -> 29266.993 | U38: =+F38+K38+P38 -> 30127.564 | V38: =+T38-U38 -> -860.571 | W38: =+H38+M38+R38 -> 29524 | X38: =+T38-W38 -> -257.007 | Y38: 0 | Z38: 1675.444 | AA38: =+Y38-Z38 -> -1675.444 | AB38: 4630 | AC38: =+Y38-AB38 -> -4630 | AD38: =+ｼﾞｭｴﾙｽﾞ!W37/1000 -> 22752.677 | AE38: 26704.175 | AF38: =+AD38-AE38 -> -3951.498 | AG38: 21572 | AH38: =+AD38-AG38 -> 1180.677 | AI38: =+Y38+AD38 -> 22752.677 | AJ38: =+Z38+AE38 -> 28379.619 | AK38: =+AI38-AJ38 -> -5626.942 | AL38: =+AB38+AG38 -> 26202 | AM38: =+AI38-AL38 -> -3449.323 | AN38: =+ｶﾞｰﾃﾞﾝ!W37/1000 -> 34114.208 | AO38: 33508.397 | AP38: =+AN38-AO38 -> 605.811 | AQ38: 40233 | AR38: =+AN38-AQ38 -> -6118.792 | AS38: =+ﾋﾞｱｶﾞｰﾃﾞﾝ!W37/1000 -> 64246.364 | AT38: 76309.517 | AU38: =+AS38-AT38 -> -12063.153 | AV38: 61193 | AW38: =+AS38-AV38 -> 3053.364 | AX38: =+AN38+AS38 -> 98360.572 | AY38: =+AO38+AT38 -> 109817.91 | AZ38: =+AX38-AY38 -> -11457.342 | BA38: =+AQ38+AV38 -> 101426 | BB38: =+AX38-BA38 -> -3065.428 | BC38: =+BC39+BC40+BC41+BC42+BC47+BC51+BC58+BC59+BC62+BC63+BC64+BC65+BC66+BC67+BC68+BC71+BC72+BC73+BC79+BC80+BC81+BC84+BC85 -> 19363.931 | BD38: =+BD39+BD40+BD41+BD42+BD47+BD51+BD58+BD59+BD62+BD63+BD64+BD65+BD66+BD67+BD68+BD71+BD72+BD73+BD79+BD80+BD81+BD84+BD85 -> 12688.171 | BE38: =+BC38+BD38 -> 32052.103 | BF38: =+料飲共通!W37/1000 -> 2443.85 | BG38: 6057.29 | BH38: =+BF38-BG38 -> -3613.44 | BI38: 254 | BJ38: =+BF38-BI38 -> 2189.85 | BK38: =+T38+AI38+AX38+BE38+BF38 -> 184876.19 | BL38: =+U38+AJ38+AY38+BG38 -> 174382.39 | BM38: =+BK38-BL38 -> 10493.808 | BN38: =+W38+AL38+BA38+BI38 -> 157406 | BO38: =+BK38-BN38 -> 27470.195 | BP38: =+BK38-BE38 -> 152824.09 | BQ38: =+BL38-Z38 -> 172706.94 | BR38: =+BP38-BQ38 -> -19882.851 | BS38: =+BN38-AB38 -> 152776 | BT38: =+BP38-BS38 -> 48.092
B39: 消耗品費 | E39: =+ﾇｰﾍﾞﾙﾌﾟｰｽ!W38/1000 -> 2520 | F39: 2546.953 | G39: =+E39-F39 -> -26.953 | H39: 2676 | I39: =+E39-H39 -> -156 | J39: =+ｶﾌｪﾙﾎﾟ!W38/1000 -> 560 | K39: 459.645 | L39: =+J39-K39 -> 100.355 | M39: 566 | N39: =+J39-M39 -> -6 | O39: =+ｶﾌｪｾﾚｽﾃ!W38/1000 -> 60 | P39: 201.582 | Q39: =+O39-P39 -> -141.582 | R39: 155 | S39: =+O39-R39 -> -95 | T39: =+E39+J39+O39 -> 3140 | U39: =+F39+K39+P39 -> 3208.18 | V39: =+T39-U39 -> -68.18 | W39: =+H39+M39+R39 -> 3397 | X39: =+T39-W39 -> -257 | Y39: 0 | Z39: 764.064 | AA39: =+Y39-Z39 -> -764.064 | AB39: 1387 | AC39: =+Y39-AB39 -> -1387 | AD39: =+ｼﾞｭｴﾙｽﾞ!W38/1000 -> 3813.5 | AE39: 5192.905 | AF39: =+AD39-AE39 -> -1379.405 | AG39: 4159 | AH39: =+AD39-AG39 -> -345.5 | AI39: =+Y39+AD39 -> 3813.5 | AJ39: =+Z39+AE39 -> 5956.969 | AK39: =+AI39-AJ39 -> -2143.469 | AL39: =+AB39+AG39 -> 5546 | AM39: =+AI39-AL39 -> -1732.5 | AN39: =+ｶﾞｰﾃﾞﾝ!W38/1000 -> 2380 | AO39: 3248.671 | AP39: =+AN39-AO39 -> -868.671 | AQ39: 3763 | AR39: =+AN39-AQ39 -> -1383 | AS39: =+ﾋﾞｱｶﾞｰﾃﾞﾝ!W38/1000 -> 4439 | AT39: 4335.033 | AU39: =+AS39-AT39 -> 103.967 | AV39: 3276 | AW39: =+AS39-AV39 -> 1163 | AX39: =+AN39+AS39 -> 6819 | AY39: =+AO39+AT39 -> 7583.704 | AZ39: =+AX39-AY39 -> -764.704 | BA39: =+AQ39+AV39 -> 7039 | BB39: =+AX39-BA39 -> -220 | BC39: =+赤れんが!X39/1000 -> 1840.8903 | BD39: =+赤れんが!Z39/1000 -> 1186.5044 | BE39: =+BC39+BD39 -> 3027.3947 | BF39: =+料飲共通!W38/1000 -> 0 | BG39: 43.38 | BH39: =+BF39-BG39 -> -43.38 | BI39: 0 | BJ39: =+BF39-BI39 -> 0 | BK39: =+T39+AI39+AX39+BE39+BF39 -> 16799.895 | BL39: =+U39+AJ39+AY39+BG39 -> 16792.233 | BM39: =+BK39-BL39 -> 7.6616995 | BN39: =+W39+AL39+BA39+BI39 -> 15982 | BO39: =+BK39-BN39 -> 817.8947 | BP39: =+BK39-BE39 -> 13772.5 | BQ39: =+BL39-Z39 -> 16028.169 | BR39: =+BP39-BQ39 -> -2255.669 | BS39: =+BN39-AB39 -> 14595 | BT39: =+BP39-BS39 -> -822.5
B40: 事務用品費 | E40: =+ﾇｰﾍﾞﾙﾌﾟｰｽ!W39/1000 -> 260 | F40: 277.748 | G40: =+E40-F40 -> -17.748 | H40: 240 | I40: =+E40-H40 -> 20 | J40: =+ｶﾌｪﾙﾎﾟ!W39/1000 -> 0 | K40: 19.966 | L40: =+J40-K40 -> -19.966 | M40: 0 | N40: =+J40-M40 -> 0 | O40: =+ｶﾌｪｾﾚｽﾃ!W39/1000 -> 0 | P40: 0 | Q40: =+O40-P40 -> 0 | R40: 0 | S40: =+O40-R40 -> 0 | T40: =+E40+J40+O40 -> 260 | U40: =+F40+K40+P40 -> 297.714 | V40: =+T40-U40 -> -37.714 | W40: =+H40+M40+R40 -> 240 | X40: =+T40-W40 -> 20 | Y40: 0 | Z40: 0 | AA40: =+Y40-Z40 -> 0 | AB40: 0 | AC40: =+Y40-AB40 -> 0 | AD40: =+ｼﾞｭｴﾙｽﾞ!W39/1000 -> 300 | AE40: 211.303 | AF40: =+AD40-AE40 -> 88.697 | AG40: 260 | AH40: =+AD40-AG40 -> 40 | AI40: =+Y40+AD40 -> 300 | AJ40: =+Z40+AE40 -> 211.303 | AK40: =+AI40-AJ40 -> 88.697 | AL40: =+AB40+AG40 -> 260 | AM40: =+AI40-AL40 -> 40 | AN40: =+ｶﾞｰﾃﾞﾝ!W39/1000 -> 300 | AO40: 361.703 | AP40: =+AN40-AO40 -> -61.703 | AQ40: 300 | AR40: =+AN40-AQ40 -> 0 | AS40: =+ﾋﾞｱｶﾞｰﾃﾞﾝ!W39/1000 -> 50 | AT40: 10.797 | AU40: =+AS40-AT40 -> 39.203 | AV40: 0 | AW40: =+AS40-AV40 -> 50 | AX40: =+AN40+AS40 -> 350 | AY40: =+AO40+AT40 -> 372.5 | AZ40: =+AX40-AY40 -> -22.5 | BA40: =+AQ40+AV40 -> 300 | BB40: =+AX40-BA40 -> 50 | BC40: =+赤れんが!X40/1000 -> 204.96244 | BD40: =+赤れんが!Z40/1000 -> 0 | BE40: =+BC40+BD40 -> 204.96244 | BF40: =+料飲共通!W39/1000 -> 0 | BG40: 0 | BH40: =+BF40-BG40 -> 0 | BI40: 0 | BJ40: =+BF40-BI40 -> 0 | BK40: =+T40+AI40+AX40+BE40+BF40 -> 1114.9624 | BL40: =+U40+AJ40+AY40+BG40 -> 881.517 | BM40: =+BK40-BL40 -> 233.44544 | BN40: =+W40+AL40+BA40+BI40 -> 800 | BO40: =+BK40-BN40 -> 314.96244 | BP40: =+BK40-BE40 -> 910 | BQ40: =+BL40-Z40 -> 881.517 | BR40: =+BP40-BQ40 -> 28.483 | BS40: =+BN40-AB40 -> 800 | BT40: =+BP40-BS40 -> 110
...

Sheet 料飲共通
A1: ■（Ｒ７年度）事業予算入力用
A3: 部門 料飲共通
A4: コード | B4: 名称 | K4: 令和 7年 4月 | L4: 令和 7年 5月 | M4: 令和 7年 6月 | N4: 令和 7年 7月 | O4: 令和 7年 8月 | P4: 令和 7年 9月 | Q4: 令和 7年 10月 | R4: 令和 7年 11月 | S4: 令和 7年 12月 | T4: 令和 8年 1月 | U4: 令和 8年 2月 | V4: 令和 8年 3月 | W4: 合計
K5: ①当期実績 | L5: ①当期実績 | M5: ①当期実績 | N5: ①当期実績 | O5: ①当期実績 | P5: ①当期実績 | Q5: ①当期実績 | R5: ①当期実績 | S5: ①当期実績 | T5: ①当期実績 | U5: ①当期実績 | V5: ①当期実績 | W5: ①当期実績
A6: 10000 | B6: 総売上高 | K6: =SUM(K7:K16) -> 0 | L6: =SUM(L7:L16) -> 0 | M6: =SUM(M7:M16) -> 0 | N6: =SUM(N7:N16) -> 0 | O6: =SUM(O7:O16) -> 0 | P6: =SUM(P7:P16) -> 0 | Q6: =SUM(Q7:Q16) -> 0 | R6: =SUM(R7:R16) -> 0 | ... V6: =SUM(V7:V16) -> 0 | W6: =SUM(K6:V6) -> 0
A7: 10001 | C7: 売上 | K7: 0 | L7: 0 | M7: 0 | N7: 0 | O7: 0 | P7: 0 | Q7: 0 | R7: 0 | S7: 0 | T7: 0 | U7: 0 | V7: 0 | W7: =SUM(K7:V7) -> 0
A8: 10002 | C8: 損保代理店収入 | K8: 0 | L8: 0 | M8: 0 | N8: 0 | O8: 0 | P8: 0 | Q8: 0 | R8: 0 | S8: 0 | T8: 0 | U8: 0 | V8: 0 | W8: =SUM(K8:V8) -> 0
A9: 10003 | C9: 販売手数料収入 | K9: 0 | L9: 0 | M9: 0 | N9: 0 | O9: 0 | P9: 0 | Q9: 0 | R9: 0 | S9: 0 | T9: 0 | U9: 0 | V9: 0 | W9: =SUM(K9:V9) -> 0
A10: 10004 | C10: 索道収入 | K10: 0 | L10: 0 | M10: 0 | N10: 0 | O10: 0 | P10: 0 | Q10: 0 | R10: 0 | S10: 0 | T10: 0 | U10: 0 | V10: 0 | W10: =SUM(K10:V10) -> 0
A11: 10005 | C11: 地代収入 | K11: 0 | L11: 0 | M11: 0 | N11: 0 | O11: 0 | P11: 0 | Q11: 0 | R11: 0 | S11: 0 | T11: 0 | U11: 0 | V11: 0 | W11: =SUM(K11:V11) -> 0
A12: 10006 | C12: 家賃収入 | K12: 0 | L12: 0 | M12: 0 | N12: 0 | O12: 0 | P12: 0 | Q12: 0 | R12: 0 | S12: 0 | T12: 0 | U12: 0 | V12: 0 | W12: =SUM(K12:V12) -> 0
A13: 10007 | C13: 駐車場収入 | K13: 0 | L13: 0 | M13: 0 | N13: 0 | O13: 0 | P13: 0 | Q13: 0 | R13: 0 | S13: 0 | T13: 0 | U13: 0 | V13: 0 | W13: =SUM(K13:V13) -> 0
A14: 10008 | C14: 受託料 | K14: 0 | L14: 0 | M14: 0 | N14: 0 | O14: 0 | P14: 0 | Q14: 0 | R14: 0 | S14: 0 | T14: 0 | U14: 0 | V14: 0 | W14: =SUM(K14:V14) -> 0
A15: 10009 | C15: 利用料金収入 | K15: 0 | L15: 0 | M15: 0 | N15: 0 | O15: 0 | P15: 0 | Q15: 0 | R15: 0 | S15: 0 | T15: 0 | U15: 0 | V15: 0 | W15: =SUM(K15:V15) -> 0
A16: 10010 | C16: 管理手数料収入 | K16: 0 | L16: 0 | M16: 0 | N16: 0 | O16: 0 | P16: 0 | Q16: 0 | R16: 0 | S16: 0 | T16: 0 | U16: 0 | V16: 0 | W16: =SUM(K16:V16) -> 0
A17: 20000 | B17: 売上原価 | K17: 0 | L17: 0 | M17: 0 | N17: 0 | O17: 0 | P17: 0 | Q17: 0 | R17: 0 | S17: 0 | T17: 0 | U17: 0 | V17: 0 | W17: =SUM(K17:V17) -> 0
A18: 30000 | B18: 売上総利益 | K18: =K6-K17 -> 0 | L18: =L6-L17 -> 0 | M18: =M6-M17 -> 0 | N18: =N6-N17 -> 0 | O18: =O6-O17 -> 0 | P18: =P6-P17 -> 0 | Q18: =Q6-Q17 -> 0 | R18: =R6-R17 -> 0 | ... V18: =V6-V17 -> 0 | W18: =SUM(K18:V18) -> 0
A19: 41000 | B19: 人件費 | K19: =SUM(K20:K22,K26,K29:K31,K35:K36) -> 1413826 | L19: =SUM(L20:L22,L26,L29:L31,L35:L36) -> 1563519 | M19: =SUM(M20:M22,M26,M29:M31,M35:M36) -> 4176417 | N19: =SUM(N20:N22,N26,N29:N31,N35:N36) -> 1952116.4 | O19: =SUM(O20:O22,O26,O29:O31,O35:O36) -> 1563519 | P19: =SUM(P20:P22,P26,P29:P31,P35:P36) -> 1563519 | Q19: =SUM(Q20:Q22,Q26,Q29:Q31,Q35:Q36) -> 2087682 | R19: =SUM(R20:R22,R26,R29:R31,R35:R36) -> 1642043.4 | ... V19: =SUM(V20:V22,V26,V29:V31,V35:V36) -> 1764317 | W19: =SUM(K19:V19) -> 25580282
