Workbook

Sheet 料飲
F1: ２０２５(令和７)年度 第６９期 決算見込 損益計算書
AK2: [単位：千円(税抜)] | BY2: [単位：千円(税抜)]
A3: 名称
T4: 大倉山 | AI4: 藻岩山 | AX4: テレビ塔 | BM4: 赤れんがテラス
E5: ﾇｰﾍﾞﾙﾌﾟｰｽ | J5: 大倉山ｶﾌｪ | O5: 大倉山ﾗｳﾝｼﾞ | Y5: ｽｷｰﾛｯｼﾞ食堂 | AD5: 藻岩山レストラン | AN5: ｶﾞｰﾃﾞﾝ | AS5: ﾋﾞｱｶﾞｰﾃﾞﾝ | BC5: ブリック | BH5: 羊蹄ぶた | BR5: 料飲共通 | BW5: 料飲部合計
E6: ①R7予算 | F6: ②R7決見 | G6: ②－① | H6: ③R6実績 | I6: ②－③ | J6: ①R7予算 | K6: ②R7決見 | L6: ②－① | M6: ③R6実績 | N6: ②－③ | O6: ①R7予算 | P6: ②R7決見 | Q6: ②－① | R6: ③R6実績 | S6: ②－③ | T6: ①R7予算 | U6: ②R7決見 | V6: ②－① | W6: ③R6実績 | X6: ②－③ | Y6: ①R7予算 | Z6: ②R7決見 | AA6: ②－① | AB6: ③R6実績 | AC6: ②－③ | AD6: ①R7予算 | AE6: ②R7決見 | AF6: ②－① | AG6: ③R6実績 | AH6: ②－③ | AI6: ①R7予算 | AJ6: ②R7決見 | AK6: ②－① | AL6: ③R6実績 | AM6: ②－③ | AN6: ①R7予算 | AO6: ②R7決見 | AP6: ②－① | AQ6: ③R6実績 | AR6: ②－③ | AS6: ①R7予算 | AT6: ②R7決見 | AU6: ②－① | AV6: ③R6実績 | AW6: ②－③ | AX6: ①R7予算 | AY6: ②R7決見 | AZ6: ②－① | BA6: ③R6実績 | BB6: ②－③ | BC6: ①R7予算 | BD6: ②R7決見 | BE6: ②－① | BF6: ③R6実績 | BG6: ②－③ | BH6: ①R7予算 | BI6: ②R7決見 | BJ6: ②－① | BK6: ③R6実績 | BL6: ②－③ | BM6: ①R7予算 | BN6: ②R7決見 | BO6: ②－① | BP6: ③R6実績 | BQ6: ②－③ | BR6: ①R7予算 | BS6: ②R7決見 | BT6: ②－① | BU6: ③R6実績 | BV6: ②－③ | BW6: ①R7予算 | BX6: ②R7決見 | BY6: ②－① | BZ6: ③R6実績 | CA6: ②－③
A7: 総売上高 | E7: 98216.5 | F7: =+ﾇｰﾍﾞﾙﾌﾟｰｽ!W6/1000 -> 101506.71 | G7: =+E7-F7 -> -3290.205 | H7: 100726 | I7: =+E7-H7 -> -2509.5 | J7: 9212.097 | K7: =+ｶﾌｪﾙﾎﾟ!W6/1000 -> 8565.626 | L7: =+J7-K7 -> 646.471 | M7: 8389 | N7: =+J7-M7 -> 823.097 | O7: 19649 | P7: =+ｶﾌｪｾﾚｽﾃ!W6/1000 -> 20165.808 | Q7: =+O7-P7 -> -516.808 | R7: 19505 | S7: =+O7-R7 -> 144 | T7: =+E7+J7+O7 -> 127077.6 | U7: =+F7+K7+P7 -> 130238.14 | V7: =+T7-U7 -> -3160.542 | W7: =+H7+M7+R7 -> 128620 | X7: =+T7-W7 -> -1542.403 | AA7: =+Y7-Z7 -> 0 | AB7: 23760 | AC7: =+Y7-AB7 -> -23760 | AD7: 164317.97 | AE7: =+ｼﾞｭｴﾙｽﾞ!W6/1000 -> 167135.97 | AF7: =+AD7-AE7 -> -2818.005 | AG7: 162532 | AH7: =+AD7-AG7 -> 1785.966 | AI7: =+Y7+AD7 -> 164317.97 | AJ7: =+Z7+AE7 -> 167135.97 | AK7: =+AI7-AJ7 -> -2818.005 | AL7: =+AB7+AG7 -> 186292 | AM7: =+AI7-AL7 -> -21974.034 | AN7: 136763.17 | AO7: =+ｶﾞｰﾃﾞﾝ!W6/1000 -> 154985.14 | AP7: =+AN7-AO7 -> -18221.971 | AQ7: 136981 | AR7: =+AN7-AQ7 -> -217.828 | AS7: 154408.3 | AT7: =+ﾋﾞｱｶﾞｰﾃﾞﾝ!W6/1000 -> 178615.74 | AU7: =+AS7-AT7 -> -24207.444 | AV7: 139737 | AW7: =+AS7-AV7 -> 14671.295 | AX7: =+AN7+AS7 -> 291171.47 | AY7: =+AO7+AT7 -> 333600.88 | AZ7: =+AX7-AY7 -> -42429.415 | BA7: =+AQ7+AV7 -> 276718 | BB7: =+AX7-BA7 -> 14453.467 | BC7: 75365.66 | BD7: =+ブリック!W6/1000 -> 61370.735 | BE7: =+BC7-BD7 -> 13994.925 | BG7: =+BC7-BF7 -> 75365.66 | BH7: 50302.4 | BI7: =+ルスツ羊蹄ぶた!W6/1000 -> 34511.1 | BJ7: =+BH7-BI7 -> 15791.3 | BL7: =+BH7-BK7 -> 50302.4 | BM7: =+BC7+BH7 -> 125668.06 | BN7: =+BD7+BI7 -> 95881.835 | BO7: =+BM7-BN7 -> 29786.225 | BP7: =+BF7+BK7 -> 0 | BQ7: =+BM7-BP7 -> 125668.06 | BR7: 0 | BS7: =+料飲共通!W6/1000 -> 0 | BT7: =+BR7-BS7 -> 0 | BU7: 0 | BV7: =+BR7-BU7 -> 0 | BW7: =+T7+AI7+AX7+BM7+BR7 -> 708235.09 | BX7: =+U7+AJ7+AY7+BN7+BS7 -> 726856.83 | BY7: =+BW7-BX7 -> -18621.737 | BZ7: =+W7+AL7+BA7+BP7+BU7 -> 591630 | CA7: =+BW7-BZ7 -> 116605.09
B8: 売上 | E8: 98216.5 | F8: =+ﾇｰﾍﾞﾙﾌﾟｰｽ!W7/1000 -> 101506.71 | G8: =+E8-F8 -> -3290.205 | H8: 100726 | I8: =+E8-H8 -> -2509.5 | J8: 9212.097 | K8: =+ｶﾌｪﾙﾎﾟ!W7/1000 -> 8565.626 | L8: =+J8-K8 -> 646.471 | M8: 8389 | N8: =+J8-M8 -> 823.097 | O8: 19649 | P8: =+ｶﾌｪｾﾚｽﾃ!W7/1000 -> 20165.808 | Q8: =+O8-P8 -> -516.808 | R8: 19505 | S8: =+O8-R8 -> 144 | T8: =+E8+J8+O8 -> 127077.6 | U8: =+F8+K8+P8 -> 130238.14 | V8: =+T8-U8 -> -3160.542 | W8: =+H8+M8+R8 -> 128620 | X8: =+T8-W8 -> -1542.403 | AA8: =+Y8-Z8 -> 0 | AB8: 23760 | AC8: =+Y8-AB8 -> -23760 | AD8: 164317.97 | AE8: =+ｼﾞｭｴﾙｽﾞ!W7/1000 -> 167135.97 | AF8: =+AD8-AE8 -> -2818.005 | AG8: 162532 | AH8: =+AD8-AG8 -> 1785.966 | AI8: =+Y8+AD8 -> 164317.97 | AJ8: =+Z8+AE8 -> 167135.97 | AK8: =+AI8-AJ8 -> -2818.005 | AL8: =+AB8+AG8 -> 186292 | AM8: =+AI8-AL8 -> -21974.034 | AN8: 136763.17 | AO8: =+ｶﾞｰﾃﾞﾝ!W7/1000 -> 154985.14 | AP8: =+AN8-AO8 -> -18221.971 | AQ8: 136981 | AR8: =+AN8-AQ8 -> -217.828 | AS8: 154408.3 | AT8: =+ﾋﾞｱｶﾞｰﾃﾞﾝ!W7/1000 -> 178615.74 | AU8: =+AS8-AT8 -> -24207.444 | AV8: 139737 | AW8: =+AS8-AV8 -> 14671.295 | AX8: =+AN8+AS8 -> 291171.47 | AY8: =+AO8+AT8 -> 333600.88 | AZ8: =+AX8-AY8 -> -42429.415 | BA8: =+AQ8+AV8 -> 276718 | BB8: =+AX8-BA8 -> 14453.467 | BC8: 75365.66 | BD8: =+ブリック!W7/1000 -> 61370.735 | BE8: =+BC8-BD8 -> 13994.925 | BG8: =+BC8-BF8 -> 75365.66 | BH8: 50302.4 | BI8: =+ルスツ羊蹄ぶた!W7/1000 -> 34511.1 | BJ8: =+BH8-BI8 -> 15791.3 | BL8: =+BH8-BK8 -> 50302.4 | BM8: =+BC8+BH8 -> 125668.06 | BN8: =+BD8+BI8 -> 95881.835 | BO8: =+BM8-BN8 -> 29786.225 | BP8: =+BF8+BK8 -> 0 | BQ8: =+BM8-BP8 -> 125668.06 | BR8: 0 | BS8: =+料飲共通!W7/1000 -> 0 | BT8: =+BR8-BS8 -> 0 | BU8: 0 | BV8: =+BR8-BU8 -> 0 | BW8: =+T8+AI8+AX8+BM8+BR8 -> 708235.09 | BX8: =+U8+AJ8+AY8+BN8+BS8 -> 726856.83 | BY8: =+BW8-BX8 -> -18621.737 | BZ8: =+W8+AL8+BA8+BU8 -> 591630 | CA8: =+BW8-BZ8 -> 116605.09
B9: 損保代理店収入 | E9: 0 | F9: =+ﾇｰﾍﾞﾙﾌﾟｰｽ!W8/1000 -> 0 | G9: =+E9-F9 -> 0 | H9: 0 | I9: =+E9-H9 -> 0 | J9: 0 | K9: =+ｶﾌｪﾙﾎﾟ!W8/1000 -> 0 | L9: =+J9-K9 -> 0 | M9: 0 | N9: =+J9-M9 -> 0 | O9: 0 | P9: =+ｶﾌｪｾﾚｽﾃ!W8/1000 -> 0 | Q9: =+O9-P9 -> 0 | R9: 0 | S9: =+O9-R9 -> 0 | T9: =+E9+J9+O9 -> 0 | U9: =+F9+K9+P9 -> 0 | V9: =+T9-U9 -> 0 | W9: =+H9+M9+R9 -> 0 | X9: =+T9-W9 -> 0 | AA9: =+Y9-Z9 -> 0 | AB9: 0 | AC9: =+Y9-AB9 -> 0 | AD9: 0 | AE9: =+ｼﾞｭｴﾙｽﾞ!W8/1000 -> 0 | AF9: =+AD9-AE9 -> 0 | AG9: 0 | AH9: =+AD9-AG9 -> 0 | AI9: =+Y9+AD9 -> 0 | AJ9: =+Z9+AE9 -> 0 | AK9: =+AI9-AJ9 -> 0 | AL9: =+AB9+AG9 -> 0 | AM9: =+AI9-AL9 -> 0 | AN9: 0 | AO9: =+ｶﾞｰﾃﾞﾝ!W8/1000 -> 0 | AP9: =+AN9-AO9 -> 0 | AQ9: 0 | AR9: =+AN9-AQ9 -> 0 | AS9: 0 | AT9: =+ﾋﾞｱｶﾞｰﾃﾞﾝ!W8/1000 -> 0 | AU9: =+AS9-AT9 -> 0 | AV9: 0 | AW9: =+AS9-AV9 -> 0 | AX9: =+AN9+AS9 -> 0 | AY9: =+AO9+AT9 -> 0 | AZ9: =+AX9-AY9 -> 0 | BA9: =+AQ9+AV9 -> 0 | BB9: =+AX9-BA9 -> 0 | BC9: 0 | BD9: =+ブリック!W8/1000 -> 0 | BE9: =+BC9-BD9 -> 0 | BG9: =+BC9-BF9 -> 0 | BH9: 0 | BI9: =+ルスツ羊蹄ぶた!W8/1000 -> 0 | BJ9: =+BH9-BI9 -> 0 | BL9: =+BH9-BK9 -> 0 | BM9: =+BC9+BH9 -> 0 | BN9: =+BD9+BI9 -> 0 | BO9: =+BM9-BN9 -> 0 | BP9: =+BF9+BK9 -> 0 | BQ9: =+BM9-BP9 -> 0 | BR9: 0 | BS9: =+料飲共通!W8/1000 -> 0 | BT9: =+BR9-BS9 -> 0 | BU9: 0 | BV9: =+BR9-BU9 -> 0 | BW9: =+T9+AI9+AX9+BM9+BR9 -> 0 | BX9: =+U9+AJ9+AY9+BN9+BS9 -> 0 | BY9: =+BW9-BX9 -> 0 | BZ9: =+W9+AL9+BA9+BU9 -> 0 | CA9: =+BW9-BZ9 -> 0
B10: 販売手数料収入 | E10: 0 | F10: =+ﾇｰﾍﾞﾙﾌﾟｰｽ!W9/1000 -> 0 | G10: =+E10-F10 -> 0 | H10: 0 | I10: =+E10-H10 -> 0 | J10: 0 | K10: =+ｶﾌｪﾙﾎﾟ!W9/1000 -> 0 | L10: =+J10-K10 -> 0 | M10: 0 | N10: =+J10-M10 -> 0 | O10: 0 | P10: =+ｶﾌｪｾﾚｽﾃ!W9/1000 -> 0 | Q10: =+O10-P10 -> 0 | R10: 0 | S10: =+O10-R10 -> 0 | T10: =+E10+J10+O10 -> 0 | U10: =+F10+K10+P10 -> 0 | V10: =+T10-U10 -> 0 | W10: =+H10+M10+R10 -> 0 | X10: =+T10-W10 -> 0 | AA10: =+Y10-Z10 -> 0 | AB10: 0 | AC10: =+Y10-AB10 -> 0 | AD10: 0 | AE10: =+ｼﾞｭｴﾙｽﾞ!W9/1000 -> 0 | AF10: =+AD10-AE10 -> 0 | AG10: 0 | AH10: =+AD10-AG10 -> 0 | AI10: =+Y10+AD10 -> 0 | AJ10: =+Z10+AE10 -> 0 | AK10: =+AI10-AJ10 -> 0 | AL10: =+AB10+AG10 -> 0 | AM10: =+AI10-AL10 -> 0 | AN10: 0 | AO10: =+ｶﾞｰﾃﾞﾝ!W9/1000 -> 0 | AP10: =+AN10-AO10 -> 0 | AQ10: 0 | AR10: =+AN10-AQ10 -> 0 | AS10: 0 | AT10: =+ﾋﾞｱｶﾞｰﾃﾞﾝ!W9/1000 -> 0 | AU10: =+AS10-AT10 -> 0 | AV10: 0 | AW10: =+AS10-AV10 -> 0 | AX10: =+AN10+AS10 -> 0 | AY10: =+AO10+AT10 -> 0 | AZ10: =+AX10-AY10 -> 0 | BA10: =+AQ10+AV10 -> 0 | BB10: =+AX10-BA10 -> 0 | BC10: 0 | BD10: =+ブリック!W9/1000 -> 0 | BE10: =+BC10-BD10 -> 0 | BG10: =+BC10-BF10 -> 0 | BH10: 0 | BI10: =+ルスツ羊蹄ぶた!W9/1000 -> 0 | BJ10: =+BH10-BI10 -> 0 | BL10: =+BH10-BK10 -> 0 | BM10: =+BC10+BH10 -> 0 | BN10: =+BD10+BI10 -> 0 | BO10: =+BM10-BN10 -> 0 | BP10: =+BF10+BK10 -> 0 | BQ10: =+BM10-BP10 -> 0 | BR10: 0 | BS10: =+料飲共通!W9/1000 -> 0 | BT10: =+BR10-BS10 -> 0 | BU10: 0 | BV10: =+BR10-BU10 -> 0 | BW10: =+T10+AI10+AX10+BM10+BR10 -> 0 | BX10: =+U10+AJ10+AY10+BN10+BS10 -> 0 | BY10: =+BW10-BX10 -> 0 | BZ10: =+W10+AL10+BA10+BU10 -> 0 | CA10: =+BW10-BZ10 -> 0
B11: 索道収入 | E11: 0 | F11: =+ﾇｰﾍﾞﾙﾌﾟｰｽ!W10/1000 -> 0 | G11: =+E11-F11 -> 0 | H11: 0 | I11: =+E11-H11 -> 0 | J11: 0 | K11: =+ｶﾌｪﾙﾎﾟ!W10/1000 -> 0 | L11: =+J11-K11 -> 0 | M11: 0 | N11: =+J11-M11 -> 0 | O11: 0 | P11: =+ｶﾌｪｾﾚｽﾃ!W10/1000 -> 0 | Q11: =+O11-P11 -> 0 | R11: 0 | S11: =+O11-R11 -> 0 | T11: =+E11+J11+O11 -> 0 | U11: =+F11+K11+P11 -> 0 | V11: =+T11-U11 -> 0 | W11: =+H11+M11+R11 -> 0 | X11: =+T11-W11 -> 0 | AA11: =+Y11-Z11 -> 0 | AB11: 0 | AC11: =+Y11-AB11 -> 0 | AD11: 0 | AE11: =+ｼﾞｭｴﾙｽﾞ!W10/1000 -> 0 | AF11: =+AD11-AE11 -> 0 | AG11: 0 | AH11: =+AD11-AG11 -> 0 | AI11: =+Y11+AD11 -> 0 | AJ11: =+Z11+AE11 -> 0 | AK11: =+AI11-AJ11 -> 0 | AL11: =+AB11+AG11 -> 0 | AM11: =+AI11-AL11 -> 0 | AN11: 0 | AO11: =+ｶﾞｰﾃﾞﾝ!W10/1000 -> 0 | AP11: =+AN11-AO11 -> 0 | AQ11: 0 | AR11: =+AN11-AQ11 -> 0 | AS11: 0 | AT11: =+ﾋﾞｱｶﾞｰﾃﾞﾝ!W10/1000 -> 0 | AU11: =+AS11-AT11 -> 0 | AV11: 0 | AW11: =+AS11-AV11 -> 0 | AX11: =+AN11+AS11 -> 0 | AY11: =+AO11+AT11 -> 0 | AZ11: =+AX11-AY11 -> 0 | BA11: =+AQ11+AV11 -> 0 | BB11: =+AX11-BA11 -> 0 | BC11: 0 | BD11: =+ブリック!W10/1000 -> 0 | BE11: =+BC11-BD11 -> 0 | BG11: =+BC11-BF11 -> 0 | BH11: 0 | BI11: =+ルスツ羊蹄ぶた!W10/1000 -> 0 | BJ11: =+BH11-BI11 -> 0 | BL11: =+BH11-BK11 -> 0 | BM11: =+BC11+BH11 -> 0 | BN11: =+BD11+BI11 -> 0 | BO11: =+BM11-BN11 -> 0 | BP11: =+BF11+BK11 -> 0 | BQ11: =+BM11-BP11 -> 0 | BR11: 0 | BS11: =+料飲共通!W10/1000 -> 0 | BT11: =+BR11-BS11 -> 0 | BU11: 0 | BV11: =+BR11-BU11 -> 0 | BW11: =+T11+AI11+AX11+BM11+BR11 -> 0 | BX11: =+U11+AJ11+AY11+BN11+BS11 -> 0 | BY11: =+BW11-BX11 -> 0 | BZ11: =+W11+AL11+BA11+BU11 -> 0 | CA11: =+BW11-BZ11 -> 0
B12: 地代収入 | E12: 0 | F12: =+ﾇｰﾍﾞﾙﾌﾟｰｽ!W11/1000 -> 0 | G12: =+E12-F12 -> 0 | H12: 0 | I12: =+E12-H12 -> 0 | J12: 0 | K12: =+ｶﾌｪﾙﾎﾟ!W11/1000 -> 0 | L12: =+J12-K12 -> 0 | M12: 0 | N12: =+J12-M12 -> 0 | O12: 0 | P12: =+ｶﾌｪｾﾚｽﾃ!W11/1000 -> 0 | Q12: =+O12-P12 -> 0 | R12: 0 | S12: =+O12-R12 -> 0 | T12: =+E12+J12+O12 -> 0 | U12: =+F12+K12+P12 -> 0 | V12: =+T12-U12 -> 0 | W12: =+H12+M12+R12 -> 0 | X12: =+T12-W12 -> 0 | AA12: =+Y12-Z12 -> 0 | AB12: 0 | AC12: =+Y12-AB12 -> 0 | AD12: 0 | AE12: =+ｼﾞｭｴﾙｽﾞ!W11/1000 -> 0 | AF12: =+AD12-AE12 -> 0 | AG12: 0 | AH12: =+AD12-AG12 -> 0 | AI12: =+Y12+AD12 -> 0 | AJ12: =+Z12+AE12 -> 0 | AK12: =+AI12-AJ12 -> 0 | AL12: =+AB12+AG12 -> 0 | AM12: =+AI12-AL12 -> 0 | AN12: 0 | AO12: =+ｶﾞｰﾃﾞﾝ!W11/1000 -> 0 | AP12: =+AN12-AO12 -> 0 | AQ12: 0 | AR12: =+AN12-AQ12 -> 0 | AS12: 0 | AT12: =+ﾋﾞｱｶﾞｰﾃﾞﾝ!W11/1000 -> 0 | AU12: =+AS12-AT12 -> 0 | AV12: 0 | AW12: =+AS12-AV12 -> 0 | AX12: =+AN12+AS12 -> 0 | AY12: =+AO12+AT12 -> 0 | AZ12: =+AX12-AY12 -> 0 | BA12: =+AQ12+AV12 -> 0 | BB12: =+AX12-BA12 -> 0 | BC12: 0 | BD12: =+ブリック!W11/1000 -> 0 | BE12: =+BC12-BD12 -> 0 | BG12: =+BC12-BF12 -> 0 | BH12: 0 | BI12: =+ルスツ羊蹄ぶた!W11/1000 -> 0 | BJ12: =+BH12-BI12 -> 0 | BL12: =+BH12-BK12 -> 0 | BM12: =+BC12+BH12 -> 0 | BN12: =+BD12+BI12 -> 0 | BO12: =+BM12-BN12 -> 0 | BP12: =+BF12+BK12 -> 0 | BQ12: =+BM12-BP12 -> 0 | BR12: 0 | BS12: =+料飲共通!W11/1000 -> 0 | BT12: =+BR12-BS12 -> 0 | BU12: 0 | BV12: =+BR12-BU12 -> 0 | BW12: =+T12+AI12+AX12+BM12+BR12 -> 0 | BX12: =+U12+AJ12+AY12+BN12+BS12 -> 0 | BY12: =+BW12-BX12 -> 0 | BZ12: =+W12+AL12+BA12+BU12 -> 0 | CA12: =+BW12-BZ12 -> 0
B13: 家賃収入 | E13: 0 | F13: =+ﾇｰﾍﾞﾙﾌﾟｰｽ!W12/1000 -> 0 | G13: =+E13-F13 -> 0 | H13: 0 | I13: =+E13-H13 -> 0 | J13: 0 | K13: =+ｶﾌｪﾙﾎﾟ!W12/1000 -> 0 | L13: =+J13-K13 -> 0 | M13: 0 | N13: =+J13-M13 -> 0 | O13: 0 | P13: =+ｶﾌｪｾﾚｽﾃ!W12/1000 -> 0 | Q13: =+O13-P13 -> 0 | R13: 0 | S13: =+O13-R13 -> 0 | T13: =+E13+J13+O13 -> 0 | U13: =+F13+K13+P13 -> 0 | V13: =+T13-U13 -> 0 | W13: =+H13+M13+R13 -> 0 | X13: =+T13-W13 -> 0 | AA13: =+Y13-Z13 -> 0 | AB13: 0 | AC13: =+Y13-AB13 -> 0 | AD13: 0 | AE13: =+ｼﾞｭｴﾙｽﾞ!W12/1000 -> 0 | AF13: =+AD13-AE13 -> 0 | AG13: 0 | AH13: =+AD13-AG13 -> 0 | AI13: =+Y13+AD13 -> 0 | AJ13: =+Z13+AE13 -> 0 | AK13: =+AI13-AJ13 -> 0 | AL13: =+AB13+AG13 -> 0 | AM13: =+AI13-AL13 -> 0 | AN13: 0 | AO13: =+ｶﾞｰﾃﾞﾝ!W12/1000 -> 0 | AP13: =+AN13-AO13 -> 0 | AQ13: 0 | AR13: =+AN13-AQ13 -> 0 | AS13: 0 | AT13: =+ﾋﾞｱｶﾞｰﾃﾞﾝ!W12/1000 -> 0 | AU13: =+AS13-AT13 -> 0 | AV13: 0 | AW13: =+AS13-AV13 -> 0 | AX13: =+AN13+AS13 -> 0 | AY13: =+AO13+AT13 -> 0 | AZ13: =+AX13-AY13 -> 0 | BA13: =+AQ13+AV13 -> 0 | BB13: =+AX13-BA13 -> 0 | BC13: 0 | BD13: =+ブリック!W12/1000 -> 0 | BE13: =+BC13-BD13 -> 0 | BG13: =+BC13-BF13 -> 0 | BH13: 0 | BI13: =+ルスツ羊蹄ぶた!W12/1000 -> 0 | BJ13: =+BH13-BI13 -> 0 | BL13: =+BH13-BK13 -> 0 | BM13: =+BC13+BH13 -> 0 | BN13: =+BD13+BI13 -> 0 | BO13: =+BM13-BN13 -> 0 | BP13: =+BF13+BK13 -> 0 | BQ13: =+BM13-BP13 -> 0 | BR13: 0 | BS13: =+料飲共通!W12/1000 -> 0 | BT13: =+BR13-BS13 -> 0 | BU13: 0 | BV13: =+BR13-BU13 -> 0 | BW13: =+T13+AI13+AX13+BM13+BR13 -> 0 | BX13: =+U13+AJ13+AY13+BN13+BS13 -> 0 | BY13: =+BW13-BX13 -> 0 | BZ13: =+W13+AL13+BA13+BU13 -> 0 | CA13: =+BW13-BZ13 -> 0
B14: 駐車場収入 | E14: 0 | F14: =+ﾇｰﾍﾞﾙﾌﾟｰｽ!W13/1000 -> 0 | G14: =+E14-F14 -> 0 | H14: 0 | I14: =+E14-H14 -> 0 | J14: 0 | K14: =+ｶﾌｪﾙﾎﾟ!W13/1000 -> 0 | L14: =+J14-K14 -> 0 | M14: 0 | N14: =+J14-M14 -> 0 | O14: 0 | P14: =+ｶﾌｪｾﾚｽﾃ!W13/1000 -> 0 | Q14: =+O14-P14 -> 0 | R14: 0 | S14: =+O14-R14 -> 0 | T14: =+E14+J14+O14 -> 0 | U14: =+F14+K14+P14 -> 0 | V14: =+T14-U14 -> 0 | W14: =+H14+M14+R14 -> 0 | X14: =+T14-W14 -> 0 | AA14: =+Y14-Z14 -> 0 | AB14: 0 | AC14: =+Y14-AB14 -> 0 | AD14: 0 | AE14: =+ｼﾞｭｴﾙｽﾞ!W13/1000 -> 0 | AF14: =+AD14-AE14 -> 0 | AG14: 0 | AH14: =+AD14-AG14 -> 0 | AI14: =+Y14+AD14 -> 0 | AJ14: =+Z14+AE14 -> 0 | AK14: =+AI14-AJ14 -> 0 | AL14: =+AB14+AG14 -> 0 | AM14: =+AI14-AL14 -> 0 | AN14: 0 | AO14: =+ｶﾞｰﾃﾞﾝ!W13/1000 -> 0 | AP14: =+AN14-AO14 -> 0 | AQ14: 0 | AR14: =+AN14-AQ14 -> 0 | AS14: 0 | AT14: =+ﾋﾞｱｶﾞｰﾃﾞﾝ!W13/1000 -> 0 | AU14: =+AS14-AT14 -> 0 | AV14: 0 | AW14: =+AS14-AV14 -> 0 | AX14: =+AN14+AS14 -> 0 | AY14: =+AO14+AT14 -> 0 | AZ14: =+AX14-AY14 -> 0 | BA14: =+AQ14+AV14 -> 0 | BB14: =+AX14-BA14 -> 0 | BC14: 0 | BD14: =+ブリック!W13/1000 -> 0 | BE14: =+BC14-BD14 -> 0 | BG14: =+BC14-BF14 -> 0 | BH14: 0 | BI14: =+ルスツ羊蹄ぶた!W13/1000 -> 0 | BJ14: =+BH14-BI14 -> 0 | BL14: =+BH14-BK14 -> 0 | BM14: =+BC14+BH14 -> 0 | BN14: =+BD14+BI14 -> 0 | BO14: =+BM14-BN14 -> 0 | BP14: =+BF14+BK14 -> 0 | BQ14: =+BM14-BP14 -> 0 | BR14: 0 | BS14: =+料飲共通!W13/1000 -> 0 | BT14: =+BR14-BS14 -> 0 | BU14: 0 | BV14: =+BR14-BU14 -> 0 | BW14: =+T14+AI14+AX14+BM14+BR14 -> 0 | BX14: =+U14+AJ14+AY14+BN14+BS14 -> 0 | BY14: =+BW14-BX14 -> 0 | BZ14: =+W14+AL14+BA14+BU14 -> 0 | CA14: =+BW14-BZ14 -> 0
B15: 受託料 | E15: 0 | F15: =+ﾇｰﾍﾞﾙﾌﾟｰｽ!W14/1000 -> 0 | G15: =+E15-F15 -> 0 | H15: 0 | I15: =+E15-H15 -> 0 | J15: 0 | K15: =+ｶﾌｪﾙﾎﾟ!W14/1000 -> 0 | L15: =+J15-K15 -> 0 | M15: 0 | N15: =+J15-M15 -> 0 | O15: 0 | P15: =+ｶﾌｪｾﾚｽﾃ!W14/1000 -> 0 | Q15: =+O15-P15 -> 0 | R15: 0 | S15: =+O15-R15 -> 0 | T15: =+E15+J15+O15 -> 0 | U15: =+F15+K15+P15 -> 0 | V15: =+T15-U15 -> 0 | W15: =+H15+M15+R15 -> 0 | X15: =+T15-W15 -> 0 | AA15: =+Y15-Z15 -> 0 | AB15: 0 | AC15: =+Y15-AB15 -> 0 | AD15: 0 | AE15: =+ｼﾞｭｴﾙｽﾞ!W14/1000 -> 0 | AF15: =+AD15-AE15 -> 0 | AG15: 0 | AH15: =+AD15-AG15 -> 0 | AI15: =+Y15+AD15 -> 0 | AJ15: =+Z15+AE15 -> 0 | AK15: =+AI15-AJ15 -> 0 | AL15: =+AB15+AG15 -> 0 | AM15: =+AI15-AL15 -> 0 | AN15: 0 | AO15: =+ｶﾞｰﾃﾞﾝ!W14/1000 -> 0 | AP15: =+AN15-AO15 -> 0 | AQ15: 0 | AR15: =+AN15-AQ15 -> 0 | AS15: 0 | AT15: =+ﾋﾞｱｶﾞｰﾃﾞﾝ!W14/1000 -> 0 | AU15: =+AS15-AT15 -> 0 | AV15: 0 | AW15: =+AS15-AV15 -> 0 | AX15: =+AN15+AS15 -> 0 | AY15: =+AO15+AT15 -> 0 | AZ15: =+AX15-AY15 -> 0 | BA15: =+AQ15+AV15 -> 0 | BB15: =+AX15-BA15 -> 0 | BC15: 0 | BD15: =+ブリック!W14/1000 -> 0 | BE15: =+BC15-BD15 -> 0 | BG15: =+BC15-BF15 -> 0 | BH15: 0 | BI15: =+ルスツ羊蹄ぶた!W14/1000 -> 0 | BJ15: =+BH15-BI15 -> 0 | BL15: =+BH15-BK15 -> 0 | BM15: =+BC15+BH15 -> 0 | BN15: =+BD15+BI15 -> 0 | BO15: =+BM15-BN15 -> 0 | BP15: =+BF15+BK15 -> 0 | BQ15: =+BM15-BP15 -> 0 | BR15: 0 | BS15: =+料飲共通!W14/1000 -> 0 | BT15: =+BR15-BS15 -> 0 | BU15: 0 | BV15: =+BR15-BU15 -> 0 | BW15: =+T15+AI15+AX15+BM15+BR15 -> 0 | BX15: =+U15+AJ15+AY15+BN15+BS15 -> 0 | BY15: =+BW15-BX15 -> 0 | BZ15: =+W15+AL15+BA15+BU15 -> 0 | CA15: =+BW15-BZ15 -> 0
B16: 利用料金収入 | E16: 0 | F16: =+ﾇｰﾍﾞﾙﾌﾟｰｽ!W15/1000 -> 0 | G16: =+E16-F16 -> 0 | H16: 0 | I16: =+E16-H16 -> 0 | J16: 0 | K16: =+ｶﾌｪﾙﾎﾟ!W15/1000 -> 0 | L16: =+J16-K16 -> 0 | M16: 0 | N16: =+J16-M16 -> 0 | O16: 0 | P16: =+ｶﾌｪｾﾚｽﾃ!W15/1000 -> 0 | Q16: =+O16-P16 -> 0 | R16: 0 | S16: =+O16-R16 -> 0 | T16: =+E16+J16+O16 -> 0 | U16: =+F16+K16+P16 -> 0 | V16: =+T16-U16 -> 0 | W16: =+H16+M16+R16 -> 0 | X16: =+T16-W16 -> 0 | AA16: =+Y16-Z16 -> 0 | AB16: 0 | AC16: =+Y16-AB16 -> 0 | AD16: 0 | AE16: =+ｼﾞｭｴﾙｽﾞ!W15/1000 -> 0 | AF16: =+AD16-AE16 -> 0 | AG16: 0 | AH16: =+AD16-AG16 -> 0 | AI16: =+Y16+AD16 -> 0 | AJ16: =+Z16+AE16 -> 0 | AK16: =+AI16-AJ16 -> 0 | AL16: =+AB16+AG16 -> 0 | AM16: =+AI16-AL16 -> 0 | AN16: 0 | AO16: =+ｶﾞｰﾃﾞﾝ!W15/1000 -> 0 | AP16: =+AN16-AO16 -> 0 | AQ16: 0 | AR16: =+AN16-AQ16 -> 0 | AS16: 0 | AT16: =+ﾋﾞｱｶﾞｰﾃﾞﾝ!W15/1000 -> 0 | AU16: =+AS16-AT16 -> 0 | AV16: 0 | AW16: =+AS16-AV16 -> 0 | AX16: =+AN16+AS16 -> 0 | AY16: =+AO16+AT16 -> 0 | AZ16: =+AX16-AY16 -> 0 | BA16: =+AQ16+AV16 -> 0 | BB16: =+AX16-BA16 -> 0 | BC16: 0 | BD16: =+ブリック!W15/1000 -> 0 | BE16: =+BC16-BD16 -> 0 | BG16: =+BC16-BF16 -> 0 | BH16: 0 | BI16: =+ルスツ羊蹄ぶた!W15/1000 -> 0 | BJ16: =+BH16-BI16 -> 0 | BL16: =+BH16-BK16 -> 0 | BM16: =+BC16+BH16 -> 0 | BN16: =+BD16+BI16 -> 0 | BO16: =+BM16-BN16 -> 0 | BP16: =+BF16+BK16 -> 0 | BQ16: =+BM16-BP16 -> 0 | BR16: 0 | BS16: =+料飲共通!W15/1000 -> 0 | BT16: =+BR16-BS16 -> 0 | BU16: 0 | BV16: =+BR16-BU16 -> 0 | BW16: =+T16+AI16+AX16+BM16+BR16 -> 0 | BX16: =+U16+AJ16+AY16+BN16+BS16 -> 0 | BY16: =+BW16-BX16 -> 0 | BZ16: =+W16+AL16+BA16+BU16 -> 0 | CA16: =+BW16-BZ16 -> 0
B17: 管理手数料収入 | E17: 0 | F17: =+ﾇｰﾍﾞﾙﾌﾟｰｽ!W16/1000 -> 0 | G17: =+E17-F17 -> 0 | H17: 0 | I17: =+E17-H17 -> 0 | J17: 0 | K17: =+ｶﾌｪﾙﾎﾟ!W16/1000 -> 0 | L17: =+J17-K17 -> 0 | M17: 0 | N17: =+J17-M17 -> 0 | O17: 0 | P17: =+ｶﾌｪｾﾚｽﾃ!W16/1000 -> 0 | Q17: =+O17-P17 -> 0 | R17: 0 | S17: =+O17-R17 -> 0 | T17: =+E17+J17+O17 -> 0 | U17: =+F17+K17+P17 -> 0 | V17: =+T17-U17 -> 0 | W17: =+H17+M17+R17 -> 0 | X17: =+T17-W17 -> 0 | AA17: =+Y17-Z17 -> 0 | AB17: 0 | AC17: =+Y17-AB17 -> 0 | AD17: 0 | AE17: =+ｼﾞｭｴﾙｽﾞ!W16/1000 -> 0 | AF17: =+AD17-AE17 -> 0 | AG17: 0 | AH17: =+AD17-AG17 -> 0 | AI17: =+Y17+AD17 -> 0 | AJ17: =+Z17+AE17 -> 0 | AK17: =+AI17-AJ17 -> 0 | AL17: =+AB17+AG17 -> 0 | AM17: =+AI17-AL17 -> 0 | AN17: 0 | AO17: =+ｶﾞｰﾃﾞﾝ!W16/1000 -> 0 | AP17: =+AN17-AO17 -> 0 | AQ17: 0 | AR17: =+AN17-AQ17 -> 0 | AS17: 0 | AT17: =+ﾋﾞｱｶﾞｰﾃﾞﾝ!W16/1000 -> 0 | AU17: =+AS17-AT17 -> 0 | AV17: 0 | AW17: =+AS17-AV17 -> 0 | AX17: =+AN17+AS17 -> 0 | AY17: =+AO17+AT17 -> 0 | AZ17: =+AX17-AY17 -> 0 | BA17: =+AQ17+AV17 -> 0 | BB17: =+AX17-BA17 -> 0 | BC17: 0 | BD17: =+ブリック!W16/1000 -> 0 | BE17: =+BC17-BD17 -> 0 | BG17: =+BC17-BF17 -> 0 | BH17: 0 | BI17: =+ルスツ羊蹄ぶた!W16/1000 -> 0 | BJ17: =+BH17-BI17 -> 0 | BL17: =+BH17-BK17 -> 0 | BM17: =+BC17+BH17 -> 0 | BN17: =+BD17+BI17 -> 0 | BO17: =+BM17-BN17 -> 0 | BP17: =+BF17+BK17 -> 0 | BQ17: =+BM17-BP17 -> 0 | BR17: 0 | BS17: =+料飲共通!W16/1000 -> 0 | BT17: =+BR17-BS17 -> 0 | BU17: 0 | BV17: =+BR17-BU17 -> 0 | BW17: =+T17+AI17+AX17+BM17+BR17 -> 0 | BX17: =+U17+AJ17+AY17+BN17+BS17 -> 0 | BY17: =+BW17-BX17 -> 0 | BZ17: =+W17+AL17+BA17+BU17 -> 0 | CA17: =+BW17-BZ17 -> 0
A18: 売上原価 | E18: 28482.785 | F18: =+ﾇｰﾍﾞﾙﾌﾟｰｽ!W17/1000 -> 29413.918 | G18: =+E18-F18 -> -931.13294 | H18: 27854 | I18: =+E18-H18 -> 628.785 | J18: 2947.871 | K18: =+ｶﾌｪﾙﾎﾟ!W17/1000 -> 8029.1284 | L18: =+J18-K18 -> -5081.2574 | M18: 2583 | N18: =+J18-M18 -> 364.87104 | O18: 5992.945 | P18: =+ｶﾌｪｾﾚｽﾃ!W17/1000 -> 6150.5714 | Q18: =+O18-P18 -> -157.62644 | R18: 6094 | S18: =+O18-R18 -> -101.055 | T18: =+E18+J18+O18 -> 37423.601 | U18: =+F18+K18+P18 -> 43593.618 | V18: =+T18-U18 -> -6170.0167 | W18: =+H18+M18+R18 -> 36531 | X18: =+T18-W18 -> 892.60104 | AA18: =+Y18-Z18 -> 0 | AB18: 414 | AC18: =+Y18-AB18 -> -414 | AD18: 47241.415 | AE18: =+ｼﾞｭｴﾙｽﾞ!W17/1000 -> 50638.731 | AF18: =+AD18-AE18 -> -3397.3161 | AG18: 47293 | AH18: =+AD18-AG18 -> -51.584775 | AI18: =+Y18+AD18 -> 47241.415 | AJ18: =+Z18+AE18 -> 50638.731 | AK18: =+AI18-AJ18 -> -3397.3161 | AL18: =+AB18+AG18 -> 47707 | AM18: =+AI18-AL18 -> -465.58478 | AN18: 42396.583 | AO18: =+ｶﾞｰﾃﾞﾝ!W17/1000 -> 53089.448 | AP18: =+AN18-AO18 -> -10692.865 | AQ18: 43158 | AR18: =+AN18-AQ18 -> -761.41668 | AS18: 49044.367 | AT18: =+ﾋﾞｱｶﾞｰﾃﾞﾝ!W17/1000 -> 60924.351 | AU18: =+AS18-AT18 -> -11879.984 | AV18: 43625 | AW18: =+AS18-AV18 -> 5419.3667 | AX18: =+AN18+AS18 -> 91440.95 | AY18: =+AO18+AT18 -> 114013.8 | AZ18: =+AX18-AY18 -> -22572.849 | BA18: =+AQ18+AV18 -> 86783 | BB18: =+AX18-BA18 -> 4657.95 | BC18: 21479 | BD18: =+ブリック!W17/1000 -> 24163.422 | BE18: =+BC18-BD18 -> -2684.4221 | BG18: =+BC18-BF18 -> 21479 | BH18: 17605.84 | BI18: =+ルスツ羊蹄ぶた!W17/1000 -> 12854.093 | BJ18: =+BH18-BI18 -> 4751.7471 | BL18: =+BH18-BK18 -> 17605.84 | BM18: =+BC18+BH18 -> 39084.84 | BN18: =+BD18+BI18 -> 37017.515 | BO18: =+BM18-BN18 -> 2067.325 | BP18: =+BF18+BK18 -> 0 | BQ18: =+BM18-BP18 -> 39084.84 | BR18: 0 | BS18: =+料飲共通!W17/1000 -> 0 | BT18: =+BR18-BS18 -> 0 | BU18: 0 | BV18: =+BR18-BU18 -> 0 | BW18: =+T18+AI18+AX18+BM18+BR18 -> 215190.81 | BX18: =+U18+AJ18+AY18+BN18+BS18 -> 245263.66 | BY18: =+BW18-BX18 -> -30072.857 | BZ18: =+W18+AL18+BA18+BU18 -> 171021 | CA18: =+BW18-BZ18 -> 44169.806
A19: 売上総利益 | E19: 69733.715 | F19: =+ﾇｰﾍﾞﾙﾌﾟｰｽ!W18/1000 -> 72092.787 | G19: =+E19-F19 -> -2359.0721 | H19: 72872 | I19: =+E19-H19 -> -3138.285 | J19: 6264.226 | K19: =+ｶﾌｪﾙﾎﾟ!W18/1000 -> 536.4976 | L19: =+J19-K19 -> 5727.7284 | M19: 5807 | N19: =+J19-M19 -> 457.22596 | O19: 13656.055 | P19: =+ｶﾌｪｾﾚｽﾃ!W18/1000 -> 14015.237 | Q19: =+O19-P19 -> -359.18156 | R19: 13411 | S19: =+O19-R19 -> 245.055 | T19: =+E19+J19+O19 -> 89653.996 | U19: =+F19+K19+P19 -> 86644.521 | V19: =+T19-U19 -> 3009.4747 | W19: =+H19+M19+R19 -> 92090 | X19: =+T19-W19 -> -2436.004 | AA19: =+Y19-Z19 -> 0 | AB19: 23346 | AC19: =+Y19-AB19 -> -23346 | AD19: 117076.55 | AE19: =+ｼﾞｭｴﾙｽﾞ!W18/1000 -> 116497.24 | AF19: =+AD19-AE19 -> 579.31106 | AG19: 115239 | AH19: =+AD19-AG19 -> 1837.5508 | AI19: =+Y19+AD19 -> 117076.55 | AJ19: =+Z19+AE19 -> 116497.24 | AK19: =+AI19-AJ19 -> 579.31106 | AL19: =+AB19+AG19 -> 138585 | AM19: =+AI19-AL19 -> -21508.449 | AN19: 94366.589 | AO19: =+ｶﾞｰﾃﾞﾝ!W18/1000 -> 101895.69 | AP19: =+AN19-AO19 -> -7529.1059 | AQ19: 93824 | AR19: =+AN19-AQ19 -> 542.58868 | AS19: 105363.93 | AT19: =+ﾋﾞｱｶﾞｰﾃﾞﾝ!W18/1000 -> 117691.39 | AU19: =+AS19-AT19 -> -12327.46 | AV19: 96113 | AW19: =+AS19-AV19 -> 9250.9283 | AX19: =+AN19+AS19 -> 199730.52 | AY19: =+AO19+AT19 -> 219587.08 | AZ19: =+AX19-AY19 -> -19856.566 | BA19: =+AQ19+AV19 -> 189937 | BB19: =+AX19-BA19 -> 9793.517 | BC19: 53886.66 | BD19: =+ブリック!W18/1000 -> 37207.313 | BE19: =+BC19-BD19 -> 16679.347 | BG19: =+BC19-BF19 -> 53886.66 | BH19: 32696.56 | BI19: =+ルスツ羊蹄ぶた!W18/1000 -> 21657.007 | BJ19: =+BH19-BI19 -> 11039.553 | BL19: =+BH19-BK19 -> 32696.56 | BM19: =+BC19+BH19 -> 86583.22 | BN19: =+BD19+BI19 -> 58864.32 | BO19: =+BM19-BN19 -> 27718.9 | BP19: =+BF19+BK19 -> 0 | BQ19: =+BM19-BP19 -> 86583.22 | BR19: 0 | BS19: =+料飲共通!W18/1000 -> 0 | BT19: =+BR19-BS19 -> 0 | BU19: 0 | BV19: =+BR19-BU19 -> 0 | BW19: =+T19+AI19+AX19+BM19+BR19 -> 493044.28 | BX19: =+U19+AJ19+AY19+BN19+BS19 -> 481593.16 | BY19: =+BW19-BX19 -> 11451.12 | BZ19: =+W19+AL19+BA19+BU19 -> 420612 | CA19: =+BW19-BZ19 -> 72432.284
A20: 人件費 | E20: 53667.197 | F20: =+ﾇｰﾍﾞﾙﾌﾟｰｽ!W19/1000 -> 63993.442 | G20: =+E20-F20 -> -10326.245 | H20: 51376 | I20: =+E20-H20 -> 2291.197 | J20: 2876.874 | K20: =+ｶﾌｪﾙﾎﾟ!W19/1000 -> 6217.763 | L20: =+J20-K20 -> -3340.889 | M20: 3200 | N20: =+J20-M20 -> -323.126 | O20: 2876.875 | P20: =+ｶﾌｪｾﾚｽﾃ!W19/1000 -> 0 | Q20: =+O20-P20 -> 2876.875 | R20: 3200 | S20: =+O20-R20 -> -323.125 | T20: =+E20+J20+O20 -> 59420.946 | U20: =+F20+K20+P20 -> 70211.205 | V20: =+T20-U20 -> -10790.259 | W20: =+H20+M20+R20 -> 57776 | X20: =+T20-W20 -> 1644.946 | AA20: =+Y20-Z20 -> 0 | AB20: 5606 | AC20: =+Y20-AB20 -> -5606 | AD20: 66777.382 | AE20: =+ｼﾞｭｴﾙｽﾞ!W19/1000 -> 60085.083 | AF20: =+AD20-AE20 -> 6692.2994 | AG20: 64580 | AH20: =+AD20-AG20 -> 2197.3824 | AI20: =+Y20+AD20 -> 66777.382 | AJ20: =+Z20+AE20 -> 60085.083 | AK20: =+AI20-AJ20 -> 6692.2994 | AL20: =+AB20+AG20 -> 70186 | AM20: =+AI20-AL20 -> -3408.6176 | AN20: 58176.028 | AO20: =+ｶﾞｰﾃﾞﾝ!W19/1000 -> 72410.586 | AP20: =+AN20-AO20 -> -14234.558 | AQ20: 76468 | AR20: =+AN20-AQ20 -> -18291.972 | AS20: 24932.582 | AT20: =+ﾋﾞｱｶﾞｰﾃﾞﾝ!W19/1000 -> 7713.721 | AU20: =+AS20-AT20 -> 17218.861 | AV20: 3911 | AW20: =+AS20-AV20 -> 21021.582 | AX20: =+AN20+AS20 -> 83108.61 | AY20: =+AO20+AT20 -> 80124.307 | AZ20: =+AX20-AY20 -> 2984.3034 | BA20: =+AQ20+AV20 -> 80379 | BB20: =+AX20-BA20 -> 2729.6104 | BC20: 30146 | BD20: =+ブリック!W19/1000 -> 42858.783 | BE20: =+BC20-BD20 -> -12712.783 | BG20: =+BC20-BF20 -> 30146 | BH20: 16230 | BI20: =+ルスツ羊蹄ぶた!W19/1000 -> 8098.068 | BJ20: =+BH20-BI20 -> 8131.932 | BL20: =+BH20-BK20 -> 16230 | BM20: =+BC20+BH20 -> 46376 | BN20: =+BD20+BI20 -> 50956.851 | BO20: =+BM20-BN20 -> -4580.851 | BP20: =+BF20+BK20 -> 0 | BQ20: =+BM20-BP20 -> 46376 | BR20: 25580.282 | BS20: =+料飲共通!W19/1000 -> 44752.275 | BT20: =+BR20-BS20 -> -19171.993 | BU20: 25666 | BV20: =+BR20-BU20 -> -85.717552 | BW20: =+T20+AI20+AX20+BM20+BR20 -> 281263.22 | BX20: =+U20+AJ20+AY20+BN20+BS20 -> 306129.72 | BY20: =+BW20-BX20 -> -24866.5 | BZ20: =+W20+AL20+BA20+BU20 -> 234007 | CA20: =+BW20-BZ20 -> 47256.221
B21: 役員報酬 | E21: 0 | F21: =+ﾇｰﾍﾞﾙﾌﾟｰｽ!W20/1000 -> 0 | G21: =+E21-F21 -> 0 | H21: 0 | I21: =+E21-H21 -> 0 | J21: 0 | K21: =+ｶﾌｪﾙﾎﾟ!W20/1000 -> 0 | L21: =+J21-K21 -> 0 | M21: 0 | N21: =+J21-M21 -> 0 | O21: 0 | P21: =+ｶﾌｪｾﾚｽﾃ!W20/1000 -> 0 | Q21: =+O21-P21 -> 0 | R21: 0 | S21: =+O21-R21 -> 0 | T21: =+E21+J21+O21 -> 0 | U21: =+F21+K21+P21 -> 0 | V21: =+T21-U21 -> 0 | W21: =+H21+M21+R21 -> 0 | X21: =+T21-W21 -> 0 | AA21: =+Y21-Z21 -> 0 | AB21: 0 | AC21: =+Y21-AB21 -> 0 | AD21: 0 | AE21: =+ｼﾞｭｴﾙｽﾞ!W20/1000 -> 0 | AF21: =+AD21-AE21 -> 0 | AG21: 0 | AH21: =+AD21-AG21 -> 0 | AI21: =+Y21+AD21 -> 0 | AJ21: =+Z21+AE21 -> 0 | AK21: =+AI21-AJ21 -> 0 | AL21: =+AB21+AG21 -> 0 | AM21: =+AI21-AL21 -> 0 | AN21: 0 | AO21: =+ｶﾞｰﾃﾞﾝ!W20/1000 -> 0 | AP21: =+AN21-AO21 -> 0 | AQ21: 0 | AR21: =+AN21-AQ21 -> 0 | AS21: 0 | AT21: =+ﾋﾞｱｶﾞｰﾃﾞﾝ!W20/1000 -> 0 | AU21: =+AS21-AT21 -> 0 | AV21: 0 | AW21: =+AS21-AV21 -> 0 | AX21: =+AN21+AS21 -> 0 | AY21: =+AO21+AT21 -> 0 | AZ21: =+AX21-AY21 -> 0 | BA21: =+AQ21+AV21 -> 0 | BB21: =+AX21-BA21 -> 0 | BD21: =+ブリック!W20/1000 -> 0 | BE21: =+BC21-BD21 -> 0 | BG21: =+BC21-BF21 -> 0 | BH21: 0 | BI21: =+ルスツ羊蹄ぶた!W20/1000 -> 0 | BJ21: =+BH21-BI21 -> 0 | BL21: =+BH21-BK21 -> 0 | BM21: =+BC21+BH21 -> 0 | BN21: =+BD21+BI21 -> 0 | BO21: =+BM21-BN21 -> 0 | BP21: =+BF21+BK21 -> 0 | BQ21: =+BM21-BP21 -> 0 | BR21: 0 | BS21: =+料飲共通!W20/1000 -> 0 | BT21: =+BR21-BS21 -> 0 | BU21: 0 | BV21: =+BR21-BU21 -> 0 | BW21: =+T21+AI21+AX21+BM21+BR21 -> 0 | BX21: =+U21+AJ21+AY21+BN21+BS21 -> 0 | BY21: =+BW21-BX21 -> 0 | BZ21: =+W21+AL21+BA21+BU21 -> 0 | CA21: =+BW21-BZ21 -> 0
B22: 社員給与費 | E22: 0 | F22: =+ﾇｰﾍﾞﾙﾌﾟｰｽ!W21/1000 -> 0 | G22: =+E22-F22 -> 0 | H22: 0 | I22: =+E22-H22 -> 0 | J22: 0 | K22: =+ｶﾌｪﾙﾎﾟ!W21/1000 -> 0 | L22: =+J22-K22 -> 0 | M22: 0 | N22: =+J22-M22 -> 0 | O22: 0 | P22: =+ｶﾌｪｾﾚｽﾃ!W21/1000 -> 0 | Q22: =+O22-P22 -> 0 | R22: 0 | S22: =+O22-R22 -> 0 | T22: =+E22+J22+O22 -> 0 | U22: =+F22+K22+P22 -> 0 | V22: =+T22-U22 -> 0 | W22: =+H22+M22+R22 -> 0 | X22: =+T22-W22 -> 0 | AA22: =+Y22-Z22 -> 0 | AB22: 0 | AC22: =+Y22-AB22 -> 0 | AD22: 0 | AE22: =+ｼﾞｭｴﾙｽﾞ!W21/1000 -> 0 | AF22: =+AD22-AE22 -> 0 | AG22: 13 | AH22: =+AD22-AG22 -> -13 | AI22: =+Y22+AD22 -> 0 | AJ22: =+Z22+AE22 -> 0 | AK22: =+AI22-AJ22 -> 0 | AL22: =+AB22+AG22 -> 13 | AM22: =+AI22-AL22 -> -13 | AN22: 0 | AO22: =+ｶﾞｰﾃﾞﾝ!W21/1000 -> 0 | AP22: =+AN22-AO22 -> 0 | AQ22: 0 | AR22: =+AN22-AQ22 -> 0 | AS22: 0 | AT22: =+ﾋﾞｱｶﾞｰﾃﾞﾝ!W21/1000 -> 0 | AU22: =+AS22-AT22 -> 0 | AV22: 0 | AW22: =+AS22-AV22 -> 0 | AX22: =+AN22+AS22 -> 0 | AY22: =+AO22+AT22 -> 0 | AZ22: =+AX22-AY22 -> 0 | BA22: =+AQ22+AV22 -> 0 | BB22: =+AX22-BA22 -> 0 | BC22: 0 | BD22: =+ブリック!W21/1000 -> 0 | BE22: =+BC22-BD22 -> 0 | BG22: =+BC22-BF22 -> 0 | BH22: 0 | BI22: =+ルスツ羊蹄ぶた!W21/1000 -> 0 | BJ22: =+BH22-BI22 -> 0 | BL22: =+BH22-BK22 -> 0 | BM22: =+BC22+BH22 -> 0 | BN22: =+BD22+BI22 -> 0 | BO22: =+BM22-BN22 -> 0 | BP22: =+BF22+BK22 -> 0 | BQ22: =+BM22-BP22 -> 0 | BR22: 21846.07 | BS22: =+料飲共通!W21/1000 -> 39163.253 | BT22: =+BR22-BS22 -> -17317.183 | BU22: 21667 | BV22: =+BR22-BU22 -> 179.07 | BW22: =+T22+AI22+AX22+BM22+BR22 -> 21846.07 | BX22: =+U22+AJ22+AY22+BN22+BS22 -> 39163.253 | BY22: =+BW22-BX22 -> -17317.183 | BZ22: =+W22+AL22+BA22+BU22 -> 21680 | CA22: =+BW22-BZ22 -> 166.07
B23: 専門等給与費 | E23: 44651.64 | F23: =+ﾇｰﾍﾞﾙﾌﾟｰｽ!W22/1000 -> 55669.735 | G23: =+E23-F23 -> -11018.095 | H23: 44167 | I23: =+E23-H23 -> 484.64 | J23: 2524.2 | K23: =+ｶﾌｪﾙﾎﾟ!W22/1000 -> 5559.69 | L23: =+J23-K23 -> -3035.49 | M23: 2876 | N23: =+J23-M23 -> -351.8 | O23: 2524.2 | P23: =+ｶﾌｪｾﾚｽﾃ!W22/1000 -> 0 | Q23: =+O23-P23 -> 2524.2 | R23: 2876 | S23: =+O23-R23 -> -351.8 | T23: =+E23+J23+O23 -> 49700.04 | U23: =+F23+K23+P23 -> 61229.425 | V23: =+T23-U23 -> -11529.385 | W23: =+H23+M23+R23 -> 49919 | X23: =+T23-W23 -> -218.96 | AA23: =+Y23-Z23 -> 0 | AB23: 5123 | AC23: =+Y23-AB23 -> -5123 | AD23: 55698.34 | AE23: =+ｼﾞｭｴﾙｽﾞ!W22/1000 -> 53261.927 | AF23: =+AD23-AE23 -> 2436.413 | AG23: 55579 | AH23: =+AD23-AG23 -> 119.34 | AI23: =+Y23+AD23 -> 55698.34 | AJ23: =+Z23+AE23 -> 53261.927 | AK23: =+AI23-AJ23 -> 2436.413 | AL23: =+AB23+AG23 -> 60702 | AM23: =+AI23-AL23 -> -5003.66 | AN23: 49303.667 | AO23: =+ｶﾞｰﾃﾞﾝ!W22/1000 -> 63994.874 | AP23: =+AN23-AO23 -> -14691.207 | AQ23: 65357 | AR23: =+AN23-AQ23 -> -16053.333 | AS23: 21130.143 | AT23: =+ﾋﾞｱｶﾞｰﾃﾞﾝ!W22/1000 -> 7101.482 | AU23: =+AS23-AT23 -> 14028.661 | AV23: 3509 | AW23: =+AS23-AV23 -> 17621.143 | AX23: =+AN23+AS23 -> 70433.81 | AY23: =+AO23+AT23 -> 71096.356 | AZ23: =+AX23-AY23 -> -662.546 | BA23: =+AQ23+AV23 -> 68866 | BB23: =+AX23-BA23 -> 1567.81 | BC23: 30146 | BD23: =+ブリック!W22/1000 -> 37204.666 | BE23: =+BC23-BD23 -> -7058.666 | BG23: =+BC23-BF23 -> 30146 | BH23: 16230 | BI23: =+ルスツ羊蹄ぶた!W22/1000 -> 6766.442 | BJ23: =+BH23-BI23 -> 9463.558 | BL23: =+BH23-BK23 -> 16230 | BM23: =+BC23+BH23 -> 46376 | BN23: =+BD23+BI23 -> 43971.108 | BO23: =+BM23-BN23 -> 2404.892 | BP23: =+BF23+BK23 -> 0 | BQ23: =+BM23-BP23 -> 46376 | BR23: 0 | BS23: =+料飲共通!W22/1000 -> 75.35 | BT23: =+BR23-BS23 -> -75.35 | BU23: 0 | BV23: =+BR23-BU23 -> 0 | BW23: =+T23+AI23+AX23+BM23+BR23 -> 222208.19 | BX23: =+U23+AJ23+AY23+BN23+BS23 -> 229634.17 | BY23: =+BW23-BX23 -> -7425.976 | BZ23: =+W23+AL23+BA23+BU23 -> 179487 | CA23: =+BW23-BZ23 -> 42721.19
C24: 専門 | E24: 44462.64 | F24: =+ﾇｰﾍﾞﾙﾌﾟｰｽ!W23/1000 -> 52395.561 | G24: =+E24-F24 -> -7932.921 | H24: 42160 | I24: =+E24-H24 -> 2302.64 | J24: 0 | K24: =+ｶﾌｪﾙﾎﾟ!W23/1000 -> 0 | L24: =+J24-K24 -> 0 | M24: 0 | N24: =+J24-M24 -> 0 | O24: 0 | P24: =+ｶﾌｪｾﾚｽﾃ!W23/1000 -> 0 | Q24: =+O24-P24 -> 0 | R24: 0 | S24: =+O24-R24 -> 0 | T24: =+E24+J24+O24 -> 44462.64 | U24: =+F24+K24+P24 -> 52395.561 | V24: =+T24-U24 -> -7932.921 | W24: =+H24+M24+R24 -> 42160 | X24: =+T24-W24 -> 2302.64 | AA24: =+Y24-Z24 -> 0 | AB24: 2118 | AC24: =+Y24-AB24 -> -2118 | AD24: 50391.64 | AE24: =+ｼﾞｭｴﾙｽﾞ!W23/1000 -> 48027.976 | AF24: =+AD24-AE24 -> 2363.664 | AG24: 49913 | AH24: =+AD24-AG24 -> 478.64 | AI24: =+Y24+AD24 -> 50391.64 | AJ24: =+Z24+AE24 -> 48027.976 | AK24: =+AI24-AJ24 -> 2363.664 | AL24: =+AB24+AG24 -> 52031 | AM24: =+AI24-AL24 -> -1639.36 | AN24: 63275.81 | AO24: =+ｶﾞｰﾃﾞﾝ!W23/1000 -> 52404.985 | AP24: =+AN24-AO24 -> 10870.825 | AQ24: 57262 | AR24: =+AN24-AQ24 -> 6013.81 | AS24: 0 | AT24: =+ﾋﾞｱｶﾞｰﾃﾞﾝ!W23/1000 -> 0 | AU24: =+AS24-AT24 -> 0 | AV24: 0 | AW24: =+AS24-AV24 -> 0 | AX24: =+AN24+AS24 -> 63275.81 | AY24: =+AO24+AT24 -> 52404.985 | AZ24: =+AX24-AY24 -> 10870.825 | BA24: =+AQ24+AV24 -> 57262 | BB24: =+AX24-BA24 -> 6013.81 | BC24: 0 | BD24: =+ブリック!W23/1000 -> 36008.561 | BE24: =+BC24-BD24 -> -36008.561 | BG24: =+BC24-BF24 -> 0 | BH24: 0 | BI24: =+ルスツ羊蹄ぶた!W23/1000 -> 2705.268 | BJ24: =+BH24-BI24 -> -2705.268 | BL24: =+BH24-BK24 -> 0 | BM24: =+BC24+BH24 -> 0 | BN24: =+BD24+BI24 -> 38713.829 | BO24: =+BM24-BN24 -> -38713.829 | BP24: =+BF24+BK24 -> 0 | BQ24: =+BM24-BP24 -> 0 | BR24: 0 | BS24: =+料飲共通!W23/1000 -> 0 | BT24: =+BR24-BS24 -> 0 | BU24: 0 | BV24: =+BR24-BU24 -> 0 | BW24: =+T24+AI24+AX24+BM24+BR24 -> 158130.09 | BX24: =+U24+AJ24+AY24+BN24+BS24 -> 191542.35 | BY24: =+BW24-BX24 -> -33412.261 | BZ24: =+W24+AL24+BA24+BU24 -> 151453 | CA24: =+BW24-BZ24 -> 6677.09
C25: 臨時 | E25: 0 | F25: =+ﾇｰﾍﾞﾙﾌﾟｰｽ!W24/1000 -> 2746.879 | G25: =+E25-F25 -> -2746.879 | H25: 0 | I25: =+E25-H25 -> 0 | J25: 0 | K25: =+ｶﾌｪﾙﾎﾟ!W24/1000 -> 0 | L25: =+J25-K25 -> 0 | M25: 0 | N25: =+J25-M25 -> 0 | O25: 0 | P25: =+ｶﾌｪｾﾚｽﾃ!W24/1000 -> 0 | Q25: =+O25-P25 -> 0 | R25: 0 | S25: =+O25-R25 -> 0 | T25: =+E25+J25+O25 -> 0 | U25: =+F25+K25+P25 -> 2746.879 | V25: =+T25-U25 -> -2746.879 | W25: =+H25+M25+R25 -> 0 | X25: =+T25-W25 -> 0 | AA25: =+Y25-Z25 -> 0 | AB25: 0 | AC25: =+Y25-AB25 -> 0 | AD25: 0 | AE25: =+ｼﾞｭｴﾙｽﾞ!W24/1000 -> 901.71 | AF25: =+AD25-AE25 -> -901.71 | AG25: 0 | AH25: =+AD25-AG25 -> 0 | AI25: =+Y25+AD25 -> 0 | AJ25: =+Z25+AE25 -> 901.71 | AK25: =+AI25-AJ25 -> -901.71 | AL25: =+AB25+AG25 -> 0 | AM25: =+AI25-AL25 -> 0 | AN25: 0 | AO25: =+ｶﾞｰﾃﾞﾝ!W24/1000 -> 3382.787 | AP25: =+AN25-AO25 -> -3382.787 | AQ25: 0 | AR25: =+AN25-AQ25 -> 0 | AS25: 0 | AT25: =+ﾋﾞｱｶﾞｰﾃﾞﾝ!W24/1000 -> 7101.482 | AU25: =+AS25-AT25 -> -7101.482 | AV25: 0 | AW25: =+AS25-AV25 -> 0 | AX25: =+AN25+AS25 -> 0 | AY25: =+AO25+AT25 -> 10484.269 | AZ25: =+AX25-AY25 -> -10484.269 | BA25: =+AQ25+AV25 -> 0 | BB25: =+AX25-BA25 -> 0 | BC25: 0 | BD25: =+ブリック!W24/1000 -> 30.807 | BE25: =+BC25-BD25 -> -30.807 | BG25: =+BC25-BF25 -> 0 | BH25: 0 | BI25: =+ルスツ羊蹄ぶた!W24/1000 -> 32.025 | BJ25: =+BH25-BI25 -> -32.025 | BL25: =+BH25-BK25 -> 0 | BM25: =+BC25+BH25 -> 0 | BN25: =+BD25+BI25 -> 62.832 | BO25: =+BM25-BN25 -> -62.832 | BP25: =+BF25+BK25 -> 0 | BQ25: =+BM25-BP25 -> 0 | BR25: 0 | BS25: =+料飲共通!W24/1000 -> 0 | BT25: =+BR25-BS25 -> 0 | BU25: 0 | BV25: =+BR25-BU25 -> 0 | BW25: =+T25+AI25+AX25+BM25+BR25 -> 0 | BX25: =+U25+AJ25+AY25+BN25+BS25 -> 14195.69 | BY25: =+BW25-BX25 -> -14195.69 | BZ25: =+W25+AL25+BA25+BU25 -> 0 | CA25: =+BW25-BZ25 -> 0
C26: パート | E26: 189 | F26: =+ﾇｰﾍﾞﾙﾌﾟｰｽ!W25/1000 -> 527.295 | G26: =+E26-F26 -> -338.295 | H26: 2007 | I26: =+E26-H26 -> -1818 | J26: 2524.2 | K26: =+ｶﾌｪﾙﾎﾟ!W25/1000 -> 5559.69 | L26: =+J26-K26 -> -3035.49 | M26: 2876 | N26: =+J26-M26 -> -351.8 | O26: 2524.2 | P26: =+ｶﾌｪｾﾚｽﾃ!W25/1000 -> 0 | Q26: =+O26-P26 -> 2524.2 | R26: 2876 | S26: =+O26-R26 -> -351.8 | T26: =+E26+J26+O26 -> 5237.4 | U26: =+F26+K26+P26 -> 6086.985 | V26: =+T26-U26 -> -849.585 | W26: =+H26+M26+R26 -> 7759 | X26: =+T26-W26 -> -2521.6 | AA26: =+Y26-Z26 -> 0 | AB26: 3005 | AC26: =+Y26-AB26 -> -3005 | AD26: 5306.7 | AE26: =+ｼﾞｭｴﾙｽﾞ!W25/1000 -> 4332.241 | AF26: =+AD26-AE26 -> 974.459 | AG26: 5666 | AH26: =+AD26-AG26 -> -359.3 | AI26: =+Y26+AD26 -> 5306.7 | AJ26: =+Z26+AE26 -> 4332.241 | AK26: =+AI26-AJ26 -> 974.459 | AL26: =+AB26+AG26 -> 8671 | AM26: =+AI26-AL26 -> -3364.3 | AN26: 3528 | AO26: =+ｶﾞｰﾃﾞﾝ!W25/1000 -> 8207.102 | AP26: =+AN26-AO26 -> -4679.102 | AQ26: 8095 | AR26: =+AN26-AQ26 -> -4567 | AS26: 3630 | AT26: =+ﾋﾞｱｶﾞｰﾃﾞﾝ!W25/1000 -> 0 | AU26: =+AS26-AT26 -> 3630 | AV26: 3509 | AW26: =+AS26-AV26 -> 121 | AX26: =+AN26+AS26 -> 7158 | AY26: =+AO26+AT26 -> 8207.102 | AZ26: =+AX26-AY26 -> -1049.102 | BA26: =+AQ26+AV26 -> 11604 | BB26: =+AX26-BA26 -> -4446 | BC26: 0 | BD26: =+ブリック!W25/1000 -> 1165.298 | BE26: =+BC26-BD26 -> -1165.298 | BG26: =+BC26-BF26 -> 0 | BH26: 0 | BI26: =+ルスツ羊蹄ぶた!W25/1000 -> 4029.149 | BJ26: =+BH26-BI26 -> -4029.149 | BL26: =+BH26-BK26 -> 0 | BM26: =+BC26+BH26 -> 0 | BN26: =+BD26+BI26 -> 5194.447 | BO26: =+BM26-BN26 -> -5194.447 | BP26: =+BF26+BK26 -> 0 | BQ26: =+BM26-BP26 -> 0 | BR26: 0 | BS26: =+料飲共通!W25/1000 -> 75.35 | BT26: =+BR26-BS26 -> -75.35 | BU26: 0 | BV26: =+BR26-BU26 -> 0 | BW26: =+T26+AI26+AX26+BM26+BR26 -> 17702.1 | BX26: =+U26+AJ26+AY26+BN26+BS26 -> 23896.125 | BY26: =+BW26-BX26 -> -6194.025 | BZ26: =+W26+AL26+BA26+BU26 -> 28034 | CA26: =+BW26-BZ26 -> -10331.9
B27: 退職金 | E27: 0 | F27: =+ﾇｰﾍﾞﾙﾌﾟｰｽ!W26/1000 -> 0 | G27: =+E27-F27 -> 0 | H27: 0 | I27: =+E27-H27 -> 0 | J27: 0 | K27: =+ｶﾌｪﾙﾎﾟ!W26/1000 -> 0 | L27: =+J27-K27 -> 0 | M27: 0 | N27: =+J27-M27 -> 0 | O27: 0 | P27: =+ｶﾌｪｾﾚｽﾃ!W26/1000 -> 0 | Q27: =+O27-P27 -> 0 | R27: 0 | S27: =+O27-R27 -> 0 | T27: =+E27+J27+O27 -> 0 | U27: =+F27+K27+P27 -> 0 | V27: =+T27-U27 -> 0 | W27: =+H27+M27+R27 -> 0 | X27: =+T27-W27 -> 0 | AA27: =+Y27-Z27 -> 0 | AB27: 0 | AC27: =+Y27-AB27 -> 0 | AD27: 0 | AE27: =+ｼﾞｭｴﾙｽﾞ!W26/1000 -> 0 | AF27: =+AD27-AE27 -> 0 | AG27: 0 | AH27: =+AD27-AG27 -> 0 | AI27: =+Y27+AD27 -> 0 | AJ27: =+Z27+AE27 -> 0 | AK27: =+AI27-AJ27 -> 0 | AL27: =+AB27+AG27 -> 0 | AM27: =+AI27-AL27 -> 0 | AN27: 0 | AO27: =+ｶﾞｰﾃﾞﾝ!W26/1000 -> 0 | AP27: =+AN27-AO27 -> 0 | AQ27: 0 | AR27: =+AN27-AQ27 -> 0 | AS27: 0 | AT27: =+ﾋﾞｱｶﾞｰﾃﾞﾝ!W26/1000 -> 0 | AU27: =+AS27-AT27 -> 0 | AV27: 0 | AW27: =+AS27-AV27 -> 0 | AX27: =+AN27+AS27 -> 0 | AY27: =+AO27+AT27 -> 0 | AZ27: =+AX27-AY27 -> 0 | BA27: =+AQ27+AV27 -> 0 | BB27: =+AX27-BA27 -> 0 | BC27: 0 | BD27: =+ブリック!W26/1000 -> 0 | BE27: =+BC27-BD27 -> 0 | BG27: =+BC27-BF27 -> 0 | BH27: 0 | BI27: =+ルスツ羊蹄ぶた!W26/1000 -> 0 | BJ27: =+BH27-BI27 -> 0 | BL27: =+BH27-BK27 -> 0 | BM27: =+BC27+BH27 -> 0 | BN27: =+BD27+BI27 -> 0 | BO27: =+BM27-BN27 -> 0 | BP27: =+BF27+BK27 -> 0 | BQ27: =+BM27-BP27 -> 0 | BR27: 0 | BS27: =+料飲共通!W26/1000 -> 0 | BT27: =+BR27-BS27 -> 0 | BU27: 0 | BV27: =+BR27-BU27 -> 0 | BW27: =+T27+AI27+AX27+BM27+BR27 -> 0 | BX27: =+U27+AJ27+AY27+BN27+BS27 -> 0 | BY27: =+BW27-BX27 -> 0 | BZ27: =+W27+AL27+BA27+BU27 -> 0 | CA27: =+BW27-BZ27 -> 0
C28: 役員 | E28: 0 | F28: =+ﾇｰﾍﾞﾙﾌﾟｰｽ!W27/1000 -> 0 | G28: =+E28-F28 -> 0 | H28: 0 | I28: =+E28-H28 -> 0 | J28: 0 | K28: =+ｶﾌｪﾙﾎﾟ!W27/1000 -> 0 | L28: =+J28-K28 -> 0 | M28: 0 | N28: =+J28-M28 -> 0 | O28: 0 | P28: =+ｶﾌｪｾﾚｽﾃ!W27/1000 -> 0 | Q28: =+O28-P28 -> 0 | R28: 0 | S28: =+O28-R28 -> 0 | T28: =+E28+J28+O28 -> 0 | U28: =+F28+K28+P28 -> 0 | V28: =+T28-U28 -> 0 | W28: =+H28+M28+R28 -> 0 | X28: =+T28-W28 -> 0 | AA28: =+Y28-Z28 -> 0 | AB28: 0 | AC28: =+Y28-AB28 -> 0 | AD28: 0 | AE28: =+ｼﾞｭｴﾙｽﾞ!W27/1000 -> 0 | AF28: =+AD28-AE28 -> 0 | AG28: 0 | AH28: =+AD28-AG28 -> 0 | AI28: =+Y28+AD28 -> 0 | AJ28: =+Z28+AE28 -> 0 | AK28: =+AI28-AJ28 -> 0 | AL28: =+AB28+AG28 -> 0 | AM28: =+AI28-AL28 -> 0 | AN28: 0 | AO28: =+ｶﾞｰﾃﾞﾝ!W27/1000 -> 0 | AP28: =+AN28-AO28 -> 0 | AQ28: 0 | AR28: =+AN28-AQ28 -> 0 | AS28: 0 | AT28: =+ﾋﾞｱｶﾞｰﾃﾞﾝ!W27/1000 -> 0 | AU28: =+AS28-AT28 -> 0 | AV28: 0 | AW28: =+AS28-AV28 -> 0 | AX28: =+AN28+AS28 -> 0 | AY28: =+AO28+AT28 -> 0 | AZ28: =+AX28-AY28 -> 0 | BA28: =+AQ28+AV28 -> 0 | BB28: =+AX28-BA28 -> 0 | BC28: 0 | BD28: =+ブリック!W27/1000 -> 0 | BE28: =+BC28-BD28 -> 0 | BG28: =+BC28-BF28 -> 0 | BH28: 0 | BI28: =+ルスツ羊蹄ぶた!W27/1000 -> 0 | BJ28: =+BH28-BI28 -> 0 | BL28: =+BH28-BK28 -> 0 | BM28: =+BC28+BH28 -> 0 | BN28: =+BD28+BI28 -> 0 | BO28: =+BM28-BN28 -> 0 | BP28: =+BF28+BK28 -> 0 | BQ28: =+BM28-BP28 -> 0 | BR28: 0 | BS28: =+料飲共通!W27/1000 -> 0 | BT28: =+BR28-BS28 -> 0 | BU28: 0 | BV28: =+BR28-BU28 -> 0 | BW28: =+T28+AI28+AX28+BM28+BR28 -> 0 | BX28: =+U28+AJ28+AY28+BN28+BS28 -> 0 | BY28: =+BW28-BX28 -> 0 | BZ28: =+W28+AL28+BA28+BU28 -> 0 | CA28: =+BW28-BZ28 -> 0
C29: 社員 | E29: 0 | F29: =+ﾇｰﾍﾞﾙﾌﾟｰｽ!W28/1000 -> 0 | G29: =+E29-F29 -> 0 | H29: 0 | I29: =+E29-H29 -> 0 | J29: 0 | K29: =+ｶﾌｪﾙﾎﾟ!W28/1000 -> 0 | L29: =+J29-K29 -> 0 | M29: 0 | N29: =+J29-M29 -> 0 | O29: 0 | P29: =+ｶﾌｪｾﾚｽﾃ!W28/1000 -> 0 | Q29: =+O29-P29 -> 0 | R29: 0 | S29: =+O29-R29 -> 0 | T29: =+E29+J29+O29 -> 0 | U29: =+F29+K29+P29 -> 0 | V29: =+T29-U29 -> 0 | W29: =+H29+M29+R29 -> 0 | X29: =+T29-W29 -> 0 | AA29: =+Y29-Z29 -> 0 | AB29: 0 | AC29: =+Y29-AB29 -> 0 | AD29: 0 | AE29: =+ｼﾞｭｴﾙｽﾞ!W28/1000 -> 0 | AF29: =+AD29-AE29 -> 0 | AG29: 0 | AH29: =+AD29-AG29 -> 0 | AI29: =+Y29+AD29 -> 0 | AJ29: =+Z29+AE29 -> 0 | AK29: =+AI29-AJ29 -> 0 | AL29: =+AB29+AG29 -> 0 | AM29: =+AI29-AL29 -> 0 | AN29: 0 | AO29: =+ｶﾞｰﾃﾞﾝ!W28/1000 -> 0 | AP29: =+AN29-AO29 -> 0 | AQ29: 0 | AR29: =+AN29-AQ29 -> 0 | AS29: 0 | AT29: =+ﾋﾞｱｶﾞｰﾃﾞﾝ!W28/1000 -> 0 | AU29: =+AS29-AT29 -> 0 | AV29: 0 | AW29: =+AS29-AV29 -> 0 | AX29: =+AN29+AS29 -> 0 | AY29: =+AO29+AT29 -> 0 | AZ29: =+AX29-AY29 -> 0 | BA29: =+AQ29+AV29 -> 0 | BB29: =+AX29-BA29 -> 0 | BC29: 0 | BD29: =+ブリック!W28/1000 -> 0 | BE29: =+BC29-BD29 -> 0 | BG29: =+BC29-BF29 -> 0 | BH29: 0 | BI29: =+ルスツ羊蹄ぶた!W28/1000 -> 0 | BJ29: =+BH29-BI29 -> 0 | BL29: =+BH29-BK29 -> 0 | BM29: =+BC29+BH29 -> 0 | BN29: =+BD29+BI29 -> 0 | BO29: =+BM29-BN29 -> 0 | BP29: =+BF29+BK29 -> 0 | BQ29: =+BM29-BP29 -> 0 | BR29: 0 | BS29: =+料飲共通!W28/1000 -> 0 | BT29: =+BR29-BS29 -> 0 | BU29: 0 | BV29: =+BR29-BU29 -> 0 | BW29: =+T29+AI29+AX29+BM29+BR29 -> 0 | BX29: =+U29+AJ29+AY29+BN29+BS29 -> 0 | BY29: =+BW29-BX29 -> 0 | BZ29: =+W29+AL29+BA29+BU29 -> 0 | CA29: =+BW29-BZ29 -> 0
B30: 法定福利費 | E30: 7178.685 | F30: =+ﾇｰﾍﾞﾙﾌﾟｰｽ!W29/1000 -> 6257.241 | G30: =+E30-F30 -> 921.44398 | H30: 5897 | I30: =+E30-H30 -> 1281.685 | J30: 241.664 | K30: =+ｶﾌｪﾙﾎﾟ!W29/1000 -> 501.876 | L30: =+J30-K30 -> -260.212 | M30: 245 | N30: =+J30-M30 -> -3.336 | O30: 241.665 | P30: =+ｶﾌｪｾﾚｽﾃ!W29/1000 -> 0 | Q30: =+O30-P30 -> 241.665 | R30: 245 | S30: =+O30-R30 -> -3.335 | T30: =+E30+J30+O30 -> 7662.014 | U30: =+F30+K30+P30 -> 6759.117 | V30: =+T30-U30 -> 902.89698 | W30: =+H30+M30+R30 -> 6387 | X30: =+T30-W30 -> 1275.014 | AA30: =+Y30-Z30 -> 0 | AB30: 298 | AC30: =+Y30-AB30 -> -298 | AD30: 8543.7104 | AE30: =+ｼﾞｭｴﾙｽﾞ!W29/1000 -> 5404.554 | AF30: =+AD30-AE30 -> 3139.1564 | AG30: 7053 | AH30: =+AD30-AG30 -> 1490.7104 | AI30: =+Y30+AD30 -> 8543.7104 | AJ30: =+Z30+AE30 -> 5404.554 | AK30: =+AI30-AJ30 -> 3139.1564 | AL30: =+AB30+AG30 -> 7351 | AM30: =+AI30-AL30 -> 1192.7104 | AN30: 6767.259 | AO30: =+ｶﾞｰﾃﾞﾝ!W29/1000 -> 5387.882 | AP30: =+AN30-AO30 -> 1379.377 | AQ30: 8223 | AR30: =+AN30-AQ30 -> -1455.741 | AS30: 2900.2534 | AT30: =+ﾋﾞｱｶﾞｰﾃﾞﾝ!W29/1000 -> 0 | AU30: =+AS30-AT30 -> 2900.2534 | AV30: 0 | AW30: =+AS30-AV30 -> 2900.2534 | AX30: =+AN30+AS30 -> 9667.5124 | AY30: =+AO30+AT30 -> 5387.882 | AZ30: =+AX30-AY30 -> 4279.6304 | BA30: =+AQ30+AV30 -> 8223 | BB30: =+AX30-BA30 -> 1444.5124 | BC30: 0 | BD30: =+ブリック!W29/1000 -> 3972.631 | BE30: =+BC30-BD30 -> -3972.631 | BG30: =+BC30-BF30 -> 0 | BH30: 0 | BI30: =+ルスツ羊蹄ぶた!W29/1000 -> 275.313 | BJ30: =+BH30-BI30 -> -275.313 | BL30: =+BH30-BK30 -> 0 | BM30: =+BC30+BH30 -> 0 | BN30: =+BD30+BI30 -> 4247.944 | BO30: =+BM30-BN30 -> -4247.944 | BP30: =+BF30+BK30 -> 0 | BQ30: =+BM30-BP30 -> 0 | BR30: 3421.3564 | BS30: =+料飲共通!W29/1000 -> 4534.958 | BT30: =+BR30-BS30 -> -1113.6016 | BU30: 3322 | BV30: =+BR30-BU30 -> 99.356448 | BW30: =+T30+AI30+AX30+BM30+BR30 -> 29294.593 | BX30: =+U30+AJ30+AY30+BN30+BS30 -> 26334.455 | BY30: =+BW30-BX30 -> 2960.1382 | BZ30: =+W30+AL30+BA30+BU30 -> 25283 | CA30: =+BW30-BZ30 -> 4011.5932
B31: 退職年金掛金 | E31: 52.8 | F31: =+ﾇｰﾍﾞﾙﾌﾟｰｽ!W30/1000 -> 68 | G31: =+E31-F31 -> -15.2 | H31: 47 | I31: =+E31-H31 -> 5.8 | J31: 0 | K31: =+ｶﾌｪﾙﾎﾟ!W30/1000 -> 0 | L31: =+J31-K31 -> 0 | M31: 0 | N31: =+J31-M31 -> 0 | O31: 0 | P31: =+ｶﾌｪｾﾚｽﾃ!W30/1000 -> 0 | Q31: =+O31-P31 -> 0 | R31: 0 | S31: =+O31-R31 -> 0 | T31: =+E31+J31+O31 -> 52.8 | U31: =+F31+K31+P31 -> 68 | V31: =+T31-U31 -> -15.2 | W31: =+H31+M31+R31 -> 47 | X31: =+T31-W31 -> 5.8 | AA31: =+Y31-Z31 -> 0 | AB31: 0 | AC31: =+Y31-AB31 -> 0 | AD31: 62.4 | AE31: =+ｼﾞｭｴﾙｽﾞ!W30/1000 -> 88.8 | AF31: =+AD31-AE31 -> -26.4 | AG31: 51 | AH31: =+AD31-AG31 -> 11.4 | AI31: =+Y31+AD31 -> 62.4 | AJ31: =+Z31+AE31 -> 88.8 | AK31: =+AI31-AJ31 -> -26.4 | AL31: =+AB31+AG31 -> 51 | AM31: =+AI31-AL31 -> 11.4 | AN31: 50.4 | AO31: =+ｶﾞｰﾃﾞﾝ!W30/1000 -> 66.8 | AP31: =+AN31-AO31 -> -16.4 | AQ31: 70 | AR31: =+AN31-AQ31 -> -19.6 | AS31: 21.6 | AT31: =+ﾋﾞｱｶﾞｰﾃﾞﾝ!W30/1000 -> 0 | AU31: =+AS31-AT31 -> 21.6 | AV31: 0 | AW31: =+AS31-AV31 -> 21.6 | AX31: =+AN31+AS31 -> 72 | AY31: =+AO31+AT31 -> 66.8 | AZ31: =+AX31-AY31 -> 5.2 | BA31: =+AQ31+AV31 -> 70 | BB31: =+AX31-BA31 -> 2 | BC31: 0 | BD31: =+ブリック!W30/1000 -> 24.2 | BE31: =+BC31-BD31 -> -24.2 | BG31: =+BC31-BF31 -> 0 | BH31: 0 | BI31: =+ルスツ羊蹄ぶた!W30/1000 -> -0.8 | BJ31: =+BH31-BI31 -> 0.8 | BL31: =+BH31-BK31 -> 0 | BM31: =+BC31+BH31 -> 0 | BN31: =+BD31+BI31 -> 23.4 | BO31: =+BM31-BN31 -> -23.4 | BP31: =+BF31+BK31 -> 0 | BQ31: =+BM31-BP31 -> 0 | BR31: 14.4 | BS31: =+料飲共通!W30/1000 -> 20 | BT31: =+BR31-BS31 -> -5.6 | BU31: 14 | BV31: =+BR31-BU31 -> 0.4 | BW31: =+T31+AI31+AX31+BM31+BR31 -> 201.6 | BX31: =+U31+AJ31+AY31+BN31+BS31 -> 267 | BY31: =+BW31-BX31 -> -65.4 | BZ31: =+W31+AL31+BA31+BU31 -> 182 | CA31: =+BW31-BZ31 -> 19.6
B32: 福利厚生費 | E32: 609.2 | F32: =+ﾇｰﾍﾞﾙﾌﾟｰｽ!W31/1000 -> 392.02 | G32: =+E32-F32 -> 217.18 | H32: 111 | I32: =+E32-H32 -> 498.2 | J32: 0 | K32: =+ｶﾌｪﾙﾎﾟ!W31/1000 -> 0 | L32: =+J32-K32 -> 0 | M32: 9 | N32: =+J32-M32 -> -9 | O32: 0 | P32: =+ｶﾌｪｾﾚｽﾃ!W31/1000 -> 0 | Q32: =+O32-P32 -> 0 | R32: 9 | S32: =+O32-R32 -> -9 | T32: =+E32+J32+O32 -> 609.2 | U32: =+F32+K32+P32 -> 392.02 | V32: =+T32-U32 -> 217.18 | W32: =+H32+M32+R32 -> 129 | X32: =+T32-W32 -> 480.2 | AA32: =+Y32-Z32 -> 0 | AB32: 0 | AC32: =+Y32-AB32 -> 0 | AD32: 623.6 | AE32: =+ｼﾞｭｴﾙｽﾞ!W31/1000 -> 209.55 | AF32: =+AD32-AE32 -> 414.05 | AG32: 249 | AH32: =+AD32-AG32 -> 374.6 | AI32: =+Y32+AD32 -> 623.6 | AJ32: =+Z32+AE32 -> 209.55 | AK32: =+AI32-AJ32 -> 414.05 | AL32: =+AB32+AG32 -> 249 | AM32: =+AI32-AL32 -> 374.6 | AN32: 446.6 | AO32: =+ｶﾞｰﾃﾞﾝ!W31/1000 -> 261.156 | AP32: =+AN32-AO32 -> 185.444 | AQ32: 516 | AR32: =+AN32-AQ32 -> -69.4 | AS32: 191.4 | AT32: =+ﾋﾞｱｶﾞｰﾃﾞﾝ!W31/1000 -> 0 | AU32: =+AS32-AT32 -> 191.4 | AV32: 0 | AW32: =+AS32-AV32 -> 191.4 | AX32: =+AN32+AS32 -> 638 | AY32: =+AO32+AT32 -> 261.156 | AZ32: =+AX32-AY32 -> 376.844 | BA32: =+AQ32+AV32 -> 516 | BB32: =+AX32-BA32 -> 122 | BC32: 0 | BD32: =+ブリック!W31/1000 -> 570.027 | BE32: =+BC32-BD32 -> -570.027 | BG32: =+BC32-BF32 -> 0 | BH32: 0 | BI32: =+ルスツ羊蹄ぶた!W31/1000 -> 480.961 | BJ32: =+BH32-BI32 -> -480.961 | BL32: =+BH32-BK32 -> 0 | BM32: =+BC32+BH32 -> 0 | BN32: =+BD32+BI32 -> 1050.988 | BO32: =+BM32-BN32 -> -1050.988 | BP32: =+BF32+BK32 -> 0 | BQ32: =+BM32-BP32 -> 0 | BR32: 61.6 | BS32: =+料飲共通!W31/1000 -> 264.054 | BT32: =+BR32-BS32 -> -202.454 | BU32: 430 | BV32: =+BR32-BU32 -> -368.4 | BW32: =+T32+AI32+AX32+BM32+BR32 -> 1932.4 | BX32: =+U32+AJ32+AY32+BN32+BS32 -> 2177.768 | BY32: =+BW32-BX32 -> -245.368 | BZ32: =+W32+AL32+BA32+BU32 -> 1324 | CA32: =+BW32-BZ32 -> 608.4
C33: 福利厚生費 | E33: 79.2 | F33: =+ﾇｰﾍﾞﾙﾌﾟｰｽ!W32/1000 -> 69 | G33: =+E33-F33 -> 10.2 | H33: 56 | I33: =+E33-H33 -> 23.2 | J33: 0 | K33: =+ｶﾌｪﾙﾎﾟ!W32/1000 -> 0 | L33: =+J33-K33 -> 0 | M33: 0 | N33: =+J33-M33 -> 0 | O33: 0 | P33: =+ｶﾌｪｾﾚｽﾃ!W32/1000 -> 0 | Q33: =+O33-P33 -> 0 | R33: 0 | S33: =+O33-R33 -> 0 | T33: =+E33+J33+O33 -> 79.2 | U33: =+F33+K33+P33 -> 69 | V33: =+T33-U33 -> 10.2 | W33: =+H33+M33+R33 -> 56 | X33: =+T33-W33 -> 23.2 | AA33: =+Y33-Z33 -> 0 | AB33: 0 | AC33: =+Y33-AB33 -> 0 | AD33: 93.6 | AE33: =+ｼﾞｭｴﾙｽﾞ!W32/1000 -> 85.8 | AF33: =+AD33-AE33 -> 7.8 | AG33: 65 | AH33: =+AD33-AG33 -> 28.6 | AI33: =+Y33+AD33 -> 93.6 | AJ33: =+Z33+AE33 -> 85.8 | AK33: =+AI33-AJ33 -> 7.8 | AL33: =+AB33+AG33 -> 65 | AM33: =+AI33-AL33 -> 28.6 | AN33: 108 | AO33: =+ｶﾞｰﾃﾞﾝ!W32/1000 -> 92.596 | AP33: =+AN33-AO33 -> 15.404 | AQ33: 75 | AR33: =+AN33-AQ33 -> 33 | AS33: 0 | AT33: =+ﾋﾞｱｶﾞｰﾃﾞﾝ!W32/1000 -> 0 | AU33: =+AS33-AT33 -> 0 | AV33: 0 | AW33: =+AS33-AV33 -> 0 | AX33: =+AN33+AS33 -> 108 | AY33: =+AO33+AT33 -> 92.596 | AZ33: =+AX33-AY33 -> 15.404 | BA33: =+AQ33+AV33 -> 75 | BB33: =+AX33-BA33 -> 33 | BC33: 0 | BD33: =+ブリック!W32/1000 -> 56.892 | BE33: =+BC33-BD33 -> -56.892 | BG33: =+BC33-BF33 -> 0 | BH33: 0 | BI33: =+ルスツ羊蹄ぶた!W32/1000 -> -0.6 | BJ33: =+BH33-BI33 -> 0.6 | BL33: =+BH33-BK33 -> 0 | BM33: =+BC33+BH33 -> 0 | BN33: =+BD33+BI33 -> 56.292 | BO33: =+BM33-BN33 -> -56.292 | BP33: =+BF33+BK33 -> 0 | BQ33: =+BM33-BP33 -> 0 | BR33: 21.6 | BS33: =+料飲共通!W32/1000 -> 67.604 | BT33: =+BR33-BS33 -> -46.004 | BU33: 32 | BV33: =+BR33-BU33 -> -10.4 | BW33: =+T33+AI33+AX33+BM33+BR33 -> 302.4 | BX33: =+U33+AJ33+AY33+BN33+BS33 -> 371.292 | BY33: =+BW33-BX33 -> -68.892 | BZ33: =+W33+AL33+BA33+BU33 -> 228 | CA33: =+BW33-BZ33 -> 74.4
C34: 被服費 | E34: 330 | F34: =+ﾇｰﾍﾞﾙﾌﾟｰｽ!W33/1000 -> 323.02 | G34: =+E34-F34 -> 6.98 | H34: 48 | I34: =+E34-H34 -> 282 | J34: 0 | K34: =+ｶﾌｪﾙﾎﾟ!W33/1000 -> 0 | L34: =+J34-K34 -> 0 | M34: 9 | N34: =+J34-M34 -> -9 | O34: 0 | P34: =+ｶﾌｪｾﾚｽﾃ!W33/1000 -> 0 | Q34: =+O34-P34 -> 0 | R34: 9 | S34: =+O34-R34 -> -9 | T34: =+E34+J34+O34 -> 330 | U34: =+F34+K34+P34 -> 323.02 | V34: =+T34-U34 -> 6.98 | W34: =+H34+M34+R34 -> 66 | X34: =+T34-W34 -> 264 | AA34: =+Y34-Z34 -> 0 | AB34: 0 | AC34: =+Y34-AB34 -> 0 | AD34: 330 | AE34: =+ｼﾞｭｴﾙｽﾞ!W33/1000 -> 123.75 | AF34: =+AD34-AE34 -> 206.25 | AG34: 177 | AH34: =+AD34-AG34 -> 153 | AI34: =+Y34+AD34 -> 330 | AJ34: =+Z34+AE34 -> 123.75 | AK34: =+AI34-AJ34 -> 206.25 | AL34: =+AB34+AG34 -> 177 | AM34: =+AI34-AL34 -> 153 | AN34: 330 | AO34: =+ｶﾞｰﾃﾞﾝ!W33/1000 -> 168.56 | AP34: =+AN34-AO34 -> 161.44 | AQ34: 436 | AR34: =+AN34-AQ34 -> -106 | AS34: 0 | AT34: =+ﾋﾞｱｶﾞｰﾃﾞﾝ!W33/1000 -> 0 | AU34: =+AS34-AT34 -> 0 | AV34: 0 | AW34: =+AS34-AV34 -> 0 | AX34: =+AN34+AS34 -> 330 | AY34: =+AO34+AT34 -> 168.56 | AZ34: =+AX34-AY34 -> 161.44 | BA34: =+AQ34+AV34 -> 436 | BB34: =+AX34-BA34 -> -106 | BC34: 0 | BD34: =+ブリック!W33/1000 -> 513.135 | BE34: =+BC34-BD34 -> -513.135 | BG34: =+BC34-BF34 -> 0 | BH34: 0 | BI34: =+ルスツ羊蹄ぶた!W33/1000 -> 472.47 | BJ34: =+BH34-BI34 -> -472.47 | BL34: =+BH34-BK34 -> 0 | BM34: =+BC34+BH34 -> 0 | BN34: =+BD34+BI34 -> 985.605 | BO34: =+BM34-BN34 -> -985.605 | BP34: =+BF34+BK34 -> 0 | BQ34: =+BM34-BP34 -> 0 | BR34: 40 | BS34: =+料飲共通!W33/1000 -> 196.45 | BT34: =+BR34-BS34 -> -156.45 | BU34: 398 | BV34: =+BR34-BU34 -> -358 | BW34: =+T34+AI34+AX34+BM34+BR34 -> 1030 | BX34: =+U34+AJ34+AY34+BN34+BS34 -> 1797.385 | BY34: =+BW34-BX34 -> -767.385 | BZ34: =+W34+AL34+BA34+BU34 -> 1077 | CA34: =+BW34-BZ34 -> -47
C35: 研修費 | E35: 200 | F35: =+ﾇｰﾍﾞﾙﾌﾟｰｽ!W34/1000 -> 0 | G35: =+E35-F35 -> 200 | H35: 7 | I35: =+E35-H35 -> 193 | J35: 0 | K35: =+ｶﾌｪﾙﾎﾟ!W34/1000 -> 0 | L35: =+J35-K35 -> 0 | M35: 0 | N35: =+J35-M35 -> 0 | O35: 0 | P35: =+ｶﾌｪｾﾚｽﾃ!W34/1000 -> 0 | Q35: =+O35-P35 -> 0 | R35: 0 | S35: =+O35-R35 -> 0 | T35: =+E35+J35+O35 -> 200 | U35: =+F35+K35+P35 -> 0 | V35: =+T35-U35 -> 200 | W35: =+H35+M35+R35 -> 7 | X35: =+T35-W35 -> 193 | AA35: =+Y35-Z35 -> 0 | AB35: 0 | AC35: =+Y35-AB35 -> 0 | AD35: 200 | AE35: =+ｼﾞｭｴﾙｽﾞ!W34/1000 -> 0 | AF35: =+AD35-AE35 -> 200 | AG35: 7 | AH35: =+AD35-AG35 -> 193 | AI35: =+Y35+AD35 -> 200 | AJ35: =+Z35+AE35 -> 0 | AK35: =+AI35-AJ35 -> 200 | AL35: =+AB35+AG35 -> 7 | AM35: =+AI35-AL35 -> 193 | AN35: 200 | AO35: =+ｶﾞｰﾃﾞﾝ!W34/1000 -> 0 | AP35: =+AN35-AO35 -> 200 | AQ35: 5 | AR35: =+AN35-AQ35 -> 195 | AS35: 0 | AT35: =+ﾋﾞｱｶﾞｰﾃﾞﾝ!W34/1000 -> 0 | AU35: =+AS35-AT35 -> 0 | AV35: 0 | AW35: =+AS35-AV35 -> 0 | AX35: =+AN35+AS35 -> 200 | AY35: =+AO35+AT35 -> 0 | AZ35: =+AX35-AY35 -> 200 | BA35: =+AQ35+AV35 -> 5 | BB35: =+AX35-BA35 -> 195 | BC35: 0 | BD35: =+ブリック!W34/1000 -> 0 | BE35: =+BC35-BD35 -> 0 | BG35: =+BC35-BF35 -> 0 | BH35: 0 | BI35: =+ルスツ羊蹄ぶた!W34/1000 -> 9.091 | BJ35: =+BH35-BI35 -> -9.091 | BL35: =+BH35-BK35 -> 0 | BM35: =+BC35+BH35 -> 0 | BN35: =+BD35+BI35 -> 9.091 | BO35: =+BM35-BN35 -> -9.091 | BP35: =+BF35+BK35 -> 0 | BQ35: =+BM35-BP35 -> 0 | BR35: 0 | BS35: =+料飲共通!W34/1000 -> 0 | BT35: =+BR35-BS35 -> 0 | BU35: 0 | BV35: =+BR35-BU35 -> 0 | BW35: =+T35+AI35+AX35+BM35+BR35 -> 600 | BX35: =+U35+AJ35+AY35+BN35+BS35 -> 9.091 | BY35: =+BW35-BX35 -> 590.909 | BZ35: =+W35+AL35+BA35+BU35 -> 19 | CA35: =+BW35-BZ35 -> 581
B36: 通勤費 | E36: 1174.872 | F36: =+ﾇｰﾍﾞﾙﾌﾟｰｽ!W35/1000 -> 1606.446 | G36: =+E36-F36 -> -431.574 | H36: 1154 | I36: =+E36-H36 -> 20.872 | J36: 111.01 | K36: =+ｶﾌｪﾙﾎﾟ!W35/1000 -> 156.197 | L36: =+J36-K36 -> -45.187 | M36: 70 | N36: =+J36-M36 -> 41.01 | O36: 111.01 | P36: =+ｶﾌｪｾﾚｽﾃ!W35/1000 -> 0 | Q36: =+O36-P36 -> 111.01 | R36: 70 | S36: =+O36-R36 -> 41.01 | T36: =+E36+J36+O36 -> 1396.892 | U36: =+F36+K36+P36 -> 1762.643 | V36: =+T36-U36 -> -365.751 | W36: =+H36+M36+R36 -> 1294 | X36: =+T36-W36 -> 102.892 | AA36: =+Y36-Z36 -> 0 | AB36: 185 | AC36: =+Y36-AB36 -> -185 | AD36: 1849.332 | AE36: =+ｼﾞｭｴﾙｽﾞ!W35/1000 -> 1120.252 | AF36: =+AD36-AE36 -> 729.08 | AG36: 1634 | AH36: =+AD36-AG36 -> 215.332 | AI36: =+Y36+AD36 -> 1849.332 | AJ36: =+Z36+AE36 -> 1120.252 | AK36: =+AI36-AJ36 -> 729.08 | AL36: =+AB36+AG36 -> 1819 | AM36: =+AI36-AL36 -> 30.332 | AN36: 1608.102 | AO36: =+ｶﾞｰﾃﾞﾝ!W35/1000 -> 2699.874 | AP36: =+AN36-AO36 -> -1091.772 | AQ36: 2302 | AR36: =+AN36-AQ36 -> -693.898 | AS36: 689.186 | AT36: =+ﾋﾞｱｶﾞｰﾃﾞﾝ!W35/1000 -> 612.239 | AU36: =+AS36-AT36 -> 76.947 | AV36: 401 | AW36: =+AS36-AV36 -> 288.186 | AX36: =+AN36+AS36 -> 2297.288 | AY36: =+AO36+AT36 -> 3312.113 | AZ36: =+AX36-AY36 -> -1014.825 | BA36: =+AQ36+AV36 -> 2703 | BB36: =+AX36-BA36 -> -405.712 | BC36: 0 | BD36: =+ブリック!W35/1000 -> 1087.259 | BE36: =+BC36-BD36 -> -1087.259 | BG36: =+BC36-BF36 -> 0 | BH36: 0 | BI36: =+ルスツ羊蹄ぶた!W35/1000 -> 576.152 | BJ36: =+BH36-BI36 -> -576.152 | BL36: =+BH36-BK36 -> 0 | BM36: =+BC36+BH36 -> 0 | BN36: =+BD36+BI36 -> 1663.411 | BO36: =+BM36-BN36 -> -1663.411 | BP36: =+BF36+BK36 -> 0 | BQ36: =+BM36-BP36 -> 0 | BR36: 236.856 | BS36: =+料飲共通!W35/1000 -> 694.66 | BT36: =+BR36-BS36 -> -457.804 | BU36: 233 | BV36: =+BR36-BU36 -> 3.856 | BW36: =+T36+AI36+AX36+BM36+BR36 -> 5780.368 | BX36: =+U36+AJ36+AY36+BN36+BS36 -> 8553.079 | BY36: =+BW36-BX36 -> -2772.711 | BZ36: =+W36+AL36+BA36+BU36 -> 6049 | CA36: =+BW36-BZ36 -> -268.632
B37: 引当金繰入額 | E37: 0 | F37: =+ﾇｰﾍﾞﾙﾌﾟｰｽ!W36/1000 -> 0 | G37: =+E37-F37 -> 0 | H37: 0 | I37: =+E37-H37 -> 0 | J37: 0 | K37: =+ｶﾌｪﾙﾎﾟ!W36/1000 -> 0 | L37: =+J37-K37 -> 0 | M37: 0 | N37: =+J37-M37 -> 0 | O37: 0 | P37: =+ｶﾌｪｾﾚｽﾃ!W36/1000 -> 0 | Q37: =+O37-P37 -> 0 | R37: 0 | S37: =+O37-R37 -> 0 | T37: =+E37+J37+O37 -> 0 | U37: =+F37+K37+P37 -> 0 | V37: =+T37-U37 -> 0 | W37: =+H37+M37+R37 -> 0 | X37: =+T37-W37 -> 0 | AA37: =+Y37-Z37 -> 0 | AB37: 0 | AC37: =+Y37-AB37 -> 0 | AD37: 0 | AE37: =+ｼﾞｭｴﾙｽﾞ!W36/1000 -> 0 | AF37: =+AD37-AE37 -> 0 | AG37: 0 | AH37: =+AD37-AG37 -> 0 | AI37: =+Y37+AD37 -> 0 | AJ37: =+Z37+AE37 -> 0 | AK37: =+AI37-AJ37 -> 0 | AL37: =+AB37+AG37 -> 0 | AM37: =+AI37-AL37 -> 0 | AN37: 0 | AO37: =+ｶﾞｰﾃﾞﾝ!W36/1000 -> 0 | AP37: =+AN37-AO37 -> 0 | AQ37: 0 | AR37: =+AN37-AQ37 -> 0 | AS37: 0 | AT37: =+ﾋﾞｱｶﾞｰﾃﾞﾝ!W36/1000 -> 0 | AU37: =+AS37-AT37 -> 0 | AV37: 0 | AW37: =+AS37-AV37 -> 0 | AX37: =+AN37+AS37 -> 0 | AY37: =+AO37+AT37 -> 0 | AZ37: =+AX37-AY37 -> 0 | BA37: =+AQ37+AV37 -> 0 | BB37: =+AX37-BA37 -> 0 | BC37: 0 | BD37: =+ブリック!W36/1000 -> 0 | BE37: =+BC37-BD37 -> 0 | BG37: =+BC37-BF37 -> 0 | BH37: 0 | BI37: =+ルスツ羊蹄ぶた!W36/1000 -> 0 | BJ37: =+BH37-BI37 -> 0 | BL37: =+BH37-BK37 -> 0 | BM37: =+BC37+BH37 -> 0 | BN37: =+BD37+BI37 -> 0 | BO37: =+BM37-BN37 -> 0 | BP37: =+BF37+BK37 -> 0 | BQ37: =+BM37-BP37 -> 0 | BR37: 0 | BS37: =+料飲共通!W36/1000 -> 0 | BT37: =+BR37-BS37 -> 0 | BU37: 0 | BV37: =+BR37-BU37 -> 0 | BW37: =+T37+AI37+AX37+BM37+BR37 -> 0 | BX37: =+U37+AJ37+AY37+BN37+BS37 -> 0 | BY37: =+BW37-BX37 -> 0 | BZ37: =+W37+AL37+BA37+BU37 -> 0 | CA37: =+BW37-BZ37 -> 0
A38: 物件費 | E38: 24819.605 | F38: =+ﾇｰﾍﾞﾙﾌﾟｰｽ!W37/1000 -> 22075.142 | G38: =+E38-F38 -> 2744.463 | H38: 24156 | I38: =+E38-H38 -> 663.605 | J38: 2843.405 | K38: =+ｶﾌｪﾙﾎﾟ!W37/1000 -> 2688.842 | L38: =+J38-K38 -> 154.563 | M38: 2898 | N38: =+J38-M38 -> -54.595 | O38: 1603.983 | P38: =+ｶﾌｪｾﾚｽﾃ!W37/1000 -> 1619.286 | Q38: =+O38-P38 -> -15.303 | R38: 1666 | S38: =+O38-R38 -> -62.017 | T38: =+E38+J38+O38 -> 29266.993 | U38: =+F38+K38+P38 -> 26383.27 | V38: =+T38-U38 -> 2883.723 | W38: =+H38+M38+R38 -> 28720 | X38: =+T38-W38 -> 546.993 | AA38: =+Y38-Z38 -> 0 | AB38: 1367 | AC38: =+Y38-AB38 -> -1367 | AD38: 22752.677 | AE38: =+ｼﾞｭｴﾙｽﾞ!W37/1000 -> 20235.614 | AF38: =+AD38-AE38 -> 2517.063 | AG38: 25991 | AH38: =+AD38-AG38 -> -3238.323 | AI38: =+Y38+AD38 -> 22752.677 | AJ38: =+Z38+AE38 -> 20235.614 | AK38: =+AI38-AJ38 -> 2517.063 | AL38: =+AB38+AG38 -> 27358 | AM38: =+AI38-AL38 -> -4605.323 | AN38: 34114.208 | AO38: =+ｶﾞｰﾃﾞﾝ!W37/1000 -> 34477.414 | AP38: =+AN38-AO38 -> -363.206 | AQ38: 36345 | AR38: =+AN38-AQ38 -> -2230.792 | AS38: 64246.364 | AT38: =+ﾋﾞｱｶﾞｰﾃﾞﾝ!W37/1000 -> 71458.464 | AU38: =+AS38-AT38 -> -7212.1 | AV38: 77278 | AW38: =+AS38-AV38 -> -13031.636 | AX38: =+AN38+AS38 -> 98360.572 | AY38: =+AO38+AT38 -> 105935.88 | AZ38: =+AX38-AY38 -> -7575.306 | BA38: =+AQ38+AV38 -> 113623 | BB38: =+AX38-BA38 -> -15262.428 | BC38: 19363.931 | BD38: =+ブリック!W37/1000 -> 30152.734 | BE38: =+BC38-BD38 -> -10788.803 | BG38: =+BC38-BF38 -> 19363.931 | BH38: 12688.171 | BI38: =+ルスツ羊蹄ぶた!W37/1000 -> 12579.179 | BJ38: =+BH38-BI38 -> 108.99246 | BL38: =+BH38-BK38 -> 12688.171 | BM38: =+BC38+BH38 -> 32052.103 | BN38: =+BD38+BI38 -> 42731.913 | BO38: =+BM38-BN38 -> -10679.81 | BP38: =+BF38+BK38 -> 0 | BQ38: =+BM38-BP38 -> 32052.103 | BR38: 2443.85 | BS38: =+料飲共通!W37/1000 -> 4455.652 | BT38: =+BR38-BS38 -> -2011.802 | BU38: 7980 | BV38: =+BR38-BU38 -> -5536.15 | BW38: =+T38+AI38+AX38+BM38+BR38 -> 184876.19 | BX38: =+U38+AJ38+AY38+BN38+BS38 -> 199742.33 | BY38: =+BW38-BX38 -> -14866.132 | BZ38: =+W38+AL38+BA38+BU38 -> 177681 | CA38: =+BW38-BZ38 -> 7195.1948
B39: 消耗品費 | E39: 2520 | F39: =+ﾇｰﾍﾞﾙﾌﾟｰｽ!W38/1000 -> 1774.83 | G39: =+E39-F39 -> 745.17 | H39: 2806 | I39: =+E39-H39 -> -286 | J39: 560 | K39: =+ｶﾌｪﾙﾎﾟ!W38/1000 -> 602.035 | L39: =+J39-K39 -> -42.035 | M39: 512 | N39: =+J39-M39 -> 48 | O39: 60 | P39: =+ｶﾌｪｾﾚｽﾃ!W38/1000 -> 30 | Q39: =+O39-P39 -> 30 | R39: 202 | S39: =+O39-R39 -> -142 | T39: =+E39+J39+O39 -> 3140 | U39: =+F39+K39+P39 -> 2406.865 | V39: =+T39-U39 -> 733.135 | W39: =+H39+M39+R39 -> 3520 | X39: =+T39-W39 -> -380 | AA39: =+Y39-Z39 -> 0 | AB39: 620 | AC39: =+Y39-AB39 -> -620 | AD39: 3813.5 | AE39: =+ｼﾞｭｴﾙｽﾞ!W38/1000 -> 3469.764 | AF39: =+AD39-AE39 -> 343.736 | AG39: 5864 | AH39: =+AD39-AG39 -> -2050.5 | AI39: =+Y39+AD39 -> 3813.5 | AJ39: =+Z39+AE39 -> 3469.764 | AK39: =+AI39-AJ39 -> 343.736 | AL39: =+AB39+AG39 -> 6484 | AM39: =+AI39-AL39 -> -2670.5 | AN39: 2380 | AO39: =+ｶﾞｰﾃﾞﾝ!W38/1000 -> 2493.685 | AP39: =+AN39-AO39 -> -113.685 | AQ39: 4106 | AR39: =+AN39-AQ39 -> -1726 | AS39: 4439 | AT39: =+ﾋﾞｱｶﾞｰﾃﾞﾝ!W38/1000 -> 5235.503 | AU39: =+AS39-AT39 -> -796.503 | AV39: 4405 | AW39: =+AS39-AV39 -> 34 | AX39: =+AN39+AS39 -> 6819 | AY39: =+AO39+AT39 -> 7729.188 | AZ39: =+AX39-AY39 -> -910.188 | BA39: =+AQ39+AV39 -> 8511 | BB39: =+AX39-BA39 -> -1692 | BC39: 1840.8903 | BD39: =+ブリック!W38/1000 -> 7297.141 | BE39: =+BC39-BD39 -> -5456.2507 | BG39: =+BC39-BF39 -> 1840.8903 | BH39: 1186.5044 | BI39: =+ルスツ羊蹄ぶた!W38/1000 -> 1346.436 | BJ39: =+BH39-BI39 -> -159.93157 | BL39: =+BH39-BK39 -> 1186.5044 | BM39: =+BC39+BH39 -> 3027.3947 | BN39: =+BD39+BI39 -> 8643.577 | BO39: =+BM39-BN39 -> -5616.1823 | BP39: =+BF39+BK39 -> 0 | BQ39: =+BM39-BP39 -> 3027.3947 | BR39: 0 | BS39: =+料飲共通!W38/1000 -> 579.2 | BT39: =+BR39-BS39 -> -579.2 | BU39: 0 | BV39: =+BR39-BU39 -> 0 | BW39: =+T39+AI39+AX39+BM39+BR39 -> 16799.895 | BX39: =+U39+AJ39+AY39+BN39+BS39 -> 22828.594 | BY39: =+BW39-BX39 -> -6028.6993 | BZ39: =+W39+AL39+BA39+BU39 -> 18515 | CA39: =+BW39-BZ39 -> -1715.1053
