Workbook

Sheet レビュー
A1: 【R5 さっぽろテレビ塔ビアガーデン振り返り】
A2: ①売上 | I2: 単位：円 | K2: ①コメント
A3: 月 | B3: 実績 | C3: 予算 | D3: 予算比 | E3: 差異 | F3: 予測 | G3: 予測比 | H3: 差異 | I3: 1日平均売上 | J3: 平均気温 | K3: 売上については左記の通り、対予算123.9％にて終了いたしました。コロナ禍前の2019年と比較しても対比125.4％（+22,223千円）の結果となりました。これまで1億円の大台に達したことはなかったということです。その大きな要因としてはスタッフの頑張りはもちろんですが、やはり史上稀に見る猛暑となったことが挙げられます。特に6月と8月は気象庁の観測史上最高値を記録し、7月においても史上2番目の平均気温となりました。ただ、天候要因については影響値として一定の条件下で記録していかなければならないもので、いかにこの天候要因を限定的にできるか？というのが引き続きの課題となります。※各月に天候要因を数値化したものを載せています。次年度へ向け今年度のデータを活かし、テーブル配置・スタッフアサインメント・予約システム再構築・RPA/DX 促進・メニューラインナップの見直し等により、さらにポテンシャルを引き出し売上を積み上げられると認識しています。
A4: 5 | B4: 1795227.3 | C4: 6890000 | D4: =B4/C4 -> 0.26055548 | E4: =B4-C4 -> -5094772.7 | F4: 1963000 | G4: =B4/F4 -> 0.91453249 | H4: =B4-F4 -> -167772.73 | I4: =B4/S4 -> 359045.45 | J4: 13.8℃ | S4: 5
A5: 6 | B5: 19049727 | C5: 25440000 | D5: =B5/C5 -> 0.74881003 | E5: =B5-C5 -> -6390272.7 | F5: 17338000 | G5: =B5/F5 -> 1.0987269 | H5: =B5-F5 -> 1711727.3 | I5: =B5/S5 -> 634990.91 | J5: 19.3℃ | S5: 30
A6: 7 | B6: 44856909 | C6: 25440000 | D6: =B6/C6 -> 1.7632433 | E6: =B6-C6 -> 19416909 | F6: 35016000 | G6: =B6/F6 -> 1.2810404 | H6: =B6-F6 -> 9840909.1 | I6: =B6/S6 -> 1446997.1 | J6: 23.8℃ | S6: 31
A7: 8 | B7: 44863045 | C7: 25440000 | D7: =B7/C7 -> 1.7634845 | E7: =B7-C7 -> 19423045 | F7: 39760000 | G7: =B7/F7 -> 1.1283462 | H7: =B7-F7 -> 5103045.5 | I7: =B7/S7 -> 1447195 | J7: 26.7℃ | S7: 31
A8: 9 | B8: 4058727.3 | C8: 9275000 | D8: =B8/C8 -> 0.43759863 | E8: =B8-C8 -> -5216272.7 | F8: 4300000 | G8: =B8/F8 -> 0.94389006 | H8: =B8-F8 -> -241272.73 | I8: =B8/S8 -> 1352909.1 | J8: 24.7℃ | S8: 3
A9: TOTAL | B9: =SUM(B4:B8) -> 1.1462364e+08 | C9: =SUM(C4:C8) -> 92485000 | D9: =B9/C9 -> 1.2393754 | E9: =B9-C9 -> 22138636 | F9: =SUM(F4:F8) -> 98377000 | G9: =B9/F9 -> 1.1651467 | H9: =B9-F9 -> 16246636 | I9: =B9/S9 -> 1146236.4 | S9: 100
A11: ②客数 | I11: 単位：名 | K11: ②コメント
A12: 月 | B12: 実績 | C12: 予算 | D12: 予算比 | E12: 差異 | F12: 予測 | G12: 予測比 | H12: 差異 | I12: 1日平均 | K12: 入客実績は左記の通りです。7/21（金）から8/16（土）の間で開催された大通りビアガーデン期間中も1日平均405名の入客となり、客数減少懸念は杞憂となりました。過去開催の数値によると盆明けは下降線を辿るはずでしたが、①にもある通り観測史上最高の平均気温となったことやチケットの駆け込み利用もあり、勢いを保ったまま最終日まで賑わいが続きました。シーズン設定をして6月末までは20:30クローズ、7月1日〜は21:30クローズとしたことは大きな成果に繋がったと考えています。7/22（土）が717名の来場とピーク、また、この週（7月第4週・通期では第9週）が最大の売上・入客となりました。次年度は予約システムをさらに活用し、入客を引き上げたいと考えています。
A13: 5 | B13: 506 | C13: 1300 | D13: =B13/C13 -> 0.38923077 | E13: =B13-C13 -> -794 | F13: 395 | G13: =B13/F13 -> 1.2810127 | H13: =B13-F13 -> 111 | I13: =B13/S13 -> 101.2 | S13: 5
A14: 6 | B14: 5309 | C14: 4800 | D14: =B14/C14 -> 1.1060417 | E14: =B14-C14 -> 509 | F14: 3450 | G14: =B14/F14 -> 1.5388406 | H14: =B14-F14 -> 1859 | I14: =B14/S14 -> 176.96667 | S14: 30
A15: 7 | B15: 11036 | C15: 4800 | D15: =B15/C15 -> 2.2991667 | E15: =B15-C15 -> 6236 | F15: 7050 | G15: =B15/F15 -> 1.5653901 | H15: =B15-F15 -> 3986 | I15: =B15/S15 -> 356 | S15: 31
A16: 8 | B16: 11093 | C16: 4800 | D16: =B16/C16 -> 2.3110417 | E16: =B16-C16 -> 6293 | F16: 8100 | G16: =B16/F16 -> 1.3695062 | H16: =B16-F16 -> 2993 | I16: =B16/S16 -> 357.83871 | S16: 31
A17: 9 | B17: 974 | C17: 1750 | D17: =B17/C17 -> 0.55657143 | E17: =B17-C17 -> -776 | F17: 880 | G17: =B17/F17 -> 1.1068182 | H17: =B17-F17 -> 94 | I17: =B17/S17 -> 324.66667 | S17: 3
A18: TOTAL | B18: =SUM(B13:B17) -> 28918 | C18: =SUM(C13:C17) -> 17450 | D18: =B18/C18 -> 1.657192 | E18: =B18-C18 -> 11468 | F18: =SUM(F13:F17) -> 19875 | G18: =B18/F18 -> 1.4549937 | H18: =B18-F18 -> 9043 | I18: =B18/S18 -> 289.18 | S18: 100
A20: ③-1 客単価 | I20: 単位：円 | K20: ③コメント
A21: 月 | B21: 実績 | C21: 予算 | D21: 予算比 | E21: 差異 | F21: 予測 | G21: 予測比 | H21: 差異 | K21: 通期での客単価は3,964円にて着地いたしました。予算設定時点では80%がプラン利用を想定しての数値でしたので、予算値からはマイナスとなっています。最終的にプラン利用率は53.6%となり、アラカルト（単品）利用率を上回りました。左記データから読み取れるのは、とてもシンプルですが、パッサージュ（フリー入客）利用率が高いと客単価が下がるという事実と、予約数を高めることにより客単価が伸びるという事実です。このことから、次年度は今回25％程であった予約利用率を35％程度まで引き上げることで、いわゆる「値上げ」の必要がなく、客単価と入客の天秤関係を限定的にしながら、【入客を高めつつ客単価も引き上げることができる】という伸び代を確認することができました。また今回はテーブルチェックを導入し、専用LPと紐付けして予約受注を行ったことにより、約83%の方がWebから予約をしてくださいました。これまでの開催は全て電話予約で対応し紙台帳管理をしていたという課題を、予約システム導入によって解決できた大きな成果と認められます。現地オペレーションとの連携を高めていけば、まだまだこうしたシステムを活かすことができます。今年度実績を基にし、人員発注と人員配置、予約システムの強みをさらに引き出しての予約受注強化（相性が良いと見られるLINE/L-STEPの活用など）や、天候要件の影響値を最小化（※悪天候時でも当日キャンセルは2割に満たない）していくことで、次年度は客席拡大、スタッフ増員に強気で臨むことができます。設備を含めて改善しつつ、さらに客単価を10％程度引き上げることで、売上も今年度の1日平均114万円から130万円（合計1億3,000万円）までは伸ばすことができると確信しています。
A22: 5 | B22: =B4/B13 -> 3547.88 | C22: 5300 | D22: =B22/C22 -> 0.66941132 | E22: =B22-C22 -> -1752.12 | F22: 4970 | G22: =B22/F22 -> 0.71385915 | H22: =B22-F22 -> -1422.12
A23: 6 | B23: =B5/B14 -> 3588.195 | C23: 5300 | D23: =B23/C23 -> 0.67701793 | E23: =B23-C23 -> -1711.805 | F23: 5026 | G23: =B23/F23 -> 0.71392658 | H23: =B23-F23 -> -1437.805
A24: 7 | B24: =B6/B15 -> 4064.5985 | C24: 5300 | D24: =B24/C24 -> 0.76690538 | E24: =B24-C24 -> -1235.4015 | F24: 4967 | G24: =B24/F24 -> 0.81832062 | H24: =B24-F24 -> -902.4015
A25: 8 | B25: =B7/B16 -> 4044.2662 | C25: 5300 | D25: =B25/C25 -> 0.7630691 | E25: =B25-C25 -> -1255.7338 | F25: 4909 | G25: =B25/F25 -> 0.82384727 | H25: =B25-F25 -> -864.73376
A26: 9 | B26: =B8/B17 -> 4167.0711 | C26: 5300 | D26: =B26/C26 -> 0.78623983 | E26: =B26-C26 -> -1132.9289 | F26: 4886 | G26: =B26/F26 -> 0.85285942 | H26: =B26-F26 -> -718.92888
A27: TOTAL | B27: =B9/B18 -> 3963.747 | C27: =C9/C18 -> 5300 | D27: =B27/C27 -> 0.7478768 | E27: =B27-C27 -> -1336.253 | F27: =F9/F18 -> 4949.7862 | G27: =B27/F27 -> 0.80079157 | H27: =B27-F27 -> -986.03914
A29: ③-2 プラン出卓数と月別プラン利用率
A30: 月 | B30: 客数 | C30: 5,500プラン | D30: 利用率 | E30: 6,600プラン | F30: 利用率 | G30: 8,800プラン | H30: 利用率 | I30: 小計
A31: 5 | B31: 506 | C31: 205 | D31: =C31/B31 -> 0.40513834 | E31: 7 | F31: =E31/B31 -> 0.013833992 | G31: 2 | H31: =G31/B31 -> 0.0039525692 | I31: =C31+E31+G31 -> 214
A32: 6 | B32: 5309 | C32: 2074 | D32: =C32/B32 -> 0.39065737 | E32: 80 | F32: =E32/B32 -> 0.015068751 | G32: 9 | H32: =G32/B32 -> 0.0016952345 | I32: =C32+E32+G32 -> 2163
A33: 7 | B33: 11036 | C33: 5792 | D33: =C33/B33 -> 0.52482784 | E33: 190 | F33: =E33/B33 -> 0.017216383 | G33: 161 | H33: =G33/B33 -> 0.014588619 | I33: =C33+E33+G33 -> 6143
A34: 8 | B34: 11093 | C34: 5149 | D34: =C34/B34 -> 0.46416659 | E34: 271 | F34: =E34/B34 -> 0.024429821 | G34: 77 | H34: =G34/B34 -> 0.0069413143 | I34: =C34+E34+G34 -> 5497
A35: 9 | B35: 974 | C35: 314 | D35: =C35/B35 -> 0.32238193 | E35: 34 | F35: =E35/B35 -> 0.034907598 | G35: 9 | H35: =G35/B35 -> 0.0092402464 | I35: =C35+E35+G35 -> 357
A36: TOTAL | B36: =SUM(B31:B35) -> 28918 | C36: =SUM(C31:C35) -> 13534 | D36: =C36/B36 -> 0.468013 | E36: =SUM(E31:E35) -> 582 | F36: =E36/B36 -> 0.020125873 | G36: =SUM(G31:G35) -> 258 | H36: =G36/B36 -> 0.0089217788 | I36: =C36+E36+G36 -> 14374
A37: 月 | B37: 客数 | C37: チケットプラン | D37: 利用率 | E37: プラン合計 | F37: 利用率 | G37: アラカルト利用 | H37: 利用率
A38: 5 | B38: 506 | C38: 0 | D38: =C38/B38 -> 0 | E38: =C38+I31 -> 214 | F38: =E38/B38 -> 0.4229249 | G38: =B38-E38 -> 292 | H38: =G38/B38 -> 0.5770751 | K38: ④memo
A39: 6 | B39: 5309 | C39: 0 | D39: =C39/B39 -> 0 | E39: =C39+I32 -> 2163 | F39: =E39/B39 -> 0.40742136 | G39: =B39-E39 -> 3146 | H39: =G39/B39 -> 0.59257864 | K39: 設備・備品課題※情報共有前 ◆英字メニュー ◆テーブル番号札（視認性・会計） ◆会計カード（プラスチック札）の作成 ◆会計の仕方がわからない ◆キャッシュレス決済が行えることの告知 ◆エクスキューズ（場内案内・トイレ・会計方法など） ◆飲み放題と単品オーダーの判別がつきづらい ◆床清掃の定期スケジュールと不定期実施のオペレーション ◆ワインの利用方法と場所 ◆ワインコーナーにローズマリーのプランター設置 ◆イベント開催 ◆キャッシャー増設検討 ◆ジョッキのサイズ ◆グラス洗浄マシンとの相性 ◆鍋洗い機（高圧洗浄機）の複数洗浄機導入 ◆Wi-Fi環境 ◆問い合わせ専用電話の設置
A40: 7 | B40: 11036 | C40: 107 | D40: =C40/B40 -> 0.0096955419 | E40: =C40+I33 -> 6250 | F40: =E40/B40 -> 0.56632838 | G40: =B40-E40 -> 4786 | H40: =G40/B40 -> 0.43367162
A41: 8 | B41: 11093 | C41: 765 | D41: =C41/B41 -> 0.068962409 | E41: =C41+I34 -> 6262 | F41: =E41/B41 -> 0.56450014 | G41: =B41-E41 -> 4831 | H41: =G41/B41 -> 0.43549986
A42: 9 | B42: 974 | C42: 240 | D42: =C42/B42 -> 0.24640657 | E42: =C42+I35 -> 597 | F42: =E42/B42 -> 0.61293634 | G42: =B42-E42 -> 377 | H42: =G42/B42 -> 0.38706366
A43: TOTAL | B43: =SUM(B38:B42) -> 28918 | C43: =SUM(C38:C42) -> 1112 | D43: =C43/B43 -> 0.038453558 | E43: =SUM(E38:E42) -> 15486 | F43: =E43/B43 -> 0.53551421 | G43: =SUM(G38:G42) -> 13432 | H43: =G43/B43 -> 0.46448579
...

Sheet 計画値・予測・実績進捗
A1: ■R5年さっぽろテレビ塔ビアガーデン売上計画（予算）・売上予測・実績進捗確認表
B2: 計画値 | E2: 予測値 | K2: 実績進捗（派遣分のみ） | R2: ノヴェロさん請求内容 | Y2: 家賃 | AA2: 概算（仮置き）
A3: 月 | B3: 売上予算 | C3: 客数 | D3: 客単価 | E3: 労働時間（予測値） | F3: 人時生産性 | G3: 想定人件費 | H3: 人件費率 | I3: 売上予測 | J3: 対予算 | K3: 売上実績 | L3: 対予測 | M3: 対予算 | N3: 実労働時間 | O3: 人時生産性 | P3: 概算人件費率 | Q3: 派遣人件費（リザルト） | R3: 人件費 | S3: 営業日数 | T3: 拘束時間 | U3: 残業時間 | V3: 人件費合計 | W3: 交通費合計 | X3: 合計 | Y3: 家賃 | Z3: 1日 | AA3: =K9 -> 1.1462364e+08
A4: 5 | B4: 6890000 | C4: 1300 | D4: =B4/C4 -> 5300 | E4: 310 | F4: =I4/E4 -> 6332.2581 | G4: =E4*R4 -> 526437.81 | H4: =G4/B4 -> 0.076406068 | I4: 1963000 | J4: =I4/B4 -> 0.28490566 | K4: ='2023.5月実績'!P93 -> 1795227.3 | L4: =K4/I4 -> 0.91453249 | M4: =K4/B4 -> 0.26055548 | N4: =T4+U4 -> 488 | O4: =K4/N4 -> 3678.7444 | P4: =Q4/K4 -> 0.46162122 | Q4: =X4 -> 828715 | R4: =Q4/N4 -> 1698.1865 | S4: 5 | T4: 479.5 | U4: 8.5 | V4: 759715 | W4: 69000 | X4: =V4+W4 -> 828715 | Y4: 150000 | Z4: 30000 | AA4: =AA3*23.8% -> 27280425 | AB4: 人件費
A5: 6 | B5: 25440000 | C5: 4800 | D5: =B5/C5 -> 5300 | E5: 3555 | F5: =I5/E5 -> 4877.0745 | G5: =E5*R5 -> 6025477.3 | H5: =G5/B5 -> 0.23685052 | I5: 17338000 | J5: =I5/B5 -> 0.68152516 | K5: ='2023.6月実績'!P93 -> 19049727 | L5: =K5/I5 -> 1.0987269 | M5: =K5/B5 -> 0.74881003 | N5: =2946+32.5 -> 2978.5 | O5: =K5/N5 -> 6395.7453 | P5: =Q5/K5 -> 0.26500904 | Q5: =X5 -> 5048350 | R5: =Q5/N5 -> 1694.9303 | S5: 30 | T5: 2946 | U5: 32.5 | V5: 4629350 | W5: 419000 | X5: =V5+W5 -> 5048350 | Y5: 2250000 | Z5: 75000 | AA5: =AA3*31.5% -> 36106445 | AB5: 材料費
A6: 7 | B6: 25440000 | C6: 4800 | D6: =B6/C6 -> 5300 | E6: 4940 | F6: =I6/E6 -> 7088.2591 | G6: =E6*R6 -> 8385722.9 | H6: =G6/B6 -> 0.32962747 | I6: 35016000 | J6: =I6/B6 -> 1.3764151 | K6: ='2023.7月実績'!L93 -> 44856909 | L6: =K6/I6 -> 1.2810404 | M6: =K6/B6 -> 1.7632433 | N6: =4281.75+241.75 -> 4523.5 | O6: =K6/N6 -> 9916.4163 | P6: =Q6/K6 -> 0.17118228 | Q6: =X6 -> 7678708 | R6: =Q6/N6 -> 1697.5148 | S6: 31 | T6: 4281.75 | U6: 241.75 | V6: 7105708 | W6: 573000 | X6: =V6+W6 -> 7678708 | Y6: 3100000 | Z6: 100000 | AA6: =AA3*7% -> 8023654.5 | AB6: 消耗品費
A7: 8 | B7: 25440000 | C7: 4800 | D7: =B7/C7 -> 5300 | E7: 5080 | F7: =I7/E7 -> 7826.7717 | G7: =E7*R7 -> 9144000 | H7: =G7/B7 -> 0.35943396 | I7: 39760000 | J7: =I7/B7 -> 1.5628931 | K7: ='2023.8月実績'!L93 -> 44863045 | L7: =K7/I7 -> 1.1283462 | M7: =K7/B7 -> 1.7634845 | N7: =T7+U7 -> 4935.5 | O7: =K7/N7 -> 9089.8684 | P7: =Q7/K7 -> 0.20105169 | Q7: =X7 -> 9019791 | R7: 1800 | S7: 31 | T7: 4717.25 | U7: 218.25 | V7: 8392791 | W7: 627000 | X7: =V7+W7 -> 9019791 | Y7: 3100000 | Z7: 100000 | AA7: =AA3*15% -> 17193545 | AB7: イニシャル
A8: 9 | B8: 9275000 | C8: 1750 | D8: =B8/C8 -> 5300 | E8: 510 | F8: =I8/E8 -> 8431.3725 | G8: =E8*R8 -> 950482.65 | H8: =G8/B8 -> 0.10247791 | I8: 4300000 | J8: =I8/B8 -> 0.46361186 | K8: ='2023.9月実績'!L93 -> 4058727.3 | L8: =K8/I8 -> 0.94389006 | M8: =K8/B8 -> 0.43759863 | N8: =T8+U8 -> 551 | O8: =K8/N8 -> 7366.1112 | P8: =Q8/K8 -> 0.25300887 | Q8: =X8 -> 1026894 | R8: =Q8/N8 -> 1863.6915 | S8: 3 | T8: 506 | U8: 45 | V8: 958894 | W8: 68000 | X8: =V8+W8 -> 1026894 | Y8: 90000 | Z8: 30000 | AA8: =Y9 -> 8690000 | AB8: 家賃
A9: TOTAL | B9: =SUM(B4:B8) -> 92485000 | C9: =SUM(C4:C8) -> 17450 | D9: =B9/C9 -> 5300 | E9: =SUM(E4:E8) -> 14395 | F9: =I9/E9 -> 6834.1091 | G9: =E9*R9 -> 25211100 | H9: =G9/B9 -> 0.27259663 | I9: =SUM(I4:I8) -> 98377000 | J9: =I9/B9 -> 1.0637076 | K9: =SUM(K4:K8) -> 1.1462364e+08 | L9: =K9/I9 -> 1.1651467 | M9: =K9/B9 -> 1.2393754 | N9: =SUM(N4:N8) -> 13476.5 | O9: =K9/N9 -> 8505.4455 | P9: =Q9/K9 -> 0.20591266 | Q9: =SUM(Q4:Q8) -> 23602458 | R9: =Q9/N9 -> 1751.3789 | S9: =SUM(S4:S8) -> 100 | T9: =SUM(T4:T8) -> 12930.5 | U9: =SUM(U4:U8) -> 546 | V9: =SUM(V4:V8) -> 21846458 | W9: =SUM(W4:W8) -> 1756000 | X9: =SUM(X4:X8) -> 23602458 | Y9: =SUM(Y4:Y8) -> 8690000 | Z9: =SUM(Z4:Z8) -> 335000 | AA9: =AA3*5% -> 5731181.8 | AB9: 流動固定費
B10: 92485000 | C10: 提出予算 | G10: ※ノヴェロ派遣分のみ算出 | I10: ※天気要因見込まず算出 | K10: 43710 | L10: 終了時点の進捗状況 | N10: =K9/S10 -> 1146236.4 | O10: =K9-B10 -> 22138636 | P10: =K9/B10 -> 1.2393754 | S10: 100 | X10: =X9/K9 -> 0.20591266 | AA10: =AA3-AA4-AA5-AA6-AA7-AA8-AA9 -> 11598384 | AB10: 利益
B11: =B9-B10 -> 0 | C11: 差異 | D11: ※予算値は115日計算でP/D（1日平均）804千円にて積み上げ。予測は100日営業、各施策と季節波動を効かせて算出。
I14: 100000000 | J14: 予算まで | K14: =B9-K9 -> -22138636 | L14: 12 | M14: =K14/L14 -> -1844886.4 | N14: 2019 | O14: 58190982 | P14: =K9/O14 -> 1.9697835
I15: 111111111 | J15: 予測まで | K15: =I9-K9 -> -16246636 | L15: 12 | M15: =K15/L15 -> -1353886.4 | N15: 2018 | O15: 44179221 | P15: =K9/O15 -> 2.5945147
J16: 一億円まで | K16: =I14-K9 -> -14623636 | L16: 12 | M16: =K16/L16 -> -1218636.4 | N16: 平均 | O16: =(O14+O15)/2 -> 51185102 | P16: =K9/O16 -> 2.2393945
G17: 2019年度 | J17: 一億一千万まで | K17: =I15-K9 -> -3512525.4 | L17: 12 | M17: =K17/L17 -> -292710.45
G18: 91399704 | H18: =K6-K7 -> -6136.3636 | I18: 945247 | J18: =I18-H18 -> 951383.36 | K18: =K9 -> 1.1462364e+08 | L18: =K18/G18 -> 1.254092 | M18: =K18-G18 -> 23223932
L25: 5187 | M25: 6717 | N25: =M25-L25 -> 1530 | O25: =M25/L25 -> 1.2949682
L26: 992 | M26: 1941 | N26: =M26-L26 -> 949 | O26: =M26/L26 -> 1.9566532
L27: 318 | M27: 2503 | N27: =M27-L27 -> 2185 | O27: =M27/L27 -> 7.8710692
L28: =SUM(L25:L27) -> 6497 | M28: =SUM(M25:M27) -> 11161 | N28: =SUM(N25:N27) -> 4664 | O28: =M28/L28 -> 1.7178698

Sheet 2023.9月実績
A1: ■R5年度 ビアガーデン売上実績
A2: 43708 | L2: =L14+L24+L34+L44+L54+L64 -> 4387600 | R2: 10
A3: FOOD | C3: ビアガーデン9月 実績TOTAL | N3: 客数 | R3: 売上
A4: 予算 | C4: 実績 | E4: 客数 | G4: 客単価 | I4: 売上予算 | L4: 9275000 | M4: 1日平均 | R4: =L4/R2 -> 927500 | T4: 天候要因（売上との関連性を数値化する）
A5: 1st week | C5: 1st week | T5: =C5 -> 1st week
A6: 曜日 | B6: 日にち | C6: 曜日 | D6: 日にち | E6: 客数 | F6: 料理売上 | G6: 料理単価 | H6: 飲料売上 | I6: 飲料単価 | J6: テント利用料 | K6: 物販 | L6: 売上合計 | M6: 合計単価 | N6: サーフィンズ | O6: forking | P6: Timee | Q6: 合計 | R6: 人時売上高 | T6: 最低 | U6: 最高 | V6: 12時 | W6: 15時 | X6: 18時 | Y6: Ave | AA6: ■天候要因 | AC6: 評価点
A7: 日 | C7: 日 | D7: =#REF! -> #REF! | E7: 263 | F7: 799050 | G7: =F7/E7 -> 3038.2129 | H7: 430900 | I7: =H7/E7 -> 1638.403 | J7: 14850 | L7: =F7+H7+J7 -> 1244800 | M7: =L7/E7 -> 4733.0798 | R7: =L7/Q7 -> #DIV/0! | T7: 24.9 | U7: 27 | V7: 3 | W7: 1 | X7: 1 | Y7: =SUM(V7:X7)/3 -> 1.6666667 | AA7: 晴れ（33度まで） | AC7: 5
A8: 月 | C8: 月 | D8: =#REF! -> #REF! | E8: 368 | F8: 1077700 | G8: =F8/E8 -> 2928.5326 | H8: 588200 | I8: =H8/E8 -> 1598.3696 | J8: 31350 | L8: =F8+H8+J8 -> 1697250 | M8: =L8/E8 -> 4612.0924 | R8: =L8/Q8 -> #DIV/0! | T8: 20.7 | U8: 29.1 | V8: 5 | W8: 1 | X8: 5 | Y8: =SUM(V8:X8)/3 -> 3.6666667 | AA8: 晴れ（25度以下） | AC8: 4
A9: 火 | C9: 火 | D9: =#REF! -> #REF! | E9: 343 | F9: 973500 | G9: =F9/E9 -> 2838.1924 | H9: 518250 | I9: =H9/E9 -> 1510.9329 | J9: 30800 | L9: =F9+H9+J9 -> 1522550 | M9: =L9/E9 -> 4438.9213 | R9: =L9/Q9 -> #DIV/0! | T9: 18.6 | U9: 29.8 | V9: 5 | W9: 5 | X9: 5 | Y9: =SUM(V9:X9)/3 -> 5 | AA9: 晴れ（33度以上）曇25度以上 | AC9: 3
A10: 水 | C10: 水 | D10: =#REF! -> #REF! | F10: 0 | G10: =F10/E10 -> #DIV/0! | H10: 0 | I10: =H10/E10 -> #DIV/0! | L10: =F10+H10+J10 -> 0 | M10: =L10/E10 -> #DIV/0! | R10: =L10/Q10 -> #DIV/0! | Y10: =SUM(V10:X10)/3 -> 0 | AA10: 曇 | AC10: 2
A11: 木 | C11: 木 | D11: =#REF! -> #REF! | G11: =F11/E11 -> #DIV/0! | I11: =H11/E11 -> #DIV/0! | L11: =F11+H11+J11 -> 0 | M11: =L11/E11 -> #DIV/0! | R11: =L11/Q11 -> #DIV/0! | Y11: =SUM(V11:X11)/3 -> 0 | AA11: 雨 | AC11: 1
A12: 金 | B12: 1 | C12: 金 | D12: =#REF! -> #REF! | G12: =F12/E12 -> #DIV/0! | I12: =H12/E12 -> #DIV/0! | L12: =F12+H12+J12 -> 0 | M12: =L12/E12 -> #DIV/0! | R12: =L12/Q12 -> #DIV/0! | Y12: =SUM(V12:X12)/3 -> 0 | AA12: 豪雨・雷雨 | AC12: 0
A13: 土 | B13: 2 | C13: 土 | D13: =#REF! -> #REF! | G13: =F13/E13 -> #DIV/0! | I13: =H13/E13 -> #DIV/0! | J13: 0 | L13: =F13+H13+J13 -> 0 | M13: =L13/E13 -> #DIV/0! | R13: =L13/Q13 -> #DIV/0! | Y13: =SUM(V13:X13)/3 -> 0 | AA13: ※5.6月は18時は最低気温を採用。7月〜は最高気温を採用。
A14: SUB TOTAL | C14: SUB TOTAL | E14: =SUM(E7:E13) -> 974 | F14: =SUM(F7:F13) -> 2850250 | G14: =F14/E14 -> 2926.3347 | H14: =SUM(H7:H13) -> 1537350 | I14: =H14/E14 -> 1578.3881 | J14: =I14/F14 -> 0.00055377181 | L14: =F14+H14 -> 4387600 | M14: =L14/E14 -> 4504.7228 | Q14: =SUM(Q7:Q13) -> 0 | R14: =L14/Q14 -> #DIV/0! | S14: 3 | T14: =SUM(T7:T13)/S14 -> 21.4 | U14: =SUM(U7:U13)/S14 -> 28.633333 | V14: =SUM(V7:V13)/S14 -> 4.3333333 | W14: =SUM(W7:W13)/S14 -> 2.3333333 | X14: =SUM(X7:X13)/S14 -> 3.6666667 | Y14: =SUM(V14:X14)/3 -> 3.4444444 | Z14: 15 | AA14: =L14/S14 -> 1462533.3 | AF14: ※1日平均売上
A15: 2nd week | C15: 2nd week | T15: =C15 -> 2nd week
A16: 曜日 | B16: 日にち | C16: 曜日 | D16: 日にち | E16: 客数 | F16: 料理売上 | G16: 料理単価 | H16: 飲料売上 | I16: 飲料単価 | J16: テント利用料 | K16: 物販 | L16: 売上合計 | M16: 合計単価 | N16: サーフィンズ | O16: forking | P16: Timee | Q16: 合計 | R16: 人時売上高 | T16: 最低 | U16: 最高 | V16: 12時 | W16: 15時 | X16: 18時 | Y16: Ave | AA16: ■天候要因 | AC16: 評価点
A17: 日 | B17: 3 | C17: 日 | D17: =#REF! -> #REF! | G17: =F17/E17 -> #DIV/0! | I17: =H17/E17 -> #DIV/0! | L17: =F17+H17+J17 -> 0 | M17: =L17/E17 -> #DIV/0! | R17: =L17/Q17 -> #DIV/0! | Y17: =SUM(V17:X17)/3 -> 0 | AA17: 晴れ（33度まで） | AC17: 5
A18: 月 | B18: 4 | C18: 月 | D18: =#REF! -> #REF! | G18: =F18/E18 -> #DIV/0! | I18: =H18/E18 -> #DIV/0! | L18: =F18+H18+J18 -> 0 | M18: =L18/E18 -> #DIV/0! | R18: =L18/Q18 -> #DIV/0! | Y18: =SUM(V18:X18)/3 -> 0 | AA18: 晴れ（25度以下） | AC18: 4
A19: 火 | B19: 5 | C19: 火 | D19: =#REF! -> #REF! | G19: =F19/E19 -> #DIV/0! | I19: =H19/E19 -> #DIV/0! | L19: =F19+H19+J19 -> 0 | M19: =L19/E19 -> #DIV/0! | R19: =L19/Q19 -> #DIV/0! | Y19: =SUM(V19:X19)/3 -> 0 | AA19: 晴れ（33度以上）曇25度以上 | AC19: 3
A20: 水 | B20: 6 | C20: 水 | D20: =#REF! -> #REF! | G20: =F20/E20 -> #DIV/0! | I20: =H20/E20 -> #DIV/0! | L20: =F20+H20+J20 -> 0 | M20: =L20/E20 -> #DIV/0! | R20: =L20/Q20 -> #DIV/0! | Y20: =SUM(V20:X20)/3 -> 0 | AA20: 曇 | AC20: 2
A21: 木 | B21: 7 | C21: 木 | D21: =#REF! -> #REF! | G21: =F21/E21 -> #DIV/0! | I21: =H21/E21 -> #DIV/0! | L21: =F21+H21+J21 -> 0 | M21: =L21/E21 -> #DIV/0! | R21: =L21/Q21 -> #DIV/0! | Y21: =SUM(V21:X21)/3 -> 0 | AA21: 雨 | AC21: 1
A22: 金 | B22: 8 | C22: 金 | D22: =#REF! -> #REF! | G22: =F22/E22 -> #DIV/0! | I22: =H22/E22 -> #DIV/0! | L22: =F22+H22+J22 -> 0 | M22: =L22/E22 -> #DIV/0! | R22: =L22/Q22 -> #DIV/0! | Y22: =SUM(V22:X22)/3 -> 0 | AA22: 豪雨・雷雨 | AC22: 0
A23: 土 | B23: 9 | C23: 土 | D23: =#REF! -> #REF! | G23: =F23/E23 -> #DIV/0! | I23: =H23/E23 -> #DIV/0! | J23: 0 | L23: =F23+H23+J23 -> 0 | M23: =L23/E23 -> #DIV/0! | R23: =L23/Q23 -> #DIV/0! | Y23: =SUM(V23:X23)/3 -> 0 | AA23: ※5.6月は18時は最低気温を採用。7月〜は最高気温を採用。
A24: SUB TOTAL | C24: SUB TOTAL | E24: =SUM(E17:E23) -> 0 | F24: =SUM(F17:F23) -> 0 | G24: =F24/E24 -> #DIV/0! | H24: =SUM(H17:H23) -> 0 | I24: =H24/E24 -> #DIV/0! | J24: =I24/F24 -> #DIV/0! | L24: =F24+H24 -> 0 | M24: =L24/E24 -> #DIV/0! | Q24: =SUM(Q17:Q23) -> 0 | R24: =L24/Q24 -> #DIV/0! | T24: =SUM(T17:T23)/S24 -> #DIV/0! | U24: =SUM(U17:U23)/S24 -> #DIV/0! | V24: =SUM(V17:V23)/S24 -> #DIV/0! | W24: =SUM(W17:W23)/S24 -> #DIV/0! | X24: =SUM(X17:X23)/S24 -> #DIV/0! | Y24: =SUM(V24:X24)/3 -> #DIV/0!
A25: 3rd week | C25: 3rd week | T25: =C25 -> 3rd week
A26: 曜日 | B26: 日にち | C26: 曜日 | D26: 日にち | E26: 客数 | F26: 料理売上 | G26: 料理単価 | H26: 飲料売上 | I26: 飲料単価 | J26: テント利用料 | K26: 物販 | L26: 売上合計 | M26: 合計単価 | N26: サーフィンズ | O26: forking | P26: Timee | Q26: 合計 | R26: 人時売上高 | T26: 最低 | U26: 最高 | V26: 12時 | W26: 15時 | X26: 18時 | Y26: Ave | AA26: ■天候要因 | AC26: 評価点
A27: 日 | B27: 10 | C27: 日 | D27: =#REF! -> #REF! | G27: =F27/E27 -> #DIV/0! | I27: =H27/E27 -> #DIV/0! | L27: =F27+H27+J27 -> 0 | M27: =L27/E27 -> #DIV/0! | R27: =L27/Q27 -> #DIV/0! | Y27: =SUM(V27:X27)/3 -> 0 | AA27: 晴れ（33度まで） | AC27: 5
A28: 月 | B28: 11 | C28: 月 | D28: =#REF! -> #REF! | G28: =F28/E28 -> #DIV/0! | I28: =H28/E28 -> #DIV/0! | L28: =F28+H28+J28 -> 0 | M28: =L28/E28 -> #DIV/0! | R28: =L28/Q28 -> #DIV/0! | Y28: =SUM(V28:X28)/3 -> 0 | AA28: 晴れ（25度以下） | AC28: 4
A29: 火 | B29: 12 | C29: 火 | D29: =#REF! -> #REF! | G29: =F29/E29 -> #DIV/0! | I29: =H29/E29 -> #DIV/0! | L29: =F29+H29+J29 -> 0 | M29: =L29/E29 -> #DIV/0! | R29: =L29/Q29 -> #DIV/0! | Y29: =SUM(V29:X29)/3 -> 0 | AA29: 晴れ（33度以上）曇25度以上 | AC29: 3
A30: 水 | B30: 13 | C30: 水 | D30: =#REF! -> #REF! | G30: =F30/E30 -> #DIV/0! | I30: =H30/E30 -> #DIV/0! | L30: =F30+H30+J30 -> 0 | M30: =L30/E30 -> #DIV/0! | R30: =L30/Q30 -> #DIV/0! | Y30: =SUM(V30:X30)/3 -> 0 | AA30: 曇 | AC30: 2
A31: 木 | B31: 14 | C31: 木 | D31: =#REF! -> #REF! | G31: =F31/E31 -> #DIV/0! | I31: =H31/E31 -> #DIV/0! | L31: =F31+H31+J31 -> 0 | M31: =L31/E31 -> #DIV/0! | R31: =L31/Q31 -> #DIV/0! | Y31: =SUM(V31:X31)/3 -> 0 | AA31: 雨 | AC31: 1
A32: 金 | B32: 15 | C32: 金 | D32: =#REF! -> #REF! | G32: =F32/E32 -> #DIV/0! | I32: =H32/E32 -> #DIV/0! | L32: =F32+H32+J32 -> 0 | M32: =L32/E32 -> #DIV/0! | R32: =L32/Q32 -> #DIV/0! | Y32: =SUM(V32:X32)/3 -> 0 | AA32: 豪雨・雷雨 | AC32: 0
A33: 土 | B33: 16 | C33: 土 | D33: =#REF! -> #REF! | G33: =F33/E33 -> #DIV/0! | I33: =H33/E33 -> #DIV/0! | J33: 0 | L33: =F33+H33+J33 -> 0 | M33: =L33/E33 -> #DIV/0! | R33: =L33/Q33 -> #DIV/0! | Y33: =SUM(V33:X33)/3 -> 0 | AA33: ※5.6月は18時は最低気温を採用。7月〜は最高気温を採用。
A34: SUB TOTAL | C34: SUB TOTAL | E34: =SUM(E27:E33) -> 0 | F34: =SUM(F27:F33) -> 0 | G34: =F34/E34 -> #DIV/0! | H34: =SUM(H27:H33) -> 0 | I34: =H34/E34 -> #DIV/0! | J34: =I34/F34 -> #DIV/0! | L34: =F34+H34 -> 0 | M34: =L34/E34 -> #DIV/0! | Q34: =SUM(Q27:Q33) -> 0 | R34: =L34/Q34 -> #DIV/0! | T34: =SUM(T27:T33)/S34 -> #DIV/0! | U34: =SUM(U27:U33)/S34 -> #DIV/0! | V34: =SUM(V27:V33)/S34 -> #DIV/0! | W34: =SUM(W27:W33)/S34 -> #DIV/0! | X34: =SUM(X27:X33)/S34 -> #DIV/0! | Y34: =SUM(V34:X34)/3 -> #DIV/0!
A35: 4th week | C35: 4th week | T35: =C35 -> 4th week
A36: 曜日 | B36: 日にち | C36: 曜日 | D36: 日にち | E36: 客数 | F36: 料理売上 | G36: 料理単価 | H36: 飲料売上 | I36: 飲料単価 | J36: テント利用料 | K36: 物販 | L36: 売上合計 | M36: 合計単価 | N36: サーフィンズ | O36: forking | P36: Timee | Q36: 合計 | R36: 人時売上高 | T36: 最低 | U36: 最高 | V36: 12時 | W36: 15時 | X36: 18時 | Y36: Ave | AA36: ■天候要因 | AC36: 評価点
A37: 日 | B37: 17 | C37: 日 | D37: =#REF! -> #REF! | G37: =F37/E37 -> #DIV/0! | I37: =H37/E37 -> #DIV/0! | L37: =F37+H37+J37 -> 0 | M37: =L37/E37 -> #DIV/0! | R37: =L37/Q37 -> #DIV/0! | Y37: =SUM(V37:X37)/3 -> 0 | AA37: 晴れ（33度まで） | AC37: 5
A38: 月 | B38: 18 | C38: 月 | D38: =#REF! -> #REF! | G38: =F38/E38 -> #DIV/0! | I38: =H38/E38 -> #DIV/0! | L38: =F38+H38+J38 -> 0 | M38: =L38/E38 -> #DIV/0! | R38: =L38/Q38 -> #DIV/0! | Y38: =SUM(V38:X38)/3 -> 0 | AA38: 晴れ（25度以下） | AC38: 4
A39: 火 | B39: 19 | C39: 火 | D39: =#REF! -> #REF! | G39: =F39/E39 -> #DIV/0! | I39: =H39/E39 -> #DIV/0! | L39: =F39+H39+J39 -> 0 | M39: =L39/E39 -> #DIV/0! | R39: =L39/Q39 -> #DIV/0! | Y39: =SUM(V39:X39)/3 -> 0 | AA39: 晴れ（33度以上）曇25度以上 | AC39: 3
A40: 水 | B40: 20 | C40: 水 | D40: =#REF! -> #REF! | G40: =F40/E40 -> #DIV/0! | I40: =H40/E40 -> #DIV/0! | L40: =F40+H40+J40 -> 0 | M40: =L40/E40 -> #DIV/0! | R40: =L40/Q40 -> #DIV/0! | Y40: =SUM(V40:X40)/3 -> 0 | AA40: 曇 | AC40: 2
...

Sheet 9月時間帯別売上実績 
A1: ■9月時間帯別売上実績&曜日別売上実績
A2: 営業日 | B2: ランチ | E2: アイドル | G2: ディナー | L2: 合計
B3: 12時 | C3: 13時 | D3: 14時 | E3: 15時 | F3: 16時 | G3: 17時 | H3: 18時 | I3: 19時 | J3: 20時 | K3: 21時
A4: 2023/09/01(金) | B4: 194750 | C4: 66600 | D4: 7050 | E4: 25050 | F4: 231550 | G4: 78150 | H4: 264250 | I4: 316650 | J4: 60750 | K4: 0 | L4: =SUM(B4:K4) -> 1244800
A5: 2023/09/02(土) | B5: 239400 | C5: 217250 | D5: 103500 | E5: 145950 | F5: 256100 | G5: 312700 | H5: 259150 | I5: 135700 | J5: 27500 | K5: 0 | L5: =SUM(B5:K5) -> 1697250
A6: 2023/09/03(日) | B6: 235000 | C6: 232850 | D6: 102400 | E6: 54600 | F6: 212550 | G6: 300300 | H6: 181000 | I6: 150450 | J6: 31400 | K6: 22000 | L6: =SUM(B6:K6) -> 1522550
A7: 2023/09/04(月) | L7: =SUM(B7:K7) -> 0
A8: 2023/09/05(火) | L8: =SUM(B8:K8) -> 0
A9: 2023/09/06(水) | L9: =SUM(B9:K9) -> 0
A10: 2023/09/07(木) | L10: =SUM(B10:K10) -> 0
A11: 2023/09/08(金) | L11: =SUM(B11:K11) -> 0
A12: 2023/09/09(土) | L12: =SUM(B12:K12) -> 0
A13: 2023/09/10(日) | L13: =SUM(B13:K13) -> 0
A14: 2023/09/11(月) | L14: =SUM(B14:K14) -> 0
A15: 2023/09/12(火) | L15: =SUM(B15:K15) -> 0
A16: 2023/09/13(水) | L16: =SUM(B16:K16) -> 0
A17: 2023/09/14(木) | L17: =SUM(B17:K17) -> 0
A18: 2023/09/15(金) | L18: =SUM(B18:K18) -> 0
... A33: 2023/09/30(土) | L33: =SUM(B33:K33) -> 0
L34: =SUM(B34:K34) -> 0
A35: 【合計】 | B35: =SUM(B4:B34) -> 669150 | C35: =SUM(C4:C34) -> 516700 | D35: =SUM(D4:D34) -> 212950 | E35: =SUM(E4:E34) -> 225600 | F35: =SUM(F4:F34) -> 700200 | G35: =SUM(G4:G34) -> 691150 | H35: =SUM(H4:H34) -> 704400 | I35: =SUM(I4:I34) -> 602800 | ... K35: =SUM(K4:K34) -> 22000 | L35: =SUM(B35:K35) -> 4464600
B36: =B35+C35+D35 -> 1398800 | E36: =E35+F35 -> 925800 | G36: =G35+H35+I35+J35+K35 -> 2140000 | L36: =SUM(B36:J36) -> 4464600
A37: 売上比率 | B37: =B36/L36 -> 0.31330914 | E37: =E36/L36 -> 0.2073646 | G37: =G36/L36 -> 0.47932626 | L37: =SUM(B37:J37) -> 1
A39: ■9月曜日別売上平均
A40: 【日曜日 平均】 | B40: 235000 | C40: 232850 | D40: 102400 | E40: 54600 | F40: 212550 | G40: 300300 | H40: 181000 | I40: 150450 | J40: 31400 | K40: 22000 | L40: =SUM(B40:K40) -> 1522550
A41: 【月曜日 平均】 | B41: 0 | C41: 0 | D41: 0 | E41: 0 | F41: 0 | G41: 0 | H41: 0 | I41: 0 | J41: 0 | K41: 0 | L41: 0
A42: 【火曜日 平均】 | B42: 0 | C42: 0 | D42: 0 | E42: 0 | F42: 0 | G42: 0 | H42: 0 | I42: 0 | J42: 0 | K42: 0 | L42: 0
A43: 【水曜日 平均】 | B43: 0 | C43: 0 | D43: 0 | E43: 0 | F43: 0 | G43: 0 | H43: 0 | I43: 0 | J43: 0 | K43: 0 | L43: 0
A44: 【木曜日 平均】 | B44: 0 | C44: 0 | D44: 0 | E44: 0 | F44: 0 | G44: 0 | H44: 0 | I44: 0 | J44: 0 | K44: 0 | L44: 0
A45: 【金曜日 平均】 | B45: 194750 | C45: 66600 | D45: 7050 | E45: 25050 | F45: 231550 | G45: 78150 | H45: 264250 | I45: 316650 | J45: 60750 | K45: 0 | L45: =SUM(B45:K45) -> 1244800
A46: 【土曜日 平均】 | B46: 239400 | C46: 217250 | D46: 103500 | E46: 145950 | F46: 256100 | G46: 312700 | H46: 259150 | I46: 135700 | J46: 27500 | K46: 0 | L46: =SUM(B46:K46) -> 1697250
A47: ■9月曜日別売上合計
A48: 【日曜日 合計】 | B48: 235000 | C48: 232850 | D48: 102400 | E48: 54600 | F48: 212550 | G48: 300300 | H48: 181000 | I48: 150450 | J48: 31400 | K48: 22000 | L48: 1522550
A49: 【月曜日 合計】 | B49: 0 | C49: 0 | D49: 0 | E49: 0 | F49: 0 | G49: 0 | H49: 0 | I49: 0 | J49: 0 | K49: 0 | L49: 0
A50: 【火曜日 合計】 | B50: 0 | C50: 0 | D50: 0 | E50: 0 | F50: 0 | G50: 0 | H50: 0 | I50: 0 | J50: 0 | K50: 0 | L50: 0
A51: 【水曜日 合計】 | B51: 0 | C51: 0 | D51: 0 | E51: 0 | F51: 0 | G51: 0 | H51: 0 | I51: 0 | J51: 0 | K51: 0 | L51: 0
A52: 【木曜日 合計】 | B52: 0 | C52: 0 | D52: 0 | E52: 0 | F52: 0 | G52: 0 | H52: 0 | I52: 0 | J52: 0 | K52: 0 | L52: 0
A53: 【金曜日 合計】 | B53: 194750 | C53: 66600 | D53: 7050 | E53: 25050 | F53: 231550 | G53: 78150 | H53: 264250 | I53: 316650 | J53: 60750 | K53: 0 | L53: 1244800
A54: 【土曜日 合計】 | B54: 239400 | C54: 217250 | D54: 103500 | E54: 145950 | F54: 256100 | G54: 312700 | H54: 259150 | I54: 135700 | J54: 27500 | K54: 0 | L54: 1697250

Sheet 2023.8月実績
A1: ■R5年度 ビアガーデン売上実績
A2: 8月 | R2: 31
C3: ビアガーデン8月 TOTAL実績 | N3: 客数 | R3: 売上
C4: 実績 | E4: 客数 | G4: 客単価 | I4: 売上予算 | M4: 1日平均 | T4: 天候要因（売上との関連性を数値化する）
A5: 1st week | C5: 1st week | T5: =C5 -> 1st week
A6: 曜日 | B6: 日にち | C6: 曜日 | D6: 日にち | E6: 客数 | F6: 料理売上 | G6: 料理単価 | H6: 飲料売上 | I6: 飲料単価 | J6: テント利用料 | K6: 物販 | L6: 売上合計 | M6: 合計単価 | N6: サーフィンズ | O6: forking | P6: Timee | Q6: 合計 | R6: 人時売上高 | T6: 最低 | U6: 最高 | V6: 12時 | W6: 15時 | X6: 18時 | Y6: Ave | AA6: ■天候要因 | AC6: 評価点
A7: 日 | C7: 日 | D7: =B7 -> 0 | G7: =F7/E7 -> #DIV/0! | I7: =H7/E7 -> #DIV/0! | J7: 0 | L7: =F7+H7+J7 -> 0 | M7: =L7/E7 -> #DIV/0! | R7: =L7/Q7 -> #DIV/0! | Y7: =SUM(V7:X7)/3 -> 0 | AA7: 晴れ（33度まで） | AC7: 5
A8: 月 | C8: 月 | D8: =B8 -> 0 | G8: =F8/E8 -> #DIV/0! | I8: =H8/E8 -> #DIV/0! | J8: 0 | L8: =F8+H8+J8 -> 0 | M8: =L8/E8 -> #DIV/0! | R8: =L8/Q8 -> #DIV/0! | Y8: =SUM(V8:X8)/3 -> 0 | AA8: 晴れ（25度以下） | AC8: 4
A9: 火 | B9: 1 | C9: 火 | D9: =B9 -> 1 | E9: 342 | F9: 997050 | G9: =F9/E9 -> 2915.3509 | H9: 560500 | I9: =H9/E9 -> 1638.8889 | J9: 25300 | L9: =F9+H9+J9 -> 1582850 | M9: =L9/E9 -> 4628.2164 | Q9: 156.5 | R9: =L9/Q9 -> 10114.058 | T9: 21.5 | U9: 31.1 | V9: 5 | W9: 3 | X9: 5 | Y9: =SUM(V9:X9)/3 -> 4.3333333 | AA9: 晴れ（33度以上）曇25度以上 | AC9: 3
A10: 水 | B10: 2 | C10: 水 | D10: =B10 -> 2 | E10: 310 | F10: 891200 | G10: =F10/E10 -> 2874.8387 | H10: 522250 | I10: =H10/E10 -> 1684.6774 | J10: 14850 | L10: =F10+H10+J10 -> 1428300 | M10: =L10/E10 -> 4607.4194 | Q10: 135 | R10: =L10/Q10 -> 10580 | T10: 24.2 | U10: 34 | V10: 3 | W10: 3 | X10: 3 | Y10: =SUM(V10:X10)/3 -> 3 | AA10: 曇 | AC10: 2
A11: 木 | B11: 3 | C11: 木 | D11: =B11 -> 3 | E11: 316 | F11: 790400 | G11: =F11/E11 -> 2501.2658 | H11: 442100 | I11: =H11/E11 -> 1399.0506 | J11: 30250 | L11: =F11+H11+J11 -> 1262750 | M11: =L11/E11 -> 3996.0443 | Q11: 173.5 | R11: =L11/Q11 -> 7278.098 | T11: 25.6 | U11: 32.2 | V11: 3 | W11: 3 | X11: 5 | Y11: =SUM(V11:X11)/3 -> 3.6666667 | AA11: 雨 | AC11: 1
A12: 金 | B12: 4 | C12: 金 | D12: =B12 -> 4 | E12: 343 | F12: 1098200 | G12: =F12/E12 -> 3201.7493 | H12: 626650 | I12: =H12/E12 -> 1826.9679 | J12: 14300 | L12: =F12+H12+J12 -> 1739150 | M12: =L12/E12 -> 5070.4082 | Q12: 163 | R12: =L12/Q12 -> 10669.632 | T12: 27.1 | U12: 31 | V12: 3 | W12: 3 | X12: 1 | Y12: =SUM(V12:X12)/3 -> 2.3333333 | AA12: 豪雨・雷雨 | AC12: 0
A13: 土 | B13: 5 | C13: 土 | D13: =B13 -> 5 | E13: 570 | F13: 1661250 | G13: =F13/E13 -> 2914.4737 | H13: 912750 | I13: =H13/E13 -> 1601.3158 | J13: 64350 | L13: =F13+H13+J13 -> 2638350 | M13: =L13/E13 -> 4628.6842 | Q13: 185.5 | R13: =L13/Q13 -> 14222.911 | T13: 22.9 | U13: 29.4 | V13: 3 | W13: 1 | X13: 3 | Y13: =SUM(V13:X13)/3 -> 2.3333333 | AA13: ※5.6月は18時は最低気温を採用。7月〜は最高気温を採用。
A14: SUB TOTAL | C14: SUB TOTAL | E14: =SUM(E7:E13) -> 1881 | F14: =SUM(F7:F13) -> 5438100 | G14: =F14/E14 -> 2891.0686 | H14: =SUM(H7:H13) -> 3064250 | I14: =H14/E14 -> 1629.0537 | J14: =SUM(J7:J13) -> 149050 | L14: =F14+H14 -> 8502350 | M14: =L14/E14 -> 4520.1223 | Q14: =SUM(Q7:Q13) -> 813.5 | R14: =L14/Q14 -> 10451.567 | S14: 5 | T14: =SUM(T7:T13)/S14 -> 24.26 | U14: =SUM(U7:U13)/S14 -> 31.54 | V14: =SUM(V7:V13)/S14 -> 3.4 | W14: =SUM(W7:W13)/S14 -> 2.6 | X14: =SUM(X7:X13)/S14 -> 3.4 | Y14: =SUM(V14:X14)/3 -> 3.1333333 | Z14: 11 | AA14: =L14/S14 -> 1700470 | AF14: ※1日平均売上
A15: 2nd week | C15: 2nd week | T15: =C15 -> 2nd week
A16: 曜日 | B16: 日にち | C16: 曜日 | D16: 日にち | E16: 客数 | F16: 料理売上 | G16: 料理単価 | H16: 飲料売上 | I16: 飲料単価 | J16: テント利用料 | K16: 物販 | L16: 売上合計 | M16: 合計単価 | N16: サーフィンズ | O16: forking | P16: Timee | Q16: 合計 | R16: 人時売上高 | T16: 最低 | U16: 最高 | V16: 12時 | W16: 15時 | X16: 18時 | Y16: Ave | AA16: ■天候要因 | AC16: 評価点
A17: 日 | B17: 6 | C17: 日 | D17: =B17 -> 6 | E17: 288 | F17: 735050 | G17: =F17/E17 -> 2552.2569 | H17: 368900 | I17: =H17/E17 -> 1280.9028 | J17: 3850 | L17: =F17+H17+J17 -> 1107800 | M17: =L17/E17 -> 3846.5278 | Q17: 187.5 | R17: =L17/Q17 -> 5908.2667 | T17: 22.2 | U17: 25.7 | V17: 1 | W17: 3 | X17: 1 | Y17: =SUM(V17:X17)/3 -> 1.6666667 | AA17: 晴れ（33度まで） | AC17: 5
A18: 月 | B18: 7 | C18: 月 | D18: =B18 -> 7 | E18: 322 | F18: 941600 | G18: =F18/E18 -> 2924.2236 | H18: 478900 | I18: =H18/E18 -> 1487.2671 | J18: 20900 | L18: =F18+H18+J18 -> 1441400 | M18: =L18/E18 -> 4476.3975 | Q18: 163 | R18: =L18/Q18 -> 8842.9448 | T18: 19.7 | U18: 26.1 | V18: 3 | W18: 3 | X18: 3 | Y18: =SUM(V18:X18)/3 -> 3 | AA18: 晴れ（25度以下） | AC18: 4
A19: 火 | B19: 8 | C19: 火 | D19: =B19 -> 8 | E19: 376 | F19: 1277000 | G19: =F19/E19 -> 3396.2766 | H19: 652650 | I19: =H19/E19 -> 1735.7713 | J19: 25300 | L19: =F19+H19+J19 -> 1954950 | M19: =L19/E19 -> 5199.3351 | Q19: 165 | R19: =L19/Q19 -> 11848.182 | T19: 23.3 | U19: 27.7 | V19: 1 | W19: 1 | X19: 5 | Y19: =SUM(V19:X19)/3 -> 2.3333333 | AA19: 晴れ（33度以上）曇25度以上 | AC19: 3
A20: 水 | B20: 9 | C20: 水 | D20: =B20 -> 9 | E20: 391 | F20: 1076850 | G20: =F20/E20 -> 2754.0921 | H20: 577750 | I20: =H20/E20 -> 1477.6215 | J20: 30800 | L20: =F20+H20+J20 -> 1685400 | M20: =L20/E20 -> 4310.4859 | Q20: 189 | R20: =L20/Q20 -> 8917.4603 | T20: 24.5 | U20: 30.8 | V20: 1 | W20: 3 | X20: 5 | Y20: =SUM(V20:X20)/3 -> 3 | AA20: 曇 | AC20: 2
A21: 木 | B21: 10 | C21: 木 | D21: =B21 -> 10 | E21: 441 | F21: 1244400 | G21: =F21/E21 -> 2821.7687 | H21: 662400 | I21: =H21/E21 -> 1502.0408 | J21: 15950 | L21: =F21+H21+J21 -> 1922750 | M21: =L21/E21 -> 4359.9773 | Q21: 184.5 | R21: =L21/Q21 -> 10421.409 | T21: 25.7 | U21: 31.1 | V21: 5 | W21: 5 | X21: 5 | Y21: =SUM(V21:X21)/3 -> 5 | AA21: 雨 | AC21: 1
A22: 金 | B22: 11 | C22: 金 | D22: =B22 -> 11 | E22: 447 | F22: 1408500 | G22: =F22/E22 -> 3151.0067 | H22: 788400 | I22: =H22/E22 -> 1763.7584 | J22: 30250 | L22: =F22+H22+J22 -> 2227150 | M22: =L22/E22 -> 4982.4385 | Q22: 184.5 | R22: =L22/Q22 -> 12071.274 | T22: 24.7 | U22: 32.3 | V22: 5 | W22: 5 | X22: 5 | Y22: =SUM(V22:X22)/3 -> 5 | AA22: 豪雨・雷雨 | AC22: 0
A23: 土 | B23: 12 | C23: 土 | D23: =B23 -> 12 | E23: 505 | F23: 1494050 | G23: =F23/E23 -> 2958.5149 | H23: 825500 | I23: =H23/E23 -> 1634.6535 | J23: 7150 | L23: =F23+H23+J23 -> 2326700 | M23: =L23/E23 -> 4607.3267 | R23: =L23/Q23 -> #DIV/0! | T23: 23.3 | U23: 32 | V23: 5 | W23: 5 | X23: 5 | Y23: =SUM(V23:X23)/3 -> 5 | AA23: ※5.6月は18時は最低気温を採用。7月〜は最高気温を採用。
A24: SUB TOTAL | C24: SUB TOTAL | E24: =SUM(E17:E23) -> 2770 | F24: =SUM(F17:F23) -> 8177450 | G24: =F24/E24 -> 2952.148 | H24: =SUM(H17:H23) -> 4354500 | I24: =H24/E24 -> 1572.0217 | J24: =SUM(J17:J23) -> 134200 | L24: =F24+H24 -> 12531950 | M24: =L24/E24 -> 4524.1697 | Q24: =SUM(Q17:Q23) -> 1073.5 | R24: =L24/Q24 -> 11673.917 | S24: 7 | T24: =SUM(T17:T23)/S24 -> 23.342857 | U24: =SUM(U17:U23)/S24 -> 29.385714 | V24: =SUM(V17:V23)/S24 -> 3 | W24: =SUM(W17:W23)/S24 -> 3.5714286 | X24: =SUM(X17:X23)/S24 -> 4.1428571 | Y24: =SUM(V24:X24)/3 -> 3.5714286 | Z24: 12 | AA24: =L24/S24 -> 1790278.6 | AF24: ※1日平均売上
A25: 3rd week | C25: 3rd week | T25: =C25 -> 3rd week
A26: 曜日 | B26: 日にち | C26: 曜日 | D26: 日にち | E26: 客数 | F26: 料理売上 | G26: 料理単価 | H26: 飲料売上 | I26: 飲料単価 | J26: テント利用料 | K26: 物販 | L26: 売上合計 | M26: 合計単価 | N26: サーフィンズ | O26: forking | P26: Timee | Q26: 合計 | R26: 人時売上高 | T26: 最低 | U26: 最高 | V26: 12時 | W26: 15時 | X26: 18時 | Y26: Ave | AA26: ■天候要因 | AC26: 評価点
A27: 日 | B27: 13 | C27: 日 | D27: =B27 -> 13 | E27: 527 | F27: 1473850 | G27: =F27/E27 -> 2796.6793 | H27: 799500 | I27: =H27/E27 -> 1517.0778 | J27: 11000 | L27: =F27+H27+J27 -> 2284350 | M27: =L27/E27 -> 4334.63 | R27: =L27/Q27 -> #DIV/0! | T27: 23.5 | U27: 30.5 | V27: 3 | W27: 5 | X27: 5 | Y27: =SUM(V27:X27)/3 -> 4.3333333 | AA27: 晴れ（33度まで） | AC27: 5
A28: 月 | B28: 14 | C28: 月 | D28: =B28 -> 14 | E28: 456 | F28: 1247650 | G28: =F28/E28 -> 2736.0746 | H28: 677000 | I28: =H28/E28 -> 1484.6491 | J28: 16500 | L28: =F28+H28+J28 -> 1941150 | M28: =L28/E28 -> 4256.9079 | R28: =L28/Q28 -> #DIV/0! | T28: 23.1 | U28: 30.7 | V28: 5 | W28: 3 | X28: 3 | Y28: =SUM(V28:X28)/3 -> 3.6666667 | AA28: 晴れ（25度以下） | AC28: 4
A29: 火 | B29: 15 | C29: 火 | D29: =B29 -> 15 | E29: 477 | F29: 1324650 | G29: =F29/E29 -> 2777.044 | H29: 665650 | I29: =H29/E29 -> 1395.4927 | J29: 21450 | L29: =F29+H29+J29 -> 2011750 | M29: =L29/E29 -> 4217.5052 | R29: =L29/Q29 -> #DIV/0! | T29: 22.5 | U29: 30 | V29: 5 | W29: 3 | X29: 3 | Y29: =SUM(V29:X29)/3 -> 3.6666667 | AA29: 晴れ（33度以上）曇25度以上 | AC29: 3
A30: 水 | B30: 16 | C30: 水 | D30: =B30 -> 16 | E30: 215 | F30: 538250 | G30: =F30/E30 -> 2503.4884 | H30: 295400 | I30: =H30/E30 -> 1373.9535 | J30: 6050 | L30: =F30+H30+J30 -> 839700 | M30: =L30/E30 -> 3905.5814 | R30: =L30/Q30 -> #DIV/0! | T30: 23.2 | U30: 26.5 | V30: 1 | W30: 1 | X30: 3 | Y30: =SUM(V30:X30)/3 -> 1.6666667 | AA30: 曇 | AC30: 2
A31: 木 | B31: 17 | C31: 木 | D31: =B31 -> 17 | E31: 277 | F31: 589350 | G31: =F31/E31 -> 2127.6173 | H31: 383500 | I31: =H31/E31 -> 1384.4765 | J31: 2200 | L31: =F31+H31+J31 -> 975050 | M31: =L31/E31 -> 3520.0361 | R31: =L31/Q31 -> #DIV/0! | T31: 25.2 | U31: 31.1 | V31: 5 | W31: 1 | X31: 1 | Y31: =SUM(V31:X31)/3 -> 2.3333333 | AA31: 雨 | AC31: 1
A32: 金 | B32: 18 | C32: 金 | D32: =B32 -> 18 | E32: 387 | F32: 1137850 | G32: =F32/E32 -> 2940.1809 | H32: 661650 | I32: =H32/E32 -> 1709.6899 | J32: 29150 | L32: =F32+H32+J32 -> 1828650 | M32: =L32/E32 -> 4725.1938 | R32: =L32/Q32 -> #DIV/0! | T32: 23.4 | U32: 31 | V32: 3 | W32: 1 | X32: 3 | Y32: =SUM(V32:X32)/3 -> 2.3333333 | AA32: 豪雨・雷雨 | AC32: 0
A33: 土 | B33: 19 | C33: 土 | D33: =B33 -> 19 | E33: 515 | F33: 1463750 | G33: =F33/E33 -> 2842.233 | H33: 817750 | I33: =H33/E33 -> 1587.8641 | J33: 20900 | L33: =F33+H33+J33 -> 2302400 | M33: =L33/E33 -> 4470.6796 | R33: =L33/Q33 -> #DIV/0! | T33: 22.9 | U33: 32.2 | V33: 3 | W33: 3 | X33: 5 | Y33: =SUM(V33:X33)/3 -> 3.6666667 | AA33: ※5.6月は18時は最低気温を採用。7月〜は最高気温を採用。
A34: SUB TOTAL | C34: SUB TOTAL | E34: =SUM(E27:E33) -> 2854 | F34: =SUM(F27:F33) -> 7775350 | G34: =F34/E34 -> 2724.3693 | H34: =SUM(H27:H33) -> 4300450 | I34: =H34/E34 -> 1506.815 | J34: =SUM(J27:J33) -> 107250 | L34: =F34+H34 -> 12075800 | M34: =L34/E34 -> 4231.1843 | Q34: =SUM(Q27:Q33) -> 0 | R34: =L34/Q34 -> #DIV/0! | S34: 7 | T34: =SUM(T27:T33)/S34 -> 23.4 | U34: =SUM(U27:U33)/S34 -> 30.285714 | V34: =SUM(V27:V33)/S34 -> 3.5714286 | W34: =SUM(W27:W33)/S34 -> 2.4285714 | X34: =SUM(X27:X33)/S34 -> 3.2857143 | Y34: =SUM(V34:X34)/3 -> 3.0952381 | Z34: 13 | AA34: =L34/S34 -> 1725114.3 | AF34: ※1日平均売上
A35: 4th week | C35: 4th week | T35: =C35 -> 4th week
A36: 曜日 | B36: 日にち | C36: 曜日 | D36: 日にち | E36: 客数 | F36: 料理売上 | G36: 料理単価 | H36: 飲料売上 | I36: 飲料単価 | J36: テント利用料 | K36: 物販 | L36: 売上合計 | M36: 合計単価 | N36: サーフィンズ | O36: forking | P36: Timee | Q36: 合計 | R36: 人時売上高 | T36: 最低 | U36: 最高 | V36: 12時 | W36: 15時 | X36: 18時 | Y36: Ave | AA36: ■天候要因 | AC36: 評価点
A37: 日 | B37: 20 | C37: 日 | D37: =B37 -> 20 | E37: 428 | F37: 1143400 | G37: =F37/E37 -> 2671.4953 | H37: 637950 | I37: =H37/E37 -> 1490.5374 | J37: 16500 | L37: =F37+H37+J37 -> 1797850 | M37: =L37/E37 -> 4200.5841 | R37: =L37/Q37 -> #DIV/0! | T37: 24.4 | U37: 29.8 | V37: 1 | W37: 5 | X37: 3 | Y37: =SUM(V37:X37)/3 -> 3 | AA37: 晴れ（33度まで） | AC37: 5
A38: 月 | B38: 21 | C38: 月 | D38: =B38 -> 21 | E38: 329 | F38: 866000 | G38: =F38/E38 -> 2632.2188 | H38: 481500 | I38: =H38/E38 -> 1463.5258 | J38: 8250 | L38: =F38+H38+J38 -> 1355750 | M38: =L38/E38 -> 4120.8207 | R38: =L38/Q38 -> #DIV/0! | T38: 23.9 | U38: 32.4 | V38: 5 | W38: 5 | X38: 4 | Y38: =SUM(V38:X38)/3 -> 4.6666667 | AA38: 晴れ（25度以下） | AC38: 4
A39: 火 | B39: 22 | C39: 火 | D39: =B39 -> 22 | E39: 281 | F39: 832300 | G39: =F39/E39 -> 2961.9217 | H39: 475750 | I39: =H39/E39 -> 1693.0605 | J39: 4950 | L39: =F39+H39+J39 -> 1313000 | M39: =L39/E39 -> 4672.5979 | R39: =L39/Q39 -> #DIV/0! | T39: 24.7 | U39: 33.2 | V39: 3 | W39: 3 | X39: 4 | Y39: =SUM(V39:X39)/3 -> 3.3333333 | AA39: 晴れ（33度以上）曇25度以上 | AC39: 3
A40: 水 | B40: 23 | C40: 水 | D40: =B40 -> 23 | E40: 258 | F40: 784400 | G40: =F40/E40 -> 3040.3101 | H40: 451600 | I40: =H40/E40 -> 1750.3876 | J40: 4400 | L40: =F40+H40+J40 -> 1240400 | M40: =L40/E40 -> 4807.7519 | R40: =L40/Q40 -> #DIV/0! | T40: 26.2 | U40: 36.3 | V40: 3 | W40: 3 | X40: 4 | Y40: =SUM(V40:X40)/3 -> 3.3333333 | AA40: 曇 | AC40: 2
...

Sheet 8月時間帯別売上実績
A1: ■8月時間帯別売上実績&曜日別売上実績
A2: 営業日 | B2: ランチ | E2: アイドル | G2: ディナー | L2: 合計
B3: 12時 | C3: 13時 | D3: 14時 | E3: 15時 | F3: 16時 | G3: 17時 | H3: 18時 | I3: 19時 | J3: 20時 | K3: 21時
A4: 2023/08/01(火) | B4: 91250 | C4: 106800 | D4: 75450 | E4: 91300 | F4: 205250 | G4: 297850 | H4: 429050 | I4: 182450 | J4: 96850 | K4: 6600 | L4: =SUM(B4:K4) -> 1582850
A5: 2023/08/02(水) | B5: 106100 | C5: 24700 | D5: 32400 | E5: 18700 | F5: 135450 | G5: 159700 | H5: 458500 | I5: 380650 | J5: 86700 | K5: 22700 | L5: =SUM(B5:K5) -> 1425600
A6: 2023/08/03(木) | B6: 85550 | C6: 20250 | D6: 35100 | E6: 74900 | F6: 38500 | G6: 369750 | H6: 335250 | I6: 233650 | J6: 67400 | K6: 2400 | L6: =SUM(B6:K6) -> 1262750
A7: 2023/08/04(金) | B7: 17000 | C7: 62450 | D7: 73800 | E7: 52750 | F7: 51750 | G7: 291750 | H7: 383800 | I7: 626050 | J7: 179800 | K7: 0 | L7: =SUM(B7:K7) -> 1739150
A8: 2023/08/05(土) | B8: 184450 | C8: 147250 | D8: 249500 | E8: 163000 | F8: 298700 | G8: 288150 | H8: 643950 | I8: 430650 | J8: 221700 | K8: 11000 | L8: =SUM(B8:K8) -> 2638350
A9: 2023/08/06(日) | B9: 173450 | C9: 55150 | D9: 87700 | E9: 99750 | F9: 156150 | G9: 175750 | H9: 200900 | I9: 109600 | J9: 49350 | K9: 0 | L9: =SUM(B9:K9) -> 1107800
A10: 2023/08/07(月) | B10: 89150 | C10: 72150 | D10: 50900 | E10: 91350 | F10: 64900 | G10: 129600 | H10: 359100 | I10: 454800 | J10: 125350 | K10: 4100 | L10: =SUM(B10:K10) -> 1441400
A11: 2023/08/08(火) | B11: 114150 | C11: 83800 | D11: 33400 | E11: 261100 | F11: 24350 | G11: 177950 | H11: 277350 | I11: 947450 | J11: 33500 | K11: 1900 | L11: =SUM(B11:K11) -> 1954950
A12: 2023/08/09(水) | B12: 109200 | C12: 127200 | D12: 50050 | E12: 32100 | F12: 91000 | G12: 460650 | H12: 294500 | I12: 489500 | J12: 30500 | K12: 700 | L12: =SUM(B12:K12) -> 1685400
A13: 2023/08/10(木) | B13: 149900 | C13: 78700 | D13: 110150 | E13: 88650 | F13: 17200 | G13: 356150 | H13: 388600 | I13: 672250 | J13: 40550 | K13: 20600 | L13: =SUM(B13:K13) -> 1922750
A14: 2023/08/11(金) | B14: 222350 | C14: 186300 | D14: 118600 | E14: 164800 | F14: 323800 | G14: 355100 | H14: 314350 | I14: 370850 | J14: 139700 | K14: 16500 | L14: =SUM(B14:K14) -> 2212350
A15: 2023/08/12(土) | B15: 190750 | C15: 188900 | D15: 80000 | E15: 159200 | F15: 276900 | G15: 270700 | H15: 532250 | I15: 442950 | J15: 145600 | K15: 1400 | L15: =SUM(B15:K15) -> 2288650
... A35: 【合計】 | B35: 4475650 | C35: 2891150 | D35: 2486550 | E35: 2963100 | F35: 3846550 | G35: 7404300 | H35: 11686300 | I35: 10435900 | J35: 2573050 | K35: 437950 | L35: =SUM(B35:K35) -> 49200500
B36: =B35+C35+D35 -> 9853350 | E36: =E35+F35 -> 6809650 | G36: =G35+H35+I35+J35+K35 -> 32537500 | L36: =SUM(B36:J36) -> 49200500
A37: 売上比率 | B37: =B36/L36 -> 0.20026931 | E37: =E36/L36 -> 0.13840611 | G37: =G36/L36 -> 0.66132458 | L37: =SUM(B37:J37) -> 1
B38: =B37+E37 -> 0.33867542
A39: ■8月曜日別売上平均
A40: 【日曜日 平均】 | B40: 239863 | C40: 88563 | D40: 120463 | E40: 133100 | F40: 205088 | G40: 238850 | H40: 344575 | I40: 215263 | J40: 88325 | K40: 9650 | L40: 1683738
A41: 【月曜日 平均】 | B41: 144000 | C41: 107238 | D41: 62075 | E41: 80950 | F41: 94963 | G41: 160600 | H41: 349425 | I41: 309275 | J41: 76575 | K41: 3375 | L41: 1388475
A42: 【火曜日 平均】 | B42: 127130 | C42: 77950 | D42: 66420 | E42: 115550 | F42: 110380 | G42: 303330 | H42: 367310 | I42: 344420 | J42: 58300 | K42: 33740 | L42: 1604530
A43: 【水曜日 平均】 | B43: 85960 | C43: 81620 | D43: 41720 | E43: 48950 | F43: 71550 | G43: 232000 | H43: 350420 | I43: 302200 | J43: 49200 | K43: 17880 | L43: 1281500
A44: 【木曜日 平均】 | B44: 93620 | C44: 61620 | D44: 46860 | E44: 69820 | F44: 35190 | G44: 228310 | H44: 327460 | I44: 361040 | J44: 36900 | K44: 12600 | L44: 1273420
A45: 【金曜日 平均】 | B45: 111188 | C45: 90725 | D45: 71688 | E45: 84538 | F45: 129525 | G45: 238125 | H45: 406375 | I45: 483000 | J45: 154013 | K45: 6875 | L45: 1776050
A46: 【土曜日 平均】 | B46: 240475 | C46: 159775 | D46: 173663 | E46: 149288 | F46: 260663 | G46: 258950 | H46: 514713 | I46: 341863 | J46: 143850 | K46: 9313 | L46: 2252550
A47: ■8月曜日別売上合計
A48: 【日曜日 合計】 | B48: 959450 | C48: 354250 | D48: 481850 | E48: 532400 | F48: 820350 | G48: 955400 | H48: 1378300 | I48: 861050 | J48: 353300 | K48: 38600 | L48: 6734950
A49: 【月曜日 合計】 | B49: 576000 | C49: 428950 | D49: 248300 | E49: 323800 | F49: 379850 | G49: 642400 | H49: 1397700 | I49: 1237100 | J49: 306300 | K49: 13500 | L49: 5553900
A50: 【火曜日 合計】 | B50: 635650 | C50: 389750 | D50: 332100 | E50: 577750 | F50: 551900 | G50: 1516650 | H50: 1836550 | I50: 1722100 | J50: 291500 | K50: 168700 | L50: 8022650
A51: 【水曜日 合計】 | B51: 429800 | C51: 408100 | D51: 208600 | E51: 244750 | F51: 357750 | G51: 1160000 | H51: 1752100 | I51: 1511000 | J51: 246000 | K51: 89400 | L51: 6407500
A52: 【木曜日 合計】 | B52: 468100 | C52: 308100 | D52: 234300 | E52: 349100 | F52: 175950 | G52: 1141550 | H52: 1637300 | I52: 1805200 | J52: 184500 | K52: 63000 | L52: 6367100
A53: 【金曜日 合計】 | B53: 444750 | C53: 362900 | D53: 286750 | E53: 338150 | F53: 518100 | G53: 952500 | H53: 1625500 | I53: 1932000 | J53: 616050 | K53: 27500 | L53: 7104200
A54: 【土曜日 合計】 | B54: 961900 | C54: 639100 | D54: 694650 | E54: 597150 | F54: 1042650 | G54: 1035800 | H54: 2058850 | I54: 1367450 | J54: 575400 | K54: 37250 | L54: 9010200

Sheet 2023.7月実績
A1: ■R5年度 ビアガーデン売上実績
A2: 7月 | L2: =L14+L24+L34+L44+L54+L64 -> 48885000 | R2: 31
A3: FOOD予測 | C3: ビアガーデン7月 TOTAL実績 | N3: 客数 | R3: 売上
A4: 予算 | C4: 実績 | E4: 客数 | G4: 客単価 | I4: 売上予算 | L4: 25440000 | M4: 1日平均 | R4: =L4/R2 -> 820645.16 | T4: 天候要因（売上との関連性を数値化する）
A5: 1st week | C5: 1st week | T5: =C5 -> 1st week
A6: 曜日 | B6: 日にち | C6: 曜日 | D6: 日にち | E6: 客数 | F6: 料理売上 | G6: 料理単価 | H6: 飲料売上 | I6: 飲料単価 | J6: テント利用料 | K6: 物販 | L6: 売上合計 | M6: 合計単価 | N6: サーフィンズ | O6: forking | P6: Timee | Q6: 合計 | R6: 人時売上高 | T6: 最低 | U6: 最高 | V6: 12時 | W6: 15時 | X6: 18時 | Y6: Ave | AA6: ■天候要因 | AC6: 評価点
A7: 日 | C7: 日 | D7: =B7 -> 0 | G7: =F7/E7 -> #DIV/0! | I7: =H7/E7 -> #DIV/0! | L7: =F7+H7+J7 -> 0 | M7: =L7/E7 -> #DIV/0! | R7: =L7/Q7 -> #DIV/0! | Y7: =SUM(V7:X7)/3 -> 0 | AA7: 晴れ（33度まで） | AC7: 5
A8: 月 | C8: 月 | D8: =B8 -> 0 | G8: =F8/E8 -> #DIV/0! | I8: =H8/E8 -> #DIV/0! | L8: =F8+H8+J8 -> 0 | M8: =L8/E8 -> #DIV/0! | R8: =L8/Q8 -> #DIV/0! | Y8: =SUM(V8:X8)/3 -> 0 | AA8: 晴れ（25度以下） | AC8: 4
A9: 火 | C9: 火 | D9: =B9 -> 0 | G9: =F9/E9 -> #DIV/0! | I9: =H9/E9 -> #DIV/0! | L9: =F9+H9+J9 -> 0 | M9: =L9/E9 -> #DIV/0! | R9: =L9/Q9 -> #DIV/0! | Y9: =SUM(V9:X9)/3 -> 0 | AA9: 晴れ（33度以上）曇25度以上 | AC9: 3
A10: 水 | C10: 水 | D10: =B10 -> 0 | G10: =F10/E10 -> #DIV/0! | I10: =H10/E10 -> #DIV/0! | L10: =F10+H10+J10 -> 0 | M10: =L10/E10 -> #DIV/0! | R10: =L10/Q10 -> #DIV/0! | Y10: =SUM(V10:X10)/3 -> 0 | AA10: 曇 | AC10: 2
A11: 木 | C11: 木 | D11: =B11 -> 0 | G11: =F11/E11 -> #DIV/0! | I11: =H11/E11 -> #DIV/0! | L11: =F11+H11+J11 -> 0 | M11: =L11/E11 -> #DIV/0! | R11: =L11/Q11 -> #DIV/0! | Y11: =SUM(V11:X11)/3 -> 0 | AA11: 雨 | AC11: 1
A12: 金 | C12: 金 | D12: =B12 -> 0 | G12: =F12/E12 -> #DIV/0! | I12: =H12/E12 -> #DIV/0! | L12: =F12+H12+J12 -> 0 | M12: =L12/E12 -> #DIV/0! | R12: =L12/Q12 -> #DIV/0! | Y12: =SUM(V12:X12)/3 -> 0 | AA12: 豪雨・雷雨 | AC12: 0
A13: 土 | B13: 1 | C13: 土 | D13: =B13 -> 1 | E13: 217 | F13: 655350 | G13: =F13/E13 -> 3020.0461 | H13: 331800 | I13: =H13/E13 -> 1529.0323 | J13: 26950 | L13: =F13+H13+J13 -> 1014100 | M13: =L13/E13 -> 4673.2719 | Q13: 151 | R13: =L13/Q13 -> 6715.894 | T13: 19.6 | U13: 21.2 | V13: 2 | W13: 4 | X13: 4 | Y13: =SUM(V13:X13)/3 -> 3.3333333 | AA13: ※5.6月は18時は最低気温を採用。7月〜は最高気温を採用。
A14: SUB TOTAL | C14: SUB TOTAL | E14: =SUM(E7:E13) -> 217 | F14: =SUM(F7:F13) -> 655350 | G14: =F14/E14 -> 3020.0461 | H14: =SUM(H7:H13) -> 331800 | I14: =H14/E14 -> 1529.0323 | J14: =SUM(J7:J13) -> 26950 | L14: =F14+H14 -> 987150 | M14: =L14/E14 -> 4549.0783 | Q14: =SUM(Q7:Q13) -> 151 | R14: =L14/Q14 -> 6537.4172 | S14: 1 | T14: =SUM(T7:T13)/S14 -> 19.6 | U14: =SUM(U7:U13)/S14 -> 21.2 | V14: =SUM(V7:V13)/S14 -> 2 | W14: =SUM(W7:W13)/S14 -> 4 | X14: =SUM(X7:X13)/S14 -> 4 | Y14: =SUM(V14:X14)/3 -> 3.3333333 | Z14: ⑥ | AA14: =L14/S14 -> 987150 | AF14: ※1日平均売上
A15: 2nd week | C15: 2nd week | T15: =C15 -> 2nd week | AF15: ※1日平均売上
A16: 曜日 | B16: 日にち | C16: 曜日 | D16: 日にち | E16: 客数 | F16: 料理売上 | G16: 料理単価 | H16: 飲料売上 | I16: 飲料単価 | J16: テント利用料 | K16: 物販 | L16: 売上合計 | M16: 合計単価 | N16: サーフィンズ | O16: forking | P16: Timee | Q16: 合計 | R16: 人時売上高 | T16: 最低 | U16: 最高 | V16: 12時 | W16: 15時 | X16: 18時 | Y16: Ave | AA16: ■天候要因 | AC16: 評価点
A17: 日 | B17: 2 | C17: 日 | D17: =B17 -> 2 | E17: 279 | F17: 753250 | G17: =F17/E17 -> 2699.8208 | H17: 387100 | I17: =H17/E17 -> 1387.4552 | J17: 12100 | L17: =F17+H17+J17 -> 1152450 | M17: =L17/E17 -> 4130.6452 | Q17: 151 | R17: =L17/Q17 -> 7632.1192 | T17: 17 | U17: 22.9 | V17: 4 | W17: 3 | X17: 2 | Y17: =SUM(V17:X17)/3 -> 3 | AA17: 晴れ（33度まで） | AC17: 5
A18: 月 | B18: 3 | C18: 月 | D18: =B18 -> 3 | E18: 154 | F18: 408400 | G18: =F18/E18 -> 2651.9481 | H18: 253650 | I18: =H18/E18 -> 1647.0779 | J18: 5500 | L18: =F18+H18+J18 -> 667550 | M18: =L18/E18 -> 4334.7403 | Q18: 145 | R18: =L18/Q18 -> 4603.7931 | T18: 17.7 | U18: 23.9 | V18: 4 | W18: 4 | X18: 4 | Y18: =SUM(V18:X18)/3 -> 4 | AA18: 晴れ（25度以下） | AC18: 4
A19: 火 | B19: 4 | C19: 火 | D19: =B19 -> 4 | E19: 201 | F19: 483850 | G19: =F19/E19 -> 2407.2139 | H19: 319300 | I19: =H19/E19 -> 1588.5572 | J19: 4950 | L19: =F19+H19+J19 -> 808100 | M19: =L19/E19 -> 4020.398 | Q19: 145 | R19: =L19/Q19 -> 5573.1034 | T19: 18.2 | U19: 24.8 | V19: 4 | W19: 4 | X19: 4 | Y19: =SUM(V19:X19)/3 -> 4 | AA19: 晴れ（33度以上）曇25度以上 | AC19: 3
A20: 水 | B20: 5 | C20: 水 | D20: =B20 -> 5 | E20: 264 | F20: 712150 | G20: =F20/E20 -> 2697.5379 | H20: 379450 | I20: =H20/E20 -> 1437.3106 | J20: 3850 | L20: =F20+H20+J20 -> 1095450 | M20: =L20/E20 -> 4149.4318 | Q20: 145 | R20: =L20/Q20 -> 7554.8276 | T20: 18 | U20: 27.4 | V20: 5 | W20: 5 | X20: 4 | Y20: =SUM(V20:X20)/3 -> 4.6666667 | AA20: 曇 | AC20: 2
A21: 木 | B21: 6 | C21: 木 | D21: =B21 -> 6 | E21: 305 | F21: 1036850 | G21: =F21/E21 -> 3399.5082 | H21: 558700 | I21: =H21/E21 -> 1831.8033 | J21: 11000 | L21: =F21+H21+J21 -> 1606550 | M21: =L21/E21 -> 5267.377 | Q21: 151 | R21: =L21/Q21 -> 10639.404 | T21: 18.4 | U21: 25.2 | V21: 3 | W21: 1 | X21: 1 | Y21: =SUM(V21:X21)/3 -> 1.6666667 | AA21: 雨 | AC21: 1
A22: 金 | B22: 7 | C22: 金 | D22: =B22 -> 7 | E22: 392 | F22: 1074950 | G22: =F22/E22 -> 2742.2194 | H22: 681300 | I22: =H22/E22 -> 1738.0102 | J22: 20350 | L22: =F22+H22+J22 -> 1776600 | M22: =L22/E22 -> 4532.1429 | Q22: 165.5 | R22: =L22/Q22 -> 10734.743 | T22: 19.2 | U22: 26.1 | V22: 3 | W22: 5 | X22: 5 | Y22: =SUM(V22:X22)/3 -> 4.3333333 | AA22: 豪雨・雷雨 | AC22: 0
A23: 土 | B23: 8 | C23: 土 | D23: =B23 -> 8 | E23: 565 | F23: 1584500 | G23: =F23/E23 -> 2804.4248 | H23: 944950 | I23: =H23/E23 -> 1672.4779 | J23: 13750 | L23: =F23+H23+J23 -> 2543200 | M23: =L23/E23 -> 4501.2389 | Q23: 165.5 | R23: =L23/Q23 -> 15366.767 | T23: 19.6 | U23: 31.4 | V23: 5 | W23: 5 | X23: 5 | Y23: =SUM(V23:X23)/3 -> 5 | AA23: ※5.6月は18時は最低気温を採用。7月〜は最高気温を採用。
A24: SUB TOTAL | C24: SUB TOTAL | E24: =SUM(E17:E23) -> 2160 | F24: =SUM(F17:F23) -> 6053950 | G24: =F24/E24 -> 2802.7546 | H24: =SUM(H17:H23) -> 3524450 | I24: =H24/E24 -> 1631.6898 | J24: =SUM(J17:J23) -> 71500 | L24: =F24+H24 -> 9578400 | M24: =L24/E24 -> 4434.4444 | Q24: =SUM(Q17:Q23) -> 1068 | R24: =L24/Q24 -> 8968.5393 | S24: 7 | T24: =SUM(T17:T23)/S24 -> 18.3 | U24: =SUM(U17:U23)/S24 -> 25.957143 | V24: =SUM(V17:V23)/S24 -> 4 | W24: =SUM(W17:W23)/S24 -> 3.8571429 | X24: =SUM(X17:X23)/S24 -> 3.5714286 | Y24: =SUM(V24:X24)/3 -> 3.8095238 | Z24: ⑦ | AA24: =L24/S24 -> 1368342.9 | AF24: ※1日平均売上
A25: 3rd week | C25: 3rd week | T25: =C25 -> 3rd week
A26: 曜日 | B26: 日にち | C26: 曜日 | D26: 日にち | E26: 客数 | F26: 料理売上 | G26: 料理単価 | H26: 飲料売上 | I26: 飲料単価 | J26: テント利用料 | K26: 物販 | L26: 売上合計 | M26: 合計単価 | N26: サーフィンズ | O26: forking | P26: Timee | Q26: 合計 | R26: 人時売上高 | T26: 最低 | U26: 最高 | V26: 12時 | W26: 15時 | X26: 18時 | Y26: Ave | AA26: ■天候要因 | AC26: 評価点
A27: 日 | B27: 9 | C27: 日 | D27: =B27 -> 9 | E27: 513 | F27: 1444350 | G27: =F27/E27 -> 2815.4971 | H27: 831600 | I27: =H27/E27 -> 1621.0526 | J27: 14850 | L27: =F27+H27+J27 -> 2290800 | M27: =L27/E27 -> 4465.4971 | Q27: 165.5 | R27: =L27/Q27 -> 13841.692 | T27: 21.3 | U27: 31.4 | V27: 1 | W27: 3 | X27: 5 | Y27: =SUM(V27:X27)/3 -> 3 | AA27: 晴れ（33度まで） | AC27: 5
A28: 月 | B28: 10 | C28: 月 | D28: =B28 -> 10 | E28: 293 | F28: 747400 | G28: =F28/E28 -> 2550.8532 | H28: 455750 | I28: =H28/E28 -> 1555.4608 | J28: 6050 | L28: =F28+H28+J28 -> 1209200 | M28: =L28/E28 -> 4126.9625 | Q28: 126 | R28: =L28/Q28 -> 9596.8254 | T28: 20.9 | U28: 28.4 | V28: 3 | W28: 3 | X28: 3 | Y28: =SUM(V28:X28)/3 -> 3 | AA28: 晴れ（25度以下） | AC28: 4
A29: 火 | B29: 11 | C29: 火 | D29: =B29 -> 11 | E29: 181 | F29: 529650 | G29: =F29/E29 -> 2926.2431 | H29: 266300 | I29: =H29/E29 -> 1471.2707 | J29: 13200 | L29: =F29+H29+J29 -> 809150 | M29: =L29/E29 -> 4470.442 | Q29: 126 | R29: =L29/Q29 -> 6421.8254 | T29: 22.3 | U29: 30.2 | V29: 5 | W29: 3 | X29: 3 | Y29: =SUM(V29:X29)/3 -> 3.6666667 | AA29: 晴れ（33度以上）曇25度以上 | AC29: 3
A30: 水 | B30: 12 | C30: 水 | D30: =B30 -> 12 | E30: 175 | F30: 518650 | G30: =F30/E30 -> 2963.7143 | H30: 266050 | I30: =H30/E30 -> 1520.2857 | J30: 12650 | L30: =F30+H30+J30 -> 797350 | M30: =L30/E30 -> 4556.2857 | Q30: 125 | R30: =L30/Q30 -> 6378.8 | T30: 21.4 | U30: 26.1 | V30: 1 | W30: 1 | X30: 1 | Y30: =SUM(V30:X30)/3 -> 1 | AA30: 曇 | AC30: 2
A31: 木 | B31: 13 | C31: 木 | D31: =B31 -> 13 | E31: 220 | F31: 610100 | G31: =F31/E31 -> 2773.1818 | H31: 339550 | I31: =H31/E31 -> 1543.4091 | J31: 1100 | L31: =F31+H31+J31 -> 950750 | M31: =L31/E31 -> 4321.5909 | Q31: 145 | R31: =L31/Q31 -> 6556.8966 | T31: 21 | U31: 26.7 | V31: 3 | W31: 3 | X31: 3 | Y31: =SUM(V31:X31)/3 -> 3 | AA31: 雨 | AC31: 1
A32: 金 | B32: 14 | C32: 金 | D32: =B32 -> 14 | E32: 373 | F32: 1107700 | G32: =F32/E32 -> 2969.7051 | H32: 596850 | I32: =H32/E32 -> 1600.134 | J32: 12100 | L32: =F32+H32+J32 -> 1716650 | M32: =L32/E32 -> 4602.2788 | Q32: 151 | R32: =L32/Q32 -> 11368.543 | T32: 20 | U32: 25.4 | V32: 3 | W32: 5 | X32: 1 | Y32: =SUM(V32:X32)/3 -> 3 | AA32: 豪雨・雷雨 | AC32: 0
A33: 土 | B33: 15 | C33: 土 | D33: =B33 -> 15 | E33: 252 | F33: 797100 | G33: =F33/E33 -> 3163.0952 | H33: 410750 | I33: =H33/E33 -> 1629.9603 | J33: 30250 | L33: =F33+H33+J33 -> 1238100 | M33: =L33/E33 -> 4913.0952 | Q33: 165.5 | R33: =L33/Q33 -> 7480.9668 | T33: 19.4 | U33: 21.4 | V33: 1 | W33: 1 | X33: 1 | Y33: =SUM(V33:X33)/3 -> 1 | AA33: ※5.6月は18時は最低気温を採用。7月〜は最高気温を採用。
A34: SUB TOTAL | C34: SUB TOTAL | E34: =SUM(E27:E33) -> 2007 | F34: =SUM(F27:F33) -> 5754950 | G34: =F34/E34 -> 2867.439 | H34: =SUM(H27:H33) -> 3166850 | I34: =H34/E34 -> 1577.9023 | J34: =SUM(J27:J33) -> 90200 | L34: =F34+H34 -> 8921800 | M34: =L34/E34 -> 4445.3413 | Q34: =SUM(Q27:Q33) -> 1004 | R34: =L34/Q34 -> 8886.255 | S34: 7 | T34: =SUM(T27:T33)/S34 -> 20.9 | U34: =SUM(U27:U33)/S34 -> 27.085714 | V34: =SUM(V27:V33)/S34 -> 2.4285714 | W34: =SUM(W27:W33)/S34 -> 2.7142857 | X34: =SUM(X27:X33)/S34 -> 2.4285714 | Y34: =SUM(V34:X34)/3 -> 2.5238095 | Z34: ⑧ | AA34: =L34/S34 -> 1274542.9 | AF34: ※1日平均売上
A35: 4th week | C35: 4th week | T35: =C35 -> 4th week
A36: 曜日 | B36: 日にち | C36: 曜日 | D36: 日にち | E36: 客数 | F36: 料理売上 | G36: 料理単価 | H36: 飲料売上 | I36: 飲料単価 | J36: テント利用料 | K36: 物販 | L36: 売上合計 | M36: 合計単価 | N36: サーフィンズ | O36: forking | P36: Timee | Q36: 合計 | R36: 人時売上高 | T36: 最低 | U36: 最高 | V36: 12時 | W36: 15時 | X36: 18時 | Y36: Ave | AA36: ■天候要因 | AC36: 評価点
A37: 日 | B37: 16 | C37: 日 | D37: =B37 -> 16 | E37: 660 | F37: 1804850 | G37: =F37/E37 -> 2734.6212 | H37: 1029900 | I37: =H37/E37 -> 1560.4545 | J37: 24750 | L37: =F37+H37+J37 -> 2859500 | M37: =L37/E37 -> 4332.5758 | Q37: 165.5 | R37: =L37/Q37 -> 17277.946 | T37: 20.1 | U37: 28 | V37: 5 | W37: 3 | X37: 3 | Y37: =SUM(V37:X37)/3 -> 3.6666667 | AA37: 晴れ（33度まで） | AC37: 5
A38: 月 | B38: 17 | C38: 月 | D38: =B38 -> 17 | E38: 353 | F38: 924150 | G38: =F38/E38 -> 2617.9887 | H38: 514000 | I38: =H38/E38 -> 1456.0907 | J38: 14850 | L38: =F38+H38+J38 -> 1453000 | M38: =L38/E38 -> 4116.1473 | Q38: 124.5 | R38: =L38/Q38 -> 11670.683 | T38: 21.7 | U38: 26 | V38: 3 | W38: 3 | X38: 3 | Y38: =SUM(V38:X38)/3 -> 3 | AA38: 晴れ（25度以下） | AC38: 4
A39: 火 | B39: 18 | C39: 火 | D39: =B39 -> 18 | E39: 280 | F39: 721150 | G39: =F39/E39 -> 2575.5357 | H39: 391100 | I39: =H39/E39 -> 1396.7857 | J39: 12650 | L39: =F39+H39+J39 -> 1124900 | M39: =L39/E39 -> 4017.5 | Q39: 126 | R39: =L39/Q39 -> 8927.7778 | T39: 19.2 | U39: 24.7 | V39: 2 | W39: 2 | X39: 3 | Y39: =SUM(V39:X39)/3 -> 2.3333333 | AA39: 晴れ（33度以上）曇25度以上 | AC39: 3
A40: 水 | B40: 19 | C40: 水 | D40: =B40 -> 19 | E40: 410 | F40: 1169800 | G40: =F40/E40 -> 2853.1707 | H40: 639000 | I40: =H40/E40 -> 1558.5366 | J40: 15400 | L40: =F40+H40+J40 -> 1824200 | M40: =L40/E40 -> 4449.2683 | Q40: 126 | R40: =L40/Q40 -> 14477.778 | T40: 19.4 | U40: 25 | V40: 3 | W40: 5 | X40: 5 | Y40: =SUM(V40:X40)/3 -> 4.3333333 | AA40: 曇 | AC40: 2
...

Sheet 7月時間帯別売上実績
A1: ■7月 時間帯別売上実績&曜日別売上実績
A2: 営業日 | B2: ランチ | E2: アイドル | G2: ディナー | L2: 合計
B3: 12時 | C3: 13時 | D3: 14時 | E3: 15時 | F3: 16時 | G3: 17時 | H3: 18時 | I3: 19時 | J3: 20時 | K3: 21時
A4: 2023/07/01(土) | B4: 85900 | C4: 86450 | D4: 105050 | E4: 37400 | F4: 90900 | G4: 190750 | H4: 209850 | I4: 175750 | J4: 32050 | K4: 0 | L4: =SUM(B4:K4) -> 1014100
A5: 2023/07/02(日) | B5: 198200 | C5: 152300 | D5: 93700 | E5: 87100 | F5: 118300 | G5: 119500 | H5: 138100 | I5: 150000 | J5: 91250 | K5: 4000 | L5: =SUM(B5:K5) -> 1152450
A6: 2023/07/03(月) | B6: 147150 | C6: 29000 | D6: 47450 | E6: 88800 | F6: 54900 | G6: 104400 | H6: 152850 | I6: 21900 | J6: 17000 | K6: 4100 | L6: =SUM(B6:K6) -> 667550
A7: 2023/07/04(火) | B7: 126250 | C7: 58800 | D7: 45800 | E7: 61400 | F7: 96550 | G7: 90550 | H7: 124950 | I7: 173050 | J7: 30750 | K7: 0 | L7: =SUM(B7:K7) -> 808100
A8: 2023/07/05(水) | B8: 110250 | C8: 71900 | D8: 154900 | E8: 106950 | F8: 66500 | G8: 73650 | H8: 310950 | I8: 167950 | J8: 32400 | K8: 0 | L8: =SUM(B8:K8) -> 1095450
A9: 2023/07/06(木) | B9: 129400 | C9: 73000 | D9: 47700 | E9: 38400 | F9: 15650 | G9: 108900 | H9: 22000 | I9: 0 | J9: 1127500 | K9: 44000 | L9: =SUM(B9:K9) -> 1606550
A10: 2023/07/07(金) | B10: 127450 | C10: 114550 | D10: 62300 | E10: 63800 | F10: 228350 | G10: 219450 | H10: 432850 | I10: 385450 | J10: 101400 | K10: 41000 | L10: =SUM(B10:K10) -> 1776600
A11: 2023/07/08(土) | B11: 327200 | C11: 236300 | D11: 233000 | E11: 299900 | F11: 149100 | G11: 272100 | H11: 293050 | I11: 373300 | J11: 357550 | K11: 1700 | L11: =SUM(B11:K11) -> 2543200
A12: 2023/07/09(日) | B12: 10150 | C12: 193350 | D12: 482800 | E12: 263150 | F12: 195750 | G12: 331000 | H12: 258150 | I12: 485100 | J12: 69250 | K12: 2100 | L12: =SUM(B12:K12) -> 2290800
A13: 2023/07/10(月) | B13: 147900 | C13: 76900 | D13: 79850 | E13: 99850 | F13: 52450 | G13: 160700 | H13: 349400 | I13: 175850 | J13: 66300 | K13: 0 | L13: =SUM(B13:K13) -> 1209200
A14: 2023/07/11(火) | B14: 143400 | C14: 128800 | D14: 44600 | E14: 3200 | F14: 40300 | G14: 119000 | H14: 76150 | I14: 235250 | J14: 18450 | K14: 0 | L14: =SUM(B14:K14) -> 809150
A15: 2023/07/12(水) | B15: 168150 | C15: 63000 | D15: 13700 | E15: 9900 | F15: 27250 | G15: 203000 | H15: 175600 | I15: 55250 | J15: 71500 | K15: 10000 | L15: =SUM(B15:K15) -> 797350
... A34: 2023/07/31(月) | B34: 60900 | C34: 64450 | D34: 18500 | E34: 35000 | F34: 67550 | G34: 52850 | H34: 275300 | I34: 273300 | J34: 121650 | K34: 7400 | L34: =SUM(B34:K34) -> 976900
A35: 【合計】 | B35: 5247250 | C35: 3312550 | D35: 3229150 | E35: 2946900 | F35: 4324150 | G35: =SUM(G4:G34) -> 6173650 | H35: =SUM(H4:H34) -> 9383850 | I35: =SUM(I4:I34) -> 7930200 | J35: =SUM(J4:J34) -> 4636050 | K35: =SUM(K4:K34) -> 2146750 | L35: =SUM(B35:K35) -> 49330500
B36: =B35+C35+D35 -> 11788950 | E36: =E35+F35 -> 7271050 | G36: =G35+H35+I35+J35+K35 -> 30270500 | L36: =SUM(B36:J36) -> 49330500
A37: 売上比率 | B37: =B36/L36 -> 0.23897893 | E37: =E36/L36 -> 0.14739461 | G37: =G36/L36 -> 0.61362646 | L37: =SUM(B37:J37) -> 1
B38: =B37+E37 -> 0.38637354
A39: ■7月 曜日別売上平均
A40: 【日曜日 平均】 | B40: 245810 | C40: 187620 | D40: 240050 | E40: 175930 | F40: 191250 | G40: 281960 | H40: 242400 | I40: 296560 | J40: 88325 | K40: 9650 | L40: 1962110
A41: 【月曜日 平均】 | B41: 152610 | C41: 64150 | D41: 68710 | E41: 76690 | F41: 78090 | G41: 151720 | H41: 237460 | I41: 208100 | J41: 76575 | K41: 3375 | L41: 1135750
A42: 【火曜日 平均】 | B42: 114813 | C42: 76238 | D42: 61850 | E42: 44550 | F42: 77900 | G42: 111163 | H42: 164713 | I42: 288563 | J42: 58300 | K42: 33740 | L42: 1085775
A43: 【水曜日 平均】 | B43: 165325 | C43: 72463 | D43: 81388 | E43: 52263 | F43: 78325 | G43: 172775 | H43: 280338 | I43: 128113 | J43: 49200 | K43: 17880 | L43: 1277100
A44: 【木曜日 平均】 | B44: 104000 | C44: 70513 | D44: 64213 | E44: 61550 | F44: 174588 | G44: 114563 | H44: 336663 | I44: 146513 | J44: 36900 | K44: 12600 | L44: 1528575
A45: 【金曜日 平均】 | B45: 134900 | C45: 126713 | D45: 62750 | E45: 84625 | F45: 153775 | G45: 288163 | H45: 475388 | I45: 403900 | J45: 154013 | K45: 6875 | L45: 1988325
A46: 【土曜日 平均】 | B46: 235800 | C46: 134000 | D46: 120910 | E46: 142370 | F46: 207820 | G46: 251720 | H46: 391230 | I46: 307710 | J46: 143850 | K46: 9313 | L46: 2064420 | N46: 2064420
A47: ■7月 曜日別売上合計
A48: 【日曜日 合計】 | B48: 959450 | C48: 354250 | D48: 481850 | E48: 532400 | F48: 820350 | G48: 955400 | H48: 1378300 | I48: 861050 | J48: 353300 | K48: 38600 | L48: 9810550
