Workbook

Sheet 2024レビュー
A1: 【R6 さっぽろテレビ塔ビアガーデン（ピコレワインガーデン）振り返り】
A2: ①売上 | I2: 単位：円 | J2: 平均気温 | L2: ①コメント
A3: 月 | B3: 実績 | C3: 予算 | D3: 予算比 | E3: 差異 | F3: 予測 | G3: 予測比 | H3: 差異 | I3: 1日平均売上 | J3: LOW | K3: HIGH | V3: BG営業天候指数 | Y3: 2024 | Z3: 平均気温 | AB3: 2023 | AC3: 平均気温 | AE3: 差異 | AF3: 平均気温
A4: 4 | B4: 499227 | C4: 260000 | D4: =B4/C4 -> 1.9201038 | E4: =B4-C4 -> 239227 | F4: 260000 | G4: =B4/F4 -> 1.9201038 | H4: =B4-F4 -> 239227 | I4: =B4/T4 -> 124806.75 | T4: 4 | U4: 月 | V4: 2024 | W4: 2023 | Y4: 月 | Z4: LOW | AA4: HIGH | AB4: 月 | AC4: LOW | AD4: HIGH | AE4: 月 | AF4: LOW | AG4: HIGH | AJ4: 2024 | AK4: 期 間 | AL4: 日 数 | AM4: 売 上 | AN4: 客 数 | AO4: 客単価 | AP4: 2023 | AQ4: 期 間 | AR4: 日 数 | AS4: 売 上 | AT4: 客 数 | AU4: 客単価 | AV4: 売 上 前 年 比 | AX4: 客 数 前 年 比 | AZ4: 客 単 価 前 年 比
A5: 5 | B5: 2919145 | C5: 1851200 | D5: =B5/C5 -> 1.5768934 | E5: =B5-C5 -> 1067945 | F5: 1851200 | G5: =B5/F5 -> 1.5768934 | H5: =B5-F5 -> 1067945 | I5: =B5/T5 -> 121631.04 | J5: 11.6℃ | K5: 17.0℃ | T5: 24 | U5: 4 | V5: 1.33 | W5: 2.1 | X5: =V5/W5 -> 0.63333333 | Y5: 4 | AB5: 4 | AE5: 4 | AF5: =Z5-AC5 -> 0 | AG5: =AA5-AD5 -> 0 | AJ5: 4~5 | AK5: PC 4/27-5/19 | AL5: 23 | AM5: 2939522 | AN5: 2348 | AO5: =AM5/AN5 -> 1251.9259 | AP5: 4~5 | AQ5: PC営業なし | AR5: 0 | AS5: 0 | AT5: 0 | AU5: =AS5/AT5 -> #DIV/0! | AV5: =AM5-AS5 -> 2939522 | AW5: =AM5/AS5 -> #DIV/0! | AX5: =AN5-AT5 -> 2348 | AY5: =AN5/AT5 -> #DIV/0! | AZ5: =AO5-AU5 -> #DIV/0! | BA5: =AO5/AU5 -> #DIV/0!
A6: 6 | B6: 19194436 | C6: 25690000 | D6: =B6/C6 -> 0.74715594 | E6: =B6-C6 -> -6495564 | F6: 22000000 | G6: =B6/F6 -> 0.87247436 | H6: =B6-F6 -> -2805564 | I6: =B6/T6 -> 639814.53 | J6: 15.6℃ | K6: 23.9℃ | T6: 30 | U6: 5 | V6: 2.78 | W6: 3.37 | X6: =V6/W6 -> 0.82492582 | Y6: 5 | Z6: 11.6 | AA6: 17 | AB6: 5 | AC6: 12.7 | AD6: 20 | AE6: 5 | AF6: =Z6-AC6 -> -1.1 | AG6: =AA6-AD6 -> -3 | AJ6: 5 | AK6: BG 5/27-5/31 | AL6: 5 | AM6: 477807 | AN6: 133 | AO6: =AM6/AN6 -> 3592.5338 | AP6: 5 | AQ6: BG 5/27-5/31 | AR6: 5 | AS6: 1795227.3 | AT6: 506 | AU6: =AS6/AT6 -> 3547.88 | AV6: =AM6-AS6 -> -1317420.3 | AW6: =AM6/AS6 -> 0.26615404 | AX6: =AN6-AT6 -> -373 | AY6: =AN6/AT6 -> 0.26284585 | AZ6: =AO6-AU6 -> 44.653849 | BA6: =AO6/AU6 -> 1.0125861
A7: 7 | B7: 47613345 | C7: 51610000 | D7: =B7/C7 -> 0.92256045 | E7: =B7-C7 -> -3996655 | F7: 50000000 | G7: =B7/F7 -> 0.9522669 | H7: =B7-F7 -> -2386655 | I7: =B7/T7 -> 1535914.4 | J7: 20.5℃ | K7: 28.0℃ | T7: 31 | U7: 6 | V7: 3.19 | W7: 3.49 | X7: =V7/W7 -> 0.91404011 | Y7: 6 | Z7: 15.6 | AA7: 23.9 | AB7: 6 | AC7: 15.6 | AD7: 24.1 | AE7: 6 | AF7: =Z7-AC7 -> 0 | AG7: =AA7-AD7 -> -0.2 | AJ7: 6 | AK7: BG フル営業 | AL7: 30 | AM7: 19170665 | AN7: 5174 | AO7: =AM7/AN7 -> 3705.1923 | AP7: 6 | AQ7: BG フル営業 | AR7: 30 | AS7: 19049727 | AT7: 5309 | AU7: =AS7/AT7 -> 3588.195 | AV7: =AM7-AS7 -> 120937.73 | AW7: =AM7/AS7 -> 1.0063485 | AX7: =AN7-AT7 -> -135 | AY7: =AN7/AT7 -> 0.97457148 | AZ7: =AO7-AU7 -> 116.9973 | BA7: =AO7/AU7 -> 1.0326062
A8: 8 | B8: 55874978 | C8: 49500000 | D8: =B8/C8 -> 1.1287874 | E8: =B8-C8 -> 6374978 | F8: 50000000 | G8: =B8/F8 -> 1.1174996 | H8: =B8-F8 -> 5874978 | I8: =B8/T8 -> 1802418.6 | J8: 22.0℃ | K8: 28.4℃ | T8: 31 | U8: 7 | V8: 3.04 | W8: 3.39 | X8: =V8/W8 -> 0.89675516 | Y8: 7 | Z8: 20.5 | AA8: 28 | AB8: 7 | AC8: 21 | AD8: 27.8 | AE8: 7 | AF8: =Z8-AC8 -> -0.5 | AG8: =AA8-AD8 -> 0.2 | AJ8: 7 | AK8: BG フル営業 | AL8: 31 | AM8: 47598067 | AN8: 11438 | AO8: =AM8/AN8 -> 4161.3977 | AP8: 7 | AQ8: BG フル営業 | AR8: 31 | AS8: 44856909 | AT8: 11036 | AU8: =AS8/AT8 -> 4064.5985 | AV8: =AM8-AS8 -> 2741157.9 | AW8: =AM8/AS8 -> 1.0611089 | AX8: =AN8-AT8 -> 402 | AY8: =AN8/AT8 -> 1.0364262 | AZ8: =AO8-AU8 -> 96.799205 | BA8: =AO8/AU8 -> 1.0238152
A9: 9 | B9: 12350827 | C9: 7000000 | D9: =B9/C9 -> 1.7644039 | E9: =B9-C9 -> 5350827 | F9: 8000000 | G9: =B9/F9 -> 1.5438534 | H9: =B9-F9 -> 4350827 | I9: =B9/T9 -> 494033.08 | J9: 15.6℃ | K9: 24.0℃ | T9: 25 | U9: 8 | V9: 3.55 | W9: 3.44 | X9: =V9/W9 -> 1.0319767 | Y9: 8 | Z9: 22 | AA9: 28.4 | AB9: 8 | AC9: 24 | AD9: 30.9 | AE9: 8 | AF9: =Z9-AC9 -> -2 | AG9: =AA9-AD9 -> -2.5 | AJ9: 8 | AK9: BG フル営業 | AL9: 31 | AM9: 55870570 | AN9: 13891 | AO9: =AM9/AN9 -> 4022.0697 | AP9: 8 | AQ9: BG フル営業 | AR9: 31 | AS9: 44860591 | AT9: 11093 | AU9: =AS9/AT9 -> 4044.045 | AV9: =AM9-AS9 -> 11009979 | AW9: =AM9/AS9 -> 1.2454265 | AX9: =AN9-AT9 -> 2798 | AY9: =AN9/AT9 -> 1.2522311 | AZ9: =AO9-AU9 -> -21.97529 | BA9: =AO9/AU9 -> 0.99456601
A10: 10 | B10: 1454318 | C10: 455000 | D10: =B10/C10 -> 3.1963033 | E10: =B10-C10 -> 999318 | F10: 692727 | G10: =B10/F10 -> 2.09941 | H10: =B10-F10 -> 761591 | I10: =B10/T10 -> 242386.33 | J10: 13.7℃ | K10: 20.7℃ | T10: 6 | U10: 9 | V10: 2.72 | W10: - | X10: =V10/W10 -> #VALUE! | Y10: 9 | Z10: 15.6 | AA10: 24 | AB10: 9 | AC10: 21.4 | AD10: 28.6 | AE10: 9 | AF10: =Z10-AC10 -> -5.8 | AG10: =AA10-AD10 -> -4.6 | AJ10: 9 | AK10: BG 9/1-9/8 | AL10: 8 | AM10: 8816632 | AN10: 2410 | AO10: =AM10/AN10 -> 3658.3535 | AP10: 9 | AQ10: BG 9/1-9/3 | AR10: 8 | AS10: 4058727.3 | AT10: =263+385+76 -> 724 | AU10: =AS10/AT10 -> 5605.9769 | AV10: =AM10-AS10 -> 4757904.7 | AW10: =AM10/AS10 -> 2.1722652 | AX10: =AN10-AT10 -> 1686 | AY10: =AN10/AT10 -> 3.3287293 | AZ10: =AO10-AU10 -> -1947.6234 | BA10: =AO10/AU10 -> 0.65258091
A11: TOTAL | B11: =SUM(B4:B10) -> 139906276 | C11: =SUM(C4:C10) -> 136366200 | D11: =B11/C11 -> 1.0259601 | E11: =B11-C11 -> 3540076 | F11: =SUM(F4:F10) -> 132803927 | G11: =B11/F11 -> 1.05348 | H11: =B11-F11 -> 7102349 | I11: =B11/T11 -> 926531.63 | T11: =SUM(T4:T10) -> 151 | U11: 10 | V11: =SUM(V5:V10)/6 -> 2.7683333 | W11: =SUM(W5:W10)/5 -> 3.158 | X11: =V11/W11 -> 0.87660967 | Y11: 10 | Z11: 13.7 | AA11: 20.7 | AB11: 10 | AE11: 10 | AF11: =Z11-AC11 -> 13.7 | AG11: =AA11-AD11 -> 20.7 | AJ11: 9~10 | AK11: PC-BG 秋営業 9/14-10/6 | AL11: 23 | AM11: 4982837 | AN11: 1704 | AO11: =AM11/AN11 -> 2924.2001 | AP11: 9~10 | AQ11: PC 9/9-10/1 | AR11: 23 | AS11: 1489815.5 | AT11: 1365 | AU11: =AS11/AT11 -> 1091.4399 | AV11: =AM11-AS11 -> 3493021.5 | AW11: =AM11/AS11 -> 3.3446002 | AX11: =AN11-AT11 -> 339 | AY11: =AN11/AT11 -> 1.2483516 | AZ11: =AO11-AU11 -> 1832.7602 | BA11: =AO11/AU11 -> 2.6792132
AJ12: ビアガのみ105日 | AL12: =AL7+AL6+AL8+AL9+AL10 -> 105 | AM12: =AM7+AM6+AM8+AM9+AM10 -> 131933741 | AN12: =AN7+AN6+AN8+AN9+AN10 -> 33046 | AO12: =AM12/AN12 -> 3992.427 | AP12: ビアガのみ105日 | AR12: =AR7+AR6+AR8+AR9+AR10 -> 105 | AS12: =AS7+AS6+AS8+AS9+AS10 -> 1.1462118e+08 | AT12: =AT7+AT6+AT8+AT9+AT10 -> 28668 | AU12: =AS12/AT12 -> 3998.2274 | AV12: =AM12-AS12 -> 17312559 | AW12: =AM12/AS12 -> 1.1510415 | AX12: =AN12-AT12 -> 4378 | AY12: =AN12/AT12 -> 1.1527138 | AZ12: =AO12-AU12 -> -5.8004049 | BA12: =AO12/AU12 -> 0.99854926
A13: ②客数 | I13: 単位：名 | L13: ②コメント | V13: =V11-W11 -> -0.38966667 | AJ13: ピコレ&ピコレ共催 | AL13: =AL5+AL11 -> 46 | AM13: =AM5+AM11 -> 7922359 | AN13: =AN5+AN11 -> 4052 | AO13: =AM13/AN13 -> 1955.1725 | AP13: ピコレ&ピコレ共催 | AR13: =AR5+AR11 -> 23 | AS13: =AS5+AS11 -> 1489815.5 | AT13: =AT5+AT11 -> 1365 | AU13: =AS13/AT13 -> 1091.4399 | AV13: =AM13-AS13 -> 6432543.5 | AW13: =AM13/AS13 -> 5.3176781 | AX13: =AN13-AT13 -> 2687 | AY13: =AN13/AT13 -> 2.9684982 | AZ13: =AO13-AU13 -> 863.73261 | BA13: =AO13/AU13 -> 1.7913698
A14: 月 | B14: 実績 | C14: 予算 | D14: 予算比 | E14: 差異 | F14: 予測 | G14: 予測比 | H14: 差異 | I14: 1日平均 | V14: 2369 | AJ14: 総合計 | AL14: =SUM(AL5:AL11) -> 151 | AM14: =SUM(AM5:AM11) -> 139856100 | AN14: =SUM(AN5:AN11) -> 37098 | AO14: =AM14/AN14 -> 3769.9094 | AP14: 総合計 | AR14: =SUM(AR5:AR11) -> 128 | AS14: =SUM(AS5:AS11) -> 1.16111e+08 | AT14: =SUM(AT5:AT11) -> 30033 | AU14: =AS14/AT14 -> 3866.1139 | AV14: =AM14-AS14 -> 23745103 | AW14: =AM14/AS14 -> 1.2045035 | AX14: =AN14-AT14 -> 7065 | AY14: =AN14/AT14 -> 1.2352412 | AZ14: =AO14-AU14 -> -96.204421 | BA14: =AO14/AU14 -> 0.97511599
A15: 4 | B15: 379 | C15: 200 | D15: =B15/C15 -> 1.895 | E15: =B15-C15 -> 179 | F15: 395 | G15: =B15/F15 -> 0.95949367 | H15: =B15-F15 -> -16 | I15: =B15/T15 -> 75.8 | T15: 5
A16: 5 | B16: =133+1236+223+278+120 -> 1990 | C16: 520 | D16: =B16/C16 -> 3.8269231 | E16: =B16-C16 -> 1470 | F16: 372 | G16: =B16/F16 -> 5.3494624 | H16: =B16-F16 -> 1618 | I16: =B16/T16 -> #DIV/0! | V16: 133
A17: 6 | B17: 5174 | C17: 7000 | D17: =B17/C17 -> 0.73914286 | E17: =B17-C17 -> -1826 | F17: 5558 | G17: =B17/F17 -> 0.9309104 | H17: =B17-F17 -> -384 | I17: =B17/T17 -> 172.46667 | T17: 30 | V17: =V14-V16 -> 2236
A18: 7 | B18: 11438 | C18: 13000 | D18: =B18/C18 -> 0.87984615 | E18: =B18-C18 -> -1562 | F18: 12016 | G18: =B18/F18 -> 0.95189747 | H18: =B18-F18 -> -578 | I18: =B18/T18 -> 368.96774 | T18: 31
A19: 8 | B19: 13891 | C19: 12500 | D19: =B19/C19 -> 1.11128 | E19: =B19-C19 -> 1391 | F19: 12386 | G19: =B19/F19 -> 1.1215082 | H19: =B19-F19 -> 1505 | I19: =B19/T19 -> 448.09677 | T19: 31
A20: 9 | B20: 3458 | C20: 2000 | D20: =B20/C20 -> 1.729 | E20: =B20-C20 -> 1458 | F20: 1976 | G20: =B20/F20 -> 1.75 | H20: =B20-F20 -> 1482 | I20: =B20/T20 -> #DIV/0!
A21: 10 | B21: 538 | C21: 350 | D21: =B21/C21 -> 1.5371429 | E21: =B21-C21 -> 188 | F21: 194 | G21: =B21/F21 -> 2.7731959 | H21: =B21-F21 -> 344 | I21: =B21/T21 -> 179.33333 | T21: 3
A22: TOTAL | B22: =SUM(B15:B21) -> 36868 | C22: =SUM(C15:C21) -> 35570 | D22: =B22/C22 -> 1.0364914 | E22: =B22-C22 -> 1298 | F22: =SUM(F15:F21) -> 32897 | G22: =B22/F22 -> 1.1207101 | H22: =B22-F22 -> 3971 | I22: =B22/T22 -> 368.68 | T22: 100
A24: ③-1 客単価 | I24: 単位：円 | L24: ③コメント
A25: 月 | B25: 実績 | C25: 予算 | D25: 予算比 | E25: 差異 | F25: 予測 | G25: 予測比 | H25: 差異
A26: 4 | B26: =B4/B15 -> 1317.2216 | C26: 1300 | D26: =B26/C26 -> 1.0132474 | E26: =B26-C26 -> 17.221636 | F26: =F4/F15 -> 658.22785 | G26: =B26/F26 -> 2.0011636 | H26: =B26-F26 -> 658.99379
A27: 5 | B27: =B5/B16 -> 1466.907 | C27: 3500 | D27: =B27/C27 -> 0.4191163 | E27: =B27-C27 -> -2033.093 | F27: =F5/F16 -> 4976.3441 | G27: =B27/F27 -> 0.29477605 | H27: =B27-F27 -> -3509.4371
A28: 6 | B28: =B6/B17 -> 3709.7866 | C28: 3600 | D28: =B28/C28 -> 1.0304963 | E28: =B28-C28 -> 109.78663 | F28: =F6/F17 -> 3958.2584 | G28: =B28/F28 -> 0.937227 | H28: =B28-F28 -> -248.47174
A29: 7 | B29: =B7/B18 -> 4162.7334 | C29: 3900 | D29: =B29/C29 -> 1.0673675 | E29: =B29-C29 -> 262.73343 | F29: =F7/F18 -> 4161.1185 | G29: =B29/F29 -> 1.0003881 | H29: =B29-F29 -> 1.6149238
A30: 8 | B30: =B8/B19 -> 4022.387 | C30: 3900 | D30: =B30/C30 -> 1.0313813 | E30: =B30-C30 -> 122.38701 | F30: =F8/F19 -> 4036.8158 | G30: =B30/F30 -> 0.99642571 | H30: =B30-F30 -> -14.428747
A31: 9 | B31: =B9/B20 -> 3571.6677 | C31: 3500 | D31: =B31/C31 -> 1.0204765 | E31: =B31-C31 -> 71.667727 | F31: =F9/F20 -> 4048.583 | G31: =B31/F31 -> 0.88220193 | H31: =B31-F31 -> -476.91527
A32: 10 | B32: =B10/B21 -> 2703.1933 | C32: 1300 | D32: =B32/C32 -> 2.0793795 | E32: =B32-C32 -> 1403.1933 | F32: =F10/F21 -> 3570.7577 | G32: =B32/F32 -> 0.75703632 | H32: =B32-F32 -> -867.56442
A33: TOTAL | B33: =B11/B22 -> 3794.7889 | C33: =C11/C22 -> 3833.7419 | D33: =B33/C33 -> 0.98983942 | E33: =B33-C33 -> -38.953049 | F33: =F11/F22 -> 4036.9616 | G33: =B33/F33 -> 0.94001113 | H33: =B33-F33 -> -242.17277
A35: ③-2 プラン出卓数と月別プラン利用率
A36: 月 | B36: 客数 | C36: 5,500プラン | D36: 利用率 | E36: 6,600プラン | F36: 利用率 | G36: 8,800プラン | H36: 利用率 | I36: 小計
A37: 4 | B37: 379 | C37: 0 | D37: =C37/B37 -> 0 | E37: 0 | F37: =E37/B37 -> 0 | G37: 0 | H37: =G37/B37 -> 0 | I37: =C37+E37+G37 -> 0
A38: 5 | B38: =133+1236+223+278+120 -> 1990 | C38: 59 | D38: =C38/B38 -> 0.029648241 | E38: 0 | F38: =E38/B38 -> 0 | G38: 4 | H38: =G38/B38 -> 0.0020100503 | I38: =C38+E38+G38 -> 63
A39: 6 | B39: 5174 | C39: 2281 | D39: =C39/B39 -> 0.44085814 | E39: 58 | F39: =E39/B39 -> 0.011209896 | G39: 17 | H39: =G39/B39 -> 0.0032856591 | I39: =C39+E39+G39 -> 2356
A40: 7 | B40: 11438 | C40: 5791 | D40: =C40/B40 -> 0.50629481 | E40: 226 | F40: =E40/B40 -> 0.019758699 | G40: 167 | H40: =G40/B40 -> 0.014600455 | I40: =C40+E40+G40 -> 6184
A41: 8 | B41: 13891 | C41: 6305 | D41: =C41/B41 -> 0.45389101 | E41: 397 | F41: =E41/B41 -> 0.028579656 | G41: 140 | H41: =G41/B41 -> 0.010078468 | I41: =C41+E41+G41 -> 6842
A42: 9 | B42: 3458 | C42: 863 | D42: =C42/B42 -> 0.24956622 | E42: 37 | F42: =E42/B42 -> 0.010699826 | G42: 2 | H42: =G42/B42 -> 0.000578369 | I42: =C42+E42+G42 -> 902
...

Sheet 2023レビュー
A1: 【R5 さっぽろテレビ塔ビアガーデン振り返り】
A2: ①売上 | I2: 単位：円 | J2: 平均気温 | L2: ①コメント
A3: 月 | B3: 実績 | C3: 予算 | D3: 予算比 | E3: 差異 | F3: 予測 | G3: 予測比 | H3: 差異 | I3: 1日平均売上 | J3: LOW | K3: HIGH | L3: 売上については左記の通り、対予算123.9％にて終了いたしました。コロナ禍前の2019年と比較しても対比125.4％（+22,223千円）の結果となりました。これまで1億円の大台に達したことはなかったということです。その大きな要因としてはスタッフの頑張りはもちろんですが、やはり史上稀に見る猛暑となったことが挙げられます。特に6月と8月は気象庁の観測史上最高値を記録し、7月においても史上2番目の平均気温となりました。ただ、天候要因については影響値として一定の条件下で記録していかなければならないもので、いかにこの天候要因を限定的にできるか？というのが引き続きの課題となります。※各月に天候要因を数値化したものを載せています。次年度へ向け今年度のデータを活かし、テーブル配置・スタッフアサインメント・予約システム再構築・RPA/DX 促進・メニューラインナップの見直し等により、さらにポテンシャルを引き出し売上を積み上げられると認識しています。
A4: 5 | B4: 1795227.3 | C4: 6890000 | D4: =B4/C4 -> 0.26055548 | E4: =B4-C4 -> -5094772.7 | F4: 1963000 | G4: =B4/F4 -> 0.91453249 | H4: =B4-F4 -> -167772.73 | I4: =B4/T4 -> 359045.45 | T4: 5
A5: 6 | B5: 19049727 | C5: 25440000 | D5: =B5/C5 -> 0.74881003 | E5: =B5-C5 -> -6390272.7 | F5: 17338000 | G5: =B5/F5 -> 1.0987269 | H5: =B5-F5 -> 1711727.3 | I5: =B5/T5 -> 634990.91 | J5: 12.7℃ | K5: 20.0℃ | T5: 30
A6: 7 | B6: 44856909 | C6: 25440000 | D6: =B6/C6 -> 1.7632433 | E6: =B6-C6 -> 19416909 | F6: 35016000 | G6: =B6/F6 -> 1.2810404 | H6: =B6-F6 -> 9840909.1 | I6: =B6/T6 -> 1446997.1 | J6: 15.6℃ | K6: 24.1℃ | T6: 31
A7: 8 | B7: 44863045 | C7: 25440000 | D7: =B7/C7 -> 1.7634845 | E7: =B7-C7 -> 19423045 | F7: 39760000 | G7: =B7/F7 -> 1.1283462 | H7: =B7-F7 -> 5103045.5 | I7: =B7/T7 -> 1447195 | J7: 21.0℃ | K7: 27.8℃ | T7: 31
A8: 9 | B8: 4058727.3 | C8: 9275000 | D8: =B8/C8 -> 0.43759863 | E8: =B8-C8 -> -5216272.7 | F8: 4300000 | G8: =B8/F8 -> 0.94389006 | H8: =B8-F8 -> -241272.73 | I8: =B8/T8 -> 1352909.1 | J8: 24.0℃ | K8: 30.9℃ | T8: 3
A9: TOTAL | B9: =SUM(B4:B8) -> 1.1462364e+08 | C9: =SUM(C4:C8) -> 92485000 | D9: =B9/C9 -> 1.2393754 | E9: =B9-C9 -> 22138636 | F9: =SUM(F4:F8) -> 98377000 | G9: =B9/F9 -> 1.1651467 | H9: =B9-F9 -> 16246636 | I9: =B9/T9 -> 1146236.4 | J9: 21.4℃ | K9: 28.6℃ | T9: 100
A11: ②客数 | I11: 単位：名 | L11: ②コメント
A12: 月 | B12: 実績 | C12: 予算 | D12: 予算比 | E12: 差異 | F12: 予測 | G12: 予測比 | H12: 差異 | I12: 1日平均 | L12: 入客実績は左記の通りです。7/21（金）から8/16（土）の間で開催された大通りビアガーデン期間中も1日平均405名の入客となり、客数減少懸念は杞憂となりました。過去開催の数値によると盆明けは下降線を辿るはずでしたが、①にもある通り観測史上最高の平均気温となったことやチケットの駆け込み利用もあり、勢いを保ったまま最終日まで賑わいが続きました。シーズン設定をして6月末までは20:30クローズ、7月1日〜は21:30クローズとしたことは大きな成果に繋がったと考えています。7/22（土）が717名の来場とピーク、また、この週（7月第4週・通期では第9週）が最大の売上・入客となりました。次年度は予約システムをさらに活用し、入客を引き上げたいと考えています。
A13: 5 | B13: 506 | C13: 1300 | D13: =B13/C13 -> 0.38923077 | E13: =B13-C13 -> -794 | F13: 395 | G13: =B13/F13 -> 1.2810127 | H13: =B13-F13 -> 111 | I13: =B13/T13 -> 101.2 | T13: 5
A14: 6 | B14: 5309 | C14: 4800 | D14: =B14/C14 -> 1.1060417 | E14: =B14-C14 -> 509 | F14: 3450 | G14: =B14/F14 -> 1.5388406 | H14: =B14-F14 -> 1859 | I14: =B14/T14 -> 176.96667 | T14: 30
A15: 7 | B15: 11036 | C15: 4800 | D15: =B15/C15 -> 2.2991667 | E15: =B15-C15 -> 6236 | F15: 7050 | G15: =B15/F15 -> 1.5653901 | H15: =B15-F15 -> 3986 | I15: =B15/T15 -> 356 | T15: 31
A16: 8 | B16: 11093 | C16: 4800 | D16: =B16/C16 -> 2.3110417 | E16: =B16-C16 -> 6293 | F16: 8100 | G16: =B16/F16 -> 1.3695062 | H16: =B16-F16 -> 2993 | I16: =B16/T16 -> 357.83871 | T16: 31
A17: 9 | B17: 974 | C17: 1750 | D17: =B17/C17 -> 0.55657143 | E17: =B17-C17 -> -776 | F17: 880 | G17: =B17/F17 -> 1.1068182 | H17: =B17-F17 -> 94 | I17: =B17/T17 -> 324.66667 | T17: 3
A18: TOTAL | B18: =SUM(B13:B17) -> 28918 | C18: =SUM(C13:C17) -> 17450 | D18: =B18/C18 -> 1.657192 | E18: =B18-C18 -> 11468 | F18: =SUM(F13:F17) -> 19875 | G18: =B18/F18 -> 1.4549937 | H18: =B18-F18 -> 9043 | I18: =B18/T18 -> 289.18 | T18: 100
A20: ③-1 客単価 | I20: 単位：円 | L20: ③コメント
A21: 月 | B21: 実績 | C21: 予算 | D21: 予算比 | E21: 差異 | F21: 予測 | G21: 予測比 | H21: 差異 | L21: 通期での客単価は3,964円にて着地いたしました。予算設定時点では80%がプラン利用を想定しての数値でしたので、予算値からはマイナスとなっています。最終的にプラン利用率は53.6%となり、アラカルト（単品）利用率を上回りました。左記データから読み取れるのは、とてもシンプルですが、パッサージュ（フリー入客）利用率が高いと客単価が下がるという事実と、予約数を高めることにより客単価が伸びるという事実です。このことから、次年度は今回25％程であった予約利用率を35％程度まで引き上げることで、いわゆる「値上げ」の必要がなく、客単価と入客の天秤関係を限定的にしながら、【入客を高めつつ客単価も引き上げることができる】という伸び代を確認することができました。また今回はテーブルチェックを導入し、専用LPと紐付けして予約受注を行ったことにより、約83%の方がWebから予約をしてくださいました。これまでの開催は全て電話予約で対応し紙台帳管理をしていたという課題を、予約システム導入によって解決できた大きな成果と認められます。現地オペレーションとの連携を高めていけば、まだまだこうしたシステムを活かすことができます。今年度実績を基にし、人員発注と人員配置、予約システムの強みをさらに引き出しての予約受注強化（相性が良いと見られるLINE/L-STEPの活用など）や、天候要件の影響値を最小化（※悪天候時でも当日キャンセルは2割に満たない）していくことで、次年度は客席拡大、スタッフ増員に強気で臨むことができます。設備を含めて改善しつつ、さらに客単価を10％程度引き上げることで、売上も今年度の1日平均114万円から130万円（合計1億3,000万円）までは伸ばすことができると確信しています。
A22: 5 | B22: =B4/B13 -> 3547.88 | C22: 5300 | D22: =B22/C22 -> 0.66941132 | E22: =B22-C22 -> -1752.12 | F22: 4970 | G22: =B22/F22 -> 0.71385915 | H22: =B22-F22 -> -1422.12
A23: 6 | B23: =B5/B14 -> 3588.195 | C23: 5300 | D23: =B23/C23 -> 0.67701793 | E23: =B23-C23 -> -1711.805 | F23: 5026 | G23: =B23/F23 -> 0.71392658 | H23: =B23-F23 -> -1437.805
A24: 7 | B24: =B6/B15 -> 4064.5985 | C24: 5300 | D24: =B24/C24 -> 0.76690538 | E24: =B24-C24 -> -1235.4015 | F24: 4967 | G24: =B24/F24 -> 0.81832062 | H24: =B24-F24 -> -902.4015
A25: 8 | B25: =B7/B16 -> 4044.2662 | C25: 5300 | D25: =B25/C25 -> 0.7630691 | E25: =B25-C25 -> -1255.7338 | F25: 4909 | G25: =B25/F25 -> 0.82384727 | H25: =B25-F25 -> -864.73376
A26: 9 | B26: =B8/B17 -> 4167.0711 | C26: 5300 | D26: =B26/C26 -> 0.78623983 | E26: =B26-C26 -> -1132.9289 | F26: 4886 | G26: =B26/F26 -> 0.85285942 | H26: =B26-F26 -> -718.92888
A27: TOTAL | B27: =B9/B18 -> 3963.747 | C27: =C9/C18 -> 5300 | D27: =B27/C27 -> 0.7478768 | E27: =B27-C27 -> -1336.253 | F27: =F9/F18 -> 4949.7862 | G27: =B27/F27 -> 0.80079157 | H27: =B27-F27 -> -986.03914
A29: ③-2 プラン出卓数と月別プラン利用率
A30: 月 | B30: 客数 | C30: 5,500プラン | D30: 利用率 | E30: 6,600プラン | F30: 利用率 | G30: 8,800プラン | H30: 利用率 | I30: 小計
A31: 5 | B31: 506 | C31: 205 | D31: =C31/B31 -> 0.40513834 | E31: 7 | F31: =E31/B31 -> 0.013833992 | G31: 2 | H31: =G31/B31 -> 0.0039525692 | I31: =C31+E31+G31 -> 214
A32: 6 | B32: 5309 | C32: 2074 | D32: =C32/B32 -> 0.39065737 | E32: 80 | F32: =E32/B32 -> 0.015068751 | G32: 9 | H32: =G32/B32 -> 0.0016952345 | I32: =C32+E32+G32 -> 2163
A33: 7 | B33: 11036 | C33: 5792 | D33: =C33/B33 -> 0.52482784 | E33: 190 | F33: =E33/B33 -> 0.017216383 | G33: 161 | H33: =G33/B33 -> 0.014588619 | I33: =C33+E33+G33 -> 6143
A34: 8 | B34: 11093 | C34: 5149 | D34: =C34/B34 -> 0.46416659 | E34: 271 | F34: =E34/B34 -> 0.024429821 | G34: 77 | H34: =G34/B34 -> 0.0069413143 | I34: =C34+E34+G34 -> 5497
A35: 9 | B35: 974 | C35: 314 | D35: =C35/B35 -> 0.32238193 | E35: 34 | F35: =E35/B35 -> 0.034907598 | G35: 9 | H35: =G35/B35 -> 0.0092402464 | I35: =C35+E35+G35 -> 357
A36: TOTAL | B36: =SUM(B31:B35) -> 28918 | C36: =SUM(C31:C35) -> 13534 | D36: =C36/B36 -> 0.468013 | E36: =SUM(E31:E35) -> 582 | F36: =E36/B36 -> 0.020125873 | G36: =SUM(G31:G35) -> 258 | H36: =G36/B36 -> 0.0089217788 | I36: =C36+E36+G36 -> 14374
A37: 月 | B37: 客数 | C37: チケットプラン | D37: 利用率 | E37: プラン合計 | F37: 利用率 | G37: アラカルト利用 | H37: 利用率
A38: 5 | B38: 506 | C38: 0 | D38: =C38/B38 -> 0 | E38: =C38+I31 -> 214 | F38: =E38/B38 -> 0.4229249 | G38: =B38-E38 -> 292 | H38: =G38/B38 -> 0.5770751 | L38: ④memo
A39: 6 | B39: 5309 | C39: 0 | D39: =C39/B39 -> 0 | E39: =C39+I32 -> 2163 | F39: =E39/B39 -> 0.40742136 | G39: =B39-E39 -> 3146 | H39: =G39/B39 -> 0.59257864 | L39: 設備・備品課題※情報共有前 ◆英字メニュー ◆テーブル番号札（視認性・会計） ◆会計カード（プラスチック札）の作成 ◆会計の仕方がわからない ◆キャッシュレス決済が行えることの告知 ◆エクスキューズ（場内案内・トイレ・会計方法など） ◆飲み放題と単品オーダーの判別がつきづらい ◆床清掃の定期スケジュールと不定期実施のオペレーション ◆ワインの利用方法と場所 ◆ワインコーナーにローズマリーのプランター設置 ◆イベント開催 ◆キャッシャー増設検討 ◆ジョッキのサイズ ◆グラス洗浄マシンとの相性 ◆鍋洗い機（高圧洗浄機）の複数洗浄機導入 ◆Wi-Fi環境 ◆問い合わせ専用電話の設置
A40: 7 | B40: 11036 | C40: 107 | D40: =C40/B40 -> 0.0096955419 | E40: =C40+I33 -> 6250 | F40: =E40/B40 -> 0.56632838 | G40: =B40-E40 -> 4786 | H40: =G40/B40 -> 0.43367162
A41: 8 | B41: 11093 | C41: 765 | D41: =C41/B41 -> 0.068962409 | E41: =C41+I34 -> 6262 | F41: =E41/B41 -> 0.56450014 | G41: =B41-E41 -> 4831 | H41: =G41/B41 -> 0.43549986
A42: 9 | B42: 974 | C42: 240 | D42: =C42/B42 -> 0.24640657 | E42: =C42+I35 -> 597 | F42: =E42/B42 -> 0.61293634 | G42: =B42-E42 -> 377 | H42: =G42/B42 -> 0.38706366
A43: TOTAL | B43: =SUM(B38:B42) -> 28918 | C43: =SUM(C38:C42) -> 1112 | D43: =C43/B43 -> 0.038453558 | E43: =SUM(E38:E42) -> 15486 | F43: =E43/B43 -> 0.53551421 | G43: =SUM(G38:G42) -> 13432 | H43: =G43/B43 -> 0.46448579
...

Sheet 天候指数対比
B2: 4月 天候指数対比 <気象庁資料マクロクリマ> | F2: 平均気温 最高 15.7℃ （13.5℃）最低 6.5℃（5.5℃） カッコ内は前年値 <M-4th> | P2: 8月 天候指数対比 <現地ミクロクリマ> | T2: 平均気温 最高 28.4℃ （30.9℃）最低 22.0℃（24.0℃） カッコ内は前年値 <M-1st>
B3: 天候状況 | E3: ポイント | F3: 2024日数＊3 | G3: 2024合計 | H3: 比率 | I3: 2023日数＊3 | J3: 2023合計 | K3: 比率 | L3: 前年差異 | P3: 天候状況 | S3: ポイント | T3: 2024日数＊3 | U3: 2024合計 | V3: 比率 | W3: 2023日数＊3 | X3: 2023合計 | Y3: 比率 | Z3: 前年差異
B4: ポジティブ | C4: 晴れ（33度まで） | E4: 5 | F4: 0 | G4: =E4*F4 -> 0 | H4: =(F4+F5+F6)/F10 -> #DIV/0! | I4: 0 | J4: =E4*I4 -> 0 | K4: =(I4+I5+I6)/I10 -> #DIV/0! | L4: =F4-I4 -> 0 | M4: =G4-J4 -> 0 | N4: =H4-K4 -> #DIV/0! | P4: ポジティブ | Q4: 晴れ（33度まで） | S4: 5 | T4: 27 | U4: =S4*T4 -> 135 | V4: =(T4+T5+T6)/T10 -> 0.69892473 | W4: 31 | X4: =S4*W4 -> 155 | Y4: =(W4+W5+W6)/W10 -> 0.82795699 | Z4: =T4-W4 -> -4 | AA4: =U4-X4 -> -20 | AB4: =V4-Y4 -> -0.12903226
C5: 晴れ（25度以下） | E5: 4 | F5: 0 | G5: =E5*F5 -> 0 | I5: 0 | J5: =E5*I5 -> 0 | L5: =F5-I5 -> 0 | M5: =G5-J5 -> 0 | Q5: 晴れ（25度以下） | S5: 4 | T5: 0 | U5: =S5*T5 -> 0 | W5: 6 | X5: =S5*W5 -> 24 | Z5: =T5-W5 -> -6 | AA5: =U5-X5 -> -24
C6: 晴れ（33度以上15以下） 曇25度以上 | E6: 3 | F6: 0 | G6: =E6*F6 -> 0 | I6: 0 | J6: =E6*I6 -> 0 | L6: =F6-I6 -> 0 | M6: =G6-J6 -> 0 | Q6: 晴れ（33度以上15以下） 曇25度以上 | S6: 3 | T6: 38 | U6: =S6*T6 -> 114 | W6: 40 | X6: =S6*W6 -> 120 | Z6: =T6-W6 -> -2 | AA6: =U6-X6 -> -6
B7: ネガティブ | C7: 曇 | E7: 2 | F7: 0 | G7: =E7*F7 -> 0 | H7: =(F7+F8+F9)/F10 -> #DIV/0! | I7: 0 | J7: =E7*I7 -> 0 | K7: =(I7+I8+I9)/I10 -> #DIV/0! | L7: =F7-I7 -> 0 | M7: =G7-J7 -> 0 | N7: =H7-K7 -> #DIV/0! | P7: ネガティブ | Q7: 曇 | S7: 2 | T7: 6 | U7: =S7*T7 -> 12 | V7: =(T7+T8+T9)/T10 -> 0.30107527 | W7: 0 | X7: =S7*W7 -> 0 | Y7: =(W7+W8+W9)/W10 -> 0.17204301 | Z7: =T7-W7 -> 6 | AA7: =U7-X7 -> 12 | AB7: =V7-Y7 -> 0.12903226
C8: 雨 | E8: 1 | F8: 0 | G8: =E8*F8 -> 0 | I8: 0 | J8: =E8*I8 -> 0 | L8: =F8-I8 -> 0 | M8: =G8-J8 -> 0 | Q8: 雨 | S8: 1 | T8: 22 | U8: =S8*T8 -> 22 | W8: 16 | X8: =S8*W8 -> 16 | Z8: =T8-W8 -> 6 | AA8: =U8-X8 -> 6
C9: 豪雨・雷雨 | E9: 0 | F9: 0 | G9: =E9*F9 -> 0 | J9: =E9*I9 -> 0 | L9: =F9-I9 -> 0 | M9: =G9-J9 -> 0 | Q9: 豪雨・雷雨 | S9: 0 | T9: 0 | U9: =S9*T9 -> 0 | W9: 0 | X9: =S9*W9 -> 0 | Z9: =T9-W9 -> 0 | AA9: =U9-X9 -> 0
B10: TOTAL | F10: =SUM(F4:F9) -> 0 | G10: =SUM(G4:G9) -> 0 | H10: =H4+H7 -> #DIV/0! | I10: =SUM(I4:I9) -> 0 | J10: =SUM(J4:J9) -> 0 | K10: =K4+K7 -> #DIV/0! | L10: =SUM(L4:L9) -> 0 | M10: =SUM(M4:M9) -> 0 | N10: =G10/J10 -> #DIV/0! | P10: TOTAL | T10: =SUM(T4:T9) -> 93 | U10: =SUM(U4:U9) -> 283 | V10: =V4+V7 -> 1 | W10: =SUM(W4:W9) -> 93 | X10: =SUM(X4:X9) -> 315 | Y10: =Y4+Y7 -> 1 | Z10: =SUM(Z4:Z9) -> 0 | AA10: =SUM(AA4:AA9) -> -32 | AB10: =U10/X10 -> 0.8984127
F11: =G10/F10 -> #DIV/0! | I11: =J10/I10 -> #DIV/0! | L11: =F11-I11 -> #DIV/0! | N11: =F11/I11 -> #DIV/0! | T11: =U10/T10 -> 3.0430108 | W11: =X10/W10 -> 3.3870968 | Z11: =T11-W11 -> -0.34408602 | AB11: =T11/W11 -> 0.8984127
B13: 5月 天候指数対比 <現地ミクロクリマ> | F13: 平均気温 最高 17.0℃ （20.0℃）最低 11.6℃（12.7℃） カッコ内は前年値 <M-4th> | P13: 9月 天候指数対比 <現地ミクロクリマ> | T13: 平均気温 最高 24.0℃ （28.6℃）最低 15.6℃（21.4℃） カッコ内は前年値 <M- 2nd>
B14: 天候状況 | E14: ポイント | F14: 2024日数＊3 | G14: 2024合計 | H14: 比率 | I14: 2023日数＊3 | J14: 2023合計 | K14: 比率 | L14: 前年差異 | P14: 天候状況 | S14: ポイント | T14: 2024日数＊3 | U14: 2024合計 | V14: 比率 | W14: 2023日数＊3 | X14: 2023合計 | Y14: 比率 | Z14: 前年差異
B15: ポジティブ | C15: 晴れ（33度まで） | E15: 5 | F15: 0 | G15: =E15*F15 -> 0 | H15: =(F15+F16+F17)/F21 -> 0.066666667 | I15: 2 | J15: =E15*I15 -> 10 | K15: =(I15+I16+I17)/I21 -> 0.4 | L15: =F15-I15 -> -2 | M15: =G15-J15 -> -10 | N15: =H15-K15 -> -0.33333333 | P15: ポジティブ | Q15: 晴れ（33度まで） | S15: 5 | T15: 16 | U15: =S15*T15 -> 80 | V15: =(T15+T16+T17)/T21 -> 0.74666667 | W15: 5 | X15: =S15*W15 -> 25 | Y15: =(W15+W16+W17)/W21 -> 0.66666667 | Z15: =T15-W15 -> 11 | AA15: =U15-X15 -> 55 | AB15: =V15-Y15 -> 0.08
C16: 晴れ（25度以下） | E16: 4 | F16: 0 | G16: =E16*F16 -> 0 | I16: 4 | J16: =E16*I16 -> 16 | L16: =F16-I16 -> -4 | M16: =G16-J16 -> -16 | Q16: 晴れ（25度以下） | S16: 4 | T16: 32 | U16: =S16*T16 -> 128 | W16: 0 | X16: =S16*W16 -> 0 | Z16: =T16-W16 -> 32 | AA16: =U16-X16 -> 128
C17: 晴れ（33度以上15以下） 曇25度以上 | E17: 3 | F17: 1 | G17: =E17*F17 -> 3 | I17: 0 | J17: =E17*I17 -> 0 | L17: =F17-I17 -> 1 | M17: =G17-J17 -> 3 | Q17: 晴れ（33度以上15以下） 曇25度以上 | S17: 3 | T17: 8 | U17: =S17*T17 -> 24 | W17: 1 | X17: =S17*W17 -> 3 | Z17: =T17-W17 -> 7 | AA17: =U17-X17 -> 21
B18: ネガティブ | C18: 曇 | E18: 2 | F18: 5 | G18: =E18*F18 -> 10 | H18: =(F18+F19+F20)/F21 -> 0.93333333 | I18: 4 | J18: =E18*I18 -> 8 | K18: =(I18+I19+I20)/I21 -> 0.6 | L18: =F18-I18 -> 1 | M18: =G18-J18 -> 2 | N18: =H18-K18 -> 0.33333333 | P18: ネガティブ | Q18: 曇 | S18: 2 | T18: 15 | U18: =S18*T18 -> 30 | V18: =(T18+T19+T20)/T21 -> 0.25333333 | W18: 0 | X18: =S18*W18 -> 0 | Y18: =(W18+W19+W20)/W21 -> 0.33333333 | Z18: =T18-W18 -> 15 | AA18: =U18-X18 -> 30 | AB18: =V18-Y18 -> -0.08
C19: 雨 | E19: 1 | F19: 7 | G19: =E19*F19 -> 7 | I19: 5 | J19: =E19*I19 -> 5 | L19: =F19-I19 -> 2 | M19: =G19-J19 -> 2 | Q19: 雨 | S19: 1 | T19: 4 | U19: =S19*T19 -> 4 | W19: 3 | X19: =S19*W19 -> 3 | Z19: =T19-W19 -> 1 | AA19: =U19-X19 -> 1
C20: 豪雨・雷雨 | E20: 0 | F20: 2 | G20: =E20*F20 -> 0 | J20: =E20*I20 -> 0 | L20: =F20-I20 -> 2 | M20: =G20-J20 -> 0 | Q20: 豪雨・雷雨 | S20: 0 | T20: 0 | U20: =S20*T20 -> 0 | X20: =S20*W20 -> 0 | Z20: =T20-W20 -> 0 | AA20: =U20-X20 -> 0
B21: TOTAL | F21: =SUM(F15:F20) -> 15 | G21: =SUM(G15:G20) -> 20 | H21: =H15+H18 -> 1 | I21: =SUM(I15:I20) -> 15 | J21: =SUM(J15:J20) -> 39 | K21: =K15+K18 -> 1 | L21: =SUM(L15:L20) -> 0 | M21: =SUM(M15:M20) -> -19 | N21: =G21/J21 -> 0.51282051 | P21: TOTAL | T21: =SUM(T15:T20) -> 75 | U21: =SUM(U15:U20) -> 266 | V21: =V15+V18 -> 1 | W21: =SUM(W15:W20) -> 9 | X21: =SUM(X15:X20) -> 31 | Y21: =Y15+Y18 -> 1 | Z21: =SUM(Z15:Z20) -> 66 | AA21: =SUM(AA15:AA20) -> 235 | AB21: =U21/X21 -> 8.5806452
F22: =G21/F21 -> 1.3333333 | I22: =J21/I21 -> 2.6 | L22: =F22-I22 -> -1.2666667 | N22: =F22/I22 -> 0.51282051 | T22: =U21/T21 -> 3.5466667 | W22: =X21/W21 -> 3.4444444 | Z22: =T22-W22 -> 0.10222222 | AB22: =T22/W22 -> 1.0296774
B24: 6月 天候指数対比 <現地ミクロクリマ> | F24: 平均気温 最高 23.9℃ （24.1℃）最低 15.6℃（15.6℃） カッコ内は前年値 <M-3rd> | P24: 10月 天候指数対比 <気象庁資料マクロクリマ> | T24: 平均気温 最高 18.3℃ （17.9℃）最低 9.0℃（9.3℃） カッコ内は前年値 <M-5th>
B25: 天候状況 | E25: ポイント | F25: 2024日数＊3 | G25: 2024合計 | H25: 比率 | I25: 2023日数＊3 | J25: 2023合計 | K25: 比率 | L25: 前年差異 | P25: 天候状況 | S25: ポイント | T25: 2024日数＊3 | U25: 2024合計 | V25: 比率 | W25: 2023日数＊3 | X25: 2023合計 | Y25: 比率 | Z25: 前年差異
B26: ポジティブ | C26: 晴れ（33度まで） | E26: 5 | F26: 13 | G26: =E26*F26 -> 65 | H26: =(F26+F27+F28)/F32 -> 0.48888889 | I26: 20 | J26: =E26*I26 -> 100 | K26: =(I26+I27+I28)/I32 -> 0.71111111 | L26: =F26-I26 -> -7 | M26: =G26-J26 -> -35 | N26: =H26-K26 -> -0.22222222 | P26: ポジティブ | Q26: 晴れ（33度まで） | S26: 5 | T26: 2 | U26: =S26*T26 -> 10 | V26: =(T26+T27+T28)/T32 -> 0.38888889 | W26: 0 | X26: =S26*W26 -> 0 | Y26: =(W26+W27+W28)/W32 -> #DIV/0! | Z26: =T26-W26 -> 2 | AA26: =U26-X26 -> 10 | AB26: =V26-Y26 -> #DIV/0!
C27: 晴れ（25度以下） | E27: 4 | F27: 16 | G27: =E27*F27 -> 64 | I27: 38 | J27: =E27*I27 -> 152 | L27: =F27-I27 -> -22 | M27: =G27-J27 -> -88 | Q27: 晴れ（25度以下） | S27: 4 | T27: 5 | U27: =S27*T27 -> 20 | W27: 0 | X27: =S27*W27 -> 0 | Z27: =T27-W27 -> 5 | AA27: =U27-X27 -> 20
C28: 晴れ（33度以上15以下） 曇25度以上 | E28: 3 | F28: 15 | G28: =E28*F28 -> 45 | I28: 6 | J28: =E28*I28 -> 18 | L28: =F28-I28 -> 9 | M28: =G28-J28 -> 27 | Q28: 晴れ（33度以上15以下） 曇25度以上 | S28: 3 | T28: 0 | U28: =S28*T28 -> 0 | W28: 0 | X28: =S28*W28 -> 0 | Z28: =T28-W28 -> 0 | AA28: =U28-X28 -> 0
B29: ネガティブ | C29: 曇 | E29: 2 | F29: 30 | G29: =E29*F29 -> 60 | H29: =(F29+F30+F31)/F32 -> 0.51111111 | I29: 7 | J29: =E29*I29 -> 14 | K29: =(I29+I30+I31)/I32 -> 0.28888889 | L29: =F29-I29 -> 23 | M29: =G29-J29 -> 46 | N29: =H29-K29 -> 0.22222222 | P29: ネガティブ | Q29: 曇 | S29: 2 | T29: 8 | U29: =S29*T29 -> 16 | V29: =(T29+T30+T31)/T32 -> 0.61111111 | W29: 0 | X29: =S29*W29 -> 0 | Y29: =(W29+W30+W31)/W32 -> #DIV/0! | Z29: =T29-W29 -> 8 | AA29: =U29-X29 -> 16 | AB29: =V29-Y29 -> #DIV/0!
C30: 雨 | E30: 1 | F30: 15 | G30: =E30*F30 -> 15 | I30: 19 | J30: =E30*I30 -> 19 | L30: =F30-I30 -> -4 | M30: =G30-J30 -> -4 | Q30: 雨 | S30: 1 | T30: 3 | U30: =S30*T30 -> 3 | W30: 0 | X30: =S30*W30 -> 0 | Z30: =T30-W30 -> 3 | AA30: =U30-X30 -> 3
C31: 豪雨・雷雨 | E31: 0 | F31: 1 | G31: =E31*F31 -> 0 | I31: 0 | J31: =E31*I31 -> 0 | L31: =F31-I31 -> 1 | M31: =G31-J31 -> 0 | Q31: 豪雨・雷雨 | S31: 0 | T31: 0 | U31: =S31*T31 -> 0 | W31: 0 | X31: =S31*W31 -> 0 | Z31: =T31-W31 -> 0 | AA31: =U31-X31 -> 0
B32: TOTAL | F32: =SUM(F26:F31) -> 90 | G32: =SUM(G26:G31) -> 249 | H32: =H26+H29 -> 1 | I32: =SUM(I26:I31) -> 90 | J32: =SUM(J26:J31) -> 303 | K32: =K26+K29 -> 1 | L32: =SUM(L26:L31) -> 0 | M32: =SUM(M26:M31) -> -54 | N32: =G32/J32 -> 0.82178218 | P32: TOTAL | T32: =SUM(T26:T31) -> 18 | U32: =SUM(U26:U31) -> 49 | V32: =V26+V29 -> 1 | W32: =SUM(W26:W31) -> 0 | X32: =SUM(X26:X31) -> 0 | Y32: =Y26+Y29 -> #DIV/0! | Z32: =SUM(Z26:Z31) -> 18 | AA32: =SUM(AA26:AA31) -> 49 | AB32: =U32/X32 -> #DIV/0!
F33: =G32/F32 -> 2.7666667 | I33: =J32/I32 -> 3.3666667 | L33: =F33-I33 -> -0.6 | N33: =F33/I33 -> 0.82178218 | T33: =U32/T32 -> 2.7222222 | W33: =X32/W32 -> #DIV/0! | Z33: =T33-W33 -> #DIV/0! | AB33: =T33/W33 -> #DIV/0!
B35: 7月 天候指数対比 <現地ミクロクリマ> | F35: 平均気温 最高 28.0℃ （27.8℃）最低 20.5℃（21.0℃） カッコ内は前年値 <M-1st> | P35: TOTAL 天候指数 対比
B36: 天候状況 | E36: ポイント | F36: 2024日数＊3 | G36: 2024合計 | H36: 比率 | I36: 2023日数＊3 | J36: 2023合計 | K36: 比率 | L36: 前年差異 | P36: 天候状況 | S36: ポイント | T36: 2024日数＊3 | U36: 2024合計 | V36: 比率 | W36: 2023日数＊3 | X36: 2023合計 | Y36: 比率 | Z36: 前年差異
B37: ポジティブ | C37: 晴れ（33度まで） | E37: 5 | F37: 26 | G37: =E37*F37 -> 130 | H37: =(F37+F38+F39)/F43 -> 0.74193548 | I37: 35 | J37: =E37*I37 -> 175 | K37: =(I37+I38+I39)/I43 -> 0.79569892 | L37: =F37-I37 -> -9 | M37: =G37-J37 -> -45 | N37: =H37-K37 -> -0.053763441 | P37: ポジティブ | Q37: 晴れ（33度まで） | S37: 5 | T37: =F4+F15+F26+F37+T4+T15+T26 -> 84 | U37: =S37*T37 -> 420 | V37: =(T37+T38+T39)/T43 -> 0.63020833 | W37: =I4+I15+I26+I37+W4+W15+W26 -> 93 | X37: =S37*W37 -> 465 | Y37: =(W37+W38+W39)/W43 -> 0.75666667 | Z37: =T37-W37 -> -9 | AA37: =U37-X37 -> -45 | AB37: =V37-Y37 -> -0.12645833
C38: 晴れ（25度以下） | E38: 4 | F38: 5 | G38: =E38*F38 -> 20 | I38: 10 | J38: =E38*I38 -> 40 | L38: =F38-I38 -> -5 | M38: =G38-J38 -> -20 | Q38: 晴れ（25度以下） | S38: 4 | T38: =F5+F16+F27+F38+T5+T16+T27 -> 58 | U38: =S38*T38 -> 232 | W38: =I5+I16+I27+I38+W5+W16+W27 -> 58 | X38: =S38*W38 -> 232 | Z38: =T38-W38 -> 0 | AA38: =U38-X38 -> 0
C39: 晴れ（33度以上15以下） 曇25度以上 | E39: 3 | F39: 38 | G39: =E39*F39 -> 114 | I39: 29 | J39: =E39*I39 -> 87 | L39: =F39-I39 -> 9 | M39: =G39-J39 -> 27 | Q39: 晴れ（33度以上15以下） 曇25度以上 | S39: 3 | T39: =F6+F17+F28+F39+T6+T17+T28 -> 100 | U39: =S39*T39 -> 300 | W39: =I6+I17+I28+I39+W6+W17+W28 -> 76 | X39: =S39*W39 -> 228 | Z39: =T39-W39 -> 24 | AA39: =U39-X39 -> 72
B40: ネガティブ | C40: 曇 | E40: 2 | F40: 9 | G40: =E40*F40 -> 18 | H40: =(F40+F41+F42)/F43 -> 0.25806452 | I40: 4 | J40: =E40*I40 -> 8 | K40: =(I40+I41+I42)/I43 -> 0.20430108 | L40: =F40-I40 -> 5 | M40: =G40-J40 -> 10 | N40: =H40-K40 -> 0.053763441 | P40: ネガティブ | Q40: 曇 | S40: 2 | T40: =F7+F18+F29+F40+T7+T18+T29 -> 73 | U40: =S40*T40 -> 146 | V40: =(T40+T41+T42)/T43 -> 0.36979167 | W40: =I7+I18+I29+I40+W7+W18+W29 -> 15 | X40: =S40*W40 -> 30 | Y40: =(W40+W41+W42)/W43 -> 0.24333333 | Z40: =T40-W40 -> 58 | AA40: =U40-X40 -> 116 | AB40: =V40-Y40 -> 0.12645833
C41: 雨 | E41: 1 | F41: 15 | G41: =E41*F41 -> 15 | I41: 15 | J41: =E41*I41 -> 15 | L41: =F41-I41 -> 0 | M41: =G41-J41 -> 0 | Q41: 雨 | S41: 1 | T41: =F8+F19+F30+F41+T8+T19+T30 -> 66 | U41: =S41*T41 -> 66 | W41: =I8+I19+I30+I41+W8+W19+W30 -> 58 | X41: =S41*W41 -> 58 | Z41: =T41-W41 -> 8 | AA41: =U41-X41 -> 8
C42: 豪雨・雷雨 | E42: 0 | F42: 0 | G42: =E42*F42 -> 0 | J42: =E42*I42 -> 0 | L42: =F42-I42 -> 0 | M42: =G42-J42 -> 0 | Q42: 豪雨・雷雨 | S42: 0 | T42: =F9+F20+F31+F42+T9+T20+T31 -> 3 | U42: =S42*T42 -> 0 | W42: =I9+I20+I31+I42+W9+W20+W31 -> 0 | X42: =S42*W42 -> 0 | Z42: =T42-W42 -> 3 | AA42: =U42-X42 -> 0
B43: TOTAL | F43: =SUM(F37:F42) -> 93 | G43: =SUM(G37:G42) -> 297 | H43: =H37+H40 -> 1 | I43: =SUM(I37:I42) -> 93 | J43: =SUM(J37:J42) -> 325 | K43: =K37+K40 -> 1 | L43: =SUM(L37:L42) -> 0 | M43: =SUM(M37:M42) -> -28 | N43: =G43/J43 -> 0.91384615 | P43: TOTAL | T43: =SUM(T37:T42) -> 384 | U43: =SUM(U37:U42) -> 1164 | V43: =V37+V40 -> 1 | W43: =SUM(W37:W42) -> 300 | X43: =SUM(X37:X42) -> 1013 | Y43: =Y37+Y40 -> 1 | Z43: =SUM(Z37:Z42) -> 84 | AA43: =SUM(AA37:AA42) -> 151 | AB43: =U43/X43 -> 1.1490622
F44: =G43/F43 -> 3.1935484 | I44: =J43/I43 -> 3.4946237 | L44: =F44-I44 -> -0.30107527 | N44: =F44/I44 -> 0.91384615 | T44: =U43/T43 -> 3.03125 | W44: =X43/W43 -> 3.3766667 | Z44: =T44-W44 -> -0.34541667 | AB44: =T44/W44 -> 0.89770484

Sheet 2024計画値・予測・実績進捗
A1: ■R6年 ポップアップ ヒツジニワイン / さっぽろテレビ塔ビアガーデン売上計画（予算）・売上予測（9/8まで）・実績進捗確認表
B2: 計画値 | E2: 予測値（目標値） | K2: 実績進捗（派遣分のみ） | R2: ノヴェロさん請求内容 | Z2: 家賃 | AB2: 概算（仮置き）
A3: 月 | B3: 売上予算 | C3: 客数 | D3: 客単価 | E3: 労働時間（予測値） | F3: 人時生産性 | G3: 想定人件費 | H3: 人件費率 | I3: 売上予測 | J3: 対予算 | K3: 売上実績 | L3: 対予測 | M3: 対予算 | N3: 実労働時間 | O3: 人時生産性 | P3: 概算人件費率 | Q3: 派遣人件費（リザルト） | R3: 人件費 | S3: 営業日数 | T3: 拘束時間 | U3: 残業時間 | V3: 人件費合計 | W3: 交通費合計 | X3: 手当 | Y3: 合計 | Z3: 家賃 | AA3: 1日 | AB3: =K11 -> 1.3990628e+08
A4: 4 | B4: 260000 | C4: 200 | D4: =B4/C4 -> 1300 | E4: 200 | F4: =I4/E4 -> 1300 | G4: =E4*R4 -> #DIV/0! | H4: =G4/B4 -> #DIV/0! | I4: 260000 | J4: =I4/B4 -> 1 | K4: 499227 | L4: =K4/I4 -> 1.9201038 | M4: =K4/B4 -> 1.9201038 | N4: =T4+U4 -> 0 | O4: =K4/N4 -> #DIV/0! | P4: =Q4/K4 -> 0 | Q4: =Y4 -> 0 | R4: =Q4/N4 -> #DIV/0! | Y4: =V4+W4 -> 0 | AA4: 30000 | AB4: =AB3*23.8% -> 33297694 | AC4: 人件費 | AH4: 499227
A5: 5 | B5: 1851200 | C5: 520 | D5: =B5/C5 -> 3560 | E5: 550 | F5: =I5/E5 -> 3365.8182 | G5: =E5*R5 -> 991969.37 | H5: =G5/B5 -> 0.53585208 | I5: 1851200 | J5: =I5/B5 -> 1 | K5: 2919145 | L5: =K5/I5 -> 1.5768934 | M5: =K5/B5 -> 1.5768934 | N5: =T5+U5 -> 579.5 | O5: =K5/N5 -> 5037.3512 | P5: =Q5/K5 -> 0.35804148 | Q5: =Y5 -> 1045175 | R5: =Q5/N5 -> 1803.5807 | S5: 5 | T5: 579.5 | U5: 0 | V5: 956175 | W5: 89000 | Y5: =V5+W5+X5 -> 1045175 | AA5: 30000 | AD5: 時給＋交通費 | AH5: 2919145
A6: 6 | B6: 25690000 | C6: 7000 | D6: =B6/C6 -> 3670 | E6: 4500 | F6: =I6/E6 -> 4888.8889 | G6: =E6*R6 -> 8136786.5 | H6: =G6/B6 -> 0.31672972 | I6: 22000000 | J6: =I6/B6 -> 0.85636434 | K6: ='2024.6月実績'!O93 -> 19194436 | L6: =K6/I6 -> 0.87247438 | M6: =K6/B6 -> 0.74715595 | N6: =T6+U6 -> 3587.5 | O6: =K6/N6 -> 5350.3655 | P6: =Q6/K6 -> 0.3379535 | Q6: =Y6 -> 6486827 | R6: =Q6/N6 -> 1808.1748 | S6: 30 | T6: 3580.5 | U6: 7 | V6: 5939877 | W6: 545000 | X6: 1950 | Y6: =V6+W6+X6 -> 6486827 | AA6: 75000 | AD6: Timee | AF6: Forking | AM6: 157
A7: 7 | B7: 51610000 | C7: 13000 | D7: =B7/C7 -> 3970 | E7: 5600 | F7: =I7/E7 -> 8928.5714 | G7: =E7*R7 -> 9577580.9 | H7: =G7/B7 -> 0.18557607 | I7: 50000000 | J7: =I7/B7 -> 0.9688045 | K7: ='2024.7月実績'!L93 -> 47613345 | L7: =K7/I7 -> 0.95226691 | M7: =K7/B7 -> 0.92256046 | N7: =T7+AD7+AF7+U7 -> 5099.25 | O7: =K7/N7 -> 9337.3232 | P7: =Q7/K7 -> 0.18316623 | Q7: =AH7 -> 8721157 | R7: =Q7/N7 -> 1710.2823 | S7: 31 | T7: 4084.25 | U7: 32 | V7: 7019597 | W7: 583000 | X7: 13738 | Y7: =V7+W7+X7 -> 7616335 | AA7: 100000 | AB7: =AB3*31.5% -> 44070477 | AC7: 材料費 | AD7: 335 | AE7: 391038 | AF7: 648 | AG7: 713784 | AH7: =Y7+AE7+AG7 -> 8721157
A8: 8 | B8: 49500000 | C8: 12500 | D8: =B8/C8 -> 3960 | E8: 5600 | F8: =I8/E8 -> 8928.5714 | G8: =E8*R8 -> 9756392.1 | H8: =G8/B8 -> 0.19709883 | I8: 50000000 | J8: =I8/B8 -> 1.010101 | K8: ='2024.8月実績'!M93 -> 55874978 | L8: =K8/I8 -> 1.1174996 | M8: =K8/B8 -> 1.1287874 | N8: =T8+U8+AD8+AF8 -> 5407 | O8: =K8/N8 -> 10333.822 | P8: =Q8/K8 -> 0.16859326 | Q8: =AH8 -> 9420145 | R8: =Q8/N8 -> 1742.2129 | S8: 31 | T8: 4444 | U8: 39 | V8: 7728270 | W8: 633000 | X8: 11262 | Y8: =V8+W8+X8 -> 8372532 | AA8: 100000 | AB8: =AB3*7% -> 9793439.4 | AC8: 消耗品費 | AD8: 48 | AE8: 52747 | AF8: 876 | AG8: 994866 | AH8: =Y8+AE8+AG8 -> 9420145
A9: 9 | B9: 7000000 | C9: 2000 | D9: =B9/C9 -> 3500 | E9: 1400 | F9: =I9/E9 -> 5714.2857 | G9: =E9*R9 -> 2660000 | H9: =G9/B9 -> 0.38 | I9: 8000000 | J9: =I9/B9 -> 1.1428571 | K9: ='2024.9月実績'!L93 -> 12350827 | L9: =K9/I9 -> 1.5438534 | M9: =K9/B9 -> 1.7644039 | N9: =T9+U9 -> 1065 | O9: =K9/N9 -> 11597.021 | P9: =Q9/K9 -> 0.2531934 | Q9: =AH9 -> 3127148 | R9: 1900 | S9: 8 | T9: 1063 | U9: 2 | V9: 1866106 | W9: 150000 | X9: 1350 | Y9: =V9+W9+X9 -> 2017456 | AA9: 30000 | AB9: 25266300 | AC9: イニシャル | AE9: =51100+5700 -> 56800 | AG9: 1052892 | AH9: =Y9+AE9+AG9 -> 3127148 | AJ9: 17040
A10: 10 | B10: 455000 | C10: 350 | D10: =B10/C10 -> 1300 | E10: 100 | F10: =I10/E10 -> #REF! | G10: =E10*R10 -> 190000 | H10: =G10/B10 -> 0.41758242 | I10: ='2024.10月実績'!#REF! -> #REF! | J10: =I10/B10 -> #REF! | K10: ='2024.10月実績'!L93 -> 1454318.2 | L10: =K10/I10 -> #REF! | M10: =K10/B10 -> 3.1963037 | N10: =T10+U10 -> 0 | O10: =K10/N10 -> #DIV/0! | P10: =Q10/K10 -> 0 | Q10: =Y10 -> 0 | R10: 1900 | Y10: =V10+W10 -> 0 | AA10: 30000 | AB10: 14000000 | AC10: 家賃 | AG10: 408303 | AI10: 業務委託＆スキマ人件費費用圧縮対策
A11: TOTAL | B11: =SUM(B4:B10) -> 136366200 | C11: =SUM(C4:C10) -> 35570 | D11: =B11/C11 -> 3833.7419 | E11: =SUM(E4:E10) -> 17950 | F11: =I11/E11 -> #REF! | G11: =E11*R11 -> 32847878 | H11: =G11/B11 -> 0.24087991 | I11: =SUM(I4:I10) -> #REF! | J11: =I11/B11 -> #REF! | K11: =SUM(K4:K10) -> 1.3990628e+08 | L11: =K11/I11 -> #REF! | M11: =K11/B11 -> 1.0259601 | N11: =SUM(N4:N10) -> 15738.25 | O11: =K11/N11 -> 8889.5702 | P11: =Q11/K11 -> 0.20585532 | Q11: =SUM(Q4:Q10) -> 28800452 | R11: =Q11/N11 -> 1829.9653 | S11: =SUM(S4:S10) -> 105 | T11: =SUM(T4:T10) -> 13751.25 | U11: =SUM(U4:U10) -> 80 | V11: =SUM(V4:V10) -> 23510025 | W11: =SUM(W4:W10) -> 2000000 | Y11: =SUM(Y4:Y10) -> 25538325 | Z11: =SUM(Z4:Z10) -> 0 | AA11: =SUM(AA4:AA10) -> 395000 | AB11: =AB3*5% -> 6995313.9 | AC11: 流動固定費 | AE11: =SUM(AE7:AE10) -> 500585 | AG11: =SUM(AG7:AG10) -> 3169845 | AI11: =AE11+AG11 -> 3670430 | AJ11: =AI11/AI13 -> 0.11303758 | AK11: =AI11/AL11 -> 2251.7975 | AL11: 1630 | AM11: =AK11/AK13 -> 0.12517081 | AN11: 5000 | AO11: 1650 | AP11: =AN11*AO11 -> 8250000 | AQ11: =AN11/AN13 -> 0.2792984 | AR11: =AP11/AP13 -> 0.25380117
B12: 136366200 | C12: 提出予算 | I12: ※天気要因見込まず算出 | K12: 44109 | L12: 終了時点の進捗状況 | N12: =K11/S12 -> 1399062.8 | O12: =K11-B12 -> 3540077.5 | P12: =K11/B12 -> 1.0259601 | Q12: =Q11/K11 -> 0.20585532 | S12: 100 | Y12: =Y11/K11 -> 0.18253881 | AB12: =AB3-AB4-AB7-AB8-AB9-AB10-AB11 -> 6483052.7 | AC12: 利益 | AI12: =Q11 -> 28800452 | AJ12: =AI12/AI13 -> 0.88696242 | AK12: 15738 | AL12: =AI12/AK12 -> 1829.9944 | AM12: =AK12/AK13 -> 0.87482919 | AN12: 12902 | AO12: 1880 | AP12: =AN12*AO12 -> 24255760 | AQ12: =AN12/AN13 -> 0.7207016 | AR12: =AP12/AP13 -> 0.74619883
B13: =B11-B12 -> 0 | C13: 差異 | AG13: 140800000 | AI13: =SUM(AI11:AI12) -> 32470882 | AJ13: =AI13/AG13 -> 0.23061706 | AK13: =SUM(AK11:AK12) -> 17989.798 | AL13: =(AL11+AL12)/2 -> 1729.9972 | AN13: =SUM(AN11:AN12) -> 17902 | AO13: =(AO11+AO12)/2 -> 1765 | AP13: =SUM(AP11:AP12) -> 32505760
I16: 100000000 | J16: 予算まで | K16: =B11-K11 -> -3540077.5 | L16: 12 | M16: =K16/L16 -> -295006.45 | N16: 2019 | O16: 58190982 | P16: =K11/O16 -> 2.4042605 | V16: 税込
B17: =B7+B8 -> 101110000 | C17: =K7+K8 -> 1.0348832e+08 | D17: =C17-B17 -> 2378323.6 | I17: 111111111 | J17: 予測まで | K17: =I11-K11 -> #REF! | L17: 12 | M17: =K17/L17 -> #REF! | N17: 2018 | O17: 44179221 | P17: =K11/O17 -> 3.1667891 | U17: 5 | V17: 1149692
J18: 一億円まで | K18: =I16-K11 -> -39906277 | L18: 12 | M18: =K18/L18 -> -3325523.1 | N18: 平均 | O18: =(O16+O17)/2 -> 51185102 | P18: =K11/O18 -> 2.7333398 | U18: 6 | V18: 7135509
G19: 2019年度 | J19: 一億一千万まで | K19: =I17-K11 -> -28795166 | L19: 12 | M19: =K19/L19 -> -2399597.2 | U19: 7 | V19: 8381268
G20: 91399704 | H20: =K8-K9 -> 43524151 | I20: 945247 | J20: =I20-H20 -> -42578904 | K20: =K11 -> 1.3990628e+08 | L20: =K20/G20 -> 1.5307082 | M20: =K20-G20 -> 48506573 | U20: 8 | V20: 9209785
U21: 9 | V21: 2219201
V22: =SUM(V17:V21) -> 28095455
I23: 115000000 | K23: =K11 -> 1.3990628e+08 | L23: =K23/I23 -> 1.2165763 | N23: =K23*1.1 -> 1.5389691e+08
M24: 150000000 | N24: =M24*10/110 -> 13636364 | O24: =M24-N24 -> 1.3636364e+08 | P24: =K11-O24 -> 3542641.1
A25: ■大通りビアガーデン2024 実績
A26: 推計 | B26: 2019 | C26: ー | D26: 2023 | E26: 2024 | F26: 2006 | H26: 2019 | I26: =G20 -> 91399704 | J26: =K11/I26 -> 1.5307082 | K26: =K11-I26 -> 48506573
A27: 来場者数 | B27: 1170000 | D27: 886000 | E27: 902000 | F27: 1523000 | H27: 2023 | I27: 114623699 | J27: =K11/I27 -> 1.2205703 | K27: =K11-I27 -> 25282578 | L27: 5187 | M27: 6717 | N27: =M27-L27 -> 1530 | O27: =M27/L27 -> 1.2949682
A28: 前年比 | B28: - | D28: 75.8 | E28: 101.8 | F28: =F27/E27 -> 1.6884701 | L28: 992 | M28: 1941 | N28: =M28-L28 -> 949 | O28: =M28/L28 -> 1.9566532
A29: ビール消費量（L） | B29: 441456 | D29: 334182 | E29: 340050 | F29: 574842 | L29: 318 | M29: 2503 | N29: =M29-L29 -> 2185 | O29: =M29/L29 -> 7.8710692
A30: 前年比 | B30: - | D30: 75.7 | E30: =E29/D29 -> 1.0175593 | F30: =F29/E29 -> 1.6904632 | L30: =SUM(L27:L29) -> 6497 | M30: =SUM(M27:M29) -> 11161 | N30: =SUM(N27:N29) -> 4664 | O30: =M30/L30 -> 1.7178698
A31: 20L樽本数 | B31: =B29/20 -> 22072.8 | D31: =D29/20 -> 16709.1 | E31: =E29/20 -> 17002.5 | F31: =F29/20 -> 28742.1 | J31: 2024 | K31: 期間 | L31: 売上 | M31: 値引き | N31: 税抜売上 | O31: 税込売上 | P31: 値引き | Q31: 税込売上合計
A32: 前年比 | D32: =D31/B31 -> 0.75699957 | E32: =E31/D31 -> 1.0175593 | F32: =F31/E31 -> 1.6904632 | J32: 4~5 | K32: ピコレ4/27-5/19 | L32: 2939522 | M32: 4040 | N32: =L32-M32 -> 2935482 | O32: 3232260 | P32: 4040 | Q32: =O32-P32 -> 3228220 | R32: 23
A33: ビール原価金額 | B33: =B31*9000 -> 198655200 | C33: 原価率想定 | D33: =D31*9000 -> 150381900 | E33: =E31*9700 -> 164924250 | F33: =F31*9000 -> 258678900 | J33: 5 | K33: ビアガ5/27-5/31 | L33: 477807 | M33: 3480 | N33: =L33-M33 -> 474327 | O33: 525570 | P33: 3480 | Q33: =O33-P33 -> 522090 | R33: 5
A34: ビール売上推定金額 | B34: =B33*3.5 -> 695293200 | C34: =B33/B34 -> 0.28571429 | D34: =D33*3.5 -> 526336650 | E34: =E33*3.5 -> 577234875 | F34: =F33*3.5 -> 905376150 | J34: 6 | K34: ビアガフル | L34: 19170665 | M34: 26790 | N34: =L34-M34 -> 19143875 | O34: 21087090 | P34: 26790 | Q34: =O34-P34 -> 21060300 | R34: 30
A35: ひとり当たりのビール購入額 | B35: =B34/B27 -> 594.26769 | C35: =C34/C27 -> #DIV/0! | D35: =D34/D27 -> 594.05942 | E35: =E34/E27 -> 639.94997 | F35: =F34/F27 -> 594.46891 | J35: 7 | K35: ビアガフル | L35: 47598067 | M35: 17800 | N35: =L35-M35 -> 47580267 | O35: 52356880 | P35: 17800 | Q35: =O35-P35 -> 52339080 | R35: 31
A36: 客単価想定 | B36: 1300 | D36: 1300 | E36: 1300 | F36: 1300 | J36: 8 | K36: ビアガフル | L36: 55870570 | M36: 5980 | N36: =L36-M36 -> 55864590 | O36: 61456496 | P36: 5980 | Q36: =O36-P36 -> 61450516 | R36: 31
A37: 推定売上額 | B37: =B27*B36 -> 1521000000 | D37: =D27*D36 -> 1151800000 | E37: =E27*E36 -> 1172600000 | F37: =F27*F36 -> 1979900000 | J37: 9 | K37: ビアガ9/1-9/8 | L37: 8816632 | M37: 5700 | N37: =L37-M37 -> 8810932 | O37: 9698100 | P37: 5700 | Q37: =O37-P37 -> 9692400 | R37: 8
J38: 9~10 | K38: ピコレ共催アキノジン | L38: 4982837 | M38: 1100 | N38: =L38-M38 -> 4981737 | O38: 5480760 | P38: 1100 | Q38: =O38-P38 -> 5479660 | R38: 23
K39: ビアガのみ105日 | L39: =L34+L33+L35+L36+L37 -> 131933741 | M39: =M34+M33+M35+M36+M37 -> 59750 | N39: =N34+N33+N35+N36+N37 -> 131873991 | O39: =O34+O33+O35+O36+O37 -> 145124136 | P39: =P34+P33+P35+P36+P37 -> 59750 | Q39: =Q34+Q33+Q35+Q36+Q37 -> 145064386 | R39: =R34+R33+R35+R36+R37 -> 105
K40: ピコレ&ピコレ共催 | L40: =L32+L38 -> 7922359 | M40: =M32+M38 -> 5140 | N40: =N32+N38 -> 7917219 | O40: =O32+O38 -> 8713020 | P40: =P32+P38 -> 5140 | Q40: =Q32+Q38 -> 8707880 | R40: =R32+R38 -> 46
K41: 総合計 | L41: =SUM(L32:L38) -> 139856100 | M41: =SUM(M32:M38) -> 64890 | N41: =SUM(N32:N38) -> 139791210 | O41: =SUM(O32:O38) -> 153837156 | P41: =SUM(P32:P38) -> 64890 | Q41: =SUM(Q32:Q38) -> 153772266 | R41: =SUM(R32:R38) -> 151
J43: 2023 | K43: 期間 | L43: 売上 | M43: 値引き | N43: 税抜売上 | O43: 税込売上 | P43: 値引き | Q43: 税込売上合計
...

Sheet 2024.10月実績
A1: ■R6年度 ピコレ＆ビアガーデン売上実績
A2: 10月 | L2: =L14+L24+L34+L44+L54+L64 -> 1599750 | R2: 10
A3: FOOD | C3: ビアガーデン10月 実績TOTAL | N3: 客数 | R3: 売上
A4: 予算 | C4: 実績 | E4: 客数 | G4: 客単価 | I4: 売上予算 | L4: 9275000 | M4: 1日平均 | R4: =L4/R2 -> 927500 | T4: 天候要因（売上との関連性を数値化する）
A5: 1st week | C5: 1st week | T5: =C5 -> 1st week
A6: 曜日 | B6: 日にち | C6: 曜日 | D6: 日にち | E6: 客数 | F6: 料理売上 | G6: 料理単価 | H6: 飲料売上 | I6: 飲料単価 | J6: テント利用料 | K6: 物販 | L6: 売上合計 | M6: 合計単価 | N6: サーフィンズ | O6: forking | P6: Timee | Q6: 合計 | R6: 人時売上高 | T6: 最低 | U6: 最高 | V6: 12時 | W6: 15時 | X6: 18時 | Y6: Ave | AA6: ■天候要因 | AC6: 評価点
A7: 日 | C7: 日 | D7: =B7 -> 0 | G7: =F7/E7 -> #DIV/0! | I7: =H7/E7 -> #DIV/0! | L7: =F7+H7+J7 -> 0 | M7: =L7/E7 -> #DIV/0! | R7: =L7/Q7 -> #DIV/0! | Y7: =SUM(V7:X7)/3 -> 0 | AA7: 晴れ（33度まで） | AC7: 5
A8: 月 | C8: 月 | D8: =B8 -> 0 | G8: =F8/E8 -> #DIV/0! | I8: =H8/E8 -> #DIV/0! | L8: =F8+H8+J8 -> 0 | M8: =L8/E8 -> #DIV/0! | R8: =L8/Q8 -> #DIV/0! | Y8: =SUM(V8:X8)/3 -> 0 | AA8: 晴れ（25度以下） | AC8: 4
A9: 火 | B9: 1 | C9: 火 | D9: =B9 -> 1 | E9: 66 | F9: 125600 | G9: =F9/E9 -> 1903.0303 | H9: 67050 | I9: =H9/E9 -> 1015.9091 | L9: =F9+H9+J9 -> 192650 | M9: =L9/E9 -> 2918.9394 | R9: =L9/Q9 -> #DIV/0! | T9: 15.1 | U9: 26.3 | V9: 5 | W9: 5 | X9: 4 | Y9: =SUM(V9:X9)/3 -> 4.6666667 | AA9: 晴れ（33度以上）曇25度以上 | AC9: 3
A10: 水 | B10: 2 | C10: 水 | D10: =B10 -> 2 | E10: 30 | F10: 78300 | G10: =F10/E10 -> 2610 | H10: 42700 | I10: =H10/E10 -> 1423.3333 | L10: =F10+H10+J10 -> 121000 | M10: =L10/E10 -> 4033.3333 | R10: =L10/Q10 -> #DIV/0! | T10: 18.2 | U10: 22 | V10: 2 | W10: 1 | X10: 2 | Y10: =SUM(V10:X10)/3 -> 1.6666667 | AA10: 曇 | AC10: 2
A11: 木 | B11: 3 | C11: 木 | D11: =B11 -> 3 | E11: 44 | F11: 72200 | G11: =F11/E11 -> 1640.9091 | H11: 44400 | I11: =H11/E11 -> 1009.0909 | L11: =F11+H11+J11 -> 116600 | M11: =L11/E11 -> 2650 | R11: =L11/Q11 -> #DIV/0! | T11: 12.1 | U11: 16.8 | V11: 2 | W11: 2 | X11: 2 | Y11: =SUM(V11:X11)/3 -> 2 | AA11: 雨 | AC11: 1
A12: 金 | B12: 4 | C12: 金 | D12: =B12 -> 4 | E12: 20 | F12: 38750 | G12: =F12/E12 -> 1937.5 | H12: 31350 | I12: =H12/E12 -> 1567.5 | L12: =F12+H12+J12 -> 70100 | M12: =L12/E12 -> 3505 | R12: =L12/Q12 -> #DIV/0! | T12: 12 | U12: 15.2 | V12: 2 | W12: 1 | X12: 1 | Y12: =SUM(V12:X12)/3 -> 1.3333333 | AA12: 豪雨・雷雨 | AC12: 0
A13: 土 | B13: 5 | C13: 土 | D13: =B13 -> 5 | E13: 181 | F13: 287100 | G13: =F13/E13 -> 1586.1878 | H13: 161100 | I13: =H13/E13 -> 890.05525 | J13: 0 | L13: =F13+H13+J13 -> 448200 | M13: =L13/E13 -> 2476.2431 | R13: =L13/Q13 -> #DIV/0! | T13: 14.1 | U13: 21.3 | V13: 4 | W13: 4 | X13: 4 | Y13: =SUM(V13:X13)/3 -> 4 | AA13: ※5.6月は18時は最低気温を採用。7月〜は最高気温を採用。
A14: SUB TOTAL | C14: SUB TOTAL | E14: =SUM(E7:E13) -> 341 | F14: =SUM(F7:F13) -> 601950 | G14: =F14/E14 -> 1765.2493 | H14: =SUM(H7:H13) -> 346600 | I14: =H14/E14 -> 1016.4223 | J14: =I14/F14 -> 0.0016885494 | L14: =F14+H14 -> 948550 | M14: =L14/E14 -> 2781.6716 | Q14: =SUM(Q7:Q13) -> 0 | R14: =L14/Q14 -> #DIV/0! | S14: 5 | T14: =SUM(T7:T13)/S14 -> 14.3 | U14: =SUM(U7:U13)/S14 -> 20.32 | V14: =SUM(V7:V13)/S14 -> 3 | W14: =SUM(W7:W13)/S14 -> 2.6 | X14: =SUM(X7:X13)/S14 -> 2.6 | Y14: =SUM(V14:X14)/3 -> 2.7333333 | Z14: 15 | AA14: =L14/S14 -> 189710 | AF14: ※1日平均売上
A15: 2nd week | C15: 2nd week | T15: =C15 -> 2nd week
A16: 曜日 | B16: 日にち | C16: 曜日 | D16: 日にち | E16: 客数 | F16: 料理売上 | G16: 料理単価 | H16: 飲料売上 | I16: 飲料単価 | J16: テント利用料 | K16: 物販 | L16: 売上合計 | M16: 合計単価 | N16: サーフィンズ | O16: forking | P16: Timee | Q16: 合計 | R16: 人時売上高 | T16: 最低 | U16: 最高 | V16: 12時 | W16: 15時 | X16: 18時 | Y16: Ave | AA16: ■天候要因 | AC16: 評価点
A17: 日 | B17: 6 | C17: 日 | D17: =B17 -> 6 | E17: 197 | F17: 409700 | G17: =F17/E17 -> 2079.6954 | H17: 241500 | I17: =H17/E17 -> 1225.8883 | L17: =F17+H17+J17 -> 651200 | M17: =L17/E17 -> 3305.5838 | R17: =L17/Q17 -> #DIV/0! | T17: 10.9 | U17: 22.5 | V17: 4 | W17: 2 | X17: 2 | Y17: =SUM(V17:X17)/3 -> 2.6666667 | AA17: 晴れ（33度まで） | AC17: 5
A18: 月 | C18: 月 | D18: =B18 -> 0 | G18: =F18/E18 -> #DIV/0! | I18: =H18/E18 -> #DIV/0! | L18: =F18+H18+J18 -> 0 | M18: =L18/E18 -> #DIV/0! | R18: =L18/Q18 -> #DIV/0! | Y18: =SUM(V18:X18)/3 -> 0 | AA18: 晴れ（25度以下） | AC18: 4
A19: 火 | C19: 火 | D19: =B19 -> 0 | G19: =F19/E19 -> #DIV/0! | I19: =H19/E19 -> #DIV/0! | L19: =F19+H19+J19 -> 0 | M19: =L19/E19 -> #DIV/0! | R19: =L19/Q19 -> #DIV/0! | Y19: =SUM(V19:X19)/3 -> 0 | AA19: 晴れ（33度以上）曇25度以上 | AC19: 3
A20: 水 | C20: 水 | D20: =B20 -> 0 | G20: =F20/E20 -> #DIV/0! | I20: =H20/E20 -> #DIV/0! | L20: =F20+H20+J20 -> 0 | M20: =L20/E20 -> #DIV/0! | R20: =L20/Q20 -> #DIV/0! | Y20: =SUM(V20:X20)/3 -> 0 | AA20: 曇 | AC20: 2
A21: 木 | C21: 木 | D21: =B21 -> 0 | G21: =F21/E21 -> #DIV/0! | I21: =H21/E21 -> #DIV/0! | L21: =F21+H21+J21 -> 0 | M21: =L21/E21 -> #DIV/0! | R21: =L21/Q21 -> #DIV/0! | Y21: =SUM(V21:X21)/3 -> 0 | AA21: 雨 | AC21: 1
A22: 金 | C22: 金 | D22: =B22 -> 0 | G22: =F22/E22 -> #DIV/0! | I22: =H22/E22 -> #DIV/0! | L22: =F22+H22+J22 -> 0 | M22: =L22/E22 -> #DIV/0! | R22: =L22/Q22 -> #DIV/0! | Y22: =SUM(V22:X22)/3 -> 0 | AA22: 豪雨・雷雨 | AC22: 0
A23: 土 | C23: 土 | D23: =B23 -> 0 | G23: =F23/E23 -> #DIV/0! | I23: =H23/E23 -> #DIV/0! | J23: 0 | L23: =F23+H23+J23 -> 0 | M23: =L23/E23 -> #DIV/0! | R23: =L23/Q23 -> #DIV/0! | Y23: =SUM(V23:X23)/3 -> 0 | AA23: ※5.6月は18時は最低気温を採用。7月〜は最高気温を採用。
A24: SUB TOTAL | C24: SUB TOTAL | E24: =SUM(E17:E23) -> 197 | F24: =SUM(F17:F23) -> 409700 | G24: =F24/E24 -> 2079.6954 | H24: =SUM(H17:H23) -> 241500 | I24: =H24/E24 -> 1225.8883 | J24: =I24/F24 -> 0.0029921609 | L24: =F24+H24 -> 651200 | M24: =L24/E24 -> 3305.5838 | Q24: =SUM(Q17:Q23) -> 0 | R24: =L24/Q24 -> #DIV/0! | S24: 1 | T24: =SUM(T17:T23)/S24 -> 10.9 | U24: =SUM(U17:U23)/S24 -> 22.5 | V24: =SUM(V17:V23)/S24 -> 4 | W24: =SUM(W17:W23)/S24 -> 2 | X24: =SUM(X17:X23)/S24 -> 2 | Y24: =SUM(V24:X24)/3 -> 2.6666667
A25: 3rd week | C25: 3rd week | T25: =C25 -> 3rd week
A26: 曜日 | B26: 日にち | C26: 曜日 | D26: 日にち | E26: 客数 | F26: 料理売上 | G26: 料理単価 | H26: 飲料売上 | I26: 飲料単価 | J26: テント利用料 | K26: 物販 | L26: 売上合計 | M26: 合計単価 | N26: サーフィンズ | O26: forking | P26: Timee | Q26: 合計 | R26: 人時売上高 | T26: 最低 | U26: 最高 | V26: 12時 | W26: 15時 | X26: 18時 | Y26: Ave | AA26: ■天候要因 | AC26: 評価点
A27: 日 | C27: 日 | D27: =B27 -> 0 | G27: =F27/E27 -> #DIV/0! | I27: =H27/E27 -> #DIV/0! | L27: =F27+H27+J27 -> 0 | M27: =L27/E27 -> #DIV/0! | R27: =L27/Q27 -> #DIV/0! | Y27: =SUM(V27:X27)/3 -> 0 | AA27: 晴れ（33度まで） | AC27: 5
A28: 月 | C28: 月 | D28: =B28 -> 0 | G28: =F28/E28 -> #DIV/0! | I28: =H28/E28 -> #DIV/0! | L28: =F28+H28+J28 -> 0 | M28: =L28/E28 -> #DIV/0! | R28: =L28/Q28 -> #DIV/0! | Y28: =SUM(V28:X28)/3 -> 0 | AA28: 晴れ（25度以下） | AC28: 4
A29: 火 | C29: 火 | D29: =B29 -> 0 | G29: =F29/E29 -> #DIV/0! | I29: =H29/E29 -> #DIV/0! | L29: =F29+H29+J29 -> 0 | M29: =L29/E29 -> #DIV/0! | R29: =L29/Q29 -> #DIV/0! | Y29: =SUM(V29:X29)/3 -> 0 | AA29: 晴れ（33度以上）曇25度以上 | AC29: 3
A30: 水 | C30: 水 | D30: =B30 -> 0 | G30: =F30/E30 -> #DIV/0! | I30: =H30/E30 -> #DIV/0! | L30: =F30+H30+J30 -> 0 | M30: =L30/E30 -> #DIV/0! | R30: =L30/Q30 -> #DIV/0! | Y30: =SUM(V30:X30)/3 -> 0 | AA30: 曇 | AC30: 2
A31: 木 | C31: 木 | D31: =B31 -> 0 | G31: =F31/E31 -> #DIV/0! | I31: =H31/E31 -> #DIV/0! | L31: =F31+H31+J31 -> 0 | M31: =L31/E31 -> #DIV/0! | R31: =L31/Q31 -> #DIV/0! | Y31: =SUM(V31:X31)/3 -> 0 | AA31: 雨 | AC31: 1
A32: 金 | C32: 金 | D32: =B32 -> 0 | G32: =F32/E32 -> #DIV/0! | I32: =H32/E32 -> #DIV/0! | L32: =F32+H32+J32 -> 0 | M32: =L32/E32 -> #DIV/0! | R32: =L32/Q32 -> #DIV/0! | Y32: =SUM(V32:X32)/3 -> 0 | AA32: 豪雨・雷雨 | AC32: 0
A33: 土 | C33: 土 | D33: =B33 -> 0 | G33: =F33/E33 -> #DIV/0! | I33: =H33/E33 -> #DIV/0! | J33: 0 | L33: =F33+H33+J33 -> 0 | M33: =L33/E33 -> #DIV/0! | R33: =L33/Q33 -> #DIV/0! | Y33: =SUM(V33:X33)/3 -> 0 | AA33: ※5.6月は18時は最低気温を採用。7月〜は最高気温を採用。
A34: SUB TOTAL | C34: SUB TOTAL | E34: =SUM(E27:E33) -> 0 | F34: =SUM(F27:F33) -> 0 | G34: =F34/E34 -> #DIV/0! | H34: =SUM(H27:H33) -> 0 | I34: =H34/E34 -> #DIV/0! | J34: =I34/F34 -> #DIV/0! | L34: =F34+H34 -> 0 | M34: =L34/E34 -> #DIV/0! | Q34: =SUM(Q27:Q33) -> 0 | R34: =L34/Q34 -> #DIV/0! | T34: =SUM(T27:T33)/S34 -> #DIV/0! | U34: =SUM(U27:U33)/S34 -> #DIV/0! | V34: =SUM(V27:V33)/S34 -> #DIV/0! | W34: =SUM(W27:W33)/S34 -> #DIV/0! | X34: =SUM(X27:X33)/S34 -> #DIV/0! | Y34: =SUM(V34:X34)/3 -> #DIV/0!
A35: 4th week | C35: 4th week | T35: =C35 -> 4th week
A36: 曜日 | B36: 日にち | C36: 曜日 | D36: 日にち | E36: 客数 | F36: 料理売上 | G36: 料理単価 | H36: 飲料売上 | I36: 飲料単価 | J36: テント利用料 | K36: 物販 | L36: 売上合計 | M36: 合計単価 | N36: サーフィンズ | O36: forking | P36: Timee | Q36: 合計 | R36: 人時売上高 | T36: 最低 | U36: 最高 | V36: 12時 | W36: 15時 | X36: 18時 | Y36: Ave | AA36: ■天候要因 | AC36: 評価点
A37: 日 | C37: 日 | D37: =B37 -> 0 | G37: =F37/E37 -> #DIV/0! | I37: =H37/E37 -> #DIV/0! | L37: =F37+H37+J37 -> 0 | M37: =L37/E37 -> #DIV/0! | R37: =L37/Q37 -> #DIV/0! | Y37: =SUM(V37:X37)/3 -> 0 | AA37: 晴れ（33度まで） | AC37: 5
A38: 月 | C38: 月 | D38: =B38 -> 0 | G38: =F38/E38 -> #DIV/0! | I38: =H38/E38 -> #DIV/0! | L38: =F38+H38+J38 -> 0 | M38: =L38/E38 -> #DIV/0! | R38: =L38/Q38 -> #DIV/0! | Y38: =SUM(V38:X38)/3 -> 0 | AA38: 晴れ（25度以下） | AC38: 4
A39: 火 | C39: 火 | D39: =B39 -> 0 | G39: =F39/E39 -> #DIV/0! | I39: =H39/E39 -> #DIV/0! | L39: =F39+H39+J39 -> 0 | M39: =L39/E39 -> #DIV/0! | R39: =L39/Q39 -> #DIV/0! | Y39: =SUM(V39:X39)/3 -> 0 | AA39: 晴れ（33度以上）曇25度以上 | AC39: 3
A40: 水 | C40: 水 | D40: =B40 -> 0 | G40: =F40/E40 -> #DIV/0! | I40: =H40/E40 -> #DIV/0! | L40: =F40+H40+J40 -> 0 | M40: =L40/E40 -> #DIV/0! | R40: =L40/Q40 -> #DIV/0! | Y40: =SUM(V40:X40)/3 -> 0 | AA40: 曇 | AC40: 2
...

Sheet 2024.9月実績
A1: ■R6年度 ピコレ＆ビアガーデン売上実績
A2: 9月 | L2: =L14+L24+L34+L44+L54+L64 -> #DIV/0! | R2: 10
A3: FOOD | C3: ビアガーデン9月 実績TOTAL | N3: 客数 | R3: 売上
A4: 予算 | C4: 実績 | E4: 客数 | G4: 客単価 | I4: 売上予算 | L4: 9275000 | M4: 1日平均 | R4: =L4/R2 -> 927500 | T4: 天候要因（売上との関連性を数値化する） | AH4: 天候要因（売上との関連性を数値化する）
A5: 1st week | C5: 1st week | T5: =C5 -> 1st week | AH5: =U5 -> 0
A6: 曜日 | B6: 日にち | C6: 曜日 | D6: 日にち | E6: 客数 | F6: 料理売上 | G6: 料理単価 | H6: 飲料売上 | I6: 飲料単価 | J6: テント利用料 | K6: 物販 | L6: 売上合計 | M6: 合計単価 | N6: サーフィンズ | O6: forking | P6: Timee | Q6: 合計 | R6: 人時売上高 | T6: 最低 | U6: 最高 | V6: 12時 | W6: 15時 | X6: 18時 | Y6: Ave | AA6: ■天候要因 | AC6: 評価点 | AH6: 最低 | AI6: 最高 | AJ6: 12時 | AK6: 15時 | AL6: 18時 | AM6: Ave | AO6: ■天候要因 | AQ6: 評価点
A7: 日 | B7: 1 | C7: 日 | D7: =B7 -> 1 | E7: 468 | F7: 1213450 | G7: =F7/E7 -> 2592.8419 | H7: 629350 | I7: =H7/E7 -> 1344.765 | J7: 10010 | L7: =F7+H7+J7+K7 -> 1852810 | M7: =L7/E7 -> 3958.9957 | R7: =L7/Q7 -> #DIV/0! | T7: 18.3 | U7: 29 | V7: 5 | W7: 5 | X7: 3 | Y7: =SUM(V7:X7)/3 -> 4.3333333 | AA7: 晴れ（33度まで） | AC7: 5 | AH7: 24.9 | AI7: 27 | AJ7: 3 | AK7: 1 | AL7: 1 | AM7: =SUM(AJ7:AL7)/3 -> 1.6666667 | AO7: 晴れ（33度まで） | AQ7: 5
A8: 月 | B8: 2 | C8: 月 | D8: =B8 -> 2 | E8: 92 | F8: 253250 | G8: =F8/E8 -> 2752.7174 | H8: 134900 | I8: =H8/E8 -> 1466.3043 | J8: 4400 | L8: =F8+H8+J8+K8 -> 392550 | M8: =L8/E8 -> 4266.8478 | R8: =L8/Q8 -> #DIV/0! | T8: 18.8 | U8: 27 | V8: 3 | W8: 3 | X8: 1 | Y8: =SUM(V8:X8)/3 -> 2.3333333 | AA8: 晴れ（25度以下） | AC8: 4 | AH8: 20.7 | AI8: 29.1 | AJ8: 5 | AK8: 1 | AL8: 5 | AM8: =SUM(AJ8:AL8)/3 -> 3.6666667 | AO8: 晴れ（25度以下） | AQ8: 4
A9: 火 | B9: 3 | C9: 火 | D9: =B9 -> 3 | E9: 194 | F9: 576050 | G9: =F9/E9 -> 2969.3299 | H9: 326000 | I9: =H9/E9 -> 1680.4124 | J9: 2310 | L9: =F9+H9+J9+K9 -> 904360 | M9: =L9/E9 -> 4661.6495 | R9: =L9/Q9 -> #DIV/0! | T9: 18.2 | U9: 27.8 | V9: 5 | W9: 5 | X9: 5 | Y9: =SUM(V9:X9)/3 -> 5 | AA9: 晴れ（33度以上）曇25度以上 | AC9: 3 | AH9: 18.6 | AI9: 29.8 | AJ9: 5 | AK9: 5 | AL9: 5 | AM9: =SUM(AJ9:AL9)/3 -> 5 | AO9: 晴れ（33度以上）曇25度以上 | AQ9: 3
A10: 水 | B10: 4 | C10: 水 | D10: =B10 -> 4 | E10: 269 | F10: 809510 | G10: =F10/E10 -> 3009.3309 | H10: 441600 | I10: =H10/E10 -> 1641.6357 | J10: 19250 | K10: 2970 | L10: =F10+H10+J10+K10 -> 1273330 | M10: =L10/E10 -> 4733.5688 | R10: =L10/Q10 -> #DIV/0! | T10: 16.8 | U10: 28.6 | V10: 5 | W10: 5 | X10: 5 | Y10: =SUM(V10:X10)/3 -> 5 | AA10: 曇 | AC10: 2 | AM10: =SUM(AJ10:AL10)/3 -> 0 | AO10: 曇 | AQ10: 2
A11: 木 | B11: 5 | C11: 木 | D11: =B11 -> 5 | E11: 186 | F11: 488650 | G11: =F11/E11 -> 2627.1505 | H11: 291050 | I11: =H11/E11 -> 1564.7849 | J11: 10450 | L11: =F11+H11+J11+K11 -> 790150 | M11: =L11/E11 -> 4248.1183 | R11: =L11/Q11 -> #DIV/0! | T11: 20.4 | U11: 27.6 | V11: 3 | W11: 3 | X11: 3 | Y11: =SUM(V11:X11)/3 -> 3 | AA11: 雨 | AC11: 1 | AM11: =SUM(AJ11:AL11)/3 -> 0 | AO11: 雨 | AQ11: 1
A12: 金 | B12: 6 | C12: 金 | D12: =B12 -> 6 | E12: 325 | F12: 781000 | G12: =F12/E12 -> 2403.0769 | H12: 432250 | I12: =H12/E12 -> 1330 | J12: 6380 | L12: =F12+H12+J12+K12 -> 1219630 | M12: =L12/E12 -> 3752.7077 | R12: =L12/Q12 -> #DIV/0! | T12: 19.6 | U12: 25.9 | V12: 5 | W12: 5 | X12: 3 | Y12: =SUM(V12:X12)/3 -> 4.3333333 | AA12: 豪雨・雷雨 | AC12: 0 | AM12: =SUM(AJ12:AL12)/3 -> 0 | AO12: 豪雨・雷雨 | AQ12: 0
A13: 土 | B13: 7 | C13: 土 | D13: =B13 -> 7 | E13: 452 | F13: 1366800 | G13: =F13/E13 -> 3023.8938 | H13: 704550 | I13: =H13/E13 -> 1558.7389 | J13: 40920 | L13: =F13+H13+J13+K13 -> 2112270 | M13: =L13/E13 -> 4673.1637 | R13: =L13/Q13 -> #DIV/0! | T13: 15.8 | U13: 26.7 | V13: 5 | W13: 5 | X13: 3 | Y13: =SUM(V13:X13)/3 -> 4.3333333 | AA13: ※5.6月は18時は最低気温を採用。7月〜は最高気温を採用。 | AM13: =SUM(AJ13:AL13)/3 -> 0 | AO13: ※5.6月は18時は最低気温を採用。7月〜は最高気温を採用。
A14: SUB TOTAL | C14: SUB TOTAL | E14: =SUM(E7:E13) -> 1986 | F14: =SUM(F7:F13) -> 5488710 | G14: =F14/E14 -> 2763.7009 | H14: =SUM(H7:H13) -> 2959700 | I14: =H14/E14 -> 1490.282 | J14: =SUM(J7:J13) -> 93720 | K14: =SUM(K7:K13) -> 2970 | L14: =F14+H14+J14+K14 -> 8545100 | M14: =L14/E14 -> 4302.6687 | Q14: =SUM(Q7:Q13) -> 0 | R14: =L14/Q14 -> #DIV/0! | S14: 7 | T14: =SUM(T7:T13)/S14 -> 18.271429 | U14: =SUM(U7:U13)/S14 -> 27.514286 | V14: =SUM(V7:V13)/S14 -> 4.4285714 | W14: =SUM(W7:W13)/S14 -> 4.4285714 | X14: =SUM(X7:X13)/S14 -> 3.2857143 | Y14: =SUM(V14:X14)/3 -> 4.047619 | Z14: 15 | AA14: =L14/S14 -> 1220728.6 | AF14: ※1日平均売上 | AG14: 3 | AH14: =SUM(AH7:AH13)/AG14 -> 21.4 | AI14: =SUM(AI7:AI13)/AG14 -> 28.633333 | AJ14: =SUM(AJ7:AJ13)/AG14 -> 4.3333333 | AK14: =SUM(AK7:AK13)/AG14 -> 2.3333333 | AL14: =SUM(AL7:AL13)/AG14 -> 3.6666667 | AM14: =SUM(AJ14:AL14)/3 -> 3.4444444 | AN14: 15 | AO14: 1462533
A15: 2nd week | C15: 2nd week | T15: =C15 -> 2nd week | AH15: =U15 -> 0
A16: 曜日 | B16: 日にち | C16: 曜日 | D16: 日にち | E16: 客数 | F16: 料理売上 | G16: 料理単価 | H16: 飲料売上 | I16: 飲料単価 | J16: テント利用料 | K16: 物販 | L16: 売上合計 | M16: 合計単価 | N16: サーフィンズ | O16: forking | P16: Timee | Q16: 合計 | R16: 人時売上高 | T16: 最低 | U16: 最高 | V16: 12時 | W16: 15時 | X16: 18時 | Y16: Ave | AA16: ■天候要因 | AC16: 評価点 | AH16: 最低 | AI16: 最高 | AJ16: 12時 | AK16: 15時 | AL16: 18時 | AM16: Ave | AO16: ■天候要因 | AQ16: 評価点
A17: 日 | B17: 8 | C17: 日 | D17: =B17 -> 8 | E17: 279 | F17: 722650 | G17: =F17/E17 -> 2590.1434 | H17: 419000 | I17: =H17/E17 -> 1501.7921 | J17: 17050 | L17: =F17+H17+J17+K17 -> 1158700 | M17: =L17/E17 -> 4153.0466 | R17: =L17/Q17 -> #DIV/0! | T17: 17.2 | U17: 31.5 | V17: 5 | W17: 5 | X17: 5 | Y17: =SUM(V17:X17)/3 -> 5 | AA17: 晴れ（33度まで） | AC17: 5 | AM17: =SUM(AJ17:AL17)/3 -> 0 | AO17: 晴れ（33度まで） | AQ17: 5
A18: 月 | B18: 9 | C18: 月 | D18: =B18 -> 9 | G18: =F18/E18 -> #DIV/0! | I18: =H18/E18 -> #DIV/0! | L18: =F18+H18+J18+K18 -> 0 | M18: =L18/E18 -> #DIV/0! | R18: =L18/Q18 -> #DIV/0! | Y18: =SUM(V18:X18)/3 -> 0 | AA18: 晴れ（25度以下） | AC18: 4 | AM18: =SUM(AJ18:AL18)/3 -> 0 | AO18: 晴れ（25度以下） | AQ18: 4
A19: 火 | B19: 10 | C19: 火 | D19: =B19 -> 10 | G19: =F19/E19 -> #DIV/0! | I19: =H19/E19 -> #DIV/0! | L19: =F19+H19+J19+K19 -> 0 | M19: =L19/E19 -> #DIV/0! | R19: =L19/Q19 -> #DIV/0! | Y19: =SUM(V19:X19)/3 -> 0 | AA19: 晴れ（33度以上）曇25度以上 | AC19: 3 | AM19: =SUM(AJ19:AL19)/3 -> 0 | AO19: 晴れ（33度以上）曇25度以上 | AQ19: 3
A20: 水 | B20: 11 | C20: 水 | D20: =B20 -> 11 | G20: =F20/E20 -> #DIV/0! | I20: =H20/E20 -> #DIV/0! | L20: =F20+H20+J20+K20 -> 0 | M20: =L20/E20 -> #DIV/0! | R20: =L20/Q20 -> #DIV/0! | Y20: =SUM(V20:X20)/3 -> 0 | AA20: 曇 | AC20: 2 | AM20: =SUM(AJ20:AL20)/3 -> 0 | AO20: 曇 | AQ20: 2
